Workbook

Sheet AC_IFSTTAR
A2: Absorption Capacity of stinox after 2h of soaking
A4: Time (m) | B4: MSSD (g) | C4: MOD (g) | D4: AC (%)
A5: 3 | B5: 124 | C5: 121.5 | D5: =(B5-C5)*100/C5 -> 2.0576132
A6: 30 | B6: 127.55 | C6: 124.9 | D6: =(B6-C6)*100/C6 -> 2.1216974
A7: 60 | B7: 97.9 | C7: 95.6 | D7: =(B7-C7)*100/C7 -> 2.4058577
A8: 90 | B8: 124.25 | C8: 120.9 | D8: =(B8-C8)*100/C8 -> 2.770885
A9: 120 | B9: 111.1 | C9: 107.6 | D9: =(B9-C9)*100/C9 -> 3.2527881 | E9: =AVERAGE(D9:D10) -> 3.0760982 | F9: AC %
A10: 120 | B10: 121.73 | C10: 118.3 | D10: =(B10-C10)*100/C10 -> 2.8994083
B12: Time | C12: Total time of soaking, in minutes
B13: MSSD ; | C13: Saturated surface dry mass of Stinox
B14: MOD; | C14: Oven-dry mass of stinox
B15: AC; | C15: Absorption capacity, calculated according to EN standard

Sheet Mix Design&Proportioning
I2: From Orbix, WA = | K2: 0.007
I6: WA from standard cone method = | L6: 0.044
I7: WA from IFSTTAR method = | L7: 0.051
K9: WA = | L9: =(L7+L6)/2 -> 0.0475
C11: mix | D11: a/b ratio | E11: w/b ratio | F11: Carbinox (g) | G11: Stinox (g) | H11: Water (g) | I11: Corrected Water (g) | J11: Addiitonal water
C12: M-1.0_0.25 | D12: 1 | E12: 0.25 | F12: =0.5*800 -> 400 | G12: =0.5*800 -> 400 | H12: =0.25*F12 -> 100 | I12: =H12+$K$2*G12 -> 102.8 | J12: =I12-H12 -> 2.8
C13: M-1.0_0.30 | D13: 1 | E13: 0.3 | F13: =0.5*800 -> 400 | G13: =0.5*800 -> 400 | H13: =0.3*F13 -> 120 | I13: =H13+$K$2*G13 -> 122.8 | J13: =I13-H13 -> 2.8
C14: M-1.0_0.35 | D14: 1 | E14: 0.35 | F14: =0.5*800 -> 400 | G14: =0.5*800 -> 400 | H14: =0.35*F14 -> 140 | I14: =H14+$K$2*G14 -> 142.8 | J14: =I14-H14 -> 2.8
C15: M-1.5_0.25 | D15: 1.5 | E15: 0.25 | F15: =(1/2.5)*800 -> 320 | G15: =(1.5/2.5)*800 -> 480 | H15: =0.25*F15 -> 80 | I15: =H15+$K$2*G15 -> 83.36 | J15: =I15-H15 -> 3.36
C16: M-1.5_0.30 | D16: 1.5 | E16: 0.3 | F16: =(1/2.5)*800 -> 320 | G16: =(1.5/2.5)*800 -> 480 | H16: =0.3*F16 -> 96 | I16: =H16+$K$2*G16 -> 99.36 | J16: =I16-H16 -> 3.36
C17: M-1.5_0.35 | D17: 1.5 | E17: 0.35 | F17: =(1/2.5)*800 -> 320 | G17: =(1.5/2.5)*800 -> 480 | H17: =0.35*F17 -> 112 | I17: =H17+$K$2*G17 -> 115.36 | J17: =I17-H17 -> 3.36 | V17: Apparent particle density
C18: M-2.5_0.25 | D18: 2 | E18: 0.25 | F18: =(1/3)*800 -> 266.66667 | G18: =(2/3)*800 -> 533.33333 | H18: =0.25*F18 -> 66.666667 | I18: =H18+$K$2*G18 -> 70.4 | J18: =I18-H18 -> 3.7333333 | V18: Cx = | W18: 2527.1
C19: M-2.5_0.30 | D19: 2 | E19: 0.3 | F19: =(1/3)*800 -> 266.66667 | G19: =(2/3)*800 -> 533.33333 | H19: =0.3*F19 -> 80 | I19: =H19+$K$2*G19 -> 83.733333 | J19: =I19-H19 -> 3.7333333 | V19: Sx = | W19: 1774.51
C20: M-2.5_0.35 | D20: 2 | E20: 0.35 | F20: =(1/3)*800 -> 266.66667 | G20: =(2/3)*800 -> 533.33333 | H20: =0.35*F20 -> 93.333333 | I20: =H20+$K$2*G20 -> 97.066667 | J20: =I20-H20 -> 3.7333333
C24: mix | D24: a/b ratio | E24: w/b ratio | F24: Carbinox (g) | G24: Stinox (g) | H24: Water (g) | I24: Corrected Water (g) | J24: Addiitonal water (g) | M24: mix | N24: a/b ratio | O24: w/b ratio | P24: Carbinox (g) | Q24: Stinox (g) | R24: Water (g) | S24: Corrected Water (g) | T24: Addiitonal water (g)
C25: TM-1.0_0.25 | D25: 1 | E25: 0.25 | F25: =0.5*800 -> 400 | G25: =0.5*800 -> 400 | H25: =0.25*F25 -> 100 | I25: =H25+0.031*G25 -> 112.4 | J25: =I25-H25 -> 12.4 | M25: TM-0.5_0.25 | N25: 0.5 | O25: 0.25 | P25: =(1/1.5)*800 -> 533.33333 | Q25: =(0.5/1.5)*800 -> 266.66667 | R25: =0.25*P25 -> 133.33333 | S25: =R25+0.031*Q25 -> 141.6 | T25: =S25-R25 -> 8.2666667
C26: TM-1.0_0.30 | D26: 1 | E26: 0.3 | F26: =0.5*800 -> 400 | G26: =0.5*800 -> 400 | H26: =0.3*F26 -> 120 | I26: =H26+0.031*G26 -> 132.4 | J26: =I26-H26 -> 12.4 | M26: TM-0.5_0.30 | N26: 0.5 | O26: 0.3 | P26: =(1/1.5)*800 -> 533.33333 | Q26: =(0.5/1.5)*800 -> 266.66667 | R26: =0.3*P26 -> 160 | S26: =R26+0.031*Q26 -> 168.26667 | T26: =S26-R26 -> 8.2666667
C27: TM-1.0_0.35 | D27: 1 | E27: 0.35 | F27: =0.5*800 -> 400 | G27: =0.5*800 -> 400 | H27: =0.35*F27 -> 140 | I27: =H27+0.031*G27 -> 152.4 | J27: =I27-H27 -> 12.4 | M27: TM-0.5_0.35 | N27: 0.5 | O27: 0.35 | P27: =(1/1.5)*800 -> 533.33333 | Q27: =(0.5/1.5)*800 -> 266.66667 | R27: =0.35*P27 -> 186.66667 | S27: =R27+0.031*Q27 -> 194.93333 | T27: =S27-R27 -> 8.2666667
C28: TM-1.5_0.25 | D28: 1.5 | E28: 0.25 | F28: =(1/2.5)*800 -> 320 | G28: =(1.5/2.5)*800 -> 480 | H28: =0.25*F28 -> 80 | I28: =H28+0.031*G28 -> 94.88 | J28: =I28-H28 -> 14.88 | M28: TM-0.7_0.25 | N28: 0.7 | O28: 0.25 | P28: =(1/1.7)*800 -> 470.58824 | Q28: =(0.7/1.7)*800 -> 329.41176 | R28: =0.25*P28 -> 117.64706 | S28: =R28+0.031*Q28 -> 127.85882 | T28: =S28-R28 -> 10.211765
C29: TM-1.5_0.30 | D29: 1.5 | E29: 0.3 | F29: =(1/2.5)*800 -> 320 | G29: =(1.5/2.5)*800 -> 480 | H29: =0.3*F29 -> 96 | I29: =H29+0.031*G29 -> 110.88 | J29: =I29-H29 -> 14.88 | M29: TM-0.7_0.30 | N29: 0.7 | O29: 0.3 | P29: =(1/1.7)*800 -> 470.58824 | Q29: =(0.7/1.7)*800 -> 329.41176 | R29: =0.3*P29 -> 141.17647 | S29: =R29+0.031*Q29 -> 151.38824 | T29: =S29-R29 -> 10.211765
C30: TM-1.5_0.35 | D30: 1.5 | E30: 0.35 | F30: =(1/2.5)*800 -> 320 | G30: =(1.5/2.5)*800 -> 480 | H30: =0.35*F30 -> 112 | I30: =H30+0.031*G30 -> 126.88 | J30: =I30-H30 -> 14.88 | M30: TM-0.7_0.35 | N30: 0.7 | O30: 0.35 | P30: =(1/1.7)*800 -> 470.58824 | Q30: =(0.7/1.7)*800 -> 329.41176 | R30: =0.35*P30 -> 164.70588 | S30: =R30+0.031*Q30 -> 174.91765 | T30: =S30-R30 -> 10.211765
C31: TM-2.0_0.25 | D31: 2 | E31: 0.25 | F31: =(1/3)*800 -> 266.66667 | G31: =(2/3)*800 -> 533.33333 | H31: =0.25*F31 -> 66.666667 | I31: =H31+0.031*G31 -> 83.2 | J31: =I31-H31 -> 16.533333 | M31: TM-1.0_0.25 | N31: 2 | O31: 0.25 | P31: =(1/2)*800 -> 400 | Q31: =(1/2)*800 -> 400 | R31: =0.25*P31 -> 100 | S31: =R31+0.031*Q31 -> 112.4 | T31: =S31-R31 -> 12.4
C32: TM-2.0_0.30 | D32: 2 | E32: 0.3 | F32: =(1/3)*800 -> 266.66667 | G32: =(2/3)*800 -> 533.33333 | H32: =0.3*F32 -> 80 | I32: =H32+0.031*G32 -> 96.533333 | J32: =I32-H32 -> 16.533333 | M32: TM-1.0_0.30 | N32: 2 | O32: 0.3 | P32: =(1/2)*800 -> 400 | Q32: =(1/2)*800 -> 400 | R32: =0.3*P32 -> 120 | S32: =R32+0.031*Q32 -> 132.4 | T32: =S32-R32 -> 12.4
C33: TM-2.0_0.35 | D33: 2 | E33: 0.35 | F33: =(1/3)*800 -> 266.66667 | G33: =(2/3)*800 -> 533.33333 | H33: =0.35*F33 -> 93.333333 | I33: =H33+0.031*G33 -> 109.86667 | J33: =I33-H33 -> 16.533333 | M33: TM-1.0_0.35 | N33: 2 | O33: 0.35 | P33: =(1/2)*800 -> 400 | Q33: =(1/2)*800 -> 400 | R33: =0.35*P33 -> 140 | S33: =R33+0.031*Q33 -> 152.4 | T33: =S33-R33 -> 12.4
AF36: =1.379/1060 -> 0.0013009434
M38: mix | N38: a/b ratio | O38: w/b ratio | P38: Carbinox (g) | Q38: Stinox (g) | R38: Water (g) | S38: Corrected Water (g) | T38: SP (g) | U38: VMA (g) | V38: D1(mm) | W38: D2(mm) | X38: DAvg
M39: TM-0.5_0.25 | N39: 0.5 | O39: 0.25 | P39: =(1/1.5)*2068 -> 1378.6667 | Q39: =(0.5/1.5)*2068 -> 689.33333 | R39: =0.25*P39 -> 344.66667 | S39: =R39+0.031*Q39 -> 366.036 | T39: =(0.008*P39) -> 11.029333 | U39: =0.00056*P39 -> 0.77205333 | V39: 165 | W39: 165 | X39: =(V39+W39)/2 -> 165 | Y39: =100*T39/P39 -> 0.8 | Z39: =100*U39/P39 -> 0.056 | AA39: 1 | AC39: =100*AA39/P39 -> 0.072533849
M40: TM-0.5_0.30 | N40: 0.5 | O40: 0.3 | P40: =(1/1.5)*2068 -> 1378.6667 | Q40: =(0.5/1.5)*2068 -> 689.33333 | R40: =0.3*P40 -> 413.6 | S40: =R40+0.031*Q40 -> 434.96933 | T40: =(0.0025*P40) -> 3.4466667 | U40: =0.00056*P40 -> 0.77205333 | V40: 155 | W40: 160 | X40: =(V40+W40)/2 -> 157.5 | Y40: =100*T40/P40 -> 0.25 | Z40: =100*U40/P40 -> 0.056
M41: TM-0.5_0.35 | N41: 0.5 | O41: 0.35 | P41: =(1/1.5)*2068 -> 1378.6667 | Q41: =(0.5/1.5)*2068 -> 689.33333 | R41: =0.35*P41 -> 482.53333 | S41: =R41+0.031*Q41 -> 503.90267 | T41: =(0*P41) -> 0 | U41: =0.00075*P41 -> 1.034 | V41: 170 | W41: 165 | X41: =(V41+W41)/2 -> 167.5 | Y41: =100*T41/P41 -> 0 | Z41: =100*U41/P41 -> 0.075
M42: TM-0.7_0.25 | N42: 0.7 | O42: 0.25 | P42: =(1/1.7)*2068 -> 1216.4706 | Q42: =(0.7/1.7)*2068 -> 851.52941 | R42: =0.25*P42 -> 304.11765 | S42: =R42+0.031*Q42 -> 330.51506 | T42: =(0.01*P42) -> 12.164706 | U42: =0.0008*P42 -> 0.97317647 | V42: 155 | W42: 150 | X42: =(V42+W42)/2 -> 152.5 | Y42: =100*T42/P42 -> 1 | Z42: =100*U42/P42 -> 0.08
M43: TM-0.7_0.30 | N43: 0.7 | O43: 0.3 | P43: =(1/1.7)*2068 -> 1216.4706 | Q43: =(0.7/1.7)*2068 -> 851.52941 | R43: =0.3*P43 -> 364.94118 | S43: =R43+0.031*Q43 -> 391.33859 | T43: =(0.005*P43) -> 6.0823529 | U43: =0.0008*P43 -> 0.97317647 | V43: 165 | W43: 160 | X43: =(V43+W43)/2 -> 162.5 | Y43: =100*T43/P43 -> 0.5 | Z43: =100*U43/P43 -> 0.08
M44: TM-0.7_0.35 | N44: 0.7 | O44: 0.35 | P44: =(1/1.7)*2068 -> 1216.4706 | Q44: =(0.7/1.7)*2068 -> 851.52941 | R44: =0.35*P44 -> 425.76471 | S44: =R44+0.031*Q44 -> 452.16212 | T44: =(0*P44) -> 0 | U44: =0.00045*P44 -> 0.54741176 | V44: 155 | W44: 155 | X44: =(V44+W44)/2 -> 155 | Y44: =100*T44/P44 -> 0 | Z44: =100*U44/P44 -> 0.045
M45: TM-1.0_0.25 | N45: 2 | O45: 0.25 | P45: =(1/2)*2068 -> 1034 | Q45: =(1/2)*2068 -> 1034 | R45: =0.25*P45 -> 258.5 | S45: =R45+0.031*Q45 -> 290.554 | T45: 18.1 | U45: 0.93 | Y45: =100*T45/P45 -> 1.7504836 | Z45: =100*U45/P45 -> 0.089941973
M46: TM-1.0_0.30 | N46: 2 | O46: 0.3 | P46: =(1/2)*2068 -> 1034 | Q46: =(1/2)*2068 -> 1034 | R46: =0.3*P46 -> 310.2 | S46: =R46+0.031*Q46 -> 342.254 | T46: =(0.01*P46) -> 10.34 | U46: =0.0009*P46 -> 0.9306 | V46: 150 | W46: 155 | X46: =(V46+W46)/2 -> 152.5 | Y46: =100*T46/P46 -> 1 | Z46: =100*U46/P46 -> 0.09
M47: TM-1.0_0.35 | N47: 2 | O47: 0.35 | P47: =(1/2)*2068 -> 1034 | Q47: =(1/2)*2068 -> 1034 | R47: =0.35*P47 -> 361.9 | S47: =R47+0.031*Q47 -> 393.954 | T47: =(0.005*P47) -> 5.17 | U47: =0.0009*P47 -> 0.9306 | V47: 160 | W47: 160 | X47: =(V47+W47)/2 -> 160 | Y47: =100*T47/P47 -> 0.5 | Z47: =100*U47/P47 -> 0.09
M51: TM-0.5_0.25 | N51: 0.5 | O51: 0.25 | P51: =P39*0.6 -> 827.2 | Q51: =Q39*0.6 -> 413.6 | R51: =0.25*P51 -> 206.8 | S51: =R51+0.031*Q51 -> 219.6216 | T51: =(0.008*P51) -> 6.6176 | U51: =0.00056*P51 -> 0.463232 | V51: 165 | W51: 165 | X51: =(V51+W51)/2 -> 165
AB54: Volume computation | AH54: Mass Per m3 of concrete
AA55: mix | AB55: a/b ratio | AC55: w/b ratio | AD55: Carbinox (m3) | AE55: Stinox (m3) | AF55: Water (m3) | AG55: Volume part in 1m3 | AH55: Carbinox (kg) | AI55: Stinox (kg) | AJ55: Total Water, WT (kg) | AK55: SP (kg) | AL55: VMA (kg) | AM55: Density (kg/m3) | AO55: SP (% Cx) | AP55: VMA (% Cx)
AA56: M-0.5_0.25 | AB56: 0.5 | AC56: 0.25 | AD56: =P39/(1000*$W$18) -> 0.00054555287 | AE56: =Q39/(1000*$W$19) -> 0.00038846405 | AF56: =S39/(1000*1000) -> 0.000366036 | AG56: =1/SUM(AD56:AF56) -> 769.19946 | AH56: =AG56*P39/1000 -> 1060.4697 | AI56: =AG56*Q39/1000 -> 530.23483 | AJ56: =AG56*S39/1000 -> 281.55469 | AK56: =Y39*AH56/100 -> 8.4837572 | AL56: =Z39*AH56/100 -> 0.59386301 | AM56: =SUM(AH56:AL56) -> 1881.3368 | AO56: =AK56*100/AH56 -> 0.8 | AP56: =AL56*100/AH56 -> 0.056
AA57: M-0.5_0.30 | AB57: 0.5 | AC57: 0.3 | AD57: =P40/(1000*$W$18) -> 0.00054555287 | AE57: =Q40/(1000*$W$19) -> 0.00038846405 | AF57: =S40/(1000*1000) -> 0.00043496933 | AG57: =1/SUM(AD57:AF57) -> 730.46753 | AH57: =AG57*P40/1000 -> 1007.0712 | AI57: =AG57*Q40/1000 -> 503.53561 | AJ57: =AG57*S40/1000 -> 317.73097 | AK57: =Y40*AH57/100 -> 2.5176781 | AL57: =Z40*AH57/100 -> 0.56395989 | AM57: =SUM(AH57:AL57) -> 1831.4195 | AO57: =AK57*100/AH57 -> 0.25 | AP57: =AL57*100/AH57 -> 0.056
...

Sheet Strength_3%CO2_full prog.
D2: Sample Dimensions
B3: Mix | C3: Sample | D3: W1 (mm) | E3: W2 (mm) | F3: W3 (mm) | G3: H1 (mm) | H3: H2 (mm) | I3: H3 (mm) | J3: W (mm) | K3: H (mm)
B4: M-0.5_0.25 | C4: 1 | D4: 39.5 | E4: 41 | F4: 41.3 | G4: 40.1 | H4: 39.93 | I4: 39.85 | J4: =AVERAGE(D4:I4) -> 40.28 | K4: =AVERAGE(G4:I4) -> 39.96
C5: 2 | D5: 37 | E5: 36.45 | F5: 35.5 | G5: 39.46 | H5: 39.51 | I5: 39.46 | J5: =AVERAGE(D5:I5) -> 37.896667 | K5: =AVERAGE(G5:I5) -> 39.476667
C6: 3 | D6: 40.5 | E6: 40.94 | F6: 41.15 | G6: 39.7 | H6: 39.87 | I6: 39.9 | J6: =AVERAGE(D6:I6) -> 40.343333 | K6: =AVERAGE(G6:I6) -> 39.823333
C7: 4 | D7: 37.2 | E7: 37.85 | F7: 39.46 | G7: 39.73 | H7: 39.04 | I7: 39.12 | J7: =AVERAGE(D7:I7) -> 38.733333 | K7: =AVERAGE(G7:I7) -> 39.296667
B8: M-0.5_0.3 | C8: 1 | D8: 37.25 | E8: 36.06 | F8: 34.26 | G8: 39.4 | H8: 39.44 | I8: 39.57 | J8: =AVERAGE(D8:I8) -> 37.663333 | K8: =AVERAGE(G8:I8) -> 39.47
C9: 2 | D9: 34.5 | E9: 34.24 | F9: 36.84 | G9: 39.28 | H9: 39.26 | I9: 38.96 | J9: =AVERAGE(D9:I9) -> 37.18 | K9: =AVERAGE(G9:I9) -> 39.166667
C10: 3 | D10: 34.96 | E10: 34.26 | F10: 35.26 | G10: 39.38 | H10: 39.65 | I10: 39.94 | J10: =AVERAGE(D10:I10) -> 37.241667 | K10: =AVERAGE(G10:I10) -> 39.656667
C11: 4 | D11: 36.1 | E11: 35.12 | F11: 35.36 | G11: 39.07 | H11: 39.13 | I11: 39.26 | J11: =AVERAGE(D11:I11) -> 37.34 | K11: =AVERAGE(G11:I11) -> 39.153333
B12: M-0.5_0.35 | C12: 1 | D12: 30.55 | E12: 32.38 | F12: 30.63 | G12: 39.25 | H12: 39.49 | I12: 39.51 | J12: =AVERAGE(D12:I12) -> 35.301667 | K12: =AVERAGE(G12:I12) -> 39.416667
C13: 2 | D13: 34.89 | E13: 35.43 | F13: 35.96 | G13: 39.57 | H13: 39.49 | I13: 39.52 | J13: =AVERAGE(D13:I13) -> 37.476667 | K13: =AVERAGE(G13:I13) -> 39.526667
C14: 3 | D14: 34.77 | E14: 36.3 | F14: 39.05 | G14: 39.3 | H14: 39.7 | I14: 39.42 | J14: =AVERAGE(D14:I14) -> 38.09 | K14: =AVERAGE(G14:I14) -> 39.473333
C15: 4 | D15: 36.8 | E15: 37.79 | F15: 37.07 | G15: 39.16 | H15: 39.35 | I15: 39.4 | J15: =AVERAGE(D15:I15) -> 38.261667 | K15: =AVERAGE(G15:I15) -> 39.303333
B16: M-0.7_0.25 | C16: 1 | D16: 37.67 | E16: 37.32 | F16: 40.28 | G16: 40.29 | H16: 39.83 | I16: 39.73 | J16: =AVERAGE(D16:I16) -> 39.186667 | K16: =AVERAGE(G16:I16) -> 39.95
C17: 2 | D17: 39.21 | E17: 39.81 | F17: 40.15 | G17: 40.77 | H17: 40.51 | I17: 40.45 | J17: =AVERAGE(D17:I17) -> 40.15 | K17: =AVERAGE(G17:I17) -> 40.576667
C18: 3 | D18: 35.7 | E18: 36.31 | F18: 37.35 | G18: 39.83 | H18: 40.36 | I18: 40.31 | J18: =AVERAGE(D18:I18) -> 38.31 | K18: =AVERAGE(G18:I18) -> 40.166667
C19: 4 | D19: 36.47 | E19: 35.51 | F19: 37.45 | G19: 39.06 | H19: 39.53 | I19: 39.53 | J19: =AVERAGE(D19:I19) -> 37.925 | K19: =AVERAGE(G19:I19) -> 39.373333
B20: M-0.7_0.3 | C20: 1 | D20: 38.29 | E20: 38.7 | F20: 34.65 | G20: 39.85 | H20: 39.71 | I20: 40.02 | J20: =AVERAGE(D20:I20) -> 38.536667 | K20: =AVERAGE(G20:I20) -> 39.86
C21: 2 | D21: 38.85 | E21: 38.36 | F21: 37.03 | G21: 38.37 | H21: 38.41 | I21: 38.41 | J21: =AVERAGE(D21:I21) -> 38.238333 | K21: =AVERAGE(G21:I21) -> 38.396667
C22: 3 | D22: 33.98 | E22: 35.45 | F22: 37.08 | G22: 39.21 | H22: 39.05 | I22: 38.86 | J22: =AVERAGE(D22:I22) -> 37.271667 | K22: =AVERAGE(G22:I22) -> 39.04
C23: 4 | D23: 34.39 | E23: 35.02 | F23: 33.48 | G23: 38.48 | H23: 39.35 | I23: 39.44 | J23: =AVERAGE(D23:I23) -> 36.693333 | K23: =AVERAGE(G23:I23) -> 39.09
B24: M-0.7_0.35 | C24: 1 | D24: 32.07 | E24: 33.3 | F24: 33.71 | G24: 39.39 | H24: 39.65 | I24: 39.8 | J24: =AVERAGE(D24:I24) -> 36.32 | K24: =AVERAGE(G24:I24) -> 39.613333
C25: 2 | D25: 35.8 | E25: 38.06 | F25: 36.23 | G25: 39.75 | H25: 39.83 | I25: 39.72 | J25: =AVERAGE(D25:I25) -> 38.231667 | K25: =AVERAGE(G25:I25) -> 39.766667
C26: 3 | D26: 33.19 | E26: 33.39 | F26: 32.17 | G26: 39.43 | H26: 39.48 | I26: 39.49 | J26: =AVERAGE(D26:I26) -> 36.191667 | K26: =AVERAGE(G26:I26) -> 39.466667
C27: 4 | D27: 36.92 | E27: 37.19 | F27: 36.5 | G27: 39.02 | H27: 39.14 | I27: 39.43 | J27: =AVERAGE(D27:I27) -> 38.033333 | K27: =AVERAGE(G27:I27) -> 39.196667
B28: M-1.0_0.3 | C28: 1 | D28: 38.06 | E28: 38.26 | F28: 38.13 | G28: 39.98 | H28: 39.96 | I28: 40.18 | J28: =AVERAGE(D28:I28) -> 39.095 | K28: =AVERAGE(G28:I28) -> 40.04
C29: 2 | D29: 40.87 | E29: 41.11 | F29: 41.16 | G29: 39.31 | H29: 39.97 | I29: 40.07 | J29: =AVERAGE(D29:I29) -> 40.415 | K29: =AVERAGE(G29:I29) -> 39.783333
C30: 3 | D30: 38.02 | E30: 40.89 | F30: 41.32 | G30: 39.99 | H30: 39.86 | I30: 39.75 | J30: =AVERAGE(D30:I30) -> 39.971667 | K30: =AVERAGE(G30:I30) -> 39.866667
C31: 4 | D31: 36.45 | E31: 37.1 | F31: 38.33 | G31: 39.48 | H31: 39.37 | I31: 39.22 | J31: =AVERAGE(D31:I31) -> 38.325 | K31: =AVERAGE(G31:I31) -> 39.356667
B32: M-1.0_0.35 | C32: 1 | D32: 38.43 | E32: 38.56 | F32: 38.67 | G32: 39.77 | H32: 39.83 | I32: 39.66 | J32: =AVERAGE(D32:I32) -> 39.153333 | K32: =AVERAGE(G32:I32) -> 39.753333
C33: 2 | D33: 34.74 | E33: 36.62 | F33: 35.78 | G33: 39.95 | H33: 39.96 | I33: 39.54 | J33: =AVERAGE(D33:I33) -> 37.765 | K33: =AVERAGE(G33:I33) -> 39.816667
B37: Flexural strength
B38: Mix | C38: Direction | D38: Sample | E38: W (mm) | F38: H (mm) | G38: Rupture load (N) | H38: Flexural Strength (Mpa) | I38: Avg. Flex. Strength (MPa) | J38: Stdev
B39: M-0.5_0.25 | C39: w | D39: 1 | E39: =J4 -> 40.28 | F39: =K4 -> 39.96 | G39: 2251 | H39: =1.5*G39*100/(E39*F39^2) -> 5.2496015 | I39: =AVERAGE(H39:H40) -> 5.9431241 | J39: =STDEV(H39:H40) -> 0.9807892 | AW39: Mix Designation | AX39: Flexural Strength (MPa) | AZ39: Compressive strength (MPa)
D40: 2 | E40: =J5 -> 37.896667 | F40: =K5 -> 39.476667 | G40: 2613 | H40: =1.5*G40*100/(E40*F40^2) -> 6.6366468 | AX40: w | AY40: v | AZ40: w | BA40: v
C41: v | D41: 3 | E41: =K6 -> 39.823333 | F41: =J6 -> 40.343333 | G41: 3038 | H41: =1.5*G41*100/(E41^2*F41) -> 7.122493 | I41: =AVERAGE(H41:H42) -> 6.2057342 | J41: =STDEV(H41:H42) -> 1.2964928 | AW41: M-0.5_0.25 | AX41: =I39 -> 5.9431241 | AY41: =I41 -> 6.2057342 | AZ41: =I73 -> 21.177486 | BA41: =I76 -> 19.335783
D42: 4 | E42: =K7 -> 39.296667 | F42: =J7 -> 38.733333 | G42: 2109 | H42: =1.5*G42*100/(E42^2*F42) -> 5.2889753 | AW42: M-0.5_0.30 | AX42: =I43 -> 2.2152964 | AY42: =I45 -> 3.7606891 | AZ42: =I79 -> 16.026182 | BA42: =I82 -> 12.047866
B43: M-0.5_0.3 | C43: w | D43: 1 | E43: =J8 -> 37.663333 | F43: =K8 -> 39.47 | G43: 835 | H43: =1.5*G43*100/(E43*F43^2) -> 2.1346404 | I43: =AVERAGE(H43:H44) -> 2.2152964 | J43: =STDEV(H43:H44) -> 0.11406485 | AW43: M-0.5_0.35 | AX43: =I47 -> 1.4498151 | AY43: =I49 -> 1.8784673 | AZ43: =I86 -> 10.600128 | BA43: =I90 -> 6.2592532
D44: 2 | E44: =J9 -> 37.18 | F44: =K9 -> 39.166667 | G44: 873 | H44: =1.5*G44*100/(E44*F44^2) -> 2.2959525 | AW44: M-0.7_0.25 | AX44: =I51 -> 5.6411171 | AY44: =I53 -> 6.6369627 | AZ44: =I94 -> 22.900667 | BA44: =I97 -> 14.22669
...

Sheet Strength_20%CO2_7 d
J2: Width | N2: Thickness
B3: Direction | C3: Sample | D3: W (mm) | E3: H (mm) | F3: Rupture load (N) | G3: Flex. Tensile Strength (Mpa) | H3: Avg. Flex. Strength (MPa) | I3: Stdev | J3: W1 (mm) | K3: W2 (mm) | L3: W3 (mm) | N3: H1 (mm) | O3: H2 (mm) | P3: H3 (mm) | R3: Mass (kg) | S3: Density (kg/m3) | T3: Stdev
B4: w | C4: 1 | D4: =AVERAGE(J4:L4) -> 29.77 | E4: =AVERAGE(N4:P4) -> 42.466667 | F4: 2393 | G4: =1.5*F4*100/(D4*E4^2) -> 6.6858831 | H4: =AVERAGE(G4:G6) -> 4.9553116 | I4: =STDEV(G4:G6) -> 1.5485748 | J4: 29.36 | K4: 30.1 | L4: 29.85 | N4: 42.8 | O4: 42.6 | P4: 42 | R4: 447.45 | S4: =R4*1000/(D4*E4*0.16) -> 2212.0632
C5: 2 | D5: =AVERAGE(J5:L5) -> 31.816667 | E5: =AVERAGE(N5:P5) -> 41.01 | F5: 1320 | G5: =1.5*F5*100/(D5*E5^2) -> 3.7002492 | J5: 32.38 | K5: 31.96 | L5: 31.11 | N5: 40.84 | O5: 40.83 | P5: 41.36 | R5: 461.85 | S5: =R5*1000/(D5*E5*0.16) -> 2212.2618 | V5: =AVERAGE(S4:S6) -> 2194.2306
C6: 3 | D6: =AVERAGE(J6:L6) -> 28.223333 | E6: =AVERAGE(N6:P6) -> 42.03 | F6: 1489 | G6: =1.5*F6*100/(D6*E6^2) -> 4.4798025 | J6: 29.93 | K6: 28.04 | L6: 26.7 | N6: 41.51 | O6: 42.01 | P6: 42.57 | R6: 409.65 | S6: =R6*1000/(D6*E6*0.16) -> 2158.3669 | T6: =STDEV(S4:S9) -> 72.098361
B7: v | C7: 1 | D7: =AVERAGE(J7:L7) -> 30.163333 | E7: =AVERAGE(N7:P7) -> 43.106667 | F7: 1970 | G7: =1.5*F7*100/(E7*D7^2) -> 7.534499 | H7: =AVERAGE(G7:G9) -> 6.0530736 | I7: =STDEV(G7:G9) -> 1.4193748 | J7: 30.02 | K7: 29.83 | L7: 30.64 | N7: 43.17 | O7: 43.23 | P7: 42.92 | R7: 435.75 | S7: =R7*1000/(D7*E7*0.16) -> 2094.564 | X7: =AVERAGE(V5:V8) -> 2146.1393
C8: 2 | D8: =AVERAGE(J8:L8) -> 30.7 | E8: =AVERAGE(N8:P8) -> 42.076667 | F8: 1565 | G8: =1.5*F8*100/(E8*D8^2) -> 5.919534 | J8: 29.44 | K8: 30.92 | L8: 31.74 | N8: 41.79 | O8: 42.52 | P8: 41.92 | R8: 419.25 | S8: =R8*1000/(D8*E8*0.16) -> 2028.4924 | V8: =AVERAGE(S7:S9) -> 2098.048
C9: 3 | D9: =AVERAGE(J9:L9) -> 29.136667 | E9: =AVERAGE(N9:P9) -> 43.823333 | F9: 1167 | G9: =1.5*F9*100/(E9*D9^2) -> 4.7051879 | J9: 28.88 | K9: 29.04 | L9: 29.49 | N9: 43.71 | O9: 44.21 | P9: 43.55 | R9: 443.55 | S9: =R9*1000/(D9*E9*0.16) -> 2171.0875
B17: Direction | C17: sample | D17: w (mm) | E17: L (mm) | F17: Cr've Load (N) | G17: Cr've Strength (Mpa) | H17: Avg. Cr've. Strength (MPa) | W17: Flexural st (MPa) | Y17: stdev | AF17: Compressive st (MPa) | AH17: stdev
B18: w | C18: 1 | D18: =D4 -> 29.77 | E18: 40 | F18: 37180 | G18: =F18/(E18*D18) -> 31.222707 | H18: =AVERAGE(G18:G23) -> 26.621445 | V18: duration | W18: w | X18: v | Y18: w | Z18: v | AE18: duration | AF18: w | AG18: v | AH18: w | AI18: v
C19: 2 | D19: =D4 -> 29.77 | E19: 40 | F19: 37180 | G19: =F19/(E19*D19) -> 31.222707 | V19: 1 | W19: 4.6 | X19: 5.5 | Y19: ='Strength_20%CO2_1 d'!I5 -> 1.1203027 | Z19: ='Strength_20%CO2_1 d'!I8 -> 0.45915732 | AE19: 1d | AF19: 23.4 | AG19: 33.5 | AH19: ='Strength_20%CO2_1 d'!I18 -> 5.4464233 | AI19: ='Strength_20%CO2_1 d'!I24 -> 6.2983931
C20: 3 | D20: =D5 -> 31.816667 | E20: 40 | F20: 14460 | G20: =F20/(E20*D20) -> 11.36197 | V20: 2 | W20: 4.6 | X20: 5 | Y20: ='Strength_20%CO2_2 d'!I5 -> 0.93782155 | Z20: ='Strength_20%CO2_2 d'!I8 -> 0.81542646 | AE20: 2d | AF20: 32.8 | AG20: 30.4 | AH20: ='Strength_20%CO2_2 d'!I18 -> 2.7748938 | AI20: ='Strength_20%CO2_2 d'!I24 -> 3.985609
C21: 4 | D21: =D5 -> 31.816667 | E21: 40 | F21: 16740 | G21: =F21/(E21*D21) -> 13.153483 | V21: 7_URH | W21: 5 | X21: 6.1 | Y21: =I4 -> 1.5485748 | Z21: =I7 -> 1.4193748 | AE21: 7d_URH | AF21: 33.8 | AG21: 40.1 | AH21: =I35 -> 3.3107705 | AI21: =I40 -> 9.4051884
C22: 5 | D22: =D6 -> 28.223333 | E22: 40 | F22: 39080 | G22: =F22/(E22*D22) -> 34.616747
C23: 6 | D23: =D6 -> 28.223333 | E23: 40 | F23: 43070 | G23: =F23/(E23*D23) -> 38.151057
B24: v | C24: 1 | D24: =E7 -> 43.106667 | E24: 40 | F24: 82660 | G24: =F24/(E24*D24) -> 47.939221 | H24: =AVERAGE(G24:G29) -> 40.090672
C25: 2 | D25: =E7 -> 43.106667 | E25: 40 | F25: 81720 | G25: =F25/(E25*D25) -> 47.394061
C26: 3 | D26: =E8 -> 42.076667 | E26: 40 | F26: 76050 | G26: =F26/(E26*D26) -> 45.185376
C27: 4 | D27: =E8 -> 42.076667 | E27: 40 | F27: 73180 | G27: =F27/(E27*D27) -> 43.480155
C28: 5 | D28: =E9 -> 43.823333 | E28: 40 | F28: 53590 | G28: =F28/(E28*D28) -> 30.571613
C29: 6 | D29: =E9 -> 43.823333 | E29: 40 | F29: 45530 | G29: =F29/(E29*D29) -> 25.973606
C32: Eliminating oulier samples
B33: Direction | C33: sample | D33: w (mm) | E33: L (mm) | F33: Cr've Load (N) | G33: Cr've Strength (Mpa) | H33: Avg. Cr've. Strength (MPa)
B34: w | C34: 1 | D34: =D18 -> 29.77 | E34: 40 | F34: 37180 | G34: =F34/(E34*D34) -> 31.222707 | H34: =AVERAGE(G34:G37) -> 33.803305 | L34: w | M34: =H34 -> 33.803305 | N34: =H4 -> 4.9553116
C35: 2 | D35: =D19 -> 29.77 | E35: 40 | F35: 37180 | G35: =F35/(E35*D35) -> 31.222707 | I35: =STDEV(G34:G37) -> 3.3107705 | L35: v | M35: =H38 -> 40.090672 | N35: =H7 -> 6.0530736
C36: 3 | D36: =D22 -> 28.223333 | E36: 40 | F36: 39080 | G36: =F36/(E36*D36) -> 34.616747
C37: 4 | D37: =D22 -> 28.223333 | E37: 40 | F37: 43070 | G37: =F37/(E37*D37) -> 38.151057
B38: v | C38: 1 | D38: =D24 -> 43.106667 | E38: 40 | F38: 82660 | G38: =F38/(E38*D38) -> 47.939221 | H38: =AVERAGE(G38:G43) -> 40.090672
C39: 2 | D39: =D25 -> 43.106667 | E39: 40 | F39: 81720 | G39: =F39/(E39*D39) -> 47.394061
C40: 3 | D40: =D26 -> 42.076667 | E40: 40 | F40: 76050 | G40: =F40/(E40*D40) -> 45.185376 | I40: =STDEV(G38:G43) -> 9.4051884
C41: 4 | D41: =D27 -> 42.076667 | E41: 40 | F41: 73180 | G41: =F41/(E41*D41) -> 43.480155
C42: 5 | D42: =D28 -> 43.823333 | E42: 40 | F42: 53590 | G42: =F42/(E42*D42) -> 30.571613
C43: 6 | D43: =D29 -> 43.823333 | E43: 40 | F43: 45530 | G43: =F43/(E43*D43) -> 25.973606

Sheet Strength_20%CO2_1 d
J2: Width | N2: Thickness
B3: Direction | C3: Sample | D3: W (mm) | E3: H (mm) | F3: Rupture load (N) | G3: Flex. Tensile Strength (Mpa) | H3: Avg. Flex. Strength (MPa) | I3: Stdev | J3: W1 (mm) | K3: W2 (mm) | L3: W3 (mm) | N3: H1 (mm) | O3: H2 (mm) | P3: H3 (mm) | R3: Mass (kg) | S3: Density (kg/m3)
B4: w | C4: 1 | D4: =AVERAGE(J4:L4) -> 31 | E4: =AVERAGE(N4:P4) -> 37.666667 | F4: 1721 | G4: =1.5*F4*100/(D4*E4^2) -> 5.8694318 | H4: =AVERAGE(G4:G6) -> 4.6073131 | J4: 31 | K4: 31 | L4: 31 | N4: 39 | O4: 37 | P4: 37 | R4: 366.1 | S4: =R4*1000/(D4*E4*0.16) -> 1959.5704
C5: 2 | D5: =AVERAGE(J5:L5) -> 33.333333 | E5: =AVERAGE(N5:P5) -> 40.666667 | F5: 1371 | G5: =1.5*F5*100/(D5*E5^2) -> 3.7305496 | I5: =STDEV(G4:G6) -> 1.1203027 | J5: 33 | K5: 33 | L5: 34 | N5: 40 | O5: 41 | P5: 41 | R5: 392.15 | S5: =R5*1000/(D5*E5*0.16) -> 1808.0686 | V5: =AVERAGE(S4:S6) -> 1856.8506
C6: 3 | D6: =AVERAGE(J6:L6) -> 29.666667 | E6: =AVERAGE(N6:P6) -> 38.333333 | F6: 1227 | G6: =1.5*F6*100/(D6*E6^2) -> 4.2219579 | J6: 29 | K6: 30 | L6: 30 | N6: 39 | O6: 38 | P6: 38 | R6: 328.05 | S6: =R6*1000/(D6*E6*0.16) -> 1802.9128 | T6: =STDEV(S4:S9) -> 88.508577 | Z6: =T6*100/1881.3 -> 4.7046498
B7: v | C7: 1 | D7: =AVERAGE(J7:L7) -> 32.333333 | E7: =AVERAGE(N7:P7) -> 41 | F7: 1730 | G7: =1.5*F7*100/(E7*D7^2) -> 6.0541412 | H7: =AVERAGE(G7:G9) -> 5.5435214 | J7: 32 | K7: 32 | L7: 33 | N7: 40 | O7: 41 | P7: 42 | R7: 424.2 | S7: =R7*1000/(D7*E7*0.16) -> 1999.9371 | X7: =AVERAGE(V5:V8) -> 1907.0449
C8: 2 | D8: =AVERAGE(J8:L8) -> 32.666667 | E8: =AVERAGE(N8:P8) -> 38 | F8: 1463 | G8: =1.5*F8*100/(E8*D8^2) -> 5.4118076 | I8: =STDEV(G7:G9) -> 0.45915732 | J8: 32 | K8: 33 | L8: 33 | N8: 38 | O8: 38 | P8: 38 | R8: 374.1 | S8: =R8*1000/(D8*E8*0.16) -> 1883.5593 | V8: =AVERAGE(S7:S9) -> 1957.2392
C9: 3 | D9: =AVERAGE(J9:L9) -> 33.333333 | E9: =AVERAGE(N9:P9) -> 39 | F9: 1492 | G9: =1.5*F9*100/(E9*D9^2) -> 5.1646154 | J9: 35 | K9: 33 | L9: 32 | N9: 38 | O9: 39 | P9: 40 | R9: 413.55 | S9: =R9*1000/(D9*E9*0.16) -> 1988.2212
B17: Direction | C17: sample | D17: w (mm) | E17: L (mm) | F17: Cr've Load (N) | G17: Cr've Strength (Mpa) | H17: Avg. Cr've. Strength (MPa) | I17: Stdev
B18: w | C18: 1 | D18: =D4 -> 31 | E18: 40 | F18: 40520 | G18: =F18/(E18*D18) -> 32.677419 | H18: =AVERAGE(G18:G23) -> 23.367867 | I18: =STDEV(G18:G23) -> 5.4464233
C19: 2 | D19: =D4 -> 31 | E19: 40 | F19: 32780 | G19: =F19/(E19*D19) -> 26.435484
C20: 3 | D20: =D5 -> 33.333333 | E20: 40 | F20: 27230 | G20: =F20/(E20*D20) -> 20.4225
C21: 4 | D21: =D5 -> 33.333333 | E21: 40 | F21: 24480 | G21: =F21/(E21*D21) -> 18.36
C22: 5 | D22: =D6 -> 29.666667 | E22: 40 | F22: 22630 | G22: =F22/(E22*D22) -> 19.070225
C23: 6 | D23: =D6 -> 29.666667 | E23: 40 | F23: 27580 | G23: =F23/(E23*D23) -> 23.241573
B24: v | C24: 1 | D24: =E7 -> 41 | E24: 40 | F24: 72190 | G24: =F24/(E24*D24) -> 44.018293 | H24: =AVERAGE(G24:G29) -> 33.498405 | I24: =STDEV(G24:G29) -> 6.2983931
C25: 2 | D25: =E7 -> 41 | E25: 40 | F25: 57320 | G25: =F25/(E25*D25) -> 34.95122
C26: 3 | D26: =E8 -> 38 | E26: 40 | F26: 43340 | G26: =F26/(E26*D26) -> 28.513158
C27: 4 | D27: =E8 -> 38 | E27: 40 | F27: 44160 | G27: =F27/(E27*D27) -> 29.052632
C28: 5 | D28: =E9 -> 39 | E28: 40 | F28: 43500 | G28: =F28/(E28*D28) -> 27.884615
C29: 6 | D29: =E9 -> 39 | E29: 40 | F29: 57050 | G29: =F29/(E29*D29) -> 36.570513

Sheet Strength_20%CO2_2 d
J2: Width | N2: Thickness
B3: Direction | C3: Sample | D3: W (mm) | E3: H (mm) | F3: Rupture load (N) | G3: Flex. Tensile Strength (Mpa) | H3: Avg. Flex. Strength (MPa) | I3: Stdev | J3: W1 (mm) | K3: W2 (mm) | L3: W3 (mm) | N3: H1 (mm) | O3: H2 (mm) | P3: H3 (mm) | R3: Mass (kg) | S3: Density (kg/m3)
B4: w | C4: 1 | D4: =AVERAGE(J4:L4) -> 31 | E4: =AVERAGE(N4:P4) -> 39 | F4: 1338 | G4: =1.5*F4*100/(D4*E4^2) -> 4.2565375 | H4: =AVERAGE(G4:G6) -> 4.572584 | J4: 30 | K4: 31 | L4: 32 | N4: 40 | O4: 39 | P4: 38 | R4: 363.15 | S4: =R4*1000/(D4*E4*0.16) -> 1877.3263
C5: 2 | D5: =AVERAGE(J5:L5) -> 37 | E5: =AVERAGE(N5:P5) -> 40 | F5: 1513 | G5: =1.5*F5*100/(D5*E5^2) -> 3.8336149 | I5: =STDEV(G4:G6) -> 0.93782155 | J5: 36 | K5: 37 | L5: 38 | N5: 40 | O5: 40 | P5: 40 | R5: 467.85 | S5: =R5*1000/(D5*E5*0.16) -> 1975.7179 | V5: =AVERAGE(S4:S6) -> 1921.0927
C6: 3 | D6: =AVERAGE(J6:L6) -> 23 | E6: =AVERAGE(N6:P6) -> 39.333333 | F6: 1335 | G6: =1.5*F6*100/(D6*E6^2) -> 5.6275995 | J6: 23 | K6: 23 | L6: 23 | N6: 39 | O6: 39 | P6: 40 | R6: 276.5 | S6: =R6*1000/(D6*E6*0.16) -> 1910.234 | T6: =STDEV(S4:S9) -> 34.831447 | AC6: =T6*100/Z7 -> 1.8514563
B7: v | C7: 1 | D7: =AVERAGE(J7:L7) -> 34 | E7: =AVERAGE(N7:P7) -> 37.333333 | F7: 1345 | G7: =1.5*F7*100/(E7*D7^2) -> 4.6747559 | H7: =AVERAGE(G7:G9) -> 5.0476089 | J7: 34 | K7: 34 | L7: 34 | N7: 40 | O7: 39 | P7: 33 | R7: 385.1 | S7: =R7*1000/(D7*E7*0.16) -> 1896.1725 | X7: =AVERAGE(V5:V8) -> 1914.9641 | Z7: 1881.3
C8: 2 | D8: =AVERAGE(J8:L8) -> 29.333333 | E8: =AVERAGE(N8:P8) -> 39.333333 | F8: 1012 | G8: =1.5*F8*100/(E8*D8^2) -> 4.4852658 | I8: =STDEV(G7:G9) -> 0.81542646 | J8: 30 | K8: 29 | L8: 29 | N8: 39 | O8: 39 | P8: 40 | R8: 356.7 | S8: =R8*1000/(D8*E8*0.16) -> 1932.2395 | V8: =AVERAGE(S7:S9) -> 1908.8355
C9: 3 | D9: =AVERAGE(J9:L9) -> 33.333333 | E9: =AVERAGE(N9:P9) -> 41 | F9: 1817 | G9: =1.5*F9*100/(E9*D9^2) -> 5.9828049 | J9: 33 | K9: 33 | L9: 34 | N9: 41 | O9: 41 | P9: 41 | R9: 415.05 | S9: =R9*1000/(D9*E9*0.16) -> 1898.0945 | Y9: =(X7-Z7)*100/Z7 -> 1.7894074
B17: Direction | C17: sample | D17: w (mm) | E17: L (mm) | F17: Cr've Load (N) | G17: Cr've Strength (Mpa) | H17: Avg. Cr've. Strength (MPa) | I17: stdev
B18: w | C18: 1 | D18: =D4 -> 31 | E18: 40 | F18: 41740 | G18: =F18/(E18*D18) -> 33.66129 | H18: =AVERAGE(G18:G23) -> 32.793434 | I18: =STDEV(G18:G23) -> 2.7748938
C19: 2 | D19: =D4 -> 31 | E19: 40 | F19: 37910 | G19: =F19/(E19*D19) -> 30.572581
C20: 3 | D20: =D5 -> 37 | E20: 40 | F20: 47640 | G20: =F20/(E20*D20) -> 32.189189
C21: 4 | D21: =D5 -> 37 | E21: 40 | F21: 53120 | G21: =F21/(E21*D21) -> 35.891892
C22: 5 | D22: =D6 -> 23 | E22: 40 | F22: 26580 | G22: =F22/(E22*D22) -> 28.891304
C23: 6 | D23: =D6 -> 23 | E23: 40 | F23: 32710 | G23: =F23/(E23*D23) -> 35.554348 | P23: =
B24: v | C24: 1 | D24: =E7 -> 37.333333 | E24: 40 | F24: 45310 | G24: =F24/(E24*D24) -> 30.341518 | H24: =AVERAGE(G24:G29) -> 30.438172 | I24: =STDEV(G24:G29) -> 3.985609
C25: 2 | D25: =E7 -> 37.333333 | E25: 40 | F25: 40710 | G25: =F25/(E25*D25) -> 27.261161
C26: 3 | D26: =E8 -> 39.333333 | E26: 40 | F26: 59590 | G26: =F26/(E26*D26) -> 37.875
C27: 4 | D27: =E8 -> 39.333333 | E27: 40 | F27: 42910 | G27: =F27/(E27*D27) -> 27.273305
C28: 5 | D28: =E9 -> 41 | E28: 40 | F28: 46930 | G28: =F28/(E28*D28) -> 28.615854
C29: 6 | D29: =E9 -> 41 | E29: 40 | F29: 51270 | G29: =F29/(E29*D29) -> 31.262195

Sheet Block Strength_3% CO2_7d
J2: Width | N2: Thickness
B3: Direction | C3: Sample | D3: W (mm) | E3: H (mm) | F3: Rupture load (N) | G3: Flex. Tensile Strength (Mpa) | H3: Avg. Flex. Strength (MPa) | I3: Stdev | J3: W1 (mm) | K3: W2 (mm) | L3: W3 (mm) | N3: H1 (mm) | O3: H2 (mm) | P3: H3 (mm) | R3: Mass (kg) | S3: Density (kg/m3) | Z3: Wi | AA3: W2 | AB3: W3 | AD3: H1 | AE3: H2 | AF3: H3
B4: w | C4: 1 | D4: =AVERAGE(J4:L4) -> 45.666667 | E4: =AVERAGE(N4:P4) -> 36.333333 | F4: 1368 | G4: =1.5*F4*100/(D4*E4^2) -> 3.4038276 | H4: =AVERAGE(G4:G6) -> 1.7898131 | J4: 48 | K4: 46 | L4: 43 | N4: 36 | O4: 36 | P4: 37 | R4: 564.8 | S4: =R4*1000/(D4*E4*0.16) -> 2127.5028 | Y4: =AVERAGE(Z4:AB4) -> 39.666667 | Z4: 38 | AA4: 40 | AB4: 41 | AC4: =AVERAGE(AD4:AF4) -> 52 | AD4: 52 | AE4: 53 | AF4: 51 | AH4: 598.6 | AI4: =AH4*1000/(Y4*AC4*0.15) -> 1934.7123 | AK4: =AVERAGE(AI4:AI5) -> 1947.1929
C5: 2 | D5: =AVERAGE(J5:L5) -> 44.666667 | E5: =AVERAGE(N5:P5) -> 33 | F5: 367 | G5: =1.5*F5*100/(D5*E5^2) -> 1.131738 | I5: =STDEV(G4:G6) -> 1.4056895 | J5: 46 | K5: 45 | L5: 43 | N5: 33 | O5: 33 | P5: 33 | R5: 471.3 | S5: =R5*1000/(D5*E5*0.16) -> 1998.3887 | U5: =AVERAGE(S4:S6) -> 2026.7422 | Y5: =AVERAGE(Z5:AB5) -> 38 | Z5: 36 | AA5: 38 | AB5: 40 | AC5: =AVERAGE(AD5:AF5) -> 54 | AD5: 53 | AE5: 55 | AF5: 54 | AH5: 643.4 | AI5: =AH5*1000/(Y5*AC5*0.16) -> 1959.6735 | AJ5: =STDEV(AI4:AI5) -> 17.650193
C6: 3 | D6: =AVERAGE(J6:L6) -> 44.666667 | E6: =AVERAGE(N6:P6) -> 35.333333 | F6: 310 | G6: =1.5*F6*100/(D6*E6^2) -> 0.83387353 | J6: 46 | K6: 45 | L6: 43 | N6: 36 | O6: 35 | P6: 35 | R6: 493.5 | S6: =R6*1000/(D6*E6*0.16) -> 1954.335
B7: V | C7: 1 | D7: =AVERAGE(J7:L7) -> 47.333333 | E7: =AVERAGE(N7:P7) -> 33.333333 | F7: 1833 | G7: =1.5*F7*100/(E7*D7^2) -> 3.6816356 | H7: =AVERAGE(G7:G8) -> 3.4640631 | J7: 46 | K7: 48 | L7: 48 | N7: 33 | O7: 34 | P7: 33 | R7: 503.4 | S7: =R7*1000/(D7*E7*0.16) -> 1994.1021 | T7: =STDEV(S4:S12) -> 55.447886 | U7: =AVERAGE(S7:S8) -> 2030.6525
C8: 2 | D8: =AVERAGE(J8:L8) -> 43.666667 | E8: =AVERAGE(N8:P8) -> 39.666667 | F8: 1637 | G8: =1.5*F8*100/(E8*D8^2) -> 3.2464906 | I8: =STDEV(G7:G8) -> 0.30769397 | J8: 45 | K8: 44 | L8: 42 | N8: 40 | O8: 41 | P8: 38 | R8: 572.9 | S8: =R8*1000/(D8*E8*0.16) -> 2067.2028 | W8: =AVERAGE(U5:U11) -> 2034.0943
C9: 3 | D9: =AVERAGE(J9:L9) -> 33.333333 | E9: =AVERAGE(N9:P9) -> 41 | F9: 1817 | G9: =1.5*F9*100/(E9*D9^2) -> 5.9828049 | J9: 33 | K9: 33 | L9: 34 | N9: 41 | O9: 41 | P9: 41 | R9: 415.05
B10: U | C10: 1 | D10: =AVERAGE(J10:L10) -> 42.333333 | E10: =AVERAGE(N10:P10) -> 37.333333 | F10: 1120 | G10: =1.5*F10*100/(E10*D10^2) -> 2.511005 | H10: =AVERAGE(G10:G12) -> 2.4093281 | J10: 42 | K10: 42 | L10: 43 | N10: 38 | O10: 37 | P10: 37 | R10: 507.6 | S10: =R10*1000/(D10*E10*0.16) -> 2007.3467
C11: 2 | D11: =AVERAGE(J11:L11) -> 41.333333 | E11: =AVERAGE(N11:P11) -> 34.333333 | F11: 983 | G11: =1.5*F11*100/(E11*D11^2) -> 2.5137839 | I11: =STDEV(G10:G12) -> 0.17852159 | J11: 42 | K11: 41 | L11: 41 | N11: 34 | O11: 34 | P11: 35 | R11: 468.8 | S11: =R11*1000/(D11*E11*0.16) -> 2064.6727 | U11: =AVERAGE(S10:S12) -> 2044.8882
C12: 3 | D12: =AVERAGE(J12:L12) -> 41 | E12: =AVERAGE(N12:P12) -> 42 | F12: 1037 | G12: =1.5*F12*100/(E12*D12^2) -> 2.2031954 | J12: 40 | K12: 41 | L12: 42 | N12: 42 | O12: 42 | P12: 42 | R12: 568.3 | S12: =R12*1000/(D12*E12*0.16) -> 2062.6452
B17: Direction | C17: sample | D17: w (mm) | E17: L (mm) | F17: Cr've Load (N) | G17: Cr've Strength (Mpa) | H17: Avg. Cr've. Strength (MPa)
B18: w | C18: 1 | D18: =D4 -> 45.666667 | E18: 40 | F18: 26670 | G18: =F18/(E18*D18) -> 14.600365 | H18: =AVERAGE(G18:G23) -> 14.1081 | R18: w | S18: 1.8 | T18: 1.4 | V18: 21.9 | W18: 0.9 | Z18: Small-scale | AA18: 1947.2
C19: 2 | D19: =D4 -> 45.666667 | E19: 40 | F19: 24530 | G19: =F19/(E19*D19) -> 13.428832 | R19: v | S19: 3.5 | T19: 0.3 | V19: 19.3 | W19: 1.3 | Z19: Block scale | AA19: 2034.1
C20: 3 | D20: =D5 -> 44.666667 | E20: 40 | F20: 25090 | G20: =F20/(E20*D20) -> 14.04291 | I20: =STDEV(G18:G23) -> 0.4597012 | R20: u | S20: 2.4 | T20: 0.2
C21: 4 | D21: =D5 -> 44.666667 | E21: 40 | F21: 26010 | G21: =F21/(E21*D21) -> 14.557836
C22: 5 | D22: =D6 -> 44.666667 | E22: 40 | F22: 24580 | G22: =F22/(E22*D22) -> 13.757463
C23: 6 | D23: =D6 -> 44.666667 | E23: 40 | F23: 25480 | G23: =F23/(E23*D23) -> 14.261194 | P23: = | R23: w | S23: 14.1 | T23: 0.5 | V23: 5.9 | W23: 1
B24: v | C24: 1 | D24: =E7 -> 33.333333 | E24: 40 | F24: 18440 | G24: =F24/(E24*D24) -> 13.83 | H24: =AVERAGE(G24:G29) -> 12.819354 | R24: v | S24: 12.8 | T24: 3.2 | V24: 6.2 | W24: 1.3
C25: 2 | D25: =E7 -> 33.333333 | E25: 40 | F25: 20210 | G25: =F25/(E25*D25) -> 15.1575 | R25: u | S25: 15.4 | T25: 1.2
C26: 3 | D26: =E8 -> 39.666667 | E26: 40 | F26: 19390 | G26: =F26/(E26*D26) -> 12.220588 | I26: =STDEV(G24:G29) -> 3.1991453
C27: 4 | D27: =E8 -> 39.666667 | E27: 40 | F27: 19670 | G27: =F27/(E27*D27) -> 12.397059
C28: 5 | D28: =E9 -> 41 | E28: 40 | F28: 11650 | G28: =F28/(E28*D28) -> 7.1036585
C29: 6 | D29: =E9 -> 41 | E29: 40 | F29: 26580 | G29: =F29/(E29*D29) -> 16.207317
B30: u | C30: 1 | D30: =D10 -> 42.333333 | E30: 40 | F30: 23830 | G30: =F30/(E30*D30) -> 14.072835 | H30: =AVERAGE(G30:G35) -> 15.410054
C31: 2 | D31: =D10 -> 42.333333 | E31: 40 | F31: 25720 | G31: =F31/(E31*D31) -> 15.188976
C32: 3 | D32: =D11 -> 41.333333 | E32: 40 | F32: 23260 | G32: =F32/(E32*D32) -> 14.068548 | I32: =STDEV(G30:G35) -> 1.16816
C33: 4 | D33: =D11 -> 41.333333 | E33: 40 | F33: 26890 | G33: =F33/(E33*D33) -> 16.264113
C34: 5 | D34: =D12 -> 41 | E34: 40 | F34: 26250 | G34: =F34/(E34*D34) -> 16.006098
C35: 6 | D35: =D12 -> 41 | E35: 40 | F35: 27650 | G35: =F35/(E35*D35) -> 16.859756
