Workbook

Sheet graphs
O5: timber beam | R5: P-NWC-A | U5: P-NWC-B | X5: P-NWC-C | AA5: P-LWC-A | AD5: P-LWC-B | AG5: P-LWC-C
O6: deflection (mm) | P6: force (N) | Q6: force (kN) | R6: deflection (mm) | S6: force (N) | T6: force (kN) | U6: deflection (mm) | V6: force (N) | W6: force (kN) | X6: deflection (mm) | Y6: force (N) | Z6: force (kN) | AA6: deflection (mm) | AB6: force (N) | AC6: force (kN) | AD6: deflection (mm) | AE6: force (N) | AF6: force (kN) | AG6: deflection (mm) | AH6: force (N) | AI6: force (kN)
O7: 0 | P7: 0 | Q7: =P7/1000 -> 0 | R7: 0 | S7: 0 | T7: =S7/1000 -> 0 | U7: 0 | V7: 0 | W7: =V7/1000 -> 0 | X7: 0 | Y7: 0 | Z7: =Y7/1000 -> 0 | AA7: 0 | AB7: 0 | AC7: =AB7/1000 -> 0 | AD7: 0 | AE7: 0 | AF7: =AE7/1000 -> 0 | AG7: 0 | AH7: 0 | AI7: =AH7/1000 -> 0
O8: 3.494399 | P8: 2213.4249 | Q8: =P8/1000 -> 2.2134249 | R8: 0.43927 | S8: 1984.7964 | T8: =S8/1000 -> 1.9847964 | U8: 0.13175 | V8: 2125.0513 | W8: =V8/1000 -> 2.1250513 | X8: 0.563975 | Y8: 2314.5535 | Z8: =Y8/1000 -> 2.3145535 | AA8: 0.36 | AB8: 2733.8071 | AC8: =AB8/1000 -> 2.7338071 | AD8: 0.07 | AE8: 2084.7792 | AF8: =AE8/1000 -> 2.0847792 | AG8: 0.6 | AH8: 2309.8536 | AI8: =AH8/1000 -> 2.3098536
O9: 5.906032 | P9: 4214.5841 | Q9: =P9/1000 -> 4.2145841 | R9: 0.993952 | S9: 3985.2355 | T9: =S9/1000 -> 3.9852355 | U9: 0.589466 | V9: 4142.6836 | W9: =V9/1000 -> 4.1426836 | X9: 1.22287 | Y9: 4340.926 | Z9: =Y9/1000 -> 4.340926 | AA9: 1.08 | AB9: 5043.861 | AC9: =AB9/1000 -> 5.043861 | AD9: 1.08 | AE9: 4553.4703 | AF9: =AE9/1000 -> 4.5534703 | AG9: 1.4 | AH9: 4315.5016 | AI9: =AH9/1000 -> 4.3155016
O10: 8.272832 | P10: 6276.2498 | Q10: =P10/1000 -> 6.2762498 | R10: 1.507864 | S10: 5996.0377 | T10: =S10/1000 -> 5.9960377 | U10: 1.077878 | V10: 6188.7149 | W10: =V10/1000 -> 6.1887149 | X10: 1.957089 | Y10: 6448.4522 | Z10: =Y10/1000 -> 6.4484522 | AA10: 2.67 | AB10: 10569.855 | AC10: =AB10/1000 -> 10.569855 | AD10: 2.24 | AE10: 8170.153 | AF10: =AE10/1000 -> 8.170153 | AG10: 2.2 | AH10: 6418.6973 | AI10: =AH10/1000 -> 6.4186973
O11: 12.004941 | P11: 8357.6679 | Q11: =P11/1000 -> 8.3576679 | R11: 2.0551 | S11: 8003.245 | T11: =S11/1000 -> 8.003245 | U11: 1.540191 | V11: 8208.5339 | W11: =V11/1000 -> 8.2085339 | X11: 2.533165 | Y11: 8512.8682 | Z11: =Y11/1000 -> 8.5128682 | AA11: 2.84 | AB11: 8503.0947 | AC11: =AB11/1000 -> 8.5030947 | AD11: 2.77 | AE11: 6116.3078 | AF11: =AE11/1000 -> 6.1163078 | AG11: 2.9 | AH11: 8505.8619 | AI11: =AH11/1000 -> 8.5058619
O12: 14.597655 | P12: 10364.232 | Q12: =P12/1000 -> 10.364232 | R12: 2.621923 | S12: 10008.43 | T12: =S12/1000 -> 10.00843 | U12: 2.027643 | V12: 10237.897 | W12: =V12/1000 -> 10.237897 | X12: 3.025944 | Y12: 10539.525 | Z12: =Y12/1000 -> 10.539525 | AA12: 2.25 | AB12: 6476.4586 | AC12: =AB12/1000 -> 6.4764586 | AD12: 3.74 | AE12: 12944.18 | AF12: =AE12/1000 -> 12.94418 | AG12: 3.7 | AH12: 10749.41 | AI12: =AH12/1000 -> 10.74941
O13: 17.053385 | P13: 12558.566 | Q13: =P13/1000 -> 12.558566 | R13: 3.22982 | S13: 12059.391 | T13: =S13/1000 -> 12.059391 | U13: 2.601148 | V13: 12339.039 | W13: =V13/1000 -> 12.339039 | X13: 3.425051 | Y13: 12552.778 | Z13: =Y13/1000 -> 12.552778 | AA13: 1.64 | AB13: 4457.6445 | AC13: =AB13/1000 -> 4.4576445 | AD13: 5.06 | AE13: 16756.299 | AF13: =AE13/1000 -> 16.756299 | AG13: 2 | AH13: 5392.2045 | AI13: =AH13/1000 -> 5.3922045
O14: 19.559654 | P14: 14717.441 | Q14: =P14/1000 -> 14.717441 | R14: 3.819047 | S14: 14096.985 | T14: =S14/1000 -> 14.096985 | U14: 2.980576 | V14: 14371.637 | W14: =V14/1000 -> 14.371637 | X14: 4.085464 | Y14: 14576.219 | Z14: =Y14/1000 -> 14.576219 | AA14: 2 | AB14: 7714.3911 | AC14: =AB14/1000 -> 7.7143911 | AD14: 6.8 | AE14: 20878.978 | AF14: =AE14/1000 -> 20.878978 | AG14: 2.8 | AH14: 7617.2701 | AI14: =AH14/1000 -> 7.6172701
O15: 21.874476 | P15: 16759.073 | Q15: =P15/1000 -> 16.759073 | R15: 4.369738 | S15: 16116.819 | T15: =S15/1000 -> 16.116819 | U15: 3.660183 | V15: 16374.569 | W15: =V15/1000 -> 16.374569 | X15: 4.872331 | Y15: 16632.361 | Z15: =Y15/1000 -> 16.632361 | AA15: 3.84 | AB15: 14392.089 | AC15: =AB15/1000 -> 14.392089 | AD15: 7.83 | AE15: 23013.339 | AF15: =AE15/1000 -> 23.013339 | AG15: 3.5 | AH15: 9748.4202 | AI15: =AH15/1000 -> 9.7484202
O16: 24.419654 | P16: 18893.965 | Q16: =P16/1000 -> 18.893965 | R16: 4.943654 | S16: 18130.943 | T16: =S16/1000 -> 18.130943 | U16: 3.930676 | V16: 18391.838 | W16: =V16/1000 -> 18.391838 | X16: 4.883906 | Y16: 18647.542 | Z16: =Y16/1000 -> 18.647542 | AA16: 5.25 | AB16: 18891.416 | AC16: =AB16/1000 -> 18.891416 | AD16: 8.88 | AE16: 27929.455 | AF16: =AE16/1000 -> 27.929455 | AG16: 4.2 | AH16: 12178.825 | AI16: =AH16/1000 -> 12.178825
O17: 40.283693 | P17: 34036.647 | Q17: =P17/1000 -> 34.036647 | R17: 5.479526 | S17: 20143.478 | T17: =S17/1000 -> 20.143478 | U17: 4.550295 | V17: 20485.155 | W17: =V17/1000 -> 20.485155 | X17: 5.811487 | Y17: 16627.945 | Z17: =Y17/1000 -> 16.627945 | AA17: 5.65 | AB17: 20906.196 | AC17: =AB17/1000 -> 20.906196 | AD17: 9.96 | AE17: 30403.258 | AF17: =AE17/1000 -> 30.403258 | AG17: 5 | AH17: 14185.933 | AI17: =AH17/1000 -> 14.185933
O18: 41.814098 | P18: 36053.69 | Q18: =P18/1000 -> 36.05369 | R18: 6.12017 | S18: 22174.29 | T18: =S18/1000 -> 22.17429 | U18: 4.886786 | V18: 18390.73 | W18: =V18/1000 -> 18.39073 | X18: 5.248228 | Y18: 14615.084 | Z18: =Y18/1000 -> 14.615084 | AA18: 6.19 | AB18: 22993.639 | AC18: =AB18/1000 -> 22.993639 | AD18: 11.09 | AE18: 32417.964 | AF18: =AE18/1000 -> 32.417964 | AG18: 5.7 | AH18: 16195.295 | AI18: =AH18/1000 -> 16.195295
... O25: 56.128911 | P25: 22161.971 | Q25: =P25/1000 -> 22.161971 | R25: 2.93042 | S25: 8017.6681 | T25: =S25/1000 -> 8.0176681 | U25: 1.909538 | V25: 8174.1872 | W25: =V25/1000 -> 8.1741872 | X25: 3.901887 | Y25: 12510.537 | Z25: =Y25/1000 -> 12.510537 | AA25: 15.56 | AB25: 48787.962 | AC25: =AB25/1000 -> 48.787962 | AD25: 16.52 | AE25: 48500.671 | AF25: =AE25/1000 -> 48.500671 | AG25: 11.9 | AH25: 33956.129 | AI25: =AH25/1000 -> 33.956129
R26: 2.37422 | S26: 5990.882 | T26: =S26/1000 -> 5.990882 | U26: 2.378714 | V26: 10185.361 | W26: =V26/1000 -> 10.185361 | X26: 4.401784 | Y26: 14521.563 | Z26: =Y26/1000 -> 14.521563 | AA26: 17.7 | AB26: 52436.859 | AC26: =AB26/1000 -> 52.436859 | AD26: 18.36 | AE26: 50697.486 | AF26: =AE26/1000 -> 50.697486 | AG26: 12.7 | AH26: 37081.916 | AI26: =AH26/1000 -> 37.081916
R27: 2.408183 | S27: 8089.2337 | T27: =S27/1000 -> 8.0892337 | U27: 2.840477 | V27: 12212.701 | W27: =V27/1000 -> 12.212701 | X27: 5.133202 | Y27: 16559.404 | Z27: =Y27/1000 -> 16.559404 | AA27: 24.63 | AB27: 55350.924 | AC27: =AB27/1000 -> 55.350924 | AD27: 19.22 | AE27: 54054.339 | AF27: =AE27/1000 -> 54.054339 | AG27: 14 | AH27: 40091.57 | AI27: =AH27/1000 -> 40.09157
R28: 3.042844 | S28: 10099.617 | T28: =S28/1000 -> 10.099617 | U28: 3.369527 | V28: 14253.355 | W28: =V28/1000 -> 14.253355 | X28: 5.702388 | Y28: 18590.87 | Z28: =Y28/1000 -> 18.59087 | AA28: 30.72 | AB28: 59811.339 | AC28: =AB28/1000 -> 59.811339 | AD28: 20.91 | AE28: 56616.122 | AF28: =AE28/1000 -> 56.616122 | AG28: 15 | AH28: 42985.312 | AI28: =AH28/1000 -> 42.985312
Q29: =P29/1000 -> 0 | R29: 3.589972 | S29: 12143.699 | T29: =S29/1000 -> 12.143699 | U29: 3.873332 | V29: 16296.45 | W29: =V29/1000 -> 16.29645 | X29: 6.233481 | Y29: 20622.161 | Z29: =Y29/1000 -> 20.622161 | AA29: 35.67 | AB29: 62026.838 | AC29: =AB29/1000 -> 62.026838 | AD29: 34.58 | AE29: 61401.902 | AF29: =AE29/1000 -> 61.401902 | AG29: 16.4 | AH29: 45938.32 | AI29: =AH29/1000 -> 45.93832
Q30: =P30/1000 -> 0 | R30: 4.108801 | S30: 14154.44 | T30: =S30/1000 -> 14.15444 | U30: 4.22437 | V30: 18327.988 | W30: =V30/1000 -> 18.327988 | X30: 6.670163 | Y30: 22624.674 | Z30: =Y30/1000 -> 22.624674 | AA30: 37.61 | AB30: 62575.297 | AC30: =AB30/1000 -> 62.575297 | AD30: 38.26 | AE30: 63070.655 | AF30: =AE30/1000 -> 63.070655 | AG30: 17.1 | AH30: 48793.731 | AI30: =AH30/1000 -> 48.793731
F31: b | G31: 0.6 | H31: 0.07 | K31: Gamma | Q31: =P31/1000 -> 0 | R31: 4.605554 | S31: 16167.256 | T31: =S31/1000 -> 16.167256 | U31: 4.859981 | V31: 20338.894 | W31: =V31/1000 -> 20.338894 | X31: 7.260398 | Y31: 24629.677 | Z31: =Y31/1000 -> 24.629677 | AA31: 46.72 | AB31: 31106.931 | AC31: =AB31/1000 -> 31.106931 | AE31: 9287.7252 | AF31: =AE31/1000 -> 9.2877252 | AG31: 18.6 | AH31: 51758.577 | AI31: =AH31/1000 -> 51.758577
B32: kn/m | C32: G | D32: =1*G31+G32*G31*H31+G35*G34*H34 -> 1.37406 | E32: =D32*5.2 -> 7.145112 | F32: rho_nwc | G32: 16 | K32: F | L32: deflection | Q32: =P32/1000 -> 0 | R32: 5.130064 | S32: 18206.745 | T32: =S32/1000 -> 18.206745 | U32: 5.33932 | V32: 22351.646 | W32: =V32/1000 -> 22.351646 | X32: 7.720289 | Y32: 26682.765 | Z32: =Y32/1000 -> 26.682765 | AB32: 29003.695 | AC32: =AB32/1000 -> 29.003695 | AE32: 7105.455 | AF32: =AE32/1000 -> 7.105455 | AG32: 19.6 | AH32: 53918.932 | AI32: =AH32/1000 -> 53.918932
C33: Q | D33: 3 | E33: =D33*G31 -> 1.8 | F33: rho_lwc | G33: 1600 | K33: 0 | L33: 0 | Q33: =P33/1000 -> 0 | R33: 5.659893 | S33: 20208.76 | T33: =S33/1000 -> 20.20876 | U33: 5.879362 | V33: 24499.955 | W33: =V33/1000 -> 24.499955 | X33: 8.712256 | Y33: 28714.91 | Z33: =Y33/1000 -> 28.71491 | AB33: 26335.154 | AC33: =AB33/1000 -> 26.335154 | AE33: 4984.4803 | AF33: =AE33/1000 -> 4.9844803 | AG33: 20.5 | AH33: 55934.831 | AI33: =AH33/1000 -> 55.934831
C34: gamma_g | D34: 1.35 | E34: 1.35 | F34: b_t | G34: 0.09 | H34: 0.27 | K34: 50 | L34: 13.1 | Q34: =P34/1000 -> 0 | R34: 6.179732 | S34: 22232.98 | T34: =S34/1000 -> 22.23298 | U34: 6.189122 | V34: 26638.779 | W34: =V34/1000 -> 26.638779 | X34: 9.338302 | Y34: 30719.773 | Z34: =Y34/1000 -> 30.719773 | AB34: 23591.653 | AC34: =AB34/1000 -> 23.591653 | AE34: 2904.0646 | AF34: =AE34/1000 -> 2.9040646 | AG34: 21.1 | AH34: 57987.015 | AI34: =AH34/1000 -> 57.987015
C35: gamma_q | D35: 1.5 | E35: 1.5 | F35: rho_t | G35: 4.2 | K35: 80 | L35: =K35*L34/K34 -> 20.96 | Q35: =P35/1000 -> 0 | R35: 6.632702 | S35: 24244.017 | T35: =S35/1000 -> 24.244017 | U35: 6.900565 | V35: 28670.17 | W35: =V35/1000 -> 28.67017 | X35: 9.975487 | Y35: 32735.869 | Z35: =Y35/1000 -> 32.735869 | AB35: 20958.692 | AC35: =AB35/1000 -> 20.958692 | AE35: 777.22574 | AF35: =AE35/1000 -> 0.77722574 | AG35: 23.2 | AH35: 60068.547 | AI35: =AH35/1000 -> 60.068547
B36: kn | C36: ULS | D36: =D34*D32+D35*D33 -> 6.354981 | E36: =E34*E32+E35*E33 -> 12.345901 | F36: =E36 -> 12.345901 | Q36: =P36/1000 -> 0 | R36: 7.175272 | S36: 26292.478 | T36: =S36/1000 -> 26.292478 | U36: 7.30288 | V36: 30703.197 | W36: =V36/1000 -> 30.703197 | X36: 10.671922 | Y36: 34772.234 | Z36: =Y36/1000 -> 34.772234 | AB36: 18444.684 | AC36: =AB36/1000 -> 18.444684 | AF36: =AE36/1000 -> 0 | AG36: 26.1 | AH36: 62138.094 | AI36: =AH36/1000 -> 62.138094
B37: kn | C37: SLS | D37: =D32+D33 -> 4.37406 | E37: =E32+E33 -> 8.945112 | F37: =E37 -> 8.945112 | Q37: =P37/1000 -> 0 | R37: 7.73496 | S37: 28318.501 | T37: =S37/1000 -> 28.318501 | U37: 7.736524 | V37: 32807.342 | W37: =V37/1000 -> 32.807342 | X37: 10.680304 | Y37: 36789.267 | Z37: =Y37/1000 -> 36.789267 | AB37: 15921.399 | AC37: =AB37/1000 -> 15.921399 | AF37: =AE37/1000 -> 0 | AG37: 29.2 | AH37: 64191.132 | AI37: =AH37/1000 -> 64.191132
E38: 0 | F38: 40 | Q38: =P38/1000 -> 0 | R38: 8.347608 | S38: 30595.31 | T38: =S38/1000 -> 30.59531 | U38: 8.619754 | V38: 34818.829 | W38: =V38/1000 -> 34.818829 | X38: 11.42167 | Y38: 38795.335 | Z38: =Y38/1000 -> 38.795335 | AB38: 13461.297 | AC38: =AB38/1000 -> 13.461297 | AF38: =AE38/1000 -> 0 | AG38: 32.5 | AH38: 66284.302 | AI38: =AH38/1000 -> 66.284302
Q39: =P39/1000 -> 0 | R39: 9.104812 | S39: 32610.786 | T39: =S39/1000 -> 32.610786 | U39: 9.140412 | V39: 36855.664 | W39: =V39/1000 -> 36.855664 | X39: 12.186516 | Y39: 40814.007 | Z39: =Y39/1000 -> 40.814007 | AB39: 11459.91 | AC39: =AB39/1000 -> 11.45991 | AF39: =AE39/1000 -> 0 | AG39: 34.6 | AH39: 68295.3 | AI39: =AH39/1000 -> 68.2953
Q40: =P40/1000 -> 0 | R40: 9.529787 | S40: 34655.448 | T40: =S40/1000 -> 34.655448 | U40: 9.649305 | V40: 38865.515 | W40: =V40/1000 -> 38.865515 | X40: 12.9073 | Y40: 42836.007 | Z40: =Y40/1000 -> 42.836007 | AB40: 9388.0209 | AC40: =AB40/1000 -> 9.3880209 | AF40: =AE40/1000 -> 0 | AG40: 39.3 | AH40: 70342.362 | AI40: =AH40/1000 -> 70.342362
Q41: =P41/1000 -> 0 | R41: 10.44006 | S41: 36706.325 | T41: =S41/1000 -> 36.706325 | U41: 10.309157 | V41: 40920.147 | W41: =V41/1000 -> 40.920147 | X41: 13.611894 | Y41: 44908.717 | Z41: =Y41/1000 -> 44.908717 | AB41: 7157.5138 | AC41: =AB41/1000 -> 7.1575138 | AF41: =AE41/1000 -> 0 | AG41: 41.8 | AH41: 72373.858 | AI41: =AH41/1000 -> 72.373858
Q42: =P42/1000 -> 0 | R42: 10.935728 | S42: 38709.016 | T42: =S42/1000 -> 38.709016 | U42: 10.919595 | V42: 42936.236 | W42: =V42/1000 -> 42.936236 | X42: 14.32941 | Y42: 46930.934 | Z42: =Y42/1000 -> 46.930934 | AB42: 5048.153 | AC42: =AB42/1000 -> 5.048153 | AF42: =AE42/1000 -> 0 | AG42: 44.1 | AH42: 73360.577 | AI42: =AH42/1000 -> 73.360577
Q43: =P43/1000 -> 0 | R43: 11.453602 | S43: 41042.469 | T43: =S43/1000 -> 41.042469 | U43: 10.930153 | V43: 45018.308 | W43: =V43/1000 -> 45.018308 | X43: 14.801244 | Y43: 48947.9 | Z43: =Y43/1000 -> 48.9479 | AB43: 2911.632 | AC43: =AB43/1000 -> 2.911632 | AF43: =AE43/1000 -> 0 | AG43: 45.7 | AH43: 54801.724 | AI43: =AH43/1000 -> 54.801724
Q44: =P44/1000 -> 0 | R44: 11.987863 | S44: 43055.363 | T44: =S44/1000 -> 43.055363 | U44: 11.517719 | V44: 47060.218 | W44: =V44/1000 -> 47.060218 | X44: 15.912199 | Y44: 50970.759 | Z44: =Y44/1000 -> 50.970759 | AC44: =AB44/1000 -> 0 | AF44: =AE44/1000 -> 0 | AH44: -279.42028 | AI44: =AH44/1000 -> -0.27942028
Q45: =P45/1000 -> 0 | R45: 12.617086 | S45: 45078.5 | T45: =S45/1000 -> 45.0785 | U45: 12.181298 | V45: 49073.081 | W45: =V45/1000 -> 49.073081 | X45: 16.355028 | Y45: 53023.089 | Z45: =Y45/1000 -> 53.023089 | AC45: =AB45/1000 -> 0 | AF45: =AE45/1000 -> 0 | AI45: =AH45/1000 -> 0
Q46: =P46/1000 -> 0 | R46: 13.264927 | S46: 47084.842 | T46: =S46/1000 -> 47.084842 | U46: 13.247437 | V46: 51123.302 | W46: =V46/1000 -> 51.123302 | X46: 16.829981 | Y46: 55053.484 | Z46: =Y46/1000 -> 55.053484 | AC46: =AB46/1000 -> 0 | AF46: =AE46/1000 -> 0 | AI46: =AH46/1000 -> 0
Q47: =P47/1000 -> 0 | R47: 13.848298 | S47: 49100.521 | T47: =S47/1000 -> 49.100521 | U47: 13.709485 | V47: 53174.994 | W47: =V47/1000 -> 53.174994 | X47: 17.833643 | Y47: 57083.09 | Z47: =Y47/1000 -> 57.08309 | AC47: =AB47/1000 -> 0 | AF47: =AE47/1000 -> 0 | AI47: =AH47/1000 -> 0
Q48: =P48/1000 -> 0 | R48: 15.024037 | S48: 51111.239 | T48: =S48/1000 -> 51.111239 | U48: 14.153168 | V48: 55228.359 | W48: =V48/1000 -> 55.228359 | X48: 18.44903 | Y48: 59092.871 | Z48: =Y48/1000 -> 59.092871 | AC48: =AB48/1000 -> 0 | AF48: =AE48/1000 -> 0 | AI48: =AH48/1000 -> 0
Q49: =P49/1000 -> 0 | R49: 15.49858 | S49: 53119.096 | T49: =S49/1000 -> 53.119096 | U49: 14.96094 | V49: 57268.394 | W49: =V49/1000 -> 57.268394 | X49: 19.403919 | Y49: 61115.699 | Z49: =Y49/1000 -> 61.115699 | AC49: =AB49/1000 -> 0 | AF49: =AE49/1000 -> 0 | AI49: =AH49/1000 -> 0
Q50: =P50/1000 -> 0 | R50: 15.996209 | S50: 55123.444 | T50: =S50/1000 -> 55.123444 | U50: 15.609897 | V50: 59295.938 | W50: =V50/1000 -> 59.295938 | X50: 19.883214 | Y50: 63155.065 | Z50: =Y50/1000 -> 63.155065 | AC50: =AB50/1000 -> 0 | AF50: =AE50/1000 -> 0 | AI50: =AH50/1000 -> 0
...

Sheet bending stiffness
D7: 0
D8: =AVERAGE(D13:F13) -> 6.35 | G8: =AVERAGE(G13:I13) -> 5.5844517
K9: EI_FPB | L9: =L16/2*L11*(3*L12^2-4*L11^2)/(24*L14) -> 8.1544572e+12 | M9: =M16/2*M11*(3*M12^2-4*M11^2)/(24*M14) -> 6.7665737e+12 | N9: =N16/2*N11*(3*N12^2-4*N11^2)/(24*N14) -> 6.3592503e+12 | O9: =O16/2*O11*(3*O12^2-4*O11^2)/(24*O14) -> 7.897442e+12 | P9: =P16/2*P11*(3*P12^2-4*P11^2)/(24*P14) -> 9.2885738e+12 | Q9: =Q16/2*Q11*(3*Q12^2-4*Q11^2)/(24*Q14) -> 7.3700225e+12 | R9: =R16/2*R11*(3*R12^2-4*R11^2)/(24*R14) -> 1.7051087e+12 | Y9: EI_FPB (kNm2) | Z9: EI_global (kNm2) | AA9: EI_local (kNm2)
D10: P-LWC-A | E10: P-LWC-B | F10: P-LWC-C | G10: P-NWC-A | H10: P-NWC-B | I10: P-NWC-C | L10: P-LWC-A | M10: P-LWC-B | N10: P-LWC-C | O10: P-NWC-A | P10: P-NWC-B | Q10: P-NWC-C | R10: Timber | W10: P-NWC | X10: A | Y10: =O9/1000^3 -> 7897.442 | Z10: =O20 -> 8720.0444 | AA10: =O28 -> 13223.855
C11: a | D11: 1650 | E11: 1650 | F11: 1650 | G11: 1650 | H11: 1650 | I11: 1650 | K11: a | L11: 1650 | M11: 1650 | N11: 1650 | O11: 1650 | P11: 1650 | Q11: 1650 | R11: 1650 | X11: B | Y11: =P9/1000^3 -> 9288.5738 | Z11: =P20 -> 9376.497 | AA11: =P28 -> 8935.3722
C12: L | D12: 5000 | E12: 5000 | F12: 5000 | G12: 5000 | H12: 5000 | I12: 5000 | K12: L | L12: 5000 | M12: 5000 | N12: 5000 | O12: 5000 | P12: 5000 | Q12: 5000 | R12: 5000 | X12: C | Y12: =Q9/1000^3 -> 7370.0225 | Z12: =Q20 -> 8162.1528 | AA12: =Q28 -> 9618.8138
C13: w2 | D13: =graphs!AA17 -> 5.65 | E13: =graphs!AD14 -> 6.8 | F13: =graphs!AG19 -> 6.6 | G13: =graphs!R33 -> 5.659893 | H13: =graphs!U31 -> 4.859981 | I13: =graphs!X29 -> 6.233481 | K13: w2 | L13: =graphs!AA14 -> 2 | M13: =[1]B!$J$175 -> 2.38 | N13: =graphs!AG12 -> 3.7 | O13: =[2]A!$J$258 -> 3.1 | P13: =[2]B!$J$194 -> 2.4 | Q13: =[2]C!$J$212 -> 3.4 | R13: =graphs!O12 -> 14.597655 | X13: Overall mean | Y13: =AVERAGE(Y10:Y12) -> 8185.3461 | Z13: =AVERAGE(Z10:Z12) -> 8752.898 | AA13: =AVERAGE(AA10:AA12) -> 10592.68
C14: w1 | D14: =graphs!AA23 -> 12.02 | E14: =graphs!AD21 -> 13.31 | F14: =graphs!AG26 -> 12.7 | G14: =graphs!R43 -> 11.453602 | H14: =graphs!U41 -> 10.309157 | I14: =graphs!X39 -> 12.186516 | K14: w1 | L14: =graphs!AA17 -> 5.65 | M14: =graphs!AD14 -> 6.8 | N14: =graphs!AG20 -> 7.3 | O14: =[2]A!$J$297 -> 5.8 | P14: =[2]B!$J$214 -> 4.8 | Q14: =[2]C!$J$251 -> 6.1 | R14: =graphs!O16 -> 24.419654 | X14: Standard deviation | Y14: =STDEV(Y10:Y12) -> 991.14901 | Z14: =STDEV(Z10:Z12) -> 607.83836 | AA14: =STDEV(AA10:AA12) -> 2304.1447
C15: F2 | D15: =graphs!AB17 -> 20906.196 | E15: =graphs!AE14 -> 20878.978 | F15: =graphs!AH19 -> 18893.544 | G15: =graphs!S33 -> 20208.76 | H15: =graphs!V31 -> 20338.894 | I15: =graphs!Y29 -> 20622.161 | K15: F2 | L15: =graphs!AB14 -> 7714.3911 | M15: =[1]B!$R$174 -> 6627.0608 | N15: =graphs!AH12 -> 10749.41 | O15: =[2]A!$R$258 -> 10101.295 | P15: =[2]B!$R$194 -> 10019.852 | Q15: =[2]C!$R$212 -> 10400 | R15: =graphs!P12 -> 10364.232 | X15: COV (%) | Y15: =Y14/Y13*100 -> 12.108822 | Z15: =Z14/Z13*100 -> 6.944424 | AA15: =AA14/AA13*100 -> 21.752235
C16: F1 | D16: =graphs!AB23 -> 39565.548 | E16: =graphs!AE21 -> 38999.999 | F16: =graphs!AH26 -> 37081.916 | G16: =graphs!S43 -> 41042.469 | H16: =graphs!V41 -> 40920.147 | I16: =graphs!Y39 -> 40814.007 | K16: F1 | L16: =graphs!AB17 -> 20906.196 | M16: =graphs!AE14 -> 20878.978 | N16: =graphs!AH20 -> 21064.943 | O16: =[2]A!$R$297 -> 20784.805 | P16: =[2]B!$R$214 -> 20231.207 | Q16: =[2]C!$R$251 -> 20400 | R16: =graphs!P16 -> 18893.965 | W16: P-LWC | X16: A | Y16: =L9/1000^3 -> 8154.4572 | Z16: =L20 -> 7964.8912 | AA16: =L28 -> 11280.177
C17: L1 | D17: =D12-2*D11 -> 1700 | E17: =E12-2*E11 -> 1700 | F17: =F12-2*F11 -> 1700 | G17: =G12-2*G11 -> 1700 | H17: =H12-2*H11 -> 1700 | I17: =I12-2*I11 -> 1700 | K17: L1 | L17: =L12-2*L11 -> 1700 | M17: =M12-2*M11 -> 1700 | N17: =N12-2*N11 -> 1700 | O17: =O12-2*O11 -> 1700 | P17: =P12-2*P11 -> 1700 | Q17: =Q12-2*Q11 -> 1700 | R17: =R12-2*R11 -> 1700 | X17: B | Y17: =M9/1000^3 -> 6766.5737 | Z17: =M20 -> 7105.907 | AA17: =M28 -> 9753.2408
B18: Eiglobal | C18: EI | D18: =(3*D11*D12^2-4*D11^3)/(24*(2*(D13-D14)/(D15-D16)))/1000^3 -> 6455.4364 | E18: =(3*E11*E12^2-4*E11^3)/(24*(2*(E13-E14)/(E15-E16)))/1000^3 -> 6134.3727 | F18: =(3*F11*F12^2-4*F11^3)/(24*(2*(F13-F14)/(F15-F16)))/1000^3 -> 6571.0154 | G18: =(3*G11*G12^2-4*G11^3)/(24*(2*(G13-G14)/(G15-G16)))/1000^3 -> 7924.6194 | H18: =(3*H11*H12^2-4*H11^3)/(24*(2*(H13-H14)/(H15-H16)))/1000^3 -> 8323.5668 | I18: =(3*I11*I12^2-4*I11^3)/(24*(2*(I13-I14)/(I15-I16)))/1000^3 -> 7474.9117 | K18: P | L18: =graphs!AB15 -> 14392.089 | M18: =graphs!AE13 -> 16756.299 | N18: =graphs!AH17 -> 14185.933 | O18: =graphs!S31 -> 16167.256 | P18: =graphs!V29 -> 16296.45 | Q18: =graphs!Y27 -> 16559.404 | R18: =graphs!P14 -> 14717.441 | X18: C | Y18: =N9/1000^3 -> 6359.2503 | Z18: =N20 -> 6314.772 | AA18: =N28 -> 3103.2629
B19: Eiglobal | C19: average | D19: =AVERAGE(D18:F18) -> 6386.9415 | G19: =AVERAGE(G18:I18) -> 7907.6993 | L19: =graphs!AA15 -> 3.84 | M19: =graphs!AD13 -> 5.06 | N19: =graphs!AG17 -> 5 | O19: =graphs!R31 -> 4.605554 | P19: =graphs!U29 -> 3.873332 | Q19: =graphs!X27 -> 5.133202 | R19: =graphs!O14 -> 19.559654 | X19: Overall mean | Y19: =AVERAGE(Y16:Y18) -> 7093.4271 | Z19: =AVERAGE(Z16:Z18) -> 7128.5234 | AA19: =AVERAGE(AA16:AA18) -> 8045.5601
C20: old_average | D20: =#REF! -> #REF! | G20: =#REF! -> #REF! | L20: =(3*L11*L12^2-4*L11^3)/(24*(2*(L13-L14)/(L15-L16)))/1000^3 -> 7964.8912 | M20: =(3*M11*M12^2-4*M11^3)/(24*(2*(M13-M14)/(M15-M16)))/1000^3 -> 7105.907 | N20: =(3*N11*N12^2-4*N11^3)/(24*(2*(N13-N14)/(N15-N16)))/1000^3 -> 6314.772 | O20: =(3*O11*O12^2-4*O11^3)/(24*(2*(O13-O14)/(O15-O16)))/1000^3 -> 8720.0444 | P20: =(3*P11*P12^2-4*P11^3)/(24*(2*(P13-P14)/(P15-P16)))/1000^3 -> 9376.497 | Q20: =(3*Q11*Q12^2-4*Q11^3)/(24*(2*(Q13-Q14)/(Q15-Q16)))/1000^3 -> 8162.1528 | R20: =(3*R11*R12^2-4*R11^3)/(24*(2*(R13-R14)/(R15-R16)))/1000^3 -> 1913.8328 | X20: Standard deviation | Y20: =STDEV(Y16:Y18) -> 941.17843 | Z20: =STDEV(Z16:Z18) -> 825.29203 | AA20: =STDEV(AA16:AA18) -> 4347.7131
B21: Eilocal | C21: EI | D21: =D11*D17^2*(D16-D15)/(16*(D14-D13))/1000^3 -> 873.00942 | E21: =E11*E17^2*(E16-E15)/(16*(E14-E13))/1000^3 -> 829.58994 | F21: =F11*F17^2*(F16-F15)/(16*(F14-F13))/1000^3 -> 888.63989 | G21: =G11*G17^2*(G16-G15)/(16*(G14-G13))/1000^3 -> 1071.6963 | H21: =H11*H17^2*(H16-H15)/(16*(H14-H13))/1000^3 -> 1125.6485 | I21: =I11*I17^2*(I16-I15)/(16*(I14-I13))/1000^3 -> 1010.8795 | K21: EI_global | L21: =AVERAGE(L20:N20) -> 7128.5234 | O21: =AVERAGE(O20:Q20) -> 8752.898 | R21: =R20 -> 1913.8328 | X21: COV (%) | Y21: =Y20/Y19*100 -> 13.268317 | Z21: =Z20/Z19*100 -> 11.577321 | AA21: =AA20/AA19*100 -> 54.038663
D22: =AVERAGE(D21:F21) -> 863.74642 | G22: =AVERAGE(G21:I21) -> 1069.4081 | K22: EI4pb | L22: =L18*L11*(3*L12^2-4*L11^2)/(24*L19)/1000^3 -> 16519.28 | M22: =M18*M11*(3*M12^2-4*M11^2)/(24*M19)/1000^3 -> 14595.739 | N22: =N18*N11*(3*N12^2-4*N11^2)/(24*N19)/1000^3 -> 12505.077 | O22: =O18*O11*(3*O12^2-4*O11^2)/(24*O19)/1000^3 -> 15472.23 | P22: =P18*P11*(3*P12^2-4*P11^2)/(24*P19)/1000^3 -> 18544.142 | Q22: =Q18*Q11*(3*Q12^2-4*Q11^2)/(24*Q19)/1000^3 -> 14218.534 | R22: =R18*R11*(3*R12^2-4*R11^2)/(24*R19)/1000^3 -> 3316.4207 | W22: Timber beam | Y22: =R9/1000^3 -> 1705.1087 | Z22: =R20 -> 1913.8328 | AA22: =R28 -> 1891.0975
L23: =AVERAGE(L22:N22) -> 14540.032 | O23: =AVERAGE(O22:Q22) -> 16078.302 | R23: =R22 -> 3316.4207
D24: EI | E24: =11500*90*270^3/12 -> 1697658750000 | K24: w2-2 | L24: =[1]A!$M$193/2+[1]A!$I$193/2 -> 1.9443215 | M24: =[1]B!$M$175/2+[1]B!$I$175/2 -> 2.034826 | N24: =[1]C!$M$162/2+[1]C!$I$162/2 -> 3.119206 | O24: =[2]A!$I$258/2+[2]A!$M$258/2 -> 2.6154965 | P24: =[2]B!$I$194/2+[2]B!$M$194/2 -> 2.1162035 | Q24: =[2]C!$I$212/2+[2]C!$M$212/2 -> 2.921173 | R24: =([1]Sheet1!$B$367+[1]Sheet1!$D$367)/2 -> 12.268239
K25: w1-2 | L25: =[1]A!$M$219/2+[1]A!$I$219/2 -> 5.2457835 | M25: =[1]B!$M$189/2+[1]B!$I$189/2 -> 6.019328 | N25: =[1]C!$M$248/2+[1]C!$I$248/2 -> 5.7285225 | O25: =[2]A!$I$297/2+[2]A!$M$297/2 -> 5.074718 | P25: =[2]B!$I$214/2+[2]B!$M$214/2 -> 4.175613 | Q25: =[2]C!$I$251/2+[2]C!$M$251/2 -> 5.311331 | R25: =[1]Sheet1!$B$424/2+[1]Sheet1!$D$424/2 -> 20.745978
D26: LWC | E26: =(D19-E24)/E24*100 -> -100 | K26: w2net | L26: =L13-L24 -> 0.0556785 | M26: =M13-M24 -> 0.345174 | N26: =N13-N24 -> 0.580794 | O26: =O13-O24 -> 0.4845035 | P26: =P13-P24 -> 0.2837965 | Q26: =Q13-Q24 -> 0.478827 | R26: =R13-R24 -> 2.3294155
D27: NWC | E27: =(G19-E24)/E24*100 -> -100 | K27: w1net | L27: =L14-L25 -> 0.4042165 | M27: =M14-M25 -> 0.780672 | N27: =N14-N25 -> 1.5714775 | O27: =O14-O25 -> 0.725282 | P27: =P14-P25 -> 0.624387 | Q27: =Q14-Q25 -> 0.788669 | R27: =R14-R25 -> 3.6736755
L28: =L11*L17^2*(L16-L15)/(16*(L27-L26))/1000^3 -> 11280.177 | M28: =M11*M17^2*(M16-M15)/(16*(M27-M26))/1000^3 -> 9753.2408 | N28: =N11*N17^2*(N16-N15)/(16*(N27-N26))/1000^3 -> 3103.2629 | O28: =O11*O17^2*(O16-O15)/(16*(O27-O26))/1000^3 -> 13223.855 | P28: =P11*P17^2*(P16-P15)/(16*(P27-P26))/1000^3 -> 8935.3722 | Q28: =Q11*Q17^2*(Q16-Q15)/(16*(Q27-Q26))/1000^3 -> 9618.8138 | R28: =R11*R17^2*(R16-R15)/(16*(R27-R26))/1000^3 -> 1891.0975
K29: EI_local | L29: =AVERAGE(L28:N28) -> 8045.5601 | O29: =AVERAGE(O28:Q28) -> 10592.68 | R29: =R28 -> 1891.0975
