Workbook

Sheet Plan
A1: Udmattelse
A3: prj nummer | B3: 44055 I-1 | J3: dato | K3: emner
A4: Plader: | B4: EQA02 | I4: Modtaget
A5: Geometri: | E5: Med tabs
B6: R= | C6: 0.1 | E6: Frekvens | F6: 5 Hz
B7: Specimen | C7: Width | D7: Thickness | E7: Area | F7: Max strain | G7: E-mod 1. load | H7: E-mod. 2. load | I7: Max load | J7: Min Load | K7: Frequency | L7: Cycles to failure | M7: Comments | N7: Prøvemaskine
A8: Date | B8: # | C8: (mm) | D8: (mm) | E8: (mm2) | F8: (%) | I8: (kN) | J8: (kN) | K8: (Hz)
B9: =+$B$4&"-0"&TEXT((ROW()-8),0) -> EQA02-01 | C9: 25.01 | D9: 4.15 | E9: =+C9*D9 -> 103.7915 | F9: _ | G9: 38.55 | H9: _ | I9: 105.5 | J9: _ | K9: 5 | L9: 1 | M9: Static | N9: 88R1342
B10: =+$B$4&"-0"&TEXT((ROW()-8),0) -> EQA02-02 | C10: 25.19 | D10: 4.35 | E10: =+C10*D10 -> 109.5765 | F10: _ | G10: 37.66 | H10: _ | I10: 108.6 | J10: _ | K10: 5 | L10: 1 | M10: Static | N10: 88R1342
A11: 42216 | B11: =+$B$4&"-0"&TEXT((ROW()-8),0) -> EQA02-03 | C11: 25.21 | D11: 4.36 | E11: =+C11*D11 -> 109.9156 | F11: 1 | G11: 38.208 | H11: 38.07 | I11: 41.84 | J11: 4.18 | K11: 5 | L11: 36156 | M11: Fatige | N11: 88R1342
A12: 42219 | B12: =+$B$4&"-0"&TEXT((ROW()-8),0) -> EQA02-04 | C12: 25.19 | D12: 4.25 | E12: =+C12*D12 -> 107.0575 | F12: 0.9 | G12: 38.71 | H12: 38.5 | I12: 37.1 | J12: 3.71 | K12: 5 | L12: 83871 | M12: Fatige | N12: 88R1342
A13: 42219 | B13: =+$B$4&"-0"&TEXT((ROW()-8),0) -> EQA02-05 | C13: 25.18 | D13: 4.21 | E13: =+C13*D13 -> 106.0078 | F13: 0.8 | G13: 38.75 | H13: 38.72 | I13: 32.84 | J13: 3.28 | K13: 5 | L13: 130906 | M13: Fatige | N13: 88R1331
A14: 42221 | B14: =+$B$4&"-0"&TEXT((ROW()-8),0) -> EQA02-06 | C14: 25.2 | D14: 4.28 | E14: =+C14*D14 -> 107.856 | F14: 1.1 | G14: 37.89 | H14: 37.62 | I14: 44.63 | J14: 4.46 | K14: 5 | L14: 24379 | M14: Fatigue | N14: 88R1331
B15: =+$B$4&"-0"&TEXT((ROW()-8),0) -> EQA02-07 | C15: 25.19 | D15: 4.13 | E15: =+C15*D15 -> 104.0347 | K15: 5
B16: =+$B$4&"-0"&TEXT((ROW()-8),0) -> EQA02-08 | C16: 25.26 | D16: 4.28 | E16: =+C16*D16 -> 108.1128 | K16: 5
A17: 42219 | B17: =+$B$4&"-0"&TEXT((ROW()-8),0) -> EQA02-09 | C17: 25.25 | D17: 4.27 | E17: =+C17*D17 -> 107.8175 | F17: 0.7 | G17: 37.93 | H17: 38.36 | I17: 28.95 | J17: 2.9 | K17: 5 | L17: 255387 | M17: Fatigue | N17: 88R1342
A18: 42220 | B18: =+$B$4&"-"&TEXT((ROW()-8),0) -> EQA02-10 | C18: 25.27 | D18: 4.27 | E18: =+C18*D18 -> 107.9029 | F18: 0.6 | G18: 38.67 | H18: 38.76 | I18: 25.1 | J18: 2.51 | K18: 5 | L18: 596316 | M18: Fatigue | N18: 88R1342
A19: 42220 | B19: =+$B$4&"-"&TEXT((ROW()-8),0) -> EQA02-11 | C19: 25.28 | D19: 4.09 | E19: =+C19*D19 -> 103.3952 | F19: 0.55 | G19: 39.8 | H19: 39.9 | I19: 22.68 | J19: 2.27 | K19: 5 | L19: 2500000 | M19: Runout | N19: 88R8501
B20: =+$B$4&"-"&TEXT((ROW()-8),0) -> EQA02-12 | C20: 25.26 | D20: 4.18 | E20: =+C20*D20 -> 105.5868 | F20: _ | G20: 38.97 | H20: _ | I20: 100.7 | J20: _ | K20: 5 | L20: 1 | M20: Static | N20: 88R1342
G22: =AVERAGE(G11:G20) -> 38.616 | H22: =AVERAGE(H11:H20) -> 38.561429

Sheet Results
A1: =+Plan!A1 -> Udmattelse | D1: =B4&" Fatigue test" -> EQA02 Fatigue test
A3: =+Plan!A3 -> prj nummer
A4: =+Plan!A4 -> Plader: | B4: =+Plan!B4 -> EQA02
A5: =+Plan!A5 -> Geometri:
C6: =+Plan!B6 -> R= | D6: =+Plan!C6 -> 0.1 | E6: =+Plan!E6 -> Frekvens | F6: =+Plan!F6 -> 5 Hz | N6: From Ten and Fat Datafiles | U6: Matlab "DataAnalysis"
A7: Date | B7: Specimen | C7: Width | D7: Thickness | E7: Area | F7: Cycles to failure | G7: Abs Max strain | H7: Strain Range | I7: Peak stress | J7: Max load | K7: Min Load | L7: Mean Load | M7: Amplitude | N7: Ini Emod | O7: E-mod | P7: E-mod 1 | Q7: E-mod 2 | R7: Bending ratio | S7: Comments | U7: From Ten-files
B8: # | C8: (mm) | D8: (mm) | E8: (mm2) | G8: (%) | H8: (%) | I8: (MPa) | J8: (kN) | K8: (kN) | L8: (kN) | M8: (kN) | N8: (GPa) | O8: (GPa) | P8: (GPa) | Q8: (GPa) | R8: |E1+E2|/|E1+E2| | T8: Spec. | U8: Modulus a [GPa]: | V8: Modulus b [GPa]: | W8: Modulus a1 [GPa]: | X8: Modulus b1 [GPa]: | Y8: Modulus a2 [GPa]: | Z8: Modulus b2 [GPa]:
A9: =+Plan!A9 -> 0 | B9: =+Plan!B9 -> EQA02-01 | C9: =+Plan!C9 -> 25.01 | D9: =+Plan!D9 -> 4.15 | E9: =+Plan!E9 -> 103.7915 | F9: =+Plan!L9 -> 1 | G9: =+Plan!F9 -> _ | H9: =IF(ISNUMBER(G9),+G9*(1-$D$6),"") | I9: =+J9/E9*1000 -> #VALUE! | J9: =+O9*G9*E9/100 -> #VALUE! | K9: =+J9*$D$6 -> #VALUE! | L9: =+(J9+K9)/2 -> #VALUE! | M9: =+(J9-K9)/2 -> #VALUE! | N9: =+U9 -> 0 | O9: =+V9 -> 0 | P9: =+X9 -> 0 | Q9: =+Z9 -> 0 | R9: =+ABS(P9-Q9)/(P9+Q9) -> #DIV/0! | S9: =+Plan!N9 -> 88R1342
A10: =+Plan!A10 -> 0 | B10: =+Plan!B10 -> EQA02-02 | C10: =+Plan!C10 -> 25.19 | D10: =+Plan!D10 -> 4.35 | E10: =+Plan!E10 -> 109.5765 | F10: =+Plan!L10 -> 1 | G10: =+Plan!F10 -> _ | H10: =IF(ISNUMBER(G10),+G10*(1-$D$6),"") | I10: =+J10/C10/D10*1000 -> #VALUE! | J10: =+O10*G10*E10/100 -> #VALUE! | K10: =+J10*$D$6 -> #VALUE! | L10: =+(J10+K10)/2 -> #VALUE! | M10: =+(J10-K10)/2 -> #VALUE! | N10: =+U10 -> 0 | O10: =+V10 -> 0 | P10: =+X10 -> 0 | Q10: =+Z10 -> 0 | R10: =+ABS(P10-Q10)/(P10+Q10) -> #DIV/0! | S10: =+Plan!N10 -> 88R1342
A11: =+Plan!A11 -> 42216 | B11: =+Plan!B11 -> EQA02-03 | C11: =+Plan!C11 -> 25.21 | D11: =+Plan!D11 -> 4.36 | E11: =+Plan!E11 -> 109.9156 | F11: =+Plan!L11 -> 36156 | G11: =+Plan!F11 -> 1 | H11: =IF(ISNUMBER(G11),+G11*(1-$D$6),"") -> 0.9 | I11: =+J11/C11/D11*1000 -> 0 | J11: =+O11*G11*E11/100 -> 0 | K11: =+J11*$D$6 -> 0 | L11: =+(J11+K11)/2 -> 0 | M11: =+(J11-K11)/2 -> 0 | N11: =+U11 -> 0 | O11: =+V11 -> 0 | P11: =+X11 -> 0 | Q11: =+Z11 -> 0 | R11: =+ABS(P11-Q11)/(P11+Q11) -> #DIV/0! | S11: =+Plan!N11 -> 88R1342
A12: =+Plan!A12 -> 42219 | B12: =+Plan!B12 -> EQA02-04 | C12: =+Plan!C12 -> 25.19 | D12: =+Plan!D12 -> 4.25 | E12: =+Plan!E12 -> 107.0575 | F12: =+Plan!L12 -> 83871 | G12: =+Plan!F12 -> 0.9 | H12: =IF(ISNUMBER(G12),+G12*(1-$D$6),"") -> 0.81 | I12: =+J12/C12/D12*1000 -> 0 | J12: =+O12*G12*E12/100 -> 0 | K12: =+J12*$D$6 -> 0 | L12: =+(J12+K12)/2 -> 0 | M12: =+(J12-K12)/2 -> 0 | N12: =+U12 -> 0 | O12: =+V12 -> 0 | P12: =+X12 -> 0 | Q12: =+Z12 -> 0 | R12: =+ABS(P12-Q12)/(P12+Q12) -> #DIV/0! | S12: =+Plan!N12 -> 88R1342
A13: =+Plan!A13 -> 42219 | B13: =+Plan!B13 -> EQA02-05 | C13: =+Plan!C13 -> 25.18 | D13: =+Plan!D13 -> 4.21 | E13: =+Plan!E13 -> 106.0078 | F13: =+Plan!L13 -> 130906 | G13: =+Plan!F13 -> 0.8 | H13: =IF(ISNUMBER(G13),+G13*(1-$D$6),"") -> 0.72 | I13: =+J13/C13/D13*1000 -> 0 | J13: =+O13*G13*E13/100 -> 0 | K13: =+J13*$D$6 -> 0 | L13: =+(J13+K13)/2 -> 0 | M13: =+(J13-K13)/2 -> 0 | R13: =+ABS(P13-Q13)/(P13+Q13) -> #DIV/0! | S13: =+Plan!N13 -> 88R1331
A14: =+Plan!A14 -> 42221 | B14: =+Plan!B14 -> EQA02-06 | C14: =+Plan!C14 -> 25.2 | D14: =+Plan!D14 -> 4.28 | E14: =+Plan!E14 -> 107.856 | F14: =+Plan!L14 -> 24379 | G14: =+Plan!F14 -> 1.1 | H14: =IF(ISNUMBER(G14),+G14*(1-$D$6),"") -> 0.99 | I14: =+J14/C14/D14*1000 -> 0 | J14: =+O14*G14*E14/100 -> 0 | K14: =+J14*$D$6 -> 0 | L14: =+(J14+K14)/2 -> 0 | M14: =+(J14-K14)/2 -> 0 | R14: =+ABS(P14-Q14)/(P14+Q14) -> #DIV/0! | S14: =+Plan!N14 -> 88R1331
A15: =+Plan!A15 -> 0 | B15: =+Plan!B15 -> EQA02-07 | C15: =+Plan!C15 -> 25.19 | D15: =+Plan!D15 -> 4.13 | E15: =+Plan!E15 -> 104.0347 | F15: =+Plan!L15 -> 0 | G15: =+Plan!F15 -> 0 | H15: =IF(ISNUMBER(G15),+G15*(1-$D$6),"") -> 0 | I15: =+J15/C15/D15*1000 -> 0 | J15: =+O15*G15*E15/100 -> 0 | K15: =+J15*$D$6 -> 0 | L15: =+(J15+K15)/2 -> 0 | M15: =+(J15-K15)/2 -> 0 | R15: =+ABS(P15-Q15)/(P15+Q15) -> #DIV/0! | S15: =+Plan!N15 -> 0
A16: =+Plan!A16 -> 0 | B16: =+Plan!B16 -> EQA02-08 | C16: =+Plan!C16 -> 25.26 | D16: =+Plan!D16 -> 4.28 | E16: =+Plan!E16 -> 108.1128 | F16: =+Plan!L16 -> 0 | G16: =+Plan!F16 -> 0 | H16: =IF(ISNUMBER(G16),+G16*(1-$D$6),"") -> 0 | I16: =+J16/C16/D16*1000 -> 0 | J16: =+O16*G16*E16/100 -> 0 | K16: =+J16*$D$6 -> 0 | L16: =+(J16+K16)/2 -> 0 | M16: =+(J16-K16)/2 -> 0 | R16: =+ABS(P16-Q16)/(P16+Q16) -> #DIV/0! | S16: =+Plan!N16 -> 0
A17: =+Plan!A17 -> 42219 | B17: =+Plan!B17 -> EQA02-09 | C17: =+Plan!C17 -> 25.25 | D17: =+Plan!D17 -> 4.27 | E17: =+Plan!E17 -> 107.8175 | F17: =+Plan!L17 -> 255387 | G17: =+Plan!F17 -> 0.7 | H17: =IF(ISNUMBER(G17),+G17*(1-$D$6),"") -> 0.63 | I17: =+J17/C17/D17*1000 -> 0 | J17: =+O17*G17*E17/100 -> 0 | K17: =+J17*$D$6 -> 0 | L17: =+(J17+K17)/2 -> 0 | M17: =+(J17-K17)/2 -> 0 | R17: =+ABS(P17-Q17)/(P17+Q17) -> #DIV/0! | S17: =+Plan!N17 -> 88R1342
A18: =+Plan!A18 -> 42220 | B18: =+Plan!B18 -> EQA02-10 | C18: =+Plan!C18 -> 25.27 | D18: =+Plan!D18 -> 4.27 | E18: =+Plan!E18 -> 107.9029 | F18: =+Plan!L18 -> 596316 | G18: =+Plan!F18 -> 0.6 | H18: =IF(ISNUMBER(G18),+G18*(1-$D$6),"") -> 0.54 | I18: =+J18/C18/D18*1000 -> 0 | J18: =+O18*G18*E18/100 -> 0 | K18: =+J18*$D$6 -> 0 | L18: =+(J18+K18)/2 -> 0 | M18: =+(J18-K18)/2 -> 0 | R18: =+ABS(P18-Q18)/(P18+Q18) -> #DIV/0! | S18: =+Plan!N18 -> 88R1342
A19: =+Plan!A19 -> 42220 | B19: =+Plan!B19 -> EQA02-11 | C19: =+Plan!C19 -> 25.28 | D19: =+Plan!D19 -> 4.09 | E19: =+Plan!E19 -> 103.3952 | F19: =+Plan!L19 -> 2500000 | G19: =+Plan!F19 -> 0.55 | H19: =IF(ISNUMBER(G19),+G19*(1-$D$6),"") -> 0.495 | I19: =+J19/C19/D19*1000 -> 0 | J19: =+O19*G19*E19/100 -> 0 | K19: =+J19*$D$6 -> 0 | L19: =+(J19+K19)/2 -> 0 | M19: =+(J19-K19)/2 -> 0 | R19: =+ABS(P19-Q19)/(P19+Q19) -> #DIV/0! | S19: =+Plan!N19 -> 88R8501
A21: SN-Curve | B21: Astm Stat | H21: Modulus (Gpa) | I21: Cycles @ 1% max strain
A22: Cycles | B22: Max Strain | C22: Cycles | D22: Strain Range | E22: Cycles | F22: Max Stress | G22: =+B4 -> EQA02 | H22: =+Plan!H22 -> 38.561429 | I22: =+'ASTM E739 stat (Max Strain)'!J13 -> 40534.605
A23: =+F9 -> 1 | B23: =+G9 -> _ | C23: =+F9 -> 1 | D23: =+H9 | E23: =+F9 -> 1 | F23: =+I9 -> #VALUE!
A24: =+F10 -> 1 | B24: =+G10 -> _ | C24: =+F10 -> 1 | D24: =+H10 | E24: =+F10 -> 1 | F24: =+I10 -> #VALUE!
A25: =+F11 -> 36156 | B25: =+G11 -> 1 | C25: =+F11 -> 36156 | D25: =+H11 -> 0.9 | E25: =+F11 -> 36156 | F25: =+I11 -> 0
A26: =+F12 -> 83871 | B26: =+G12 -> 0.9 | C26: =+F12 -> 83871 | D26: =+H12 -> 0.81 | E26: =+F12 -> 83871 | F26: =+I12 -> 0
A27: =+F13 -> 130906 | B27: =+G13 -> 0.8 | C27: =+F13 -> 130906 | D27: =+H13 -> 0.72 | E27: =+F13 -> 130906 | F27: =+I13 -> 0
A28: =+F14 -> 24379 | B28: =+G14 -> 1.1 | C28: =+F14 -> 24379 | D28: =+H14 -> 0.99 | E28: =+F14 -> 24379 | F28: =+I14 -> 0
A29: =+F15 -> 0 | B29: =+G15 -> 0 | C29: =+F15 -> 0 | D29: =+H15 -> 0 | E29: =+F15 -> 0 | F29: =+I15 -> 0
A30: =+F16 -> 0 | B30: =+G16 -> 0 | C30: =+F16 -> 0 | D30: =+H16 -> 0 | E30: =+F16 -> 0 | F30: =+I16 -> 0
A31: =+F17 -> 255387 | B31: =+G17 -> 0.7 | C31: =+F17 -> 255387 | D31: =+H17 -> 0.63 | E31: =+F17 -> 255387 | F31: =+I17 -> 0
A32: =+F18 -> 596316 | B32: =+G18 -> 0.6 | C32: =+F18 -> 596316 | D32: =+H18 -> 0.54 | E32: =+F18 -> 596316 | F32: =+I18 -> 0
A33: =+F19 -> 2500000 | B33: =+G19 -> 0.55 | C33: =+F19 -> 2500000 | D33: =+H19 -> 0.495 | E33: =+F19 -> 2500000 | F33: =+I19 -> 0

Sheet ASTM E739 stat (Max Strain)
A1: SN Points | C1: X | D1: Y | E1: X^2 | F1: Y^2 | G1: X*Y | H1: N | I1: =COUNT(C:C) -> 6 | M1: X | N1: YHAT | O1: X | P1: Xconfi | Q1: Yavg | R1: Y1 | S1: Y2 | T1: SN-line | V1: Lower conf | X1: Upper Conf | Z1: SUMMARY OUTPUT
H2: SUMX | I2: =SUM(C:C) -> -0.47802553 | M2: =+C2 -> 0 | N2: =+$I$13+$I$12*M2 -> 4.6078259 | O2: =LOG($I$19+($I$20-$I$19)*(ROW()-2)/100) -> -0.25963731 | P2: =SQRT(2*$I$16*$K$24)*SQRT((1/$I$1)+((O2-$I$10)^2/$I$7)) -> 0.1555675 | Q2: =+$I$13+$I$12*O2 -> 5.9773598 | R2: =+$I$13+$I$12*O2-P2 -> 5.8217923 | S2: =+$I$13+$I$12*O2+P2 -> 6.1329273 | T2: =10^Q2 -> 949204.59 | U2: =10^$O2 -> 0.55 | V2: =10^R2 -> 663425.75 | W2: =10^$O2 -> 0.55 | X2: =10^S2 -> 1358086.2 | Y2: =10^$O2 -> 0.55
H3: SUMY | I3: =SUM(D:D) -> 30.168443 | M3: =+C3 -> 0 | N3: =+$I$13+$I$12*M3 -> 4.6078259 | O3: =LOG($I$19+($I$20-$I$19)*(ROW()-2)/100) -> -0.25531594 | P3: =SQRT(2*$I$16*$K$24)*SQRT((1/$I$1)+((O3-$I$10)^2/$I$7)) -> 0.15258324 | Q3: =+$I$13+$I$12*O3 -> 5.9545655 | R3: =+$I$13+$I$12*O3-P3 -> 5.8019822 | S3: =+$I$13+$I$12*O3+P3 -> 6.1071487 | T3: =10^Q3 -> 900669.51 | U3: =10^O3 -> 0.5555 | V3: =10^R3 -> 633843.77 | W3: =10^$O3 -> 0.5555 | X3: =10^S3 -> 1279819.4 | Y3: =10^$O3 -> 0.5555 | Z3: Regression Statistics
A4: =+Results!B25 -> 1 | B4: =+Results!A25 -> 36156 | C4: =LOG(A4) -> 0 | D4: =LOG(B4) -> 4.5581804 | E4: =+C4^2 -> 0 | F4: =+D4^2 -> 20.777008 | G4: =+C4*D4 -> 0 | H4: SUMXX | I4: =SUM(E:E) -> 0.086410138 | M4: =+C4 -> 0 | N4: =+$I$13+$I$12*M4 -> 4.6078259 | O4: =LOG($I$19+($I$20-$I$19)*(ROW()-2)/100) -> -0.25103714 | P4: =SQRT(2*$I$16*$K$24)*SQRT((1/$I$1)+((O4-$I$10)^2/$I$7)) -> 0.14964331 | Q4: =+$I$13+$I$12*O4 -> 5.9319957 | R4: =+$I$13+$I$12*O4-P4 -> 5.7823524 | S4: =+$I$13+$I$12*O4+P4 -> 6.081639 | T4: =10^Q4 -> 855058.2 | U4: =10^O4 -> 0.561 | V4: =10^R4 -> 605832.22 | W4: =10^$O4 -> 0.561 | X4: =10^S4 -> 1206810.2 | Y4: =10^$O4 -> 0.561 | Z4: Multiple R | AA4: 0.88244047
A5: =+Results!B26 -> 0.9 | B5: =+Results!A26 -> 83871 | C5: =LOG(A5) -> -0.045757491 | D5: =LOG(B5) -> 4.9236118 | E5: =+C5^2 -> 0.0020937479 | F5: =+D5^2 -> 24.241953 | G5: =+C5*D5 -> -0.22529212 | H5: SUMYY | I5: =SUM(F:F) -> 153.04207 | M5: =+C5 -> -0.045757491 | N5: =+$I$13+$I$12*M5 -> 4.8491874 | O5: =LOG($I$19+($I$20-$I$19)*(ROW()-2)/100) -> -0.24680009 | P5: =SQRT(2*$I$16*$K$24)*SQRT((1/$I$1)+((O5-$I$10)^2/$I$7)) -> 0.1467476 | Q5: =+$I$13+$I$12*O5 -> 5.9096461 | R5: =+$I$13+$I$12*O5-P5 -> 5.7628985 | S5: =+$I$13+$I$12*O5+P5 -> 6.0563937 | T5: =10^Q5 -> 812168.4 | U5: =10^O5 -> 0.5665 | V5: =10^R5 -> 579293.28 | W5: =10^$O5 -> 0.5665 | X5: =10^S5 -> 1138659 | Y5: =10^$O5 -> 0.5665 | Z5: R Square | AA5: 0.77870118
A6: =+Results!B27 -> 0.8 | B6: =+Results!A27 -> 130906 | C6: =LOG(A6) -> -0.096910013 | D6: =LOG(B6) -> 5.1169596 | E6: =+C6^2 -> 0.0093915506 | F6: =+D6^2 -> 26.183275 | G6: =+C6*D6 -> -0.49588462 | H6: SUMXY | I6: =SUM(G:G) -> -2.6584543 | M6: =+C6 -> -0.096910013 | N6: =+$I$13+$I$12*M6 -> 5.1190065 | O6: =LOG($I$19+($I$20-$I$19)*(ROW()-2)/100) -> -0.24260397 | P6: =SQRT(2*$I$16*$K$24)*SQRT((1/$I$1)+((O6-$I$10)^2/$I$7)) -> 0.14389601 | Q6: =+$I$13+$I$12*O6 -> 5.8875124 | R6: =+$I$13+$I$12*O6-P6 -> 5.7436164 | S6: =+$I$13+$I$12*O6+P6 -> 6.0314085 | T6: =10^Q6 -> 771813.62 | U6: =10^O6 -> 0.572 | V6: =10^R6 -> 554136.07 | W6: =10^$O6 -> 0.572 | X6: =10^S6 -> 1075000 | Y6: =10^$O6 -> 0.572 | Z6: Adjusted R Square | AA6: 0.75103883
A7: =+Results!B28 -> 1.1 | B7: =+Results!A28 -> 24379 | C7: =LOG(A7) -> 0.041392685 | D7: =LOG(B7) -> 4.3870159 | E7: =+C7^2 -> 0.0017133544 | F7: =+D7^2 -> 19.245908 | G7: =+C7*D7 -> 0.18159037 | H7: SAKX | I7: =+I4-I2^2/$I$1 -> 0.048325404 | M7: =+C7 -> 0.041392685 | N7: =+$I$13+$I$12*M7 -> 4.389488 | O7: =LOG($I$19+($I$20-$I$19)*(ROW()-2)/100) -> -0.23844801 | P7: =SQRT(2*$I$16*$K$24)*SQRT((1/$I$1)+((O7-$I$10)^2/$I$7)) -> 0.14108852 | Q7: =+$I$13+$I$12*O7 -> 5.8655906 | R7: =+$I$13+$I$12*O7-P7 -> 5.7245021 | S7: =+$I$13+$I$12*O7+P7 -> 6.0066791 | T7: =10^Q7 -> 733821.78 | U7: =10^O7 -> 0.5775 | V7: =10^R7 -> 530276.13 | W7: =10^$O7 -> 0.5775 | X7: =10^S7 -> 1015498.1 | Y7: =10^$O7 -> 0.5775 | Z7: Standard Error | AA7: 4.8757094
H8: SAKY (SAKtotal) | I8: =+I5-I3^2/$I$1 -> 1.3529146 | M8: =+C8 -> 0 | N8: =+$I$13+$I$12*M8 -> 4.6078259 | O8: =LOG($I$19+($I$20-$I$19)*(ROW()-2)/100) -> -0.23433145 | P8: =SQRT(2*$I$16*$K$24)*SQRT((1/$I$1)+((O8-$I$10)^2/$I$7)) -> 0.13832513 | Q8: =+$I$13+$I$12*O8 -> 5.8438765 | R8: =+$I$13+$I$12*O8-P8 -> 5.7055514 | S8: =+$I$13+$I$12*O8+P8 -> 5.9822017 | T8: =10^Q8 -> 698033.95 | U8: =10^O8 -> 0.583 | V8: =10^R8 -> 507634.84 | W8: =10^$O8 -> 0.583 | X8: =10^S8 -> 959846.27 | Y8: =10^$O8 -> 0.583 | Z8: Observations | AA8: 10
H9: SAPXY | I9: =+I6-I2*I3/$I$1 -> -0.25490665 | M9: =+C9 -> 0 | N9: =+$I$13+$I$12*M9 -> 4.6078259 | O9: =LOG($I$19+($I$20-$I$19)*(ROW()-2)/100) -> -0.23025353 | P9: =SQRT(2*$I$16*$K$24)*SQRT((1/$I$1)+((O9-$I$10)^2/$I$7)) -> 0.1356059 | Q9: =+$I$13+$I$12*O9 -> 5.8223664 | R9: =+$I$13+$I$12*O9-P9 -> 5.6867605 | S9: =+$I$13+$I$12*O9+P9 -> 5.9579723 | T9: =10^Q9 -> 664303.27 | U9: =10^O9 -> 0.5885 | V9: =10^R9 -> 486139.03 | W9: =10^$O9 -> 0.5885 | X9: =10^S9 -> 907762.61 | Y9: =10^$O9 -> 0.5885
A10: =+Results!B31 -> 0.7 | B10: =+Results!A31 -> 255387 | C10: =LOG(A10) -> -0.15490196 | D10: =LOG(B10) -> 5.4071988 | E10: =+C10^2 -> 0.023994617 | F10: =+D10^2 -> 29.237799 | G10: =+C10*D10 -> -0.83758569 | H10: XMEAN | I10: =+I2/$I$1 -> -0.079670921 | M10: =+C10 -> -0.15490196 | N10: =+$I$13+$I$12*M10 -> 5.4249022 | O10: =LOG($I$19+($I$20-$I$19)*(ROW()-2)/100) -> -0.22621356 | P10: =SQRT(2*$I$16*$K$24)*SQRT((1/$I$1)+((O10-$I$10)^2/$I$7)) -> 0.13293093 | Q10: =+$I$13+$I$12*O10 -> 5.8010563 | R10: =+$I$13+$I$12*O10-P10 -> 5.6681254 | S10: =+$I$13+$I$12*O10+P10 -> 5.9339873 | T10: =10^Q10 -> 632493.89 | U10: =10^O10 -> 0.594 | V10: =10^R10 -> 465720.55 | W10: =10^$O10 -> 0.594 | X10: =10^S10 -> 858988.33 | Y10: =10^$O10 -> 0.594 | Z10: ANOVA
A11: =+Results!B32 -> 0.6 | B11: =+Results!A32 -> 596316 | C11: =LOG(A11) -> -0.22184875 | D11: =LOG(B11) -> 5.7754765 | E11: =+C11^2 -> 0.049216868 | F11: =+D11^2 -> 33.356128 | G11: =+C11*D11 -> -1.2812822 | H11: YMEAN | I11: =+I3/$I$1 -> 5.0280738 | M11: =+C11 -> -0.22184875 | N11: =+$I$13+$I$12*M11 -> 5.7780329 | O11: =LOG($I$19+($I$20-$I$19)*(ROW()-2)/100) -> -0.22221081 | P11: =SQRT(2*$I$16*$K$24)*SQRT((1/$I$1)+((O11-$I$10)^2/$I$7)) -> 0.13030039 | Q11: =+$I$13+$I$12*O11 -> 5.7799427 | R11: =+$I$13+$I$12*O11-P11 -> 5.6496423 | S11: =+$I$13+$I$12*O11+P11 -> 5.9102431 | T11: =10^Q11 -> 602480.07 | U11: =10^O11 -> 0.5995 | V11: =10^R11 -> 446315.83 | W11: =10^$O11 -> 0.5995 | X11: =10^S11 -> 813285.58 | Y11: =10^$O11 -> 0.5995 | AA11: df | AB11: SS | AC11: MS | AD11: F | AE11: Significance F
A12: =+Results!B33 -> 0.55 | B12: =+Results!A33 -> 2500000 | H12: A1 | I12: =+I9/I7 -> -5.2747961 | J12: =+I12 -> -5.2747961 | K12: =1/J12 -> -0.18958079 | M12: =+C12 -> 0 | N12: =+$I$13+$I$12*M12 -> 4.6078259 | O12: =LOG($I$19+($I$20-$I$19)*(ROW()-2)/100) -> -0.21824463 | P12: =SQRT(2*$I$16*$K$24)*SQRT((1/$I$1)+((O12-$I$10)^2/$I$7)) -> 0.12771447 | Q12: =+$I$13+$I$12*O12 -> 5.7590219 | R12: =+$I$13+$I$12*O12-P12 -> 5.6313074 | S12: =+$I$13+$I$12*O12+P12 -> 5.8867363 | T12: =10^Q12 -> 574145.35 | U12: =10^O12 -> 0.605 | V12: =10^R12 -> 427865.61 | W12: =10^$O12 -> 0.605 | X12: =10^S12 -> 770435.57 | Y12: =10^$O12 -> 0.605 | Z12: Regression | AA12: 1 | AB12: 669.20218 | AC12: 669.20218 | AD12: 28.150215 | AE12: 0.00072341619
H13: A0 | I13: =+I11-I12*I10 -> 4.6078259 | J13: =10^I13 -> 40534.605 | K13: =+J13^J12 -> 4.9505961e-25 | M13: =+C13 -> 0 | N13: =+$I$13+$I$12*M13 -> 4.6078259 | O13: =LOG($I$19+($I$20-$I$19)*(ROW()-2)/100) -> -0.21431433 | P13: =SQRT(2*$I$16*$K$24)*SQRT((1/$I$1)+((O13-$I$10)^2/$I$7)) -> 0.12517345 | Q13: =+$I$13+$I$12*O13 -> 5.7382904 | R13: =+$I$13+$I$12*O13-P13 -> 5.6131169 | S13: =+$I$13+$I$12*O13+P13 -> 5.8634638 | T13: =10^Q13 -> 547381.8 | U13: =10^O13 -> 0.6105 | V13: =10^R13 -> 410314.54 | W13: =10^$O13 -> 0.6105 | X13: =10^S13 -> 730236.96 | Y13: =10^$O13 -> 0.6105 | Z13: Residual | AA13: 8 | AB13: 190.18034 | AC13: 23.772542
H14: R2 | I14: =+I9^2/(I7*I8) -> 0.99384002 | J14: ="(X="&TEXT(J13,"0.0")&"Y^"&TEXT(J12,"0.00")&")" -> (X=40534.6Y^-5.27) | M14: =+C14 -> 0 | N14: =+$I$13+$I$12*M14 -> 4.6078259 | O14: =LOG($I$19+($I$20-$I$19)*(ROW()-2)/100) -> -0.21041929 | P14: =SQRT(2*$I$16*$K$24)*SQRT((1/$I$1)+((O14-$I$10)^2/$I$7)) -> 0.12267764 | Q14: =+$I$13+$I$12*O14 -> 5.7177448 | R14: =+$I$13+$I$12*O14-P14 -> 5.5950672 | S14: =+$I$13+$I$12*O14+P14 -> 5.8404224 | T14: =10^Q14 -> 522089.3 | U14: =10^O14 -> 0.616 | V14: =10^R14 -> 393610.94 | W14: =10^$O14 -> 0.616 | X14: =10^S14 -> 692504.23 | Y14: =10^$O14 -> 0.616 | Z14: Total | AA14: 9 | AB14: 859.38251
H15: T-VALUE | I15: =VLOOKUP($J$24,$H$33:$J$69,2) -> 2.7764 | M15: =+C15 -> 0 | N15: =+$I$13+$I$12*M15 -> 4.6078259 | O15: =LOG($I$19+($I$20-$I$19)*(ROW()-2)/100) -> -0.20655887 | P15: =SQRT(2*$I$16*$K$24)*SQRT((1/$I$1)+((O15-$I$10)^2/$I$7)) -> 0.12022739 | Q15: =+$I$13+$I$12*O15 -> 5.6973819 | R15: =+$I$13+$I$12*O15-P15 -> 5.5771545 | S15: =+$I$13+$I$12*O15+P15 -> 5.8176093 | T15: =10^Q15 -> 498174.92 | U15: =10^O15 -> 0.6215 | V15: =10^R15 -> 377706.51 | W15: =10^$O15 -> 0.6215 | X15: =10^S15 -> 657066.39 | Y15: =10^$O15 -> 0.6215
H16: F-VALUE | I16: =VLOOKUP($J$24,$H$33:$J$69,3) -> 6.94 | M16: =+C16 -> 0 | N16: =+$I$13+$I$12*M16 -> 4.6078259 | O16: =LOG($I$19+($I$20-$I$19)*(ROW()-2)/100) -> -0.20273246 | P16: =SQRT(2*$I$16*$K$24)*SQRT((1/$I$1)+((O16-$I$10)^2/$I$7)) -> 0.11782315 | Q16: =+$I$13+$I$12*O16 -> 5.6771983 | R16: =+$I$13+$I$12*O16-P16 -> 5.5593752 | S16: =+$I$13+$I$12*O16+P16 -> 5.7950215 | T16: =10^Q16 -> 475552.36 | U16: =10^O16 -> 0.627 | V16: =10^R16 -> 362556.07 | W16: =10^$O16 -> 0.627 | X16: =10^S16 -> 623765.7 | Y16: =10^$O16 -> 0.627 | AA16: Coefficients | AB16: Standard Error | AC16: t Stat | AD16: P-value | AE16: Lower 95% | AF16: Upper 95% | AG16: Lower 95.0% | AH16: Upper 95.0%
H17: CONFIA1 | I17: =+I15*SQRT($K$24/$I$7) -> 0.57648651 | J17: =+I12+I17 -> -4.6983096 | K17: =+I12-I17 -> -5.8512826 | M17: =+C17 -> 0 | N17: =+$I$13+$I$12*M17 -> 4.6078259 | O17: =LOG($I$19+($I$20-$I$19)*(ROW()-2)/100) -> -0.19893947 | P17: =SQRT(2*$I$16*$K$24)*SQRT((1/$I$1)+((O17-$I$10)^2/$I$7)) -> 0.11546539 | Q17: =+$I$13+$I$12*O17 -> 5.6571911 | R17: =+$I$13+$I$12*O17-P17 -> 5.5417257 | S17: =+$I$13+$I$12*O17+P17 -> 5.7726565 | T17: =10^Q17 -> 454141.4 | U17: =10^O17 -> 0.6325 | V17: =10^R17 -> 348117.38 | W17: =10^$O17 -> 0.6325 | X17: =10^S17 -> 592456.53 | Y17: =10^$O17 -> 0.6325 | Z17: Intercept | AA17: 86.958826 | AB17: 2.9348407 | AC17: 29.629828 | AD17: 1.8247423e-09 | AE17: 80.191067 | AF17: 93.726586 | AG17: 80.191067 | AH17: 93.726586
H18: CONFIA0 | I18: =+I15*SQRT(K24/I1) -> 0.051737003 | J18: =+I13-I18 -> 4.5560889 | K18: =+I13+I18 -> 4.6595629 | M18: =+C18 -> 0 | N18: =+$I$13+$I$12*M18 -> 4.6078259 | O18: =LOG($I$19+($I$20-$I$19)*(ROW()-2)/100) -> -0.19517932 | P18: =SQRT(2*$I$16*$K$24)*SQRT((1/$I$1)+((O18-$I$10)^2/$I$7)) -> 0.11315466 | Q18: =+$I$13+$I$12*O18 -> 5.6373571 | R18: =+$I$13+$I$12*O18-P18 -> 5.5242024 | S18: =+$I$13+$I$12*O18+P18 -> 5.7505117 | T18: =10^Q18 -> 433867.46 | U18: =10^O18 -> 0.638 | V18: =10^R18 -> 334350.84 | W18: =10^$O18 -> 0.638 | X18: =10^S18 -> 563004.33 | Y18: =10^$O18 -> 0.638 | Z18: X Variable 1 | AA18: -0.00039353116 | AB18: 7.4171706e-05 | AC18: -5.3056776 | AD18: 0.00072341619 | AE18: -0.00056457153 | AF18: -0.00022249079 | AG18: -0.00056457153 | AH18: -0.00022249079
H19: Xmin | I19: 0.55 | M19: =+C19 -> 0 | N19: =+$I$13+$I$12*M19 -> 4.6078259 | O19: =LOG($I$19+($I$20-$I$19)*(ROW()-2)/100) -> -0.19145145 | P19: =SQRT(2*$I$16*$K$24)*SQRT((1/$I$1)+((O19-$I$10)^2/$I$7)) -> 0.11089155 | Q19: =+$I$13+$I$12*O19 -> 5.6176933 | R19: =+$I$13+$I$12*O19-P19 -> 5.5068018 | S19: =+$I$13+$I$12*O19+P19 -> 5.7285849 | T19: =10^Q19 -> 414661.11 | U19: =10^O19 -> 0.6435 | V19: =10^R19 -> 321219.39 | W19: =10^$O19 -> 0.6435 | X19: =10^S19 -> 535284.74 | Y19: =10^$O19 -> 0.6435
H20: Xmax | I20: 1.1 | O20: =LOG($I$19+($I$20-$I$19)*(ROW()-2)/100) -> -0.1877553 | P20: =SQRT(2*$I$16*$K$24)*SQRT((1/$I$1)+((O20-$I$10)^2/$I$7)) -> 0.10867673 | Q20: =+$I$13+$I$12*O20 -> 5.5981969 | R20: =+$I$13+$I$12*O20-P20 -> 5.4895202 | S20: =+$I$13+$I$12*O20+P20 -> 5.7068736 | T20: =10^Q20 -> 396457.73 | U20: =10^O20 -> 0.649 | V20: =10^R20 -> 308688.3 | W20: =10^$O20 -> 0.649 | X20: =10^S20 -> 509182.68 | Y20: =10^$O20 -> 0.649
H21: Variansanalysetabel | O21: =LOG($I$19+($I$20-$I$19)*(ROW()-2)/100) -> -0.18409035 | P21: =SQRT(2*$I$16*$K$24)*SQRT((1/$I$1)+((O21-$I$10)^2/$I$7)) -> 0.10651091 | Q21: =+$I$13+$I$12*O21 -> 5.578865 | R21: =+$I$13+$I$12*O21-P21 -> 5.4723541 | S21: =+$I$13+$I$12*O21+P21 -> 5.6853759 | T21: =10^Q21 -> 379197.1 | U21: =10^O21 -> 0.6545 | V21: =10^R21 -> 296724.97 | W21: =10^$O21 -> 0.6545 | X21: =10^S21 -> 484591.64 | Y21: =10^$O21 -> 0.6545
I22: SAK | J22: f | K22: S2 | L22: F | O22: =LOG($I$19+($I$20-$I$19)*(ROW()-2)/100) -> -0.18045606 | P22: =SQRT(2*$I$16*$K$24)*SQRT((1/$I$1)+((O22-$I$10)^2/$I$7)) -> 0.10439489 | Q22: =+$I$13+$I$12*O22 -> 5.5596949 | R22: =+$I$13+$I$12*O22-P22 -> 5.4553 | S22: =+$I$13+$I$12*O22+P22 -> 5.6640898 | T22: =10^Q22 -> 362823.07 | U22: =10^O22 -> 0.66 | V22: =10^R22 -> 285298.84 | W22: =10^$O22 -> 0.66 | X22: =10^S22 -> 461412.96 | Y22: =10^$O22 -> 0.66 | Z22: RESIDUAL OUTPUT
H23: Regress | I23: =+I9^2/I7 -> 1.3445806 | J23: 1 | K23: =+I23/1 -> 1.3445806 | L23: =+K23/K24 -> 645.3527 | O23: =LOG($I$19+($I$20-$I$19)*(ROW()-2)/100) -> -0.17685194 | P23: =SQRT(2*$I$16*$K$24)*SQRT((1/$I$1)+((O23-$I$10)^2/$I$7)) -> 0.10232949 | Q23: =+$I$13+$I$12*O23 -> 5.5406839 | R23: =+$I$13+$I$12*O23-P23 -> 5.4383544 | S23: =+$I$13+$I$12*O23+P23 -> 5.6430134 | T23: =10^Q23 -> 347283.28 | U23: =10^O23 -> 0.6655 | V23: =10^R23 -> 274381.22 | W23: =10^$O23 -> 0.6655 | X23: =10^S23 -> 439555.15 | Y23: =10^$O23 -> 0.6655
H24: Residual | I24: =+I8-I23 -> 0.0083339274 | J24: =+I1-2 -> 4 | K24: =+I24/($I$1-2) -> 0.0020834818 | O24: =LOG($I$19+($I$20-$I$19)*(ROW()-2)/100) -> -0.17327748 | P24: =SQRT(2*$I$16*$K$24)*SQRT((1/$I$1)+((O24-$I$10)^2/$I$7)) -> 0.10031564 | Q24: =+$I$13+$I$12*O24 -> 5.5218293 | R24: =+$I$13+$I$12*O24-P24 -> 5.4215137 | S24: =+$I$13+$I$12*O24+P24 -> 5.622145 | T24: =10^Q24 -> 332528.85 | U24: =10^O24 -> 0.671 | V24: =10^R24 -> 263945.15 | W24: =10^$O24 -> 0.671 | X24: =10^S24 -> 418933.38 | Y24: =10^$O24 -> 0.671 | Z24: Observation | AA24: Predicted Y | AB24: Residuals | AC24: Standard Residuals
H25: Total | I25: =SUM(I23:I24) -> 1.3529146 | J25: =SUM(J23:J24) -> 5 | O25: =LOG($I$19+($I$20-$I$19)*(ROW()-2)/100) -> -0.1697322 | P25: =SQRT(2*$I$16*$K$24)*SQRT((1/$I$1)+((O25-$I$10)^2/$I$7)) -> 0.098354288 | Q25: =+$I$13+$I$12*O25 -> 5.5031287 | R25: =+$I$13+$I$12*O25-P25 -> 5.4047744 | S25: =+$I$13+$I$12*O25+P25 -> 5.601483 | T25: =10^Q25 -> 318514.12 | U25: =10^O25 -> 0.6765 | V25: =10^R25 -> 253965.31 | W25: =10^$O25 -> 0.6765 | X25: =10^S25 -> 399468.91 | Y25: =10^$O25 -> 0.6765 | Z25: 1 | AA25: 64.962009 | AB25: 0.4744117 | AC25: 0.10320336
O26: =LOG($I$19+($I$20-$I$19)*(ROW()-2)/100) -> -0.16621563 | P26: =SQRT(2*$I$16*$K$24)*SQRT((1/$I$1)+((O26-$I$10)^2/$I$7)) -> 0.096446464 | Q26: =+$I$13+$I$12*O26 -> 5.4845795 | R26: =+$I$13+$I$12*O26-P26 -> 5.388133 | S26: =+$I$13+$I$12*O26+P26 -> 5.5810259 | T26: =10^Q26 -> 305196.46 | U26: =10^O26 -> 0.682 | V26: =10^R26 -> 244417.91 | W26: =10^$O26 -> 0.682 | X26: =10^S26 -> 381088.59 | Y26: =10^$O26 -> 0.682 | Z26: 2 | AA26: 84.735375 | AB26: 8.1224338 | AC26: 1.7669515
O27: =LOG($I$19+($I$20-$I$19)*(ROW()-2)/100) -> -0.1627273 | P27: =SQRT(2*$I$16*$K$24)*SQRT((1/$I$1)+((O27-$I$10)^2/$I$7)) -> 0.094593249 | Q27: =+$I$13+$I$12*O27 -> 5.4661793 | R27: =+$I$13+$I$12*O27-P27 -> 5.371586 | S27: =+$I$13+$I$12*O27+P27 -> 5.5607725 | T27: =10^Q27 -> 292535.96 | U27: =10^O27 -> 0.6875 | V27: =10^R27 -> 235280.55 | W27: =10^$O27 -> 0.6875 | X27: =10^S27 -> 363724.47 | Y27: =10^$O27 -> 0.6875 | Z27: 3 | AA27: 72.39896 | AB27: -3.7728516 | AC27: -0.82074485
O28: =LOG($I$19+($I$20-$I$19)*(ROW()-2)/100) -> -0.15926677 | P28: =SQRT(2*$I$16*$K$24)*SQRT((1/$I$1)+((O28-$I$10)^2/$I$7)) -> 0.092795775 | Q28: =+$I$13+$I$12*O28 -> 5.4479257 | R28: =+$I$13+$I$12*O28-P28 -> 5.3551299 | S28: =+$I$13+$I$12*O28+P28 -> 5.5407214 | T28: =10^Q28 -> 280495.35 | U28: =10^O28 -> 0.693 | V28: =10^R28 -> 226532.17 | W28: =10^$O28 -> 0.693 | X28: =10^S28 -> 347313.32 | Y28: =10^$O28 -> 0.693 | Z28: 4 | AA28: 83.96799 | AB28: 3.5389413 | AC28: 0.76986009
H29: N = | I29: =10^$I$13 -> 40534.605 | J29: * | K29: S^ | L29: =+I12 -> -5.2747961 | O29: =LOG($I$19+($I$20-$I$19)*(ROW()-2)/100) -> -0.15583359 | P29: =SQRT(2*$I$16*$K$24)*SQRT((1/$I$1)+((O29-$I$10)^2/$I$7)) -> 0.091055229 | Q29: =+$I$13+$I$12*O29 -> 5.4298164 | R29: =+$I$13+$I$12*O29-P29 -> 5.3387611 | S29: =+$I$13+$I$12*O29+P29 -> 5.5208716 | T29: =10^Q29 -> 269039.7 | U29: =10^O29 -> 0.6985 | V29: =10^R29 -> 218152.97 | W29: =10^$O29 -> 0.6985 | X29: =10^S29 -> 331796.34 | Y29: =10^$O29 -> 0.6985 | Z29: 5 | AA29: 80.249514 | AB29: -3.0746271 | AC29: -0.66885335
O30: =LOG($I$19+($I$20-$I$19)*(ROW()-2)/100) -> -0.15242734 | P30: =SQRT(2*$I$16*$K$24)*SQRT((1/$I$1)+((O30-$I$10)^2/$I$7)) -> 0.089372841 | Q30: =+$I$13+$I$12*O30 -> 5.4118491 | R30: =+$I$13+$I$12*O30-P30 -> 5.3224763 | S30: =+$I$13+$I$12*O30+P30 -> 5.5012219 | T30: =10^Q30 -> 258136.31 | U30: =10^O30 -> 0.704 | V30: =10^R30 -> 210124.29 | W30: =10^$O30 -> 0.704 | X30: =10^S30 -> 317118.76 | Y30: =10^$O30 -> 0.704 | Z30: 6 | AA30: 78.183475 | AB30: -4.5407035 | AC30: -0.9877831
O31: =LOG($I$19+($I$20-$I$19)*(ROW()-2)/100) -> -0.1490476 | P31: =SQRT(2*$I$16*$K$24)*SQRT((1/$I$1)+((O31-$I$10)^2/$I$7)) -> 0.08774988 | Q31: =+$I$13+$I$12*O31 -> 5.3940217 | R31: =+$I$13+$I$12*O31-P31 -> 5.3062718 | S31: =+$I$13+$I$12*O31+P31 -> 5.4817715 | T31: =10^Q31 -> 247754.56 | U31: =10^O31 -> 0.7095 | V31: =10^R31 -> 202428.55 | W31: =10^$O31 -> 0.7095 | X31: =10^S31 -> 303229.56 | Y31: =10^$O31 -> 0.7095 | Z31: 7 | AA31: 58.292049 | AB31: 5.5384636 | AC31: 1.2048355
H32: N | I32: TVALUE | J32: FVALUE | L32: 0.95 | O32: =LOG($I$19+($I$20-$I$19)*(ROW()-2)/100) -> -0.14569396 | P32: =SQRT(2*$I$16*$K$24)*SQRT((1/$I$1)+((O32-$I$10)^2/$I$7)) -> 0.08618765 | Q32: =+$I$13+$I$12*O32 -> 5.3763319 | R32: =+$I$13+$I$12*O32-P32 -> 5.2901442 | S32: =+$I$13+$I$12*O32+P32 -> 5.4625195 | T32: =10^Q32 -> 237865.73 | U32: =10^O32 -> 0.715 | V32: =10^R32 -> 195049.22 | W32: =10^$O32 -> 0.715 | X32: =10^S32 -> 290081.16 | Y32: =10^$O32 -> 0.715 | Z32: 8 | AA32: 76.17686 | AB32: -1.661665 | AC32: -0.36147805
H33: 1 | I33: 12.706 | J33: 199.5 | O33: =LOG($I$19+($I$20-$I$19)*(ROW()-2)/100) -> -0.14236601 | P33: =SQRT(2*$I$16*$K$24)*SQRT((1/$I$1)+((O33-$I$10)^2/$I$7)) -> 0.08468748 | Q33: =+$I$13+$I$12*O33 -> 5.3587777 | R33: =+$I$13+$I$12*O33-P33 -> 5.2740902 | S33: =+$I$13+$I$12*O33+P33 -> 5.4434651 | T33: =10^Q33 -> 228442.89 | U33: =10^O33 -> 0.7205 | V33: =10^R33 -> 187970.71 | W33: =10^$O33 -> 0.7205 | X33: =10^S33 -> 277629.19 | Y33: =10^$O33 -> 0.7205 | Z33: 9 | AA33: 66.378327 | AB33: 1.0806765 | AC33: 0.23508999
H34: 2 | I34: 4.303 | J34: 19 | O34: =LOG($I$19+($I$20-$I$19)*(ROW()-2)/100) -> -0.13906338 | P34: =SQRT(2*$I$16*$K$24)*SQRT((1/$I$1)+((O34-$I$10)^2/$I$7)) -> 0.083250714 | Q34: =+$I$13+$I$12*O34 -> 5.3413569 | R34: =+$I$13+$I$12*O34-P34 -> 5.2581062 | S34: =+$I$13+$I$12*O34+P34 -> 5.4246076 | T34: =10^Q34 -> 219460.78 | U34: =10^O34 -> 0.726 | V34: =10^R34 -> 181178.31 | W34: =10^$O34 -> 0.726 | X34: =10^S34 -> 265832.23 | Y34: =10^$O34 -> 0.726 | Z34: 10 | AA34: 71.750028 | AB34: -5.7050796 | AC34: -1.2410811
H35: 3 | I35: 3.182 | J35: 9.55 | O35: =LOG($I$19+($I$20-$I$19)*(ROW()-2)/100) -> -0.13578567 | P35: =SQRT(2*$I$16*$K$24)*SQRT((1/$I$1)+((O35-$I$10)^2/$I$7)) -> 0.081878699 | Q35: =+$I$13+$I$12*O35 -> 5.3240677 | R35: =+$I$13+$I$12*O35-P35 -> 5.242189 | S35: =+$I$13+$I$12*O35+P35 -> 5.4059464 | T35: =10^Q35 -> 210895.67 | U35: =10^O35 -> 0.7315 | V35: =10^R35 -> 174658.2 | W35: =10^$O35 -> 0.7315 | X35: =10^S35 -> 254651.58 | Y35: =10^$O35 -> 0.7315 | Z35: 11 | AA35: 1.8219741 | AB35: -0.023572384 | AC35: -2.1105589
H36: 4 | I36: 2.7764 | J36: 6.94 | O36: =LOG($I$19+($I$20-$I$19)*(ROW()-2)/100) -> -0.13253251 | P36: =SQRT(2*$I$16*$K$24)*SQRT((1/$I$1)+((O36-$I$10)^2/$I$7)) -> 0.080572777 | Q36: =+$I$13+$I$12*O36 -> 5.3069079 | R36: =+$I$13+$I$12*O36-P36 -> 5.2263352 | S36: =+$I$13+$I$12*O36+P36 -> 5.3874807 | T36: =10^Q36 -> 202725.29 | U36: =10^O36 -> 0.737 | V36: =10^R36 -> 168397.31 | W36: =10^$O36 -> 0.737 | X36: =10^S36 -> 244051.06 | Y36: =10^$O36 -> 0.737 | Z36: 12 | AA36: 1.7418459 | AB36: 0.0051980261 | AC36: 0.46540648
H37: 5 | I37: 2.5706 | J37: 5.79 | O37: =LOG($I$19+($I$20-$I$19)*(ROW()-2)/100) -> -0.12930354 | P37: =SQRT(2*$I$16*$K$24)*SQRT((1/$I$1)+((O37-$I$10)^2/$I$7)) -> 0.079334267 | Q37: =+$I$13+$I$12*O37 -> 5.2898758 | R37: =+$I$13+$I$12*O37-P37 -> 5.2105415 | S37: =+$I$13+$I$12*O37+P37 -> 5.36921 | T37: =10^Q37 -> 194928.69 | U37: =10^O37 -> 0.7425 | V37: =10^R37 -> 162383.35 | W37: =10^$O37 -> 0.7425 | X37: =10^S37 -> 233996.86 | Y37: =10^$O37 -> 0.7425
H38: 6 | I38: 2.4469 | J38: 5.14 | O38: =LOG($I$19+($I$20-$I$19)*(ROW()-2)/100) -> -0.1260984 | P38: =SQRT(2*$I$16*$K$24)*SQRT((1/$I$1)+((O38-$I$10)^2/$I$7)) -> 0.078164453 | Q38: =+$I$13+$I$12*O38 -> 5.2729693 | R38: =+$I$13+$I$12*O38-P38 -> 5.1948049 | S38: =+$I$13+$I$12*O38+P38 -> 5.3511338 | T38: =10^Q38 -> 187486.2 | U38: =10^O38 -> 0.748 | V38: =10^R38 -> 156604.72 | W38: =10^$O38 -> 0.748 | X38: =10^S38 -> 224457.32 | Y38: =10^$O38 -> 0.748
H39: 7 | I39: 2.3646 | J39: 4.74 | O39: =LOG($I$19+($I$20-$I$19)*(ROW()-2)/100) -> -0.12291674 | P39: =SQRT(2*$I$16*$K$24)*SQRT((1/$I$1)+((O39-$I$10)^2/$I$7)) -> 0.077064567 | Q39: =+$I$13+$I$12*O39 -> 5.2561867 | R39: =+$I$13+$I$12*O39-P39 -> 5.1791221 | S39: =+$I$13+$I$12*O39+P39 -> 5.3332513 | T39: =10^Q39 -> 180379.31 | U39: =10^O39 -> 0.7535 | V39: =10^R39 -> 151050.49 | W39: =10^$O39 -> 0.7535 | X39: =10^S39 -> 215402.77 | Y39: =10^$O39 -> 0.7535
H40: 8 | I40: 2.306 | J40: 4.46 | O40: =LOG($I$19+($I$20-$I$19)*(ROW()-2)/100) -> -0.11975822 | P40: =SQRT(2*$I$16*$K$24)*SQRT((1/$I$1)+((O40-$I$10)^2/$I$7)) -> 0.076035773 | Q40: =+$I$13+$I$12*O40 -> 5.2395262 | R40: =+$I$13+$I$12*O40-P40 -> 5.1634904 | S40: =+$I$13+$I$12*O40+P40 -> 5.3155619 | T40: =10^Q40 -> 173590.58 | U40: =10^O40 -> 0.759 | V40: =10^R40 -> 145710.35 | W40: =10^$O40 -> 0.759 | X40: =10^S40 -> 206805.43 | Y40: =10^$O40 -> 0.759
...

Sheet ASTM E739 stat (Strain Range)
A1: SN Points | C1: X | D1: Y | E1: X^2 | F1: Y^2 | G1: X*Y | H1: N | I1: =COUNT(C:C) -> 2 | M1: X | N1: YHAT | O1: X | P1: Xconfi | Q1: Yavg | R1: Y1 | S1: Y2 | T1: SN-line | V1: Lower conf | X1: Upper Conf | Z1: SUMMARY OUTPUT
A2: =+Results!D23 | B2: =+Results!C23 -> 1 | C2: =LOG(A2) -> #VALUE! | D2: =LOG(B2) -> 0 | E2: =+C2^2 -> #VALUE! | F2: =+D2^2 -> 0 | G2: =+C2*D2 -> #VALUE! | H2: SUMX | I2: =SUM(C:C) -> #VALUE! | M2: =+C2 -> #VALUE! | N2: =+$I$13+$I$12*M2 -> #VALUE! | O2: =LOG($I$19+($I$20-$I$19)*(ROW()-2)/100) -> -0.091514981 | P2: =SQRT(2*$I$16*$K$24)*SQRT((1/$I$1)+((O2-$I$10)^2/$I$7)) -> #N/A | Q2: =+$I$13+$I$12*O2 -> #VALUE! | R2: =+$I$13+$I$12*O2-P2 -> #VALUE! | S2: =+$I$13+$I$12*O2+P2 -> #VALUE! | T2: =10^Q2 -> #VALUE! | U2: =10^$O2 -> 0.81 | V2: =10^R2 -> #VALUE! | W2: =10^$O2 -> 0.81 | X2: =10^S2 -> #VALUE! | Y2: =10^$O2 -> 0.81
A3: =+Results!D24 | B3: =+Results!C24 -> 1 | C3: =LOG(A3) -> #VALUE! | D3: =LOG(B3) -> 0 | E3: =+C3^2 -> #VALUE! | F3: =+D3^2 -> 0 | G3: =+C3*D3 -> #VALUE! | H3: SUMY | I3: =SUM(D:D) -> 9.4817922 | M3: =+C3 -> #VALUE! | N3: =+$I$13+$I$12*M3 -> #VALUE! | O3: =LOG($I$19+($I$20-$I$19)*(ROW()-2)/100) -> -0.0910327 | P3: =SQRT(2*$I$16*$K$24)*SQRT((1/$I$1)+((O3-$I$10)^2/$I$7)) -> #N/A | Q3: =+$I$13+$I$12*O3 -> #VALUE! | R3: =+$I$13+$I$12*O3-P3 -> #VALUE! | S3: =+$I$13+$I$12*O3+P3 -> #VALUE! | T3: =10^Q3 -> #VALUE! | U3: =10^O3 -> 0.8109 | V3: =10^R3 -> #VALUE! | W3: =10^$O3 -> 0.8109 | X3: =10^S3 -> #VALUE! | Y3: =10^$O3 -> 0.8109 | Z3: Regression Statistics
A4: =+Results!D25 -> 0.9 | B4: =+Results!C25 -> 36156 | C4: =LOG(A4) -> -0.045757491 | D4: =LOG(B4) -> 4.5581804 | E4: =+C4^2 -> 0.0020937479 | F4: =+D4^2 -> 20.777008 | G4: =+C4*D4 -> -0.2085709 | H4: SUMXX | I4: =SUM(E:E) -> #VALUE! | M4: =+C4 -> -0.045757491 | N4: =+$I$13+$I$12*M4 -> #VALUE! | O4: =LOG($I$19+($I$20-$I$19)*(ROW()-2)/100) -> -0.090550953 | P4: =SQRT(2*$I$16*$K$24)*SQRT((1/$I$1)+((O4-$I$10)^2/$I$7)) -> #N/A | Q4: =+$I$13+$I$12*O4 -> #VALUE! | R4: =+$I$13+$I$12*O4-P4 -> #VALUE! | S4: =+$I$13+$I$12*O4+P4 -> #VALUE! | T4: =10^Q4 -> #VALUE! | U4: =10^O4 -> 0.8118 | V4: =10^R4 -> #VALUE! | W4: =10^$O4 -> 0.8118 | X4: =10^S4 -> #VALUE! | Y4: =10^$O4 -> 0.8118 | Z4: Multiple R | AA4: 0.88244047
A5: =+Results!D26 -> 0.81 | B5: =+Results!C26 -> 83871 | C5: =LOG(A5) -> -0.091514981 | D5: =LOG(B5) -> 4.9236118 | E5: =+C5^2 -> 0.0083749918 | F5: =+D5^2 -> 24.241953 | G5: =+C5*D5 -> -0.45058424 | H5: SUMYY | I5: =SUM(F:F) -> 45.018962 | M5: =+C5 -> -0.091514981 | N5: =+$I$13+$I$12*M5 -> #VALUE! | O5: =LOG($I$19+($I$20-$I$19)*(ROW()-2)/100) -> -0.09006974 | P5: =SQRT(2*$I$16*$K$24)*SQRT((1/$I$1)+((O5-$I$10)^2/$I$7)) -> #N/A | Q5: =+$I$13+$I$12*O5 -> #VALUE! | R5: =+$I$13+$I$12*O5-P5 -> #VALUE! | S5: =+$I$13+$I$12*O5+P5 -> #VALUE! | T5: =10^Q5 -> #VALUE! | U5: =10^O5 -> 0.8127 | V5: =10^R5 -> #VALUE! | W5: =10^$O5 -> 0.8127 | X5: =10^S5 -> #VALUE! | Y5: =10^$O5 -> 0.8127 | Z5: R Square | AA5: 0.77870118
H6: SUMXY | I6: =SUM(G:G) -> #VALUE! | M6: =+C6 -> 0 | N6: =+$I$13+$I$12*M6 -> #VALUE! | O6: =LOG($I$19+($I$20-$I$19)*(ROW()-2)/100) -> -0.08958906 | P6: =SQRT(2*$I$16*$K$24)*SQRT((1/$I$1)+((O6-$I$10)^2/$I$7)) -> #N/A | Q6: =+$I$13+$I$12*O6 -> #VALUE! | R6: =+$I$13+$I$12*O6-P6 -> #VALUE! | S6: =+$I$13+$I$12*O6+P6 -> #VALUE! | T6: =10^Q6 -> #VALUE! | U6: =10^O6 -> 0.8136 | V6: =10^R6 -> #VALUE! | W6: =10^$O6 -> 0.8136 | X6: =10^S6 -> #VALUE! | Y6: =10^$O6 -> 0.8136 | Z6: Adjusted R Square | AA6: 0.75103883
H7: SAKX | I7: =+I4-I2^2/$I$1 -> #VALUE! | M7: =+C7 -> 0 | N7: =+$I$13+$I$12*M7 -> #VALUE! | O7: =LOG($I$19+($I$20-$I$19)*(ROW()-2)/100) -> -0.089108911 | P7: =SQRT(2*$I$16*$K$24)*SQRT((1/$I$1)+((O7-$I$10)^2/$I$7)) -> #N/A | Q7: =+$I$13+$I$12*O7 -> #VALUE! | R7: =+$I$13+$I$12*O7-P7 -> #VALUE! | S7: =+$I$13+$I$12*O7+P7 -> #VALUE! | T7: =10^Q7 -> #VALUE! | U7: =10^O7 -> 0.8145 | V7: =10^R7 -> #VALUE! | W7: =10^$O7 -> 0.8145 | X7: =10^S7 -> #VALUE! | Y7: =10^$O7 -> 0.8145 | Z7: Standard Error | AA7: 4.8757094
H8: SAKY (SAKtotal) | I8: =+I5-I3^2/$I$1 -> 0.06677007 | M8: =+C8 -> 0 | N8: =+$I$13+$I$12*M8 -> #VALUE! | O8: =LOG($I$19+($I$20-$I$19)*(ROW()-2)/100) -> -0.088629293 | P8: =SQRT(2*$I$16*$K$24)*SQRT((1/$I$1)+((O8-$I$10)^2/$I$7)) -> #N/A | Q8: =+$I$13+$I$12*O8 -> #VALUE! | R8: =+$I$13+$I$12*O8-P8 -> #VALUE! | S8: =+$I$13+$I$12*O8+P8 -> #VALUE! | T8: =10^Q8 -> #VALUE! | U8: =10^O8 -> 0.8154 | V8: =10^R8 -> #VALUE! | W8: =10^$O8 -> 0.8154 | X8: =10^S8 -> #VALUE! | Y8: =10^$O8 -> 0.8154 | Z8: Observations | AA8: 10
H9: SAPXY | I9: =+I6-I2*I3/$I$1 -> #VALUE! | M9: =+C9 -> 0 | N9: =+$I$13+$I$12*M9 -> #VALUE! | O9: =LOG($I$19+($I$20-$I$19)*(ROW()-2)/100) -> -0.088150204 | P9: =SQRT(2*$I$16*$K$24)*SQRT((1/$I$1)+((O9-$I$10)^2/$I$7)) -> #N/A | Q9: =+$I$13+$I$12*O9 -> #VALUE! | R9: =+$I$13+$I$12*O9-P9 -> #VALUE! | S9: =+$I$13+$I$12*O9+P9 -> #VALUE! | T9: =10^Q9 -> #VALUE! | U9: =10^O9 -> 0.8163 | V9: =10^R9 -> #VALUE! | W9: =10^$O9 -> 0.8163 | X9: =10^S9 -> #VALUE! | Y9: =10^$O9 -> 0.8163
H10: XMEAN | I10: =+I2/$I$1 -> #VALUE! | M10: =+C10 -> 0 | N10: =+$I$13+$I$12*M10 -> #VALUE! | O10: =LOG($I$19+($I$20-$I$19)*(ROW()-2)/100) -> -0.087671642 | P10: =SQRT(2*$I$16*$K$24)*SQRT((1/$I$1)+((O10-$I$10)^2/$I$7)) -> #N/A | Q10: =+$I$13+$I$12*O10 -> #VALUE! | R10: =+$I$13+$I$12*O10-P10 -> #VALUE! | S10: =+$I$13+$I$12*O10+P10 -> #VALUE! | T10: =10^Q10 -> #VALUE! | U10: =10^O10 -> 0.8172 | V10: =10^R10 -> #VALUE! | W10: =10^$O10 -> 0.8172 | X10: =10^S10 -> #VALUE! | Y10: =10^$O10 -> 0.8172 | Z10: ANOVA
H11: YMEAN | I11: =+I3/$I$1 -> 4.7408961 | M11: =+C11 -> 0 | N11: =+$I$13+$I$12*M11 -> #VALUE! | O11: =LOG($I$19+($I$20-$I$19)*(ROW()-2)/100) -> -0.087193607 | P11: =SQRT(2*$I$16*$K$24)*SQRT((1/$I$1)+((O11-$I$10)^2/$I$7)) -> #N/A | Q11: =+$I$13+$I$12*O11 -> #VALUE! | R11: =+$I$13+$I$12*O11-P11 -> #VALUE! | S11: =+$I$13+$I$12*O11+P11 -> #VALUE! | T11: =10^Q11 -> #VALUE! | U11: =10^O11 -> 0.8181 | V11: =10^R11 -> #VALUE! | W11: =10^$O11 -> 0.8181 | X11: =10^S11 -> #VALUE! | Y11: =10^$O11 -> 0.8181 | AA11: df | AB11: SS | AC11: MS | AD11: F | AE11: Significance F
H12: A1 | I12: =+I9/I7 -> #VALUE! | J12: =+I12 -> #VALUE! | K12: =1/J12 -> #VALUE! | M12: =+C12 -> 0 | N12: =+$I$13+$I$12*M12 -> #VALUE! | O12: =LOG($I$19+($I$20-$I$19)*(ROW()-2)/100) -> -0.086716098 | P12: =SQRT(2*$I$16*$K$24)*SQRT((1/$I$1)+((O12-$I$10)^2/$I$7)) -> #N/A | Q12: =+$I$13+$I$12*O12 -> #VALUE! | R12: =+$I$13+$I$12*O12-P12 -> #VALUE! | S12: =+$I$13+$I$12*O12+P12 -> #VALUE! | T12: =10^Q12 -> #VALUE! | U12: =10^O12 -> 0.819 | V12: =10^R12 -> #VALUE! | W12: =10^$O12 -> 0.819 | X12: =10^S12 -> #VALUE! | Y12: =10^$O12 -> 0.819 | Z12: Regression | AA12: 1 | AB12: 669.20218 | AC12: 669.20218 | AD12: 28.150215 | AE12: 0.00072341619
H13: A0 | I13: =+I11-I12*I10 -> #VALUE! | J13: =10^I13 -> #VALUE! | K13: =+J13^J12 -> #VALUE! | M13: =+C13 -> 0 | N13: =+$I$13+$I$12*M13 -> #VALUE! | O13: =LOG($I$19+($I$20-$I$19)*(ROW()-2)/100) -> -0.086239114 | P13: =SQRT(2*$I$16*$K$24)*SQRT((1/$I$1)+((O13-$I$10)^2/$I$7)) -> #N/A | Q13: =+$I$13+$I$12*O13 -> #VALUE! | R13: =+$I$13+$I$12*O13-P13 -> #VALUE! | S13: =+$I$13+$I$12*O13+P13 -> #VALUE! | T13: =10^Q13 -> #VALUE! | U13: =10^O13 -> 0.8199 | V13: =10^R13 -> #VALUE! | W13: =10^$O13 -> 0.8199 | X13: =10^S13 -> #VALUE! | Y13: =10^$O13 -> 0.8199 | Z13: Residual | AA13: 8 | AB13: 190.18034 | AC13: 23.772542
H14: R2 | I14: =+I9^2/(I7*I8) -> #VALUE! | J14: ="(X="&TEXT(J13,"0.0")&"Y^"&TEXT(J12,"0.00")&")" -> #VALUE! | M14: =+C14 -> 0 | N14: =+$I$13+$I$12*M14 -> #VALUE! | O14: =LOG($I$19+($I$20-$I$19)*(ROW()-2)/100) -> -0.085762652 | P14: =SQRT(2*$I$16*$K$24)*SQRT((1/$I$1)+((O14-$I$10)^2/$I$7)) -> #N/A | Q14: =+$I$13+$I$12*O14 -> #VALUE! | R14: =+$I$13+$I$12*O14-P14 -> #VALUE! | S14: =+$I$13+$I$12*O14+P14 -> #VALUE! | T14: =10^Q14 -> #VALUE! | U14: =10^O14 -> 0.8208 | V14: =10^R14 -> #VALUE! | W14: =10^$O14 -> 0.8208 | X14: =10^S14 -> #VALUE! | Y14: =10^$O14 -> 0.8208 | Z14: Total | AA14: 9 | AB14: 859.38251
H15: T-VALUE | I15: =VLOOKUP($J$24,$H$33:$J$69,2) -> #N/A | M15: =+C15 -> 0 | N15: =+$I$13+$I$12*M15 -> #VALUE! | O15: =LOG($I$19+($I$20-$I$19)*(ROW()-2)/100) -> -0.085286713 | P15: =SQRT(2*$I$16*$K$24)*SQRT((1/$I$1)+((O15-$I$10)^2/$I$7)) -> #N/A | Q15: =+$I$13+$I$12*O15 -> #VALUE! | R15: =+$I$13+$I$12*O15-P15 -> #VALUE! | S15: =+$I$13+$I$12*O15+P15 -> #VALUE! | T15: =10^Q15 -> #VALUE! | U15: =10^O15 -> 0.8217 | V15: =10^R15 -> #VALUE! | W15: =10^$O15 -> 0.8217 | X15: =10^S15 -> #VALUE! | Y15: =10^$O15 -> 0.8217
H16: F-VALUE | I16: =VLOOKUP($J$24,$H$33:$J$69,3) -> #N/A | M16: =+C16 -> 0 | N16: =+$I$13+$I$12*M16 -> #VALUE! | O16: =LOG($I$19+($I$20-$I$19)*(ROW()-2)/100) -> -0.084811295 | P16: =SQRT(2*$I$16*$K$24)*SQRT((1/$I$1)+((O16-$I$10)^2/$I$7)) -> #N/A | Q16: =+$I$13+$I$12*O16 -> #VALUE! | R16: =+$I$13+$I$12*O16-P16 -> #VALUE! | S16: =+$I$13+$I$12*O16+P16 -> #VALUE! | T16: =10^Q16 -> #VALUE! | U16: =10^O16 -> 0.8226 | V16: =10^R16 -> #VALUE! | W16: =10^$O16 -> 0.8226 | X16: =10^S16 -> #VALUE! | Y16: =10^$O16 -> 0.8226 | AA16: Coefficients | AB16: Standard Error | AC16: t Stat | AD16: P-value | AE16: Lower 95% | AF16: Upper 95% | AG16: Lower 95.0% | AH16: Upper 95.0%
H17: CONFIA1 | I17: =+I15*SQRT($K$24/$I$7) -> #N/A | J17: =+I12+I17 -> #VALUE! | K17: =+I12-I17 -> #VALUE! | M17: =+C17 -> 0 | N17: =+$I$13+$I$12*M17 -> #VALUE! | O17: =LOG($I$19+($I$20-$I$19)*(ROW()-2)/100) -> -0.084336396 | P17: =SQRT(2*$I$16*$K$24)*SQRT((1/$I$1)+((O17-$I$10)^2/$I$7)) -> #N/A | Q17: =+$I$13+$I$12*O17 -> #VALUE! | R17: =+$I$13+$I$12*O17-P17 -> #VALUE! | S17: =+$I$13+$I$12*O17+P17 -> #VALUE! | T17: =10^Q17 -> #VALUE! | U17: =10^O17 -> 0.8235 | V17: =10^R17 -> #VALUE! | W17: =10^$O17 -> 0.8235 | X17: =10^S17 -> #VALUE! | Y17: =10^$O17 -> 0.8235 | Z17: Intercept | AA17: 86.958826 | AB17: 2.9348407 | AC17: 29.629828 | AD17: 1.8247423e-09 | AE17: 80.191067 | AF17: 93.726586 | AG17: 80.191067 | AH17: 93.726586
H18: CONFIA0 | I18: =+I15*SQRT(K24/I1) -> #N/A | J18: =+I13-I18 -> #VALUE! | K18: =+I13+I18 -> #VALUE! | M18: =+C18 -> 0 | N18: =+$I$13+$I$12*M18 -> #VALUE! | O18: =LOG($I$19+($I$20-$I$19)*(ROW()-2)/100) -> -0.083862017 | P18: =SQRT(2*$I$16*$K$24)*SQRT((1/$I$1)+((O18-$I$10)^2/$I$7)) -> #N/A | Q18: =+$I$13+$I$12*O18 -> #VALUE! | R18: =+$I$13+$I$12*O18-P18 -> #VALUE! | S18: =+$I$13+$I$12*O18+P18 -> #VALUE! | T18: =10^Q18 -> #VALUE! | U18: =10^O18 -> 0.8244 | V18: =10^R18 -> #VALUE! | W18: =10^$O18 -> 0.8244 | X18: =10^S18 -> #VALUE! | Y18: =10^$O18 -> 0.8244 | Z18: X Variable 1 | AA18: -0.00039353116 | AB18: 7.4171706e-05 | AC18: -5.3056776 | AD18: 0.00072341619 | AE18: -0.00056457153 | AF18: -0.00022249079 | AG18: -0.00056457153 | AH18: -0.00022249079
H19: Xmin | I19: =MIN(A:A) -> 0.81 | M19: =+C19 -> 0 | N19: =+$I$13+$I$12*M19 -> #VALUE! | O19: =LOG($I$19+($I$20-$I$19)*(ROW()-2)/100) -> -0.083388155 | P19: =SQRT(2*$I$16*$K$24)*SQRT((1/$I$1)+((O19-$I$10)^2/$I$7)) -> #N/A | Q19: =+$I$13+$I$12*O19 -> #VALUE! | R19: =+$I$13+$I$12*O19-P19 -> #VALUE! | S19: =+$I$13+$I$12*O19+P19 -> #VALUE! | T19: =10^Q19 -> #VALUE! | U19: =10^O19 -> 0.8253 | V19: =10^R19 -> #VALUE! | W19: =10^$O19 -> 0.8253 | X19: =10^S19 -> #VALUE! | Y19: =10^$O19 -> 0.8253
H20: Xmax | I20: =MAX(A:A) -> 0.9 | O20: =LOG($I$19+($I$20-$I$19)*(ROW()-2)/100) -> -0.082914809 | P20: =SQRT(2*$I$16*$K$24)*SQRT((1/$I$1)+((O20-$I$10)^2/$I$7)) -> #N/A | Q20: =+$I$13+$I$12*O20 -> #VALUE! | R20: =+$I$13+$I$12*O20-P20 -> #VALUE! | S20: =+$I$13+$I$12*O20+P20 -> #VALUE! | T20: =10^Q20 -> #VALUE! | U20: =10^O20 -> 0.8262 | V20: =10^R20 -> #VALUE! | W20: =10^$O20 -> 0.8262 | X20: =10^S20 -> #VALUE! | Y20: =10^$O20 -> 0.8262
H21: Variansanalysetabel | O21: =LOG($I$19+($I$20-$I$19)*(ROW()-2)/100) -> -0.082441979 | P21: =SQRT(2*$I$16*$K$24)*SQRT((1/$I$1)+((O21-$I$10)^2/$I$7)) -> #N/A | Q21: =+$I$13+$I$12*O21 -> #VALUE! | R21: =+$I$13+$I$12*O21-P21 -> #VALUE! | S21: =+$I$13+$I$12*O21+P21 -> #VALUE! | T21: =10^Q21 -> #VALUE! | U21: =10^O21 -> 0.8271 | V21: =10^R21 -> #VALUE! | W21: =10^$O21 -> 0.8271 | X21: =10^S21 -> #VALUE! | Y21: =10^$O21 -> 0.8271
I22: SAK | J22: f | K22: S2 | L22: F | O22: =LOG($I$19+($I$20-$I$19)*(ROW()-2)/100) -> -0.081969663 | P22: =SQRT(2*$I$16*$K$24)*SQRT((1/$I$1)+((O22-$I$10)^2/$I$7)) -> #N/A | Q22: =+$I$13+$I$12*O22 -> #VALUE! | R22: =+$I$13+$I$12*O22-P22 -> #VALUE! | S22: =+$I$13+$I$12*O22+P22 -> #VALUE! | T22: =10^Q22 -> #VALUE! | U22: =10^O22 -> 0.828 | V22: =10^R22 -> #VALUE! | W22: =10^$O22 -> 0.828 | X22: =10^S22 -> #VALUE! | Y22: =10^$O22 -> 0.828 | Z22: RESIDUAL OUTPUT
H23: Regress | I23: =+I9^2/I7 -> #VALUE! | J23: 1 | K23: =+I23/1 -> #VALUE! | L23: =+K23/K24 -> #VALUE! | O23: =LOG($I$19+($I$20-$I$19)*(ROW()-2)/100) -> -0.08149786 | P23: =SQRT(2*$I$16*$K$24)*SQRT((1/$I$1)+((O23-$I$10)^2/$I$7)) -> #N/A | Q23: =+$I$13+$I$12*O23 -> #VALUE! | R23: =+$I$13+$I$12*O23-P23 -> #VALUE! | S23: =+$I$13+$I$12*O23+P23 -> #VALUE! | T23: =10^Q23 -> #VALUE! | U23: =10^O23 -> 0.8289 | V23: =10^R23 -> #VALUE! | W23: =10^$O23 -> 0.8289 | X23: =10^S23 -> #VALUE! | Y23: =10^$O23 -> 0.8289
H24: Residual | I24: =+I8-I23 -> #VALUE! | J24: =+I1-2 -> 0 | K24: =+I24/($I$1-2) -> #VALUE! | O24: =LOG($I$19+($I$20-$I$19)*(ROW()-2)/100) -> -0.08102657 | P24: =SQRT(2*$I$16*$K$24)*SQRT((1/$I$1)+((O24-$I$10)^2/$I$7)) -> #N/A | Q24: =+$I$13+$I$12*O24 -> #VALUE! | R24: =+$I$13+$I$12*O24-P24 -> #VALUE! | S24: =+$I$13+$I$12*O24+P24 -> #VALUE! | T24: =10^Q24 -> #VALUE! | U24: =10^O24 -> 0.8298 | V24: =10^R24 -> #VALUE! | W24: =10^$O24 -> 0.8298 | X24: =10^S24 -> #VALUE! | Y24: =10^$O24 -> 0.8298 | Z24: Observation | AA24: Predicted Y | AB24: Residuals | AC24: Standard Residuals
H25: Total | I25: =SUM(I23:I24) -> #VALUE! | J25: =SUM(J23:J24) -> 1 | O25: =LOG($I$19+($I$20-$I$19)*(ROW()-2)/100) -> -0.08055579 | P25: =SQRT(2*$I$16*$K$24)*SQRT((1/$I$1)+((O25-$I$10)^2/$I$7)) -> #N/A | Q25: =+$I$13+$I$12*O25 -> #VALUE! | R25: =+$I$13+$I$12*O25-P25 -> #VALUE! | S25: =+$I$13+$I$12*O25+P25 -> #VALUE! | T25: =10^Q25 -> #VALUE! | U25: =10^O25 -> 0.8307 | V25: =10^R25 -> #VALUE! | W25: =10^$O25 -> 0.8307 | X25: =10^S25 -> #VALUE! | Y25: =10^$O25 -> 0.8307 | Z25: 1 | AA25: 64.962009 | AB25: 0.4744117 | AC25: 0.10320336
O26: =LOG($I$19+($I$20-$I$19)*(ROW()-2)/100) -> -0.080085519 | P26: =SQRT(2*$I$16*$K$24)*SQRT((1/$I$1)+((O26-$I$10)^2/$I$7)) -> #N/A | Q26: =+$I$13+$I$12*O26 -> #VALUE! | R26: =+$I$13+$I$12*O26-P26 -> #VALUE! | S26: =+$I$13+$I$12*O26+P26 -> #VALUE! | T26: =10^Q26 -> #VALUE! | U26: =10^O26 -> 0.8316 | V26: =10^R26 -> #VALUE! | W26: =10^$O26 -> 0.8316 | X26: =10^S26 -> #VALUE! | Y26: =10^$O26 -> 0.8316 | Z26: 2 | AA26: 84.735375 | AB26: 8.1224338 | AC26: 1.7669515
O27: =LOG($I$19+($I$20-$I$19)*(ROW()-2)/100) -> -0.079615758 | P27: =SQRT(2*$I$16*$K$24)*SQRT((1/$I$1)+((O27-$I$10)^2/$I$7)) -> #N/A | Q27: =+$I$13+$I$12*O27 -> #VALUE! | R27: =+$I$13+$I$12*O27-P27 -> #VALUE! | S27: =+$I$13+$I$12*O27+P27 -> #VALUE! | T27: =10^Q27 -> #VALUE! | U27: =10^O27 -> 0.8325 | V27: =10^R27 -> #VALUE! | W27: =10^$O27 -> 0.8325 | X27: =10^S27 -> #VALUE! | Y27: =10^$O27 -> 0.8325 | Z27: 3 | AA27: 72.39896 | AB27: -3.7728516 | AC27: -0.82074485
O28: =LOG($I$19+($I$20-$I$19)*(ROW()-2)/100) -> -0.079146504 | P28: =SQRT(2*$I$16*$K$24)*SQRT((1/$I$1)+((O28-$I$10)^2/$I$7)) -> #N/A | Q28: =+$I$13+$I$12*O28 -> #VALUE! | R28: =+$I$13+$I$12*O28-P28 -> #VALUE! | S28: =+$I$13+$I$12*O28+P28 -> #VALUE! | T28: =10^Q28 -> #VALUE! | U28: =10^O28 -> 0.8334 | V28: =10^R28 -> #VALUE! | W28: =10^$O28 -> 0.8334 | X28: =10^S28 -> #VALUE! | Y28: =10^$O28 -> 0.8334 | Z28: 4 | AA28: 83.96799 | AB28: 3.5389413 | AC28: 0.76986009
H29: N = | I29: =10^$I$13 -> #VALUE! | J29: * | K29: S^ | L29: =+I12 -> #VALUE! | O29: =LOG($I$19+($I$20-$I$19)*(ROW()-2)/100) -> -0.078677756 | P29: =SQRT(2*$I$16*$K$24)*SQRT((1/$I$1)+((O29-$I$10)^2/$I$7)) -> #N/A | Q29: =+$I$13+$I$12*O29 -> #VALUE! | R29: =+$I$13+$I$12*O29-P29 -> #VALUE! | S29: =+$I$13+$I$12*O29+P29 -> #VALUE! | T29: =10^Q29 -> #VALUE! | U29: =10^O29 -> 0.8343 | V29: =10^R29 -> #VALUE! | W29: =10^$O29 -> 0.8343 | X29: =10^S29 -> #VALUE! | Y29: =10^$O29 -> 0.8343 | Z29: 5 | AA29: 80.249514 | AB29: -3.0746271 | AC29: -0.66885335
O30: =LOG($I$19+($I$20-$I$19)*(ROW()-2)/100) -> -0.078209514 | P30: =SQRT(2*$I$16*$K$24)*SQRT((1/$I$1)+((O30-$I$10)^2/$I$7)) -> #N/A | Q30: =+$I$13+$I$12*O30 -> #VALUE! | R30: =+$I$13+$I$12*O30-P30 -> #VALUE! | S30: =+$I$13+$I$12*O30+P30 -> #VALUE! | T30: =10^Q30 -> #VALUE! | U30: =10^O30 -> 0.8352 | V30: =10^R30 -> #VALUE! | W30: =10^$O30 -> 0.8352 | X30: =10^S30 -> #VALUE! | Y30: =10^$O30 -> 0.8352 | Z30: 6 | AA30: 78.183475 | AB30: -4.5407035 | AC30: -0.9877831
O31: =LOG($I$19+($I$20-$I$19)*(ROW()-2)/100) -> -0.077741777 | P31: =SQRT(2*$I$16*$K$24)*SQRT((1/$I$1)+((O31-$I$10)^2/$I$7)) -> #N/A | Q31: =+$I$13+$I$12*O31 -> #VALUE! | R31: =+$I$13+$I$12*O31-P31 -> #VALUE! | S31: =+$I$13+$I$12*O31+P31 -> #VALUE! | T31: =10^Q31 -> #VALUE! | U31: =10^O31 -> 0.8361 | V31: =10^R31 -> #VALUE! | W31: =10^$O31 -> 0.8361 | X31: =10^S31 -> #VALUE! | Y31: =10^$O31 -> 0.8361 | Z31: 7 | AA31: 58.292049 | AB31: 5.5384636 | AC31: 1.2048355
H32: N | I32: TVALUE | J32: FVALUE | L32: 0.95 | O32: =LOG($I$19+($I$20-$I$19)*(ROW()-2)/100) -> -0.077274542 | P32: =SQRT(2*$I$16*$K$24)*SQRT((1/$I$1)+((O32-$I$10)^2/$I$7)) -> #N/A | Q32: =+$I$13+$I$12*O32 -> #VALUE! | R32: =+$I$13+$I$12*O32-P32 -> #VALUE! | S32: =+$I$13+$I$12*O32+P32 -> #VALUE! | T32: =10^Q32 -> #VALUE! | U32: =10^O32 -> 0.837 | V32: =10^R32 -> #VALUE! | W32: =10^$O32 -> 0.837 | X32: =10^S32 -> #VALUE! | Y32: =10^$O32 -> 0.837 | Z32: 8 | AA32: 76.17686 | AB32: -1.661665 | AC32: -0.36147805
H33: 1 | I33: 12.706 | J33: 199.5 | O33: =LOG($I$19+($I$20-$I$19)*(ROW()-2)/100) -> -0.07680781 | P33: =SQRT(2*$I$16*$K$24)*SQRT((1/$I$1)+((O33-$I$10)^2/$I$7)) -> #N/A | Q33: =+$I$13+$I$12*O33 -> #VALUE! | R33: =+$I$13+$I$12*O33-P33 -> #VALUE! | S33: =+$I$13+$I$12*O33+P33 -> #VALUE! | T33: =10^Q33 -> #VALUE! | U33: =10^O33 -> 0.8379 | V33: =10^R33 -> #VALUE! | W33: =10^$O33 -> 0.8379 | X33: =10^S33 -> #VALUE! | Y33: =10^$O33 -> 0.8379 | Z33: 9 | AA33: 66.378327 | AB33: 1.0806765 | AC33: 0.23508999
H34: 2 | I34: 4.303 | J34: 19 | O34: =LOG($I$19+($I$20-$I$19)*(ROW()-2)/100) -> -0.076341578 | P34: =SQRT(2*$I$16*$K$24)*SQRT((1/$I$1)+((O34-$I$10)^2/$I$7)) -> #N/A | Q34: =+$I$13+$I$12*O34 -> #VALUE! | R34: =+$I$13+$I$12*O34-P34 -> #VALUE! | S34: =+$I$13+$I$12*O34+P34 -> #VALUE! | T34: =10^Q34 -> #VALUE! | U34: =10^O34 -> 0.8388 | V34: =10^R34 -> #VALUE! | W34: =10^$O34 -> 0.8388 | X34: =10^S34 -> #VALUE! | Y34: =10^$O34 -> 0.8388 | Z34: 10 | AA34: 71.750028 | AB34: -5.7050796 | AC34: -1.2410811
H35: 3 | I35: 3.182 | J35: 9.55 | O35: =LOG($I$19+($I$20-$I$19)*(ROW()-2)/100) -> -0.075875847 | P35: =SQRT(2*$I$16*$K$24)*SQRT((1/$I$1)+((O35-$I$10)^2/$I$7)) -> #N/A | Q35: =+$I$13+$I$12*O35 -> #VALUE! | R35: =+$I$13+$I$12*O35-P35 -> #VALUE! | S35: =+$I$13+$I$12*O35+P35 -> #VALUE! | T35: =10^Q35 -> #VALUE! | U35: =10^O35 -> 0.8397 | V35: =10^R35 -> #VALUE! | W35: =10^$O35 -> 0.8397 | X35: =10^S35 -> #VALUE! | Y35: =10^$O35 -> 0.8397 | Z35: 11 | AA35: 1.8219741 | AB35: -0.023572384 | AC35: -2.1105589
H36: 4 | I36: 2.7764 | J36: 6.94 | O36: =LOG($I$19+($I$20-$I$19)*(ROW()-2)/100) -> -0.075410614 | P36: =SQRT(2*$I$16*$K$24)*SQRT((1/$I$1)+((O36-$I$10)^2/$I$7)) -> #N/A | Q36: =+$I$13+$I$12*O36 -> #VALUE! | R36: =+$I$13+$I$12*O36-P36 -> #VALUE! | S36: =+$I$13+$I$12*O36+P36 -> #VALUE! | T36: =10^Q36 -> #VALUE! | U36: =10^O36 -> 0.8406 | V36: =10^R36 -> #VALUE! | W36: =10^$O36 -> 0.8406 | X36: =10^S36 -> #VALUE! | Y36: =10^$O36 -> 0.8406 | Z36: 12 | AA36: 1.7418459 | AB36: 0.0051980261 | AC36: 0.46540648
H37: 5 | I37: 2.5706 | J37: 5.79 | O37: =LOG($I$19+($I$20-$I$19)*(ROW()-2)/100) -> -0.07494588 | P37: =SQRT(2*$I$16*$K$24)*SQRT((1/$I$1)+((O37-$I$10)^2/$I$7)) -> #N/A | Q37: =+$I$13+$I$12*O37 -> #VALUE! | R37: =+$I$13+$I$12*O37-P37 -> #VALUE! | S37: =+$I$13+$I$12*O37+P37 -> #VALUE! | T37: =10^Q37 -> #VALUE! | U37: =10^O37 -> 0.8415 | V37: =10^R37 -> #VALUE! | W37: =10^$O37 -> 0.8415 | X37: =10^S37 -> #VALUE! | Y37: =10^$O37 -> 0.8415
H38: 6 | I38: 2.4469 | J38: 5.14 | O38: =LOG($I$19+($I$20-$I$19)*(ROW()-2)/100) -> -0.074481642 | P38: =SQRT(2*$I$16*$K$24)*SQRT((1/$I$1)+((O38-$I$10)^2/$I$7)) -> #N/A | Q38: =+$I$13+$I$12*O38 -> #VALUE! | R38: =+$I$13+$I$12*O38-P38 -> #VALUE! | S38: =+$I$13+$I$12*O38+P38 -> #VALUE! | T38: =10^Q38 -> #VALUE! | U38: =10^O38 -> 0.8424 | V38: =10^R38 -> #VALUE! | W38: =10^$O38 -> 0.8424 | X38: =10^S38 -> #VALUE! | Y38: =10^$O38 -> 0.8424
H39: 7 | I39: 2.3646 | J39: 4.74 | O39: =LOG($I$19+($I$20-$I$19)*(ROW()-2)/100) -> -0.0740179 | P39: =SQRT(2*$I$16*$K$24)*SQRT((1/$I$1)+((O39-$I$10)^2/$I$7)) -> #N/A | Q39: =+$I$13+$I$12*O39 -> #VALUE! | R39: =+$I$13+$I$12*O39-P39 -> #VALUE! | S39: =+$I$13+$I$12*O39+P39 -> #VALUE! | T39: =10^Q39 -> #VALUE! | U39: =10^O39 -> 0.8433 | V39: =10^R39 -> #VALUE! | W39: =10^$O39 -> 0.8433 | X39: =10^S39 -> #VALUE! | Y39: =10^$O39 -> 0.8433
H40: 8 | I40: 2.306 | J40: 4.46 | O40: =LOG($I$19+($I$20-$I$19)*(ROW()-2)/100) -> -0.073554652 | P40: =SQRT(2*$I$16*$K$24)*SQRT((1/$I$1)+((O40-$I$10)^2/$I$7)) -> #N/A | Q40: =+$I$13+$I$12*O40 -> #VALUE! | R40: =+$I$13+$I$12*O40-P40 -> #VALUE! | S40: =+$I$13+$I$12*O40+P40 -> #VALUE! | T40: =10^Q40 -> #VALUE! | U40: =10^O40 -> 0.8442 | V40: =10^R40 -> #VALUE! | W40: =10^$O40 -> 0.8442 | X40: =10^S40 -> #VALUE! | Y40: =10^$O40 -> 0.8442
...

Sheet ASTM E739 stat (Max Stress)
A1: SN Points | C1: X | D1: Y | E1: X^2 | F1: Y^2 | G1: X*Y | H1: N | I1: =COUNT(C:C) -> 0 | M1: X | N1: YHAT | O1: X | P1: Xconfi | Q1: Yavg | R1: Y1 | S1: Y2 | T1: SN-line | V1: Lower conf | X1: Upper Conf | Z1: SUMMARY OUTPUT
A2: =+Results!F23 -> #VALUE! | B2: =+Results!E23 -> 1 | C2: =LOG(A2) -> #VALUE! | D2: =LOG(B2) -> 0 | E2: =+C2^2 -> #VALUE! | F2: =+D2^2 -> 0 | G2: =+C2*D2 -> #VALUE! | H2: SUMX | I2: =SUM(C:C) -> #VALUE! | M2: =+C2 -> #VALUE! | N2: =+$I$13+$I$12*M2 -> #DIV/0! | O2: =LOG($I$19+($I$20-$I$19)*(ROW()-2)/100) -> #VALUE! | P2: =SQRT(2*$I$16*$K$24)*SQRT((1/$I$1)+((O2-$I$10)^2/$I$7)) -> #N/A | Q2: =+$I$13+$I$12*O2 -> #DIV/0! | R2: =+$I$13+$I$12*O2-P2 -> #DIV/0! | S2: =+$I$13+$I$12*O2+P2 -> #DIV/0! | T2: =10^Q2 -> #DIV/0! | U2: =10^$O2 -> #VALUE! | V2: =10^R2 -> #DIV/0! | W2: =10^$O2 -> #VALUE! | X2: =10^S2 -> #DIV/0! | Y2: =10^$O2 -> #VALUE!
A3: =+Results!F24 -> #VALUE! | B3: =+Results!E24 -> 1 | C3: =LOG(A3) -> #VALUE! | D3: =LOG(B3) -> 0 | E3: =+C3^2 -> #VALUE! | F3: =+D3^2 -> 0 | G3: =+C3*D3 -> #VALUE! | H3: SUMY | I3: =SUM(D:D) -> 9.4817922 | M3: =+C3 -> #VALUE! | N3: =+$I$13+$I$12*M3 -> #DIV/0! | O3: =LOG($I$19+($I$20-$I$19)*(ROW()-2)/100) -> #VALUE! | P3: =SQRT(2*$I$16*$K$24)*SQRT((1/$I$1)+((O3-$I$10)^2/$I$7)) -> #N/A | Q3: =+$I$13+$I$12*O3 -> #DIV/0! | R3: =+$I$13+$I$12*O3-P3 -> #DIV/0! | S3: =+$I$13+$I$12*O3+P3 -> #DIV/0! | T3: =10^Q3 -> #DIV/0! | U3: =10^O3 -> #VALUE! | V3: =10^R3 -> #DIV/0! | W3: =10^$O3 -> #VALUE! | X3: =10^S3 -> #DIV/0! | Y3: =10^$O3 -> #VALUE! | Z3: Regression Statistics
A4: =+Results!F25 -> 0 | B4: =+Results!E25 -> 36156 | C4: =LOG(A4) -> #NUM! | D4: =LOG(B4) -> 4.5581804 | E4: =+C4^2 -> #NUM! | F4: =+D4^2 -> 20.777008 | G4: =+C4*D4 -> #NUM! | H4: SUMXX | I4: =SUM(E:E) -> #VALUE! | M4: =+C4 -> #NUM! | N4: =+$I$13+$I$12*M4 -> #DIV/0! | O4: =LOG($I$19+($I$20-$I$19)*(ROW()-2)/100) -> #VALUE! | P4: =SQRT(2*$I$16*$K$24)*SQRT((1/$I$1)+((O4-$I$10)^2/$I$7)) -> #N/A | Q4: =+$I$13+$I$12*O4 -> #DIV/0! | R4: =+$I$13+$I$12*O4-P4 -> #DIV/0! | S4: =+$I$13+$I$12*O4+P4 -> #DIV/0! | T4: =10^Q4 -> #DIV/0! | U4: =10^O4 -> #VALUE! | V4: =10^R4 -> #DIV/0! | W4: =10^$O4 -> #VALUE! | X4: =10^S4 -> #DIV/0! | Y4: =10^$O4 -> #VALUE! | Z4: Multiple R | AA4: 0.88244047
A5: =+Results!F26 -> 0 | B5: =+Results!E26 -> 83871 | C5: =LOG(A5) -> #NUM! | D5: =LOG(B5) -> 4.9236118 | E5: =+C5^2 -> #NUM! | F5: =+D5^2 -> 24.241953 | G5: =+C5*D5 -> #NUM! | H5: SUMYY | I5: =SUM(F:F) -> 45.018962 | M5: =+C5 -> #NUM! | N5: =+$I$13+$I$12*M5 -> #DIV/0! | O5: =LOG($I$19+($I$20-$I$19)*(ROW()-2)/100) -> #VALUE! | P5: =SQRT(2*$I$16*$K$24)*SQRT((1/$I$1)+((O5-$I$10)^2/$I$7)) -> #N/A | Q5: =+$I$13+$I$12*O5 -> #DIV/0! | R5: =+$I$13+$I$12*O5-P5 -> #DIV/0! | S5: =+$I$13+$I$12*O5+P5 -> #DIV/0! | T5: =10^Q5 -> #DIV/0! | U5: =10^O5 -> #VALUE! | V5: =10^R5 -> #DIV/0! | W5: =10^$O5 -> #VALUE! | X5: =10^S5 -> #DIV/0! | Y5: =10^$O5 -> #VALUE! | Z5: R Square | AA5: 0.77870118
H6: SUMXY | I6: =SUM(G:G) -> #VALUE! | M6: =+C6 -> 0 | N6: =+$I$13+$I$12*M6 -> #DIV/0! | O6: =LOG($I$19+($I$20-$I$19)*(ROW()-2)/100) -> #VALUE! | P6: =SQRT(2*$I$16*$K$24)*SQRT((1/$I$1)+((O6-$I$10)^2/$I$7)) -> #N/A | Q6: =+$I$13+$I$12*O6 -> #DIV/0! | R6: =+$I$13+$I$12*O6-P6 -> #DIV/0! | S6: =+$I$13+$I$12*O6+P6 -> #DIV/0! | T6: =10^Q6 -> #DIV/0! | U6: =10^O6 -> #VALUE! | V6: =10^R6 -> #DIV/0! | W6: =10^$O6 -> #VALUE! | X6: =10^S6 -> #DIV/0! | Y6: =10^$O6 -> #VALUE! | Z6: Adjusted R Square | AA6: 0.75103883
H7: SAKX | I7: =+I4-I2^2/$I$1 -> #VALUE! | M7: =+C7 -> 0 | N7: =+$I$13+$I$12*M7 -> #DIV/0! | O7: =LOG($I$19+($I$20-$I$19)*(ROW()-2)/100) -> #VALUE! | P7: =SQRT(2*$I$16*$K$24)*SQRT((1/$I$1)+((O7-$I$10)^2/$I$7)) -> #N/A | Q7: =+$I$13+$I$12*O7 -> #DIV/0! | R7: =+$I$13+$I$12*O7-P7 -> #DIV/0! | S7: =+$I$13+$I$12*O7+P7 -> #DIV/0! | T7: =10^Q7 -> #DIV/0! | U7: =10^O7 -> #VALUE! | V7: =10^R7 -> #DIV/0! | W7: =10^$O7 -> #VALUE! | X7: =10^S7 -> #DIV/0! | Y7: =10^$O7 -> #VALUE! | Z7: Standard Error | AA7: 4.8757094
H8: SAKY (SAKtotal) | I8: =+I5-I3^2/$I$1 -> #DIV/0! | M8: =+C8 -> 0 | N8: =+$I$13+$I$12*M8 -> #DIV/0! | O8: =LOG($I$19+($I$20-$I$19)*(ROW()-2)/100) -> #VALUE! | P8: =SQRT(2*$I$16*$K$24)*SQRT((1/$I$1)+((O8-$I$10)^2/$I$7)) -> #N/A | Q8: =+$I$13+$I$12*O8 -> #DIV/0! | R8: =+$I$13+$I$12*O8-P8 -> #DIV/0! | S8: =+$I$13+$I$12*O8+P8 -> #DIV/0! | T8: =10^Q8 -> #DIV/0! | U8: =10^O8 -> #VALUE! | V8: =10^R8 -> #DIV/0! | W8: =10^$O8 -> #VALUE! | X8: =10^S8 -> #DIV/0! | Y8: =10^$O8 -> #VALUE! | Z8: Observations | AA8: 10
H9: SAPXY | I9: =+I6-I2*I3/$I$1 -> #VALUE! | M9: =+C9 -> 0 | N9: =+$I$13+$I$12*M9 -> #DIV/0! | O9: =LOG($I$19+($I$20-$I$19)*(ROW()-2)/100) -> #VALUE! | P9: =SQRT(2*$I$16*$K$24)*SQRT((1/$I$1)+((O9-$I$10)^2/$I$7)) -> #N/A | Q9: =+$I$13+$I$12*O9 -> #DIV/0! | R9: =+$I$13+$I$12*O9-P9 -> #DIV/0! | S9: =+$I$13+$I$12*O9+P9 -> #DIV/0! | T9: =10^Q9 -> #DIV/0! | U9: =10^O9 -> #VALUE! | V9: =10^R9 -> #DIV/0! | W9: =10^$O9 -> #VALUE! | X9: =10^S9 -> #DIV/0! | Y9: =10^$O9 -> #VALUE!
H10: XMEAN | I10: =+I2/$I$1 -> #VALUE! | M10: =+C10 -> 0 | N10: =+$I$13+$I$12*M10 -> #DIV/0! | O10: =LOG($I$19+($I$20-$I$19)*(ROW()-2)/100) -> #VALUE! | P10: =SQRT(2*$I$16*$K$24)*SQRT((1/$I$1)+((O10-$I$10)^2/$I$7)) -> #N/A | Q10: =+$I$13+$I$12*O10 -> #DIV/0! | R10: =+$I$13+$I$12*O10-P10 -> #DIV/0! | S10: =+$I$13+$I$12*O10+P10 -> #DIV/0! | T10: =10^Q10 -> #DIV/0! | U10: =10^O10 -> #VALUE! | V10: =10^R10 -> #DIV/0! | W10: =10^$O10 -> #VALUE! | X10: =10^S10 -> #DIV/0! | Y10: =10^$O10 -> #VALUE! | Z10: ANOVA
