Workbook

Sheet Plan
A1: Udmattelse
A3: prj nummer | B3: 44584-?? | J3: dato | K3: emner
A4: Plader: | B4: EQA01 | I4: Modtaget
A5: Geometri: | E5: Med tabs
B6: R= | C6: 0.1 | E6: Frekvens | F6: 5 Hz
B7: Specimen | C7: Width | D7: Thickness | E7: Area | F7: Max strain | G7: E-mod 1. load | H7: E-mod. 2. load | I7: Max load | J7: Min Load | K7: Frequency | L7: Cycles to failure | M7: Comments | N7: Prøvemaskine
A8: Date | B8: # | C8: (mm) | D8: (mm) | E8: (mm2) | F8: (%) | I8: (kN) | J8: (kN) | K8: (Hz)
A9: 42223 | B9: =+$B$4&"-0"&TEXT((ROW()-8),0) -> EQA01-01 | C9: 25.24 | D9: 4.25 | E9: =+C9*D9 -> 107.27 | G9: 37.58 | N9: 88R1342
A10: 42223 | B10: =+$B$4&"-0"&TEXT((ROW()-8),0) -> EQA01-02 | C10: 25.29 | D10: 4.34 | E10: =+C10*D10 -> 109.7586 | G10: 37.7 | N10: 88R1342
A11: 42223 | B11: =+$B$4&"-0"&TEXT((ROW()-8),0) -> EQA01-03 | C11: 25.3 | D11: 4.23 | E11: =+C11*D11 -> 107.019 | F11: 1.5 | G11: 37.99 | H11: 38.23 | I11: 61.37 | J11: 6.14 | K11: 3 | L11: 10766 | M11: 34 C at 3 Hz | N11: 88R1342
A12: 42222 | B12: =+$B$4&"-0"&TEXT((ROW()-8),0) -> EQA01-04 | C12: 25.29 | D12: 4.3 | E12: =+C12*D12 -> 108.747 | F12: 1.1 | G12: 37.82 | H12: 37.92 | I12: 45.37 | J12: 4.54 | K12: 4 | L12: 148187 | M12: 32 C at 4 Hz | N12: 88R1342
A13: 42222 | B13: =+$B$4&"-0"&TEXT((ROW()-8),0) -> EQA01-05 | C13: 25.26 | D13: 4.17 | E13: =+C13*D13 -> 105.3342 | F13: 0.9 | G13: 38.55 | H13: 38.68 | I13: 36.67 | J13: 3.67 | K13: 5 | L13: 581856 | N13: 88R1331
A14: 42222 | B14: =+$B$4&"-0"&TEXT((ROW()-8),0) -> EQA01-06 | C14: 25.28 | D14: 4.26 | E14: =+C14*D14 -> 107.6928 | F14: 1 | G14: 37.82 | H14: 37.69 | I14: 40.57 | J14: 4.06 | K14: 4 | L14: 290916 | M14: Vent from 5 to 4 hz becasue of amplitude control | N14: 88R1332
B15: =+$B$4&"-0"&TEXT((ROW()-8),0) -> EQA01-07 | C15: 25.32 | D15: 4.07 | E15: =+C15*D15 -> 103.0524
B16: =+$B$4&"-0"&TEXT((ROW()-8),0) -> EQA01-08 | C16: 25.39 | D16: 4.33 | E16: =+C16*D16 -> 109.9387 | M16: run at last, geometry not perfect
A17: 42223 | B17: =+$B$4&"-0"&TEXT((ROW()-8),0) -> EQA01-09 | C17: 25.41 | D17: 4.17 | E17: =+C17*D17 -> 105.9597 | F17: 1.3 | G17: 39.37 | H17: 39.42 | I17: 54.3 | J17: 5.43 | K17: 3 | L17: 35032 | M17: 33 C at 3 Hz | N17: 88R1342
A18: 42223 | B18: =+$B$4&"-"&TEXT((ROW()-8),0) -> EQA01-10 | C18: 25.38 | D18: 4.16 | E18: =+C18*D18 -> 105.5808 | F18: 0.8 | G18: 38.26 | H18: 38.28 | I18: 32.34 | J18: 3.23 | K18: 5 | L18: 2000000 | M18: 32 C at 5 Hz/Runout | N18: 88R1332
A19: 42226 | B19: =+$B$4&"-"&TEXT((ROW()-8),0) -> EQA01-11 | C19: 25.41 | D19: 4.21 | E19: =+C19*D19 -> 106.9761 | F19: 1.2 | G19: 39.8 | H19: 38.93 | I19: 49.97 | J19: 4.99 | K19: 3 | L19: 53299 | N19: 88R1342
A20: 42226 | B20: =+$B$4&"-"&TEXT((ROW()-8),0) -> EQA01-12 | C20: 25.34 | D20: 4.25 | E20: =+C20*D20 -> 107.695 | F20: 0.85 | G20: 37.32 | H20: 37.16 | I20: 34.02 | J20: 3.4 | L20: 1350848 | N20: 88R1331
G22: =AVERAGE(G11:G20) -> 38.36625 | H22: =AVERAGE(H11:H20) -> 38.28875
L25: 10766
L26: 148187
L27: 581856
L28: 290916
L29: 35032
L30: 2000000
L31: 53299
L32: 1350848

Sheet Results
A1: =+Plan!A1 -> Udmattelse | D1: =B4&" Fatigue test" -> EQA01 Fatigue test
A3: =+Plan!A3 -> prj nummer
A4: =+Plan!A4 -> Plader: | B4: =+Plan!B4 -> EQA01
A5: =+Plan!A5 -> Geometri:
C6: =+Plan!B6 -> R= | D6: =+Plan!C6 -> 0.1 | E6: =+Plan!E6 -> Frekvens | F6: =+Plan!F6 -> 5 Hz | N6: From Ten and Fat Datafiles | U6: Matlab "DataAnalysis"
A7: Date | B7: Specimen | C7: Width | D7: Thickness | E7: Area | F7: Cycles to failure | G7: Abs Max strain | H7: Strain Range | I7: Peak stress | J7: Max load | K7: Min Load | L7: Mean Load | M7: Amplitude | N7: Ini Emod | O7: E-mod | P7: E-mod 1 | Q7: E-mod 2 | R7: Bending ratio | S7: Comments | U7: From Ten-files
B8: # | C8: (mm) | D8: (mm) | E8: (mm2) | G8: (%) | H8: (%) | I8: (MPa) | J8: (kN) | K8: (kN) | L8: (kN) | M8: (kN) | N8: (GPa) | O8: (GPa) | P8: (GPa) | Q8: (GPa) | R8: |E1+E2|/|E1+E2| | T8: Spec. | U8: Modulus a [GPa]: | V8: Modulus b [GPa]: | W8: Modulus a1 [GPa]: | X8: Modulus b1 [GPa]: | Y8: Modulus a2 [GPa]: | Z8: Modulus b2 [GPa]:
A9: =+Plan!A9 -> 42223 | B9: =+Plan!B9 -> EQA01-01 | C9: =+Plan!C9 -> 25.24 | D9: =+Plan!D9 -> 4.25 | E9: =+Plan!E9 -> 107.27 | F9: =+Plan!L9 -> 0 | G9: =+Plan!F9 -> 0 | H9: =IF(ISNUMBER(G9),+G9*(1-$D$6),"") -> 0 | I9: =+J9/E9*1000 -> 0 | J9: =+O9*G9*E9/100 -> 0 | K9: =+J9*$D$6 -> 0 | L9: =+(J9+K9)/2 -> 0 | M9: =+(J9-K9)/2 -> 0 | N9: =+U9 -> 0 | O9: =+V9 -> 37.58 | P9: =+X9 -> 0 | Q9: =+Z9 -> 0 | R9: =+ABS(P9-Q9)/(P9+Q9) -> #DIV/0! | S9: =+Plan!N9 -> 88R1342 | V9: =Plan!G9 -> 37.58
A10: =+Plan!A10 -> 42223 | B10: =+Plan!B10 -> EQA01-02 | C10: =+Plan!C10 -> 25.29 | D10: =+Plan!D10 -> 4.34 | E10: =+Plan!E10 -> 109.7586 | F10: =+Plan!L10 -> 0 | G10: =+Plan!F10 -> 0 | H10: =IF(ISNUMBER(G10),+G10*(1-$D$6),"") -> 0 | I10: =+J10/C10/D10*1000 -> 0 | J10: =+O10*G10*E10/100 -> 0 | K10: =+J10*$D$6 -> 0 | L10: =+(J10+K10)/2 -> 0 | M10: =+(J10-K10)/2 -> 0 | N10: =+U10 -> 0 | O10: =+V10 -> 37.7 | P10: =+X10 -> 0 | Q10: =+Z10 -> 0 | R10: =+ABS(P10-Q10)/(P10+Q10) -> #DIV/0! | S10: =+Plan!N10 -> 88R1342 | V10: =Plan!G10 -> 37.7
A11: =+Plan!A11 -> 42223 | B11: =+Plan!B11 -> EQA01-03 | C11: =+Plan!C11 -> 25.3 | D11: =+Plan!D11 -> 4.23 | E11: =+Plan!E11 -> 107.019 | F11: =+Plan!L11 -> 10766 | G11: =+Plan!F11 -> 1.5 | H11: =IF(ISNUMBER(G11),+G11*(1-$D$6),"") -> 1.35 | I11: =+J11/C11/D11*1000 -> 573.42719 | J11: =+O11*G11*E11/100 -> 61.367604 | K11: =+J11*$D$6 -> 6.1367604 | L11: =+(J11+K11)/2 -> 33.752182 | M11: =+(J11-K11)/2 -> 27.615422 | N11: =+U11 -> 37.984872 | O11: =+V11 -> 38.228479 | P11: =+X11 -> 38.254426 | Q11: =+Z11 -> 38.201659 | R11: =+ABS(P11-Q11)/(P11+Q11) -> 0.00069016089 | S11: =+Plan!N11 -> 88R1342 | T11: EQA01-03 | U11: 37.984872 | V11: 38.228479 | W11: 38.721035 | X11: 38.254426 | Y11: 37.276068 | Z11: 38.201659
A12: =+Plan!A12 -> 42222 | B12: =+Plan!B12 -> EQA01-04 | C12: =+Plan!C12 -> 25.29 | D12: =+Plan!D12 -> 4.3 | E12: =+Plan!E12 -> 108.747 | F12: =+Plan!L12 -> 148187 | G12: =+Plan!F12 -> 1.1 | H12: =IF(ISNUMBER(G12),+G12*(1-$D$6),"") -> 0.99 | I12: =+J12/C12/D12*1000 -> 417.16891 | J12: =+O12*G12*E12/100 -> 45.365867 | K12: =+J12*$D$6 -> 4.5365867 | L12: =+(J12+K12)/2 -> 24.951227 | M12: =+(J12-K12)/2 -> 20.41464 | N12: =+U12 -> 37.820213 | O12: =+V12 -> 37.924446 | P12: =+X12 -> 38.051265 | Q12: =+Z12 -> 37.798123 | R12: =+ABS(P12-Q12)/(P12+Q12) -> 0.0033374297 | S12: =+Plan!N12 -> 88R1342 | T12: EQA01-04 | U12: 37.820213 | V12: 37.924446 | W12: 38.125467 | X12: 38.051265 | Y12: 37.51891 | Z12: 37.798123
A13: =+Plan!A13 -> 42222 | B13: =+Plan!B13 -> EQA01-05 | C13: =+Plan!C13 -> 25.26 | D13: =+Plan!D13 -> 4.17 | E13: =+Plan!E13 -> 105.3342 | F13: =+Plan!L13 -> 581856 | G13: =+Plan!F13 -> 0.9 | H13: =IF(ISNUMBER(G13),+G13*(1-$D$6),"") -> 0.81 | I13: =+J13/C13/D13*1000 -> 348.11375 | J13: =+O13*G13*E13/100 -> 36.668283 | K13: =+J13*$D$6 -> 3.6668283 | L13: =+(J13+K13)/2 -> 20.167556 | M13: =+(J13-K13)/2 -> 16.500727 | O13: =+V13 -> 38.679305 | R13: =+ABS(P13-Q13)/(P13+Q13) -> #DIV/0! | S13: =+Plan!N13 -> 88R1331 | T13: EQA01-05 | U13: 38.554064 | V13: 38.679305 | W13: 38.338395 | X13: 38.562886 | Y13: 38.771794 | Z13: 38.796214
A14: =+Plan!A14 -> 42222 | B14: =+Plan!B14 -> EQA01-06 | C14: =+Plan!C14 -> 25.28 | D14: =+Plan!D14 -> 4.26 | E14: =+Plan!E14 -> 107.6928 | F14: =+Plan!L14 -> 290916 | G14: =+Plan!F14 -> 1 | H14: =IF(ISNUMBER(G14),+G14*(1-$D$6),"") -> 0.9 | I14: =+J14/C14/D14*1000 -> 376.86882 | J14: =+O14*G14*E14/100 -> 40.586058 | K14: =+J14*$D$6 -> 4.0586058 | L14: =+(J14+K14)/2 -> 22.322332 | M14: =+(J14-K14)/2 -> 18.263726 | O14: =+V14 -> 37.686882 | R14: =+ABS(P14-Q14)/(P14+Q14) -> #DIV/0! | S14: =+Plan!N14 -> 88R1332 | T14: EQA01-06 | U14: 37.821127 | V14: 37.686882 | W14: 37.349323 | X14: 37.265368 | Y14: 38.303642 | Z14: 38.117153
A15: =+Plan!A15 -> 0 | B15: =+Plan!B15 -> EQA01-07 | C15: =+Plan!C15 -> 25.32 | D15: =+Plan!D15 -> 4.07 | E15: =+Plan!E15 -> 103.0524 | F15: =+Plan!L15 -> 0 | G15: =+Plan!F15 -> 0 | H15: =IF(ISNUMBER(G15),+G15*(1-$D$6),"") -> 0 | I15: =+J15/C15/D15*1000 -> 0 | J15: =+O15*G15*E15/100 -> 0 | K15: =+J15*$D$6 -> 0 | L15: =+(J15+K15)/2 -> 0 | M15: =+(J15-K15)/2 -> 0 | O15: =+V15 -> 0 | R15: =+ABS(P15-Q15)/(P15+Q15) -> #DIV/0! | S15: =+Plan!N15 -> 0
A16: =+Plan!A16 -> 0 | B16: =+Plan!B16 -> EQA01-08 | C16: =+Plan!C16 -> 25.39 | D16: =+Plan!D16 -> 4.33 | E16: =+Plan!E16 -> 109.9387 | F16: =+Plan!L16 -> 0 | G16: =+Plan!F16 -> 0 | H16: =IF(ISNUMBER(G16),+G16*(1-$D$6),"") -> 0 | I16: =+J16/C16/D16*1000 -> 0 | J16: =+O16*G16*E16/100 -> 0 | K16: =+J16*$D$6 -> 0 | L16: =+(J16+K16)/2 -> 0 | M16: =+(J16-K16)/2 -> 0 | O16: =+V16 -> 0 | R16: =+ABS(P16-Q16)/(P16+Q16) -> #DIV/0! | S16: =+Plan!N16 -> 0
A17: =+Plan!A17 -> 42223 | B17: =+Plan!B17 -> EQA01-09 | C17: =+Plan!C17 -> 25.41 | D17: =+Plan!D17 -> 4.17 | E17: =+Plan!E17 -> 105.9597 | F17: =+Plan!L17 -> 35032 | G17: =+Plan!F17 -> 1.3 | H17: =IF(ISNUMBER(G17),+G17*(1-$D$6),"") -> 1.17 | I17: =+J17/C17/D17*1000 -> 512.45767 | J17: =+O17*G17*E17/100 -> 54.299861 | K17: =+J17*$D$6 -> 5.4299861 | L17: =+(J17+K17)/2 -> 29.864924 | M17: =+(J17-K17)/2 -> 24.434938 | O17: =+V17 -> 39.419821 | R17: =+ABS(P17-Q17)/(P17+Q17) -> #DIV/0! | S17: =+Plan!N17 -> 88R1342 | T17: EQA01-09 | U17: 39.369884 | V17: 39.419821 | W17: 38.327322 | X17: 38.388979 | Y17: 40.459856 | Z17: 40.505381
A18: =+Plan!A18 -> 42223 | B18: =+Plan!B18 -> EQA01-10 | C18: =+Plan!C18 -> 25.38 | D18: =+Plan!D18 -> 4.16 | E18: =+Plan!E18 -> 105.5808 | F18: =+Plan!L18 -> 2000000 | G18: =+Plan!F18 -> 0.8 | H18: =IF(ISNUMBER(G18),+G18*(1-$D$6),"") -> 0.72 | I18: =+J18/C18/D18*1000 -> 306.26963 | J18: =+O18*G18*E18/100 -> 32.336193 | K18: =+J18*$D$6 -> 3.2336193 | L18: =+(J18+K18)/2 -> 17.784906 | M18: =+(J18-K18)/2 -> 14.551287 | O18: =+V18 -> 38.283704 | R18: =+ABS(P18-Q18)/(P18+Q18) -> #DIV/0! | S18: =+Plan!N18 -> 88R1332 | T18: EQA01-10 | U18: 38.260672 | V18: 38.283704 | W18: 38.263121 | X18: 38.294539 | Y18: 38.257876 | Z18: 38.272631
A19: =+Plan!A19 -> 42226 | B19: =+Plan!B19 -> EQA01-11 | C19: =+Plan!C19 -> 25.41 | D19: =+Plan!D19 -> 4.21 | E19: =+Plan!E19 -> 106.9761 | F19: =+Plan!L19 -> 53299 | G19: =+Plan!F19 -> 1.2 | H19: =IF(ISNUMBER(G19),+G19*(1-$D$6),"") -> 1.08 | I19: =+J19/C19/D19*1000 -> 467.13605 | J19: =+O19*G19*E19/100 -> 49.972393 | K19: =+J19*$D$6 -> 4.9972393 | L19: =+(J19+K19)/2 -> 27.484816 | M19: =+(J19-K19)/2 -> 22.487577 | O19: =+V19 -> 38.928004 | R19: =+ABS(P19-Q19)/(P19+Q19) -> #DIV/0! | S19: =+Plan!N19 -> 88R1342 | T19: EQA01-11 | U19: 39.798487 | V19: 38.928004 | W19: 38.223931 | X19: 38.328819 | Y19: 41.494061 | Z19: 39.544401
A20: =+Plan!A20 -> 42226 | B20: =+Plan!B20 -> EQA01-12 | C20: =+Plan!C20 -> 25.34 | D20: =+Plan!D20 -> 4.25 | E20: =+Plan!E20 -> 107.695 | F20: =+Plan!L20 -> 1350848 | G20: =+Plan!F20 -> 0.85 | H20: =IF(ISNUMBER(G20),+G20*(1-$D$6),"") -> 0.765 | I20: =+J20/C20/D20*1000 -> 315.90393 | J20: =+O20*G20*E20/100 -> 34.021274 | K20: =+J20*$D$6 -> 3.4021274 | L20: =+(J20+K20)/2 -> 18.7117 | M20: =+(J20-K20)/2 -> 15.309573 | O20: =+V20 -> 37.165168 | R20: =+ABS(P20-Q20)/(P20+Q20) -> #DIV/0! | S20: =+Plan!N20 -> 88R1331 | T20: EQA01-12 | U20: 37.320143 | V20: 37.165168 | W20: 37.271027 | X20: 36.983108 | Y20: 37.369275 | Z20: 37.348979
A21: SN-Curve | B21: Astm Stat
A22: Cycles | B22: Max Strain | C22: Cycles | D22: Strain Range | E22: Cycles | F22: Max Stress | H22: Modulus (Gpa) | I22: Cycles @ 1% max strain
A23: =+F9 -> 0 | B23: =+G9 -> 0 | C23: =+F9 -> 0 | D23: =+H9 -> 0 | E23: =+F9 -> 0 | F23: =+I9 -> 0 | G23: =+B4 -> EQA01 | H23: =+Plan!H22 -> 38.28875 | I23: =+'ASTM E739 stat (Max Strain)'!J13 -> 293312.96
A24: =+F10 -> 0 | B24: =+G10 -> 0 | C24: =+F10 -> 0 | D24: =+H10 -> 0 | E24: =+F10 -> 0 | F24: =+I10 -> 0
A25: =+F11 -> 10766 | B25: =+G11 -> 1.5 | C25: =+F11 -> 10766 | D25: =+H11 -> 1.35 | E25: =+F11 -> 10766 | F25: =+I11 -> 573.42719
A26: =+F12 -> 148187 | B26: =+G12 -> 1.1 | C26: =+F12 -> 148187 | D26: =+H12 -> 0.99 | E26: =+F12 -> 148187 | F26: =+I12 -> 417.16891
A27: =+F13 -> 581856 | B27: =+G13 -> 0.9 | C27: =+F13 -> 581856 | D27: =+H13 -> 0.81 | E27: =+F13 -> 581856 | F27: =+I13 -> 348.11375
A28: =+F14 -> 290916 | B28: =+G14 -> 1 | C28: =+F14 -> 290916 | D28: =+H14 -> 0.9 | E28: =+F14 -> 290916 | F28: =+I14 -> 376.86882
A29: =+F15 -> 0 | B29: =+G15 -> 0 | C29: =+F15 -> 0 | D29: =+H15 -> 0 | E29: =+F15 -> 0 | F29: =+I15 -> 0
A30: =+F16 -> 0 | B30: =+G16 -> 0 | C30: =+F16 -> 0 | D30: =+H16 -> 0 | E30: =+F16 -> 0 | F30: =+I16 -> 0
A31: =+F17 -> 35032 | B31: =+G17 -> 1.3 | C31: =+F17 -> 35032 | D31: =+H17 -> 1.17 | E31: =+F17 -> 35032 | F31: =+I17 -> 512.45767
A32: =+F18 -> 2000000 | B32: =+G18 -> 0.8 | C32: =+F18 -> 2000000 | D32: =+H18 -> 0.72 | E32: =+F18 -> 2000000 | F32: =+I18 -> 306.26963
A33: =+F19 -> 53299 | B33: =+G19 -> 1.2 | C33: =+F19 -> 53299 | D33: =+H19 -> 1.08 | E33: =+F19 -> 53299 | F33: =+I19 -> 467.13605
A34: =+F20 -> 1350848 | B34: =+G20 -> 0.85 | C34: =+F20 -> 1350848 | D34: =+H20 -> 0.765 | E34: =+F20 -> 1350848 | F34: =+I20 -> 315.90393

Sheet ASTM E739 stat (Max Strain)
A1: SN Points | C1: X | D1: Y | E1: X^2 | F1: Y^2 | G1: X*Y | H1: N | I1: =COUNT(C:C) -> 7 | M1: X | N1: YHAT | O1: X | P1: Xconfi | Q1: Yavg | R1: Y1 | S1: Y2 | T1: SN-line | V1: Lower conf | X1: Upper Conf | Z1: SUMMARY OUTPUT
H2: SUMX | I2: =SUM(C:C) -> 0.29426998 | M2: =+C2 -> 0 | N2: =+$I$13+$I$12*M2 -> 5.4673313 | O2: =LOG($I$19+($I$20-$I$19)*(ROW()-2)/100) -> 0.17609126 | P2: =SQRT(2*$I$16*$K$24)*SQRT((1/$I$1)+((O2-$I$10)^2/$I$7)) -> 0.16824442 | Q2: =+$I$13+$I$12*O2 -> 4.0083829 | R2: =+$I$13+$I$12*O2-P2 -> 3.8401385 | S2: =+$I$13+$I$12*O2+P2 -> 4.1766273 | T2: =10^Q2 -> 10194.899 | U2: =10^$O2 -> 1.5 | V2: =10^R2 -> 6920.5162 | W2: =10^$O2 -> 1.5 | X2: =10^S2 -> 15018.527 | Y2: =10^$O2 -> 1.5
H3: SUMY | I3: =SUM(D:D) -> 35.833238 | M3: =+C3 -> 0 | N3: =+$I$13+$I$12*M3 -> 5.4673313 | O3: =LOG($I$19+($I$20-$I$19)*(ROW()-2)/100) -> 0.17376882 | P3: =SQRT(2*$I$16*$K$24)*SQRT((1/$I$1)+((O3-$I$10)^2/$I$7)) -> 0.16612356 | Q3: =+$I$13+$I$12*O3 -> 4.0276247 | R3: =+$I$13+$I$12*O3-P3 -> 3.8615012 | S3: =+$I$13+$I$12*O3+P3 -> 4.1937483 | T3: =10^Q3 -> 10656.749 | U3: =10^O3 -> 1.492 | V3: =10^R3 -> 7269.4434 | W3: =10^$O3 -> 1.492 | X3: =10^S3 -> 15622.419 | Y3: =10^$O3 -> 1.492 | Z3: Regression Statistics
A4: =+Results!B25 -> 1.5 | B4: =+Results!A25 -> 10766 | C4: =LOG(A4) -> 0.17609126 | D4: =LOG(B4) -> 4.0320544 | E4: =+C4^2 -> 0.031008132 | F4: =+D4^2 -> 16.257462 | G4: =+C4*D4 -> 0.71000953 | H4: SUMXX | I4: =SUM(E:E) -> 0.059049679 | M4: =+C4 -> 0.17609126 | N4: =+$I$13+$I$12*M4 -> 4.0083829 | O4: =LOG($I$19+($I$20-$I$19)*(ROW()-2)/100) -> 0.1714339 | P4: =SQRT(2*$I$16*$K$24)*SQRT((1/$I$1)+((O4-$I$10)^2/$I$7)) -> 0.16400174 | Q4: =+$I$13+$I$12*O4 -> 4.04697 | R4: =+$I$13+$I$12*O4-P4 -> 3.8829682 | S4: =+$I$13+$I$12*O4+P4 -> 4.2109717 | T4: =10^Q4 -> 11142.175 | U4: =10^O4 -> 1.484 | V4: =10^R4 -> 7637.7992 | W4: =10^$O4 -> 1.484 | X4: =10^S4 -> 16254.429 | Y4: =10^$O4 -> 1.484 | Z4: Multiple R | AA4: 0.88244047
A5: =+Results!B26 -> 1.1 | B5: =+Results!A26 -> 148187 | C5: =LOG(A5) -> 0.041392685 | D5: =LOG(B5) -> 5.1708101 | E5: =+C5^2 -> 0.0017133544 | F5: =+D5^2 -> 26.737277 | G5: =+C5*D5 -> 0.21403371 | H5: SUMYY | I5: =SUM(F:F) -> 186.65896 | M5: =+C5 -> 0.041392685 | N5: =+$I$13+$I$12*M5 -> 5.1243853 | O5: =LOG($I$19+($I$20-$I$19)*(ROW()-2)/100) -> 0.16908636 | P5: =SQRT(2*$I$16*$K$24)*SQRT((1/$I$1)+((O5-$I$10)^2/$I$7)) -> 0.16187942 | Q5: =+$I$13+$I$12*O5 -> 4.0664198 | R5: =+$I$13+$I$12*O5-P5 -> 3.9045404 | S5: =+$I$13+$I$12*O5+P5 -> 4.2282992 | T5: =10^Q5 -> 11652.519 | U5: =10^O5 -> 1.476 | V5: =10^R5 -> 8026.7621 | W5: =10^$O5 -> 1.476 | X5: =10^S5 -> 16916.06 | Y5: =10^$O5 -> 1.476 | Z5: R Square | AA5: 0.77870118
A6: =+Results!B27 -> 0.9 | B6: =+Results!A27 -> 581856 | C6: =LOG(A6) -> -0.045757491 | D6: =LOG(B6) -> 5.7648155 | E6: =+C6^2 -> 0.0020937479 | F6: =+D6^2 -> 33.233098 | G6: =+C6*D6 -> -0.26378349 | H6: SUMXY | I6: =SUM(G:G) -> 1.119634 | M6: =+C6 -> -0.045757491 | N6: =+$I$13+$I$12*M6 -> 5.8464404 | O6: =LOG($I$19+($I$20-$I$19)*(ROW()-2)/100) -> 0.16672606 | P6: =SQRT(2*$I$16*$K$24)*SQRT((1/$I$1)+((O6-$I$10)^2/$I$7)) -> 0.15975709 | Q6: =+$I$13+$I$12*O6 -> 4.0859753 | R6: =+$I$13+$I$12*O6-P6 -> 3.9262183 | S6: =+$I$13+$I$12*O6+P6 -> 4.2457324 | T6: =10^Q6 -> 12189.204 | U6: =10^O6 -> 1.468 | V6: =10^R6 -> 8437.5868 | W6: =10^$O6 -> 1.468 | X6: =10^S6 -> 17608.908 | Y6: =10^$O6 -> 1.468 | Z6: Adjusted R Square | AA6: 0.75103883
A7: =+Results!B28 -> 1 | B7: =+Results!A28 -> 290916 | C7: =LOG(A7) -> 0 | D7: =LOG(B7) -> 5.4637676 | E7: =+C7^2 -> 0 | F7: =+D7^2 -> 29.852756 | G7: =+C7*D7 -> 0 | H7: SAKX | I7: =+I4-I2^2/$I$1 -> 0.046678991 | M7: =+C7 -> 0 | N7: =+$I$13+$I$12*M7 -> 5.4673313 | O7: =LOG($I$19+($I$20-$I$19)*(ROW()-2)/100) -> 0.16435286 | P7: =SQRT(2*$I$16*$K$24)*SQRT((1/$I$1)+((O7-$I$10)^2/$I$7)) -> 0.15763529 | Q7: =+$I$13+$I$12*O7 -> 4.1056377 | R7: =+$I$13+$I$12*O7-P7 -> 3.9480024 | S7: =+$I$13+$I$12*O7+P7 -> 4.263273 | T7: =10^Q7 -> 12753.745 | U7: =10^O7 -> 1.46 | V7: =10^R7 -> 8871.6101 | W7: =10^$O7 -> 1.46 | X7: =10^S7 -> 18334.667 | Y7: =10^$O7 -> 1.46 | Z7: Standard Error | AA7: 4.8757094
H8: SAKY (SAKtotal) | I8: =+I5-I3^2/$I$1 -> 3.2274 | M8: =+C8 -> 0 | N8: =+$I$13+$I$12*M8 -> 5.4673313 | O8: =LOG($I$19+($I$20-$I$19)*(ROW()-2)/100) -> 0.16196662 | P8: =SQRT(2*$I$16*$K$24)*SQRT((1/$I$1)+((O8-$I$10)^2/$I$7)) -> 0.1555146 | Q8: =+$I$13+$I$12*O8 -> 4.1254082 | R8: =+$I$13+$I$12*O8-P8 -> 3.9698936 | S8: =+$I$13+$I$12*O8+P8 -> 4.2809228 | T8: =10^Q8 -> 13347.753 | U8: =10^O8 -> 1.452 | V8: =10^R8 -> 9330.2562 | W8: =10^$O8 -> 1.452 | X8: =10^S8 -> 19095.136 | Y8: =10^$O8 -> 1.452 | Z8: Observations | AA8: 10
H9: SAPXY | I9: =+I6-I2*I3/$I$1 -> -0.38674399 | M9: =+C9 -> 0 | N9: =+$I$13+$I$12*M9 -> 5.4673313 | O9: =LOG($I$19+($I$20-$I$19)*(ROW()-2)/100) -> 0.15956719 | P9: =SQRT(2*$I$16*$K$24)*SQRT((1/$I$1)+((O9-$I$10)^2/$I$7)) -> 0.15339562 | Q9: =+$I$13+$I$12*O9 -> 4.1452878 | R9: =+$I$13+$I$12*O9-P9 -> 3.9918922 | S9: =+$I$13+$I$12*O9+P9 -> 4.2986834 | T9: =10^Q9 -> 13972.941 | U9: =10^O9 -> 1.444 | V9: =10^R9 -> 9815.0429 | W9: =10^$O9 -> 1.444 | X9: =10^S9 -> 19892.229 | Y9: =10^$O9 -> 1.444
A10: =+Results!B31 -> 1.3 | B10: =+Results!A31 -> 35032 | C10: =LOG(A10) -> 0.11394335 | D10: =LOG(B10) -> 4.5444649 | E10: =+C10^2 -> 0.012983088 | F10: =+D10^2 -> 20.652162 | G10: =+C10*D10 -> 0.51781157 | H10: XMEAN | I10: =+I2/$I$1 -> 0.042038568 | M10: =+C10 -> 0.11394335 | N10: =+$I$13+$I$12*M10 -> 4.5232897 | O10: =LOG($I$19+($I$20-$I$19)*(ROW()-2)/100) -> 0.15715444 | P10: =SQRT(2*$I$16*$K$24)*SQRT((1/$I$1)+((O10-$I$10)^2/$I$7)) -> 0.15127904 | Q10: =+$I$13+$I$12*O10 -> 4.1652779 | R10: =+$I$13+$I$12*O10-P10 -> 4.0139989 | S10: =+$I$13+$I$12*O10+P10 -> 4.316557 | T10: =10^Q10 -> 14631.132 | U10: =10^O10 -> 1.436 | V10: =10^R10 -> 10327.588 | W10: =10^$O10 -> 1.436 | X10: =10^S10 -> 20727.979 | Y10: =10^$O10 -> 1.436 | Z10: ANOVA
A11: =+Results!B32 -> 0.8 | B11: =+Results!A32 -> 2000000 | H11: YMEAN | I11: =+I3/$I$1 -> 5.119034 | M11: =+C11 -> 0 | N11: =+$I$13+$I$12*M11 -> 5.4673313 | O11: =LOG($I$19+($I$20-$I$19)*(ROW()-2)/100) -> 0.15472821 | P11: =SQRT(2*$I$16*$K$24)*SQRT((1/$I$1)+((O11-$I$10)^2/$I$7)) -> 0.14916556 | Q11: =+$I$13+$I$12*O11 -> 4.1853797 | R11: =+$I$13+$I$12*O11-P11 -> 4.0362142 | S11: =+$I$13+$I$12*O11+P11 -> 4.3345453 | T11: =10^Q11 -> 15324.267 | U11: =10^O11 -> 1.428 | V11: =10^R11 -> 10869.615 | W11: =10^$O11 -> 1.428 | X11: =10^S11 -> 21604.552 | Y11: =10^$O11 -> 1.428 | AA11: df | AB11: SS | AC11: MS | AD11: F | AE11: Significance F
A12: =+Results!B33 -> 1.2 | B12: =+Results!A33 -> 53299 | C12: =LOG(A12) -> 0.079181246 | D12: =LOG(B12) -> 4.7267191 | E12: =+C12^2 -> 0.0062696697 | F12: =+D12^2 -> 22.341873 | G12: =+C12*D12 -> 0.3742675 | H12: A1 | I12: =+I9/I7 -> -8.2851832 | J12: =+I12 -> -8.2851832 | K12: =1/J12 -> -0.12069739 | M12: =+C12 -> 0.079181246 | N12: =+$I$13+$I$12*M12 -> 4.8113001 | O12: =LOG($I$19+($I$20-$I$19)*(ROW()-2)/100) -> 0.15228834 | P12: =SQRT(2*$I$16*$K$24)*SQRT((1/$I$1)+((O12-$I$10)^2/$I$7)) -> 0.14705595 | Q12: =+$I$13+$I$12*O12 -> 4.2055944 | R12: =+$I$13+$I$12*O12-P12 -> 4.0585385 | S12: =+$I$13+$I$12*O12+P12 -> 4.3526504 | T12: =10^Q12 -> 16054.413 | U12: =10^O12 -> 1.42 | V12: =10^R12 -> 11442.962 | W12: =10^$O12 -> 1.42 | X12: =10^S12 -> 22524.252 | Y12: =10^$O12 -> 1.42 | Z12: Regression | AA12: 1 | AB12: 669.20218 | AC12: 669.20218 | AD12: 28.150215 | AE12: 0.00072341619
A13: =+Results!B34 -> 0.85 | B13: =+Results!A34 -> 1350848 | C13: =LOG(A13) -> -0.070581074 | D13: =LOG(B13) -> 6.1306065 | E13: =+C13^2 -> 0.004981688 | F13: =+D13^2 -> 37.584336 | G13: =+C13*D13 -> -0.43270479 | H13: A0 | I13: =+I11-I12*I10 -> 5.4673313 | J13: =10^I13 -> 293312.96 | K13: =+J13^J12 -> 5.0368508e-46 | M13: =+C13 -> -0.070581074 | N13: =+$I$13+$I$12*M13 -> 6.0521084 | O13: =LOG($I$19+($I$20-$I$19)*(ROW()-2)/100) -> 0.1498347 | P13: =SQRT(2*$I$16*$K$24)*SQRT((1/$I$1)+((O13-$I$10)^2/$I$7)) -> 0.14495104 | Q13: =+$I$13+$I$12*O13 -> 4.2259233 | R13: =+$I$13+$I$12*O13-P13 -> 4.0809723 | S13: =+$I$13+$I$12*O13+P13 -> 4.3708744 | T13: =10^Q13 -> 16823.771 | U13: =10^O13 -> 1.412 | V13: =10^R13 -> 12049.591 | W13: =10^$O13 -> 1.412 | X13: =10^S13 -> 23489.533 | Y13: =10^$O13 -> 1.412 | Z13: Residual | AA13: 8 | AB13: 190.18034 | AC13: 23.772542
H14: R2 | I14: =+I9^2/(I7*I8) -> 0.99282542 | J14: ="(X="&TEXT(J13,"0.0")&"Y^"&TEXT(J12,"0.00")&")" -> (X=293313.0Y^-8.29) | M14: =+C14 -> 0 | N14: =+$I$13+$I$12*M14 -> 5.4673313 | O14: =LOG($I$19+($I$20-$I$19)*(ROW()-2)/100) -> 0.14736711 | P14: =SQRT(2*$I$16*$K$24)*SQRT((1/$I$1)+((O14-$I$10)^2/$I$7)) -> 0.14285173 | Q14: =+$I$13+$I$12*O14 -> 4.2463678 | R14: =+$I$13+$I$12*O14-P14 -> 4.103516 | S14: =+$I$13+$I$12*O14+P14 -> 4.3892195 | T14: =10^Q14 -> 17634.687 | U14: =10^O14 -> 1.404 | V14: =10^R14 -> 12691.59 | W14: =10^$O14 -> 1.404 | X14: =10^S14 -> 24503.013 | Y14: =10^$O14 -> 1.404 | Z14: Total | AA14: 9 | AB14: 859.38251
H15: T-VALUE | I15: =VLOOKUP($J$24,$H$33:$J$69,2) -> 2.5706 | M15: =+C15 -> 0 | N15: =+$I$13+$I$12*M15 -> 5.4673313 | O15: =LOG($I$19+($I$20-$I$19)*(ROW()-2)/100) -> 0.14488542 | P15: =SQRT(2*$I$16*$K$24)*SQRT((1/$I$1)+((O15-$I$10)^2/$I$7)) -> 0.14075896 | Q15: =+$I$13+$I$12*O15 -> 4.266929 | R15: =+$I$13+$I$12*O15-P15 -> 4.1261701 | S15: =+$I$13+$I$12*O15+P15 -> 4.407688 | T15: =10^Q15 -> 18489.664 | U15: =10^O15 -> 1.396 | V15: =10^R15 -> 13371.19 | W15: =10^$O15 -> 1.396 | X15: =10^S15 -> 25567.483 | Y15: =10^$O15 -> 1.396
H16: F-VALUE | I16: =VLOOKUP($J$24,$H$33:$J$69,3) -> 5.79 | M16: =+C16 -> 0 | N16: =+$I$13+$I$12*M16 -> 5.4673313 | O16: =LOG($I$19+($I$20-$I$19)*(ROW()-2)/100) -> 0.14238947 | P16: =SQRT(2*$I$16*$K$24)*SQRT((1/$I$1)+((O16-$I$10)^2/$I$7)) -> 0.13867378 | Q16: =+$I$13+$I$12*O16 -> 4.2876084 | R16: =+$I$13+$I$12*O16-P16 -> 4.1489347 | S16: =+$I$13+$I$12*O16+P16 -> 4.4262822 | T16: =10^Q16 -> 19391.368 | U16: =10^O16 -> 1.388 | V16: =10^R16 -> 14090.768 | W16: =10^$O16 -> 1.388 | X16: =10^S16 -> 26685.922 | Y16: =10^$O16 -> 1.388 | AA16: Coefficients | AB16: Standard Error | AC16: t Stat | AD16: P-value | AE16: Lower 95% | AF16: Upper 95% | AG16: Lower 95.0% | AH16: Upper 95.0%
H17: CONFIA1 | I17: =+I15*SQRT($K$24/$I$7) -> 0.80967983 | J17: =+I12+I17 -> -7.4755033 | K17: =+I12-I17 -> -9.094863 | M17: =+C17 -> 0 | N17: =+$I$13+$I$12*M17 -> 5.4673313 | O17: =LOG($I$19+($I$20-$I$19)*(ROW()-2)/100) -> 0.13987909 | P17: =SQRT(2*$I$16*$K$24)*SQRT((1/$I$1)+((O17-$I$10)^2/$I$7)) -> 0.13659729 | Q17: =+$I$13+$I$12*O17 -> 4.3084074 | R17: =+$I$13+$I$12*O17-P17 -> 4.1718101 | S17: =+$I$13+$I$12*O17+P17 -> 4.4450047 | T17: =10^Q17 -> 20342.644 | U17: =10^O17 -> 1.38 | V17: =10^R17 -> 14852.861 | W17: =10^$O17 -> 1.38 | X17: =10^S17 -> 27861.512 | Y17: =10^$O17 -> 1.38 | Z17: Intercept | AA17: 86.958826 | AB17: 2.9348407 | AC17: 29.629828 | AD17: 1.8247423e-09 | AE17: 80.191067 | AF17: 93.726586 | AG17: 80.191067 | AH17: 93.726586
H18: CONFIA0 | I18: =+I15*SQRT(K24/I1) -> 0.06611881 | J18: =+I13-I18 -> 5.4012124 | K18: =+I13+I18 -> 5.5334501 | M18: =+C18 -> 0 | N18: =+$I$13+$I$12*M18 -> 5.4673313 | O18: =LOG($I$19+($I$20-$I$19)*(ROW()-2)/100) -> 0.13735411 | P18: =SQRT(2*$I$16*$K$24)*SQRT((1/$I$1)+((O18-$I$10)^2/$I$7)) -> 0.13453068 | Q18: =+$I$13+$I$12*O18 -> 4.3293273 | R18: =+$I$13+$I$12*O18-P18 -> 4.1947966 | S18: =+$I$13+$I$12*O18+P18 -> 4.463858 | T18: =10^Q18 -> 21346.529 | U18: =10^O18 -> 1.372 | V18: =10^R18 -> 15660.174 | W18: =10^$O18 -> 1.372 | X18: =10^S18 -> 29097.653 | Y18: =10^$O18 -> 1.372 | Z18: X Variable 1 | AA18: -0.00039353116 | AB18: 7.4171706e-05 | AC18: -5.3056776 | AD18: 0.00072341619 | AE18: -0.00056457153 | AF18: -0.00022249079 | AG18: -0.00056457153 | AH18: -0.00022249079
H19: Xmin | I19: 1.5 | M19: =+C19 -> 0 | N19: =+$I$13+$I$12*M19 -> 5.4673313 | O19: =LOG($I$19+($I$20-$I$19)*(ROW()-2)/100) -> 0.13481437 | P19: =SQRT(2*$I$16*$K$24)*SQRT((1/$I$1)+((O19-$I$10)^2/$I$7)) -> 0.13247525 | Q19: =+$I$13+$I$12*O19 -> 4.3503695 | R19: =+$I$13+$I$12*O19-P19 -> 4.2178942 | S19: =+$I$13+$I$12*O19+P19 -> 4.4828447 | T19: =10^Q19 -> 22406.266 | U19: =10^O19 -> 1.364 | V19: =10^R19 -> 16515.596 | W19: =10^$O19 -> 1.364 | X19: =10^S19 -> 30397.982 | Y19: =10^$O19 -> 1.364
H20: Xmax | I20: 0.7 | O20: =LOG($I$19+($I$20-$I$19)*(ROW()-2)/100) -> 0.13225969 | P20: =SQRT(2*$I$16*$K$24)*SQRT((1/$I$1)+((O20-$I$10)^2/$I$7)) -> 0.13043237 | Q20: =+$I$13+$I$12*O20 -> 4.3715355 | R20: =+$I$13+$I$12*O20-P20 -> 4.2411031 | S20: =+$I$13+$I$12*O20+P20 -> 4.5019679 | T20: =10^Q20 -> 23525.318 | U20: =10^O20 -> 1.356 | V20: =10^R20 -> 17422.205 | W20: =10^$O20 -> 1.356 | X20: =10^S20 -> 31766.39 | Y20: =10^$O20 -> 1.356
H21: Variansanalysetabel | O21: =LOG($I$19+($I$20-$I$19)*(ROW()-2)/100) -> 0.12968989 | P21: =SQRT(2*$I$16*$K$24)*SQRT((1/$I$1)+((O21-$I$10)^2/$I$7)) -> 0.12840352 | Q21: =+$I$13+$I$12*O21 -> 4.3928267 | R21: =+$I$13+$I$12*O21-P21 -> 4.2644232 | S21: =+$I$13+$I$12*O21+P21 -> 4.5212303 | T21: =10^Q21 -> 24707.382 | U21: =10^O21 -> 1.348 | V21: =10^R21 -> 18383.289 | W21: =10^$O21 -> 1.348 | X21: =10^S21 -> 33207.047 | Y21: =10^$O21 -> 1.348
I22: SAK | J22: f | K22: S2 | L22: F | O22: =LOG($I$19+($I$20-$I$19)*(ROW()-2)/100) -> 0.1271048 | P22: =SQRT(2*$I$16*$K$24)*SQRT((1/$I$1)+((O22-$I$10)^2/$I$7)) -> 0.12639031 | Q22: =+$I$13+$I$12*O22 -> 4.4142447 | R22: =+$I$13+$I$12*O22-P22 -> 4.2878544 | S22: =+$I$13+$I$12*O22+P22 -> 4.540635 | T22: =10^Q22 -> 25956.415 | U22: =10^O22 -> 1.34 | V22: =10^R22 -> 19402.353 | W22: =10^$O22 -> 1.34 | X22: =10^S22 -> 34724.421 | Y22: =10^$O22 -> 1.34 | Z22: RESIDUAL OUTPUT
H23: Regress | I23: =+I9^2/I7 -> 3.2042448 | J23: 1 | K23: =+I23/1 -> 3.2042448 | L23: =+K23/K24 -> 691.9052 | O23: =LOG($I$19+($I$20-$I$19)*(ROW()-2)/100) -> 0.12450422 | P23: =SQRT(2*$I$16*$K$24)*SQRT((1/$I$1)+((O23-$I$10)^2/$I$7)) -> 0.12439444 | Q23: =+$I$13+$I$12*O23 -> 4.4357909 | R23: =+$I$13+$I$12*O23-P23 -> 4.3113965 | S23: =+$I$13+$I$12*O23+P23 -> 4.5601854 | T23: =10^Q23 -> 27276.644 | U23: =10^O23 -> 1.332 | V23: =10^R23 -> 20483.139 | W23: =10^$O23 -> 1.332 | X23: =10^S23 -> 36323.307 | Y23: =10^$O23 -> 1.332
H24: Residual | I24: =+I8-I23 -> 0.02315523 | J24: =+I1-2 -> 5 | K24: =+I24/($I$1-2) -> 0.004631046 | O24: =LOG($I$19+($I$20-$I$19)*(ROW()-2)/100) -> 0.12188799 | P24: =SQRT(2*$I$16*$K$24)*SQRT((1/$I$1)+((O24-$I$10)^2/$I$7)) -> 0.12241776 | Q24: =+$I$13+$I$12*O24 -> 4.457467 | R24: =+$I$13+$I$12*O24-P24 -> 4.3350492 | S24: =+$I$13+$I$12*O24+P24 -> 4.5798847 | T24: =10^Q24 -> 28672.593 | U24: =10^O24 -> 1.324 | V24: =10^R24 -> 21629.636 | W24: =10^$O24 -> 1.324 | X24: =10^S24 -> 38008.85 | Y24: =10^$O24 -> 1.324 | Z24: Observation | AA24: Predicted Y | AB24: Residuals | AC24: Standard Residuals
H25: Total | I25: =SUM(I23:I24) -> 3.2274 | J25: =SUM(J23:J24) -> 6 | O25: =LOG($I$19+($I$20-$I$19)*(ROW()-2)/100) -> 0.11925589 | P25: =SQRT(2*$I$16*$K$24)*SQRT((1/$I$1)+((O25-$I$10)^2/$I$7)) -> 0.12046225 | Q25: =+$I$13+$I$12*O25 -> 4.4792744 | R25: =+$I$13+$I$12*O25-P25 -> 4.3588121 | S25: =+$I$13+$I$12*O25+P25 -> 4.5997366 | T25: =10^Q25 -> 30149.101 | U25: =10^O25 -> 1.316 | V25: =10^R25 -> 22846.102 | W25: =10^$O25 -> 1.316 | X25: =10^S25 -> 39786.58 | Y25: =10^$O25 -> 1.316 | Z25: 1 | AA25: 64.962009 | AB25: 0.4744117 | AC25: 0.10320336
O26: =LOG($I$19+($I$20-$I$19)*(ROW()-2)/100) -> 0.11660774 | P26: =SQRT(2*$I$16*$K$24)*SQRT((1/$I$1)+((O26-$I$10)^2/$I$7)) -> 0.11853003 | Q26: =+$I$13+$I$12*O26 -> 4.5012147 | R26: =+$I$13+$I$12*O26-P26 -> 4.3826847 | S26: =+$I$13+$I$12*O26+P26 -> 4.6197448 | T26: =10^Q26 -> 31711.35 | U26: =10^O26 -> 1.308 | V26: =10^R26 -> 24137.079 | W26: =10^$O26 -> 1.308 | X26: =10^S26 -> 41662.445 | Y26: =10^$O26 -> 1.308 | Z26: 2 | AA26: 84.735375 | AB26: 8.1224338 | AC26: 1.7669515
O27: =LOG($I$19+($I$20-$I$19)*(ROW()-2)/100) -> 0.11394335 | P27: =SQRT(2*$I$16*$K$24)*SQRT((1/$I$1)+((O27-$I$10)^2/$I$7)) -> 0.11662336 | Q27: =+$I$13+$I$12*O27 -> 4.5232897 | R27: =+$I$13+$I$12*O27-P27 -> 4.4066663 | S27: =+$I$13+$I$12*O27+P27 -> 4.6399131 | T27: =10^Q27 -> 33364.891 | U27: =10^O27 -> 1.3 | V27: =10^R27 -> 25507.409 | W27: =10^$O27 -> 1.3 | X27: =10^S27 -> 43642.847 | Y27: =10^$O27 -> 1.3 | Z27: 3 | AA27: 72.39896 | AB27: -3.7728516 | AC27: -0.82074485
O28: =LOG($I$19+($I$20-$I$19)*(ROW()-2)/100) -> 0.11126251 | P28: =SQRT(2*$I$16*$K$24)*SQRT((1/$I$1)+((O28-$I$10)^2/$I$7)) -> 0.1147447 | Q28: =+$I$13+$I$12*O28 -> 4.5455009 | R28: =+$I$13+$I$12*O28-P28 -> 4.4307562 | S28: =+$I$13+$I$12*O28+P28 -> 4.6602456 | T28: =10^Q28 -> 35115.669 | U28: =10^O28 -> 1.292 | V28: =10^R28 -> 26962.257 | W28: =10^$O28 -> 1.292 | X28: =10^S28 -> 45734.68 | Y28: =10^$O28 -> 1.292 | Z28: 4 | AA28: 83.96799 | AB28: 3.5389413 | AC28: 0.76986009
H29: N = | I29: =10^$I$13 -> 293312.96 | J29: * | K29: S^ | L29: =+I12 -> -8.2851832 | O29: =LOG($I$19+($I$20-$I$19)*(ROW()-2)/100) -> 0.10856502 | P29: =SQRT(2*$I$16*$K$24)*SQRT((1/$I$1)+((O29-$I$10)^2/$I$7)) -> 0.11289664 | Q29: =+$I$13+$I$12*O29 -> 4.5678501 | R29: =+$I$13+$I$12*O29-P29 -> 4.4549535 | S29: =+$I$13+$I$12*O29+P29 -> 4.6807468 | T29: =10^Q29 -> 36970.059 | U29: =10^O29 -> 1.284 | V29: =10^R29 -> 28507.13 | W29: =10^$O29 -> 1.284 | X29: =10^S29 -> 47945.382 | Y29: =10^$O29 -> 1.284 | Z29: 5 | AA29: 80.249514 | AB29: -3.0746271 | AC29: -0.66885335
O30: =LOG($I$19+($I$20-$I$19)*(ROW()-2)/100) -> 0.10585067 | P30: =SQRT(2*$I$16*$K$24)*SQRT((1/$I$1)+((O30-$I$10)^2/$I$7)) -> 0.11108197 | Q30: =+$I$13+$I$12*O30 -> 4.590339 | R30: =+$I$13+$I$12*O30-P30 -> 4.4792571 | S30: =+$I$13+$I$12*O30+P30 -> 4.701421 | T30: =10^Q30 -> 38934.896 | U30: =10^O30 -> 1.276 | V30: =10^R30 -> 30147.899 | W30: =10^$O30 -> 1.276 | X30: =10^S30 -> 50282.978 | Y30: =10^$O30 -> 1.276 | Z30: 6 | AA30: 78.183475 | AB30: -4.5407035 | AC30: -0.9877831
O31: =LOG($I$19+($I$20-$I$19)*(ROW()-2)/100) -> 0.10311925 | P31: =SQRT(2*$I$16*$K$24)*SQRT((1/$I$1)+((O31-$I$10)^2/$I$7)) -> 0.10930365 | Q31: =+$I$13+$I$12*O31 -> 4.6129693 | R31: =+$I$13+$I$12*O31-P31 -> 4.5036657 | S31: =+$I$13+$I$12*O31+P31 -> 4.722273 | T31: =10^Q31 -> 41017.515 | U31: =10^O31 -> 1.268 | V31: =10^R31 -> 31890.82 | W31: =10^$O31 -> 1.268 | X31: =10^S31 -> 52756.138 | Y31: =10^$O31 -> 1.268 | Z31: 7 | AA31: 58.292049 | AB31: 5.5384636 | AC31: 1.2048355
H32: N | I32: TVALUE | J32: FVALUE | L32: 0.95 | O32: =LOG($I$19+($I$20-$I$19)*(ROW()-2)/100) -> 0.10037055 | P32: =SQRT(2*$I$16*$K$24)*SQRT((1/$I$1)+((O32-$I$10)^2/$I$7)) -> 0.10756486 | Q32: =+$I$13+$I$12*O32 -> 4.6357429 | R32: =+$I$13+$I$12*O32-P32 -> 4.528178 | S32: =+$I$13+$I$12*O32+P32 -> 4.7433078 | T32: =10^Q32 -> 43225.786 | U32: =10^O32 -> 1.26 | V32: =10^R32 -> 33742.561 | W32: =10^$O32 -> 1.26 | X32: =10^S32 -> 55374.237 | Y32: =10^$O32 -> 1.26 | Z32: 8 | AA32: 76.17686 | AB32: -1.661665 | AC32: -0.36147805
H33: 1 | I33: 12.706 | J33: 199.5 | O33: =LOG($I$19+($I$20-$I$19)*(ROW()-2)/100) -> 0.097604329 | P33: =SQRT(2*$I$16*$K$24)*SQRT((1/$I$1)+((O33-$I$10)^2/$I$7)) -> 0.10586894 | Q33: =+$I$13+$I$12*O33 -> 4.6586615 | R33: =+$I$13+$I$12*O33-P33 -> 4.5527926 | S33: =+$I$13+$I$12*O33+P33 -> 4.7645304 | T33: =10^Q33 -> 45568.161 | U33: =10^O33 -> 1.252 | V33: =10^R33 -> 35710.223 | W33: =10^$O33 -> 1.252 | X33: =10^S33 -> 58147.42 | Y33: =10^$O33 -> 1.252 | Z33: 9 | AA33: 66.378327 | AB33: 1.0806765 | AC33: 0.23508999
H34: 2 | I34: 4.303 | J34: 19 | O34: =LOG($I$19+($I$20-$I$19)*(ROW()-2)/100) -> 0.09482038 | P34: =SQRT(2*$I$16*$K$24)*SQRT((1/$I$1)+((O34-$I$10)^2/$I$7)) -> 0.10421947 | Q34: =+$I$13+$I$12*O34 -> 4.681727 | R34: =+$I$13+$I$12*O34-P34 -> 4.5775076 | S34: =+$I$13+$I$12*O34+P34 -> 4.7859465 | T34: =10^Q34 -> 48053.722 | U34: =10^O34 -> 1.244 | V34: =10^R34 -> 37801.372 | W34: =10^$O34 -> 1.244 | X34: =10^S34 -> 61086.677 | Y34: =10^$O34 -> 1.244 | Z34: 10 | AA34: 71.750028 | AB34: -5.7050796 | AC34: -1.2410811
H35: 3 | I35: 3.182 | J35: 9.55 | O35: =LOG($I$19+($I$20-$I$19)*(ROW()-2)/100) -> 0.092018471 | P35: =SQRT(2*$I$16*$K$24)*SQRT((1/$I$1)+((O35-$I$10)^2/$I$7)) -> 0.10262022 | Q35: =+$I$13+$I$12*O35 -> 4.7049414 | R35: =+$I$13+$I$12*O35-P35 -> 4.6023211 | S35: =+$I$13+$I$12*O35+P35 -> 4.8075616 | T35: =10^Q35 -> 50692.226 | U35: =10^O35 -> 1.236 | V35: =10^R35 -> 40024.061 | W35: =10^$O35 -> 1.236 | X35: =10^S35 -> 64203.925 | Y35: =10^$O35 -> 1.236 | Z35: 11 | AA35: 1.8219741 | AB35: -0.023572384 | AC35: -2.1105589
H36: 4 | I36: 2.7764 | J36: 6.94 | O36: =LOG($I$19+($I$20-$I$19)*(ROW()-2)/100) -> 0.089198367 | P36: =SQRT(2*$I$16*$K$24)*SQRT((1/$I$1)+((O36-$I$10)^2/$I$7)) -> 0.10107515 | Q36: =+$I$13+$I$12*O36 -> 4.7283064 | R36: =+$I$13+$I$12*O36-P36 -> 4.6272313 | S36: =+$I$13+$I$12*O36+P36 -> 4.8293816 | T36: =10^Q36 -> 53494.169 | U36: =10^O36 -> 1.228 | V36: =10^R36 -> 42386.865 | W36: =10^$O36 -> 1.228 | X36: =10^S36 -> 67512.096 | Y36: =10^$O36 -> 1.228 | Z36: 12 | AA36: 1.7418459 | AB36: 0.0051980261 | AC36: 0.46540648
H37: 5 | I37: 2.5706 | J37: 5.79 | O37: =LOG($I$19+($I$20-$I$19)*(ROW()-2)/100) -> 0.086359831 | P37: =SQRT(2*$I$16*$K$24)*SQRT((1/$I$1)+((O37-$I$10)^2/$I$7)) -> 0.099588451 | Q37: =+$I$13+$I$12*O37 -> 4.7518242 | R37: =+$I$13+$I$12*O37-P37 -> 4.6522358 | S37: =+$I$13+$I$12*O37+P37 -> 4.8514127 | T37: =10^Q37 -> 56470.838 | U37: =10^O37 -> 1.22 | V37: =10^R37 -> 44898.908 | W37: =10^$O37 -> 1.22 | X37: =10^S37 -> 71025.236 | Y37: =10^$O37 -> 1.22
H38: 6 | I38: 2.4469 | J38: 5.14 | O38: =LOG($I$19+($I$20-$I$19)*(ROW()-2)/100) -> 0.08350262 | P38: =SQRT(2*$I$16*$K$24)*SQRT((1/$I$1)+((O38-$I$10)^2/$I$7)) -> 0.098164488 | Q38: =+$I$13+$I$12*O38 -> 4.7754967 | R38: =+$I$13+$I$12*O38-P38 -> 4.6773323 | S38: =+$I$13+$I$12*O38+P38 -> 4.8736612 | T38: =10^Q38 -> 59634.386 | U38: =10^O38 -> 1.212 | V38: =10^R38 -> 47569.902 | W38: =10^$O38 -> 1.212 | X38: =10^S38 -> 74758.613 | Y38: =10^$O38 -> 1.212
H39: 7 | I39: 2.3646 | J39: 4.74 | O39: =LOG($I$19+($I$20-$I$19)*(ROW()-2)/100) -> 0.080626487 | P39: =SQRT(2*$I$16*$K$24)*SQRT((1/$I$1)+((O39-$I$10)^2/$I$7)) -> 0.096807818 | Q39: =+$I$13+$I$12*O39 -> 4.799326 | R39: =+$I$13+$I$12*O39-P39 -> 4.7025182 | S39: =+$I$13+$I$12*O39+P39 -> 4.8961339 | T39: =10^Q39 -> 62997.895 | U39: =10^O39 -> 1.204 | V39: =10^R39 -> 50410.177 | W39: =10^$O39 -> 1.204 | X39: =10^S39 -> 78728.841 | Y39: =10^$O39 -> 1.204
H40: 8 | I40: 2.306 | J40: 4.46 | O40: =LOG($I$19+($I$20-$I$19)*(ROW()-2)/100) -> 0.07773118 | P40: =SQRT(2*$I$16*$K$24)*SQRT((1/$I$1)+((O40-$I$10)^2/$I$7)) -> 0.095523163 | Q40: =+$I$13+$I$12*O40 -> 4.8233142 | R40: =+$I$13+$I$12*O40-P40 -> 4.727791 | S40: =+$I$13+$I$12*O40+P40 -> 4.9188374 | T40: =10^Q40 -> 66575.462 | U40: =10^O40 -> 1.196 | V40: =10^R40 -> 53430.72 | W40: =10^$O40 -> 1.196 | X40: =10^S40 -> 82954.004 | Y40: =10^$O40 -> 1.196
...

Sheet ASTM E739 stat (Strain Range)
A1: SN Points | C1: X | D1: Y | E1: X^2 | F1: Y^2 | G1: X*Y | H1: N | I1: =COUNT(C:C) -> 7 | M1: X | N1: YHAT | O1: X | P1: Xconfi | Q1: Yavg | R1: Y1 | S1: Y2 | T1: SN-line | V1: Lower conf | X1: Upper Conf | Z1: SUMMARY OUTPUT
H2: SUMX | I2: =SUM(C:C) -> -0.026032456 | M2: =+C2 -> 0 | N2: =+$I$13+$I$12*M2 -> 5.0882221 | O2: =LOG($I$19+($I$20-$I$19)*(ROW()-2)/100) -> -0.1426675 | P2: =SQRT(2*$I$16*$K$24)*SQRT((1/$I$1)+((O2-$I$10)^2/$I$7)) -> 0.17274759 | Q2: =+$I$13+$I$12*O2 -> 6.2702485 | R2: =+$I$13+$I$12*O2-P2 -> 6.0975009 | S2: =+$I$13+$I$12*O2+P2 -> 6.4429961 | T2: =10^Q2 -> 1863152.7 | U2: =10^$O2 -> 0.72 | V2: =10^R2 -> 1251701.8 | W2: =10^$O2 -> 0.72 | X2: =10^S2 -> 2773294.9 | Y2: =10^$O2 -> 0.72
H3: SUMY | I3: =SUM(D:D) -> 35.833238 | M3: =+C3 -> 0 | N3: =+$I$13+$I$12*M3 -> 5.0882221 | O3: =LOG($I$19+($I$20-$I$19)*(ROW()-2)/100) -> -0.13888396 | P3: =SQRT(2*$I$16*$K$24)*SQRT((1/$I$1)+((O3-$I$10)^2/$I$7)) -> 0.16926378 | Q3: =+$I$13+$I$12*O3 -> 6.2389011 | R3: =+$I$13+$I$12*O3-P3 -> 6.0696373 | S3: =+$I$13+$I$12*O3+P3 -> 6.4081649 | T3: =10^Q3 -> 1733409.1 | U3: =10^O3 -> 0.7263 | V3: =10^R3 -> 1173916.7 | W3: =10^$O3 -> 0.7263 | X3: =10^S3 -> 2559557.3 | Y3: =10^$O3 -> 0.7263 | Z3: Regression Statistics
A4: =+Results!D25 -> 1.35 | B4: =+Results!C25 -> 10766 | C4: =LOG(A4) -> 0.13033377 | D4: =LOG(B4) -> 4.0320544 | E4: =+C4^2 -> 0.016986891 | F4: =+D4^2 -> 16.257462 | G4: =+C4*D4 -> 0.52551284 | H4: SUMXX | I4: =SUM(E:E) -> 0.046775803 | M4: =+C4 -> 0.13033377 | N4: =+$I$13+$I$12*M4 -> 4.0083829 | O4: =LOG($I$19+($I$20-$I$19)*(ROW()-2)/100) -> -0.13513309 | P4: =SQRT(2*$I$16*$K$24)*SQRT((1/$I$1)+((O4-$I$10)^2/$I$7)) -> 0.1658357 | Q4: =+$I$13+$I$12*O4 -> 6.2078244 | R4: =+$I$13+$I$12*O4-P4 -> 6.0419887 | S4: =+$I$13+$I$12*O4+P4 -> 6.3736601 | T4: =10^Q4 -> 1613706.1 | U4: =10^O4 -> 0.7326 | V4: =10^R4 -> 1101510.7 | W4: =10^$O4 -> 0.7326 | X4: =10^S4 -> 2364068.9 | Y4: =10^$O4 -> 0.7326 | Z4: Multiple R | AA4: 0.88244047
A5: =+Results!D26 -> 0.99 | B5: =+Results!C26 -> 148187 | C5: =LOG(A5) -> -0.0043648054 | D5: =LOG(B5) -> 5.1708101 | E5: =+C5^2 -> 1.9051526e-05 | F5: =+D5^2 -> 26.737277 | G5: =+C5*D5 -> -0.02256958 | H5: SUMYY | I5: =SUM(F:F) -> 186.65896 | M5: =+C5 -> -0.0043648054 | N5: =+$I$13+$I$12*M5 -> 5.1243853 | O5: =LOG($I$19+($I$20-$I$19)*(ROW()-2)/100) -> -0.13141433 | P5: =SQRT(2*$I$16*$K$24)*SQRT((1/$I$1)+((O5-$I$10)^2/$I$7)) -> 0.16246378 | Q5: =+$I$13+$I$12*O5 -> 6.1770139 | R5: =+$I$13+$I$12*O5-P5 -> 6.0145501 | S5: =+$I$13+$I$12*O5+P5 -> 6.3394777 | T5: =10^Q5 -> 1503190 | U5: =10^O5 -> 0.7389 | V5: =10^R5 -> 1034070.4 | W5: =10^$O5 -> 0.7389 | X5: =10^S5 -> 2185131.9 | Y5: =10^$O5 -> 0.7389 | Z5: R Square | AA5: 0.77870118
A6: =+Results!D27 -> 0.81 | B6: =+Results!C27 -> 581856 | C6: =LOG(A6) -> -0.091514981 | D6: =LOG(B6) -> 5.7648155 | E6: =+C6^2 -> 0.0083749918 | F6: =+D6^2 -> 33.233098 | G6: =+C6*D6 -> -0.52756698 | H6: SUMXY | I6: =SUM(G:G) -> -0.52000502 | M6: =+C6 -> -0.091514981 | N6: =+$I$13+$I$12*M6 -> 5.8464404 | O6: =LOG($I$19+($I$20-$I$19)*(ROW()-2)/100) -> -0.12772715 | P6: =SQRT(2*$I$16*$K$24)*SQRT((1/$I$1)+((O6-$I$10)^2/$I$7)) -> 0.15914852 | Q6: =+$I$13+$I$12*O6 -> 6.1464649 | R6: =+$I$13+$I$12*O6-P6 -> 5.9873164 | S6: =+$I$13+$I$12*O6+P6 -> 6.3056134 | T6: =10^Q6 -> 1401086.4 | U6: =10^O6 -> 0.7452 | V6: =10^R6 -> 971217.28 | W6: =10^$O6 -> 0.7452 | X6: =10^S6 -> 2021219.4 | Y6: =10^$O6 -> 0.7452 | Z6: Adjusted R Square | AA6: 0.75103883
A7: =+Results!D28 -> 0.9 | B7: =+Results!C28 -> 290916 | C7: =LOG(A7) -> -0.045757491 | D7: =LOG(B7) -> 5.4637676 | E7: =+C7^2 -> 0.0020937479 | F7: =+D7^2 -> 29.852756 | G7: =+C7*D7 -> -0.25000829 | H7: SAKX | I7: =+I4-I2^2/$I$1 -> 0.046678991 | M7: =+C7 -> -0.045757491 | N7: =+$I$13+$I$12*M7 -> 5.4673313 | O7: =LOG($I$19+($I$20-$I$19)*(ROW()-2)/100) -> -0.12407102 | P7: =SQRT(2*$I$16*$K$24)*SQRT((1/$I$1)+((O7-$I$10)^2/$I$7)) -> 0.15589049 | Q7: =+$I$13+$I$12*O7 -> 6.1161731 | R7: =+$I$13+$I$12*O7-P7 -> 5.9602827 | S7: =+$I$13+$I$12*O7+P7 -> 6.2720636 | T7: =10^Q7 -> 1306691.7 | U7: =10^O7 -> 0.7515 | V7: =10^R7 -> 912604.6 | W7: =10^$O7 -> 0.7515 | X7: =10^S7 -> 1870956.3 | Y7: =10^$O7 -> 0.7515 | Z7: Standard Error | AA7: 4.8757094
H8: SAKY (SAKtotal) | I8: =+I5-I3^2/$I$1 -> 3.2274 | M8: =+C8 -> 0 | N8: =+$I$13+$I$12*M8 -> 5.0882221 | O8: =LOG($I$19+($I$20-$I$19)*(ROW()-2)/100) -> -0.1204454 | P8: =SQRT(2*$I$16*$K$24)*SQRT((1/$I$1)+((O8-$I$10)^2/$I$7)) -> 0.15269034 | Q8: =+$I$13+$I$12*O8 -> 6.0861343 | R8: =+$I$13+$I$12*O8-P8 -> 5.9334439 | S8: =+$I$13+$I$12*O8+P8 -> 6.2388246 | T8: =10^Q8 -> 1219366.5 | U8: =10^O8 -> 0.7578 | V8: =10^R8 -> 857914.32 | W8: =10^$O8 -> 0.7578 | X8: =10^S8 -> 1733103.9 | Y8: =10^$O8 -> 0.7578 | Z8: Observations | AA8: 10
H9: SAPXY | I9: =+I6-I2*I3/$I$1 -> -0.38674399 | M9: =+C9 -> 0 | N9: =+$I$13+$I$12*M9 -> 5.0882221 | O9: =LOG($I$19+($I$20-$I$19)*(ROW()-2)/100) -> -0.1168498 | P9: =SQRT(2*$I$16*$K$24)*SQRT((1/$I$1)+((O9-$I$10)^2/$I$7)) -> 0.14954878 | Q9: =+$I$13+$I$12*O9 -> 6.0563441 | R9: =+$I$13+$I$12*O9-P9 -> 5.9067953 | S9: =+$I$13+$I$12*O9+P9 -> 6.2058928 | T9: =10^Q9 -> 1138528.9 | U9: =10^O9 -> 0.7641 | V9: =10^R9 -> 806854.61 | W9: =10^$O9 -> 0.7641 | X9: =10^S9 -> 1606544.8 | Y9: =10^$O9 -> 0.7641
A10: =+Results!D31 -> 1.17 | B10: =+Results!C31 -> 35032 | C10: =LOG(A10) -> 0.068185862 | D10: =LOG(B10) -> 4.5444649 | E10: =+C10^2 -> 0.0046493117 | F10: =+D10^2 -> 20.652162 | G10: =+C10*D10 -> 0.30986826 | H10: XMEAN | I10: =+I2/$I$1 -> -0.0037189223 | M10: =+C10 -> 0.068185862 | N10: =+$I$13+$I$12*M10 -> 4.5232897 | O10: =LOG($I$19+($I$20-$I$19)*(ROW()-2)/100) -> -0.11328373 | P10: =SQRT(2*$I$16*$K$24)*SQRT((1/$I$1)+((O10-$I$10)^2/$I$7)) -> 0.14646663 | Q10: =+$I$13+$I$12*O10 -> 6.0267985 | R10: =+$I$13+$I$12*O10-P10 -> 5.8803319 | S10: =+$I$13+$I$12*O10+P10 -> 6.1732651 | T10: =10^Q10 -> 1063649.4 | U10: =10^O10 -> 0.7704 | V10: =10^R10 -> 759157.44 | W10: =10^$O10 -> 0.7704 | X10: =10^S10 -> 1490270.5 | Y10: =10^$O10 -> 0.7704 | Z10: ANOVA
A11: =+Results!D32 -> 0.72 | B11: =+Results!C32 -> 2000000 | H11: YMEAN | I11: =+I3/$I$1 -> 5.119034 | M11: =+C11 -> 0 | N11: =+$I$13+$I$12*M11 -> 5.0882221 | O11: =LOG($I$19+($I$20-$I$19)*(ROW()-2)/100) -> -0.10974669 | P11: =SQRT(2*$I$16*$K$24)*SQRT((1/$I$1)+((O11-$I$10)^2/$I$7)) -> 0.14344477 | Q11: =+$I$13+$I$12*O11 -> 5.9974935 | R11: =+$I$13+$I$12*O11-P11 -> 5.8540488 | S11: =+$I$13+$I$12*O11+P11 -> 6.1409383 | T11: =10^Q11 -> 994245.26 | U11: =10^O11 -> 0.7767 | V11: =10^R11 -> 714576.55 | W11: =10^$O11 -> 0.7767 | X11: =10^S11 -> 1383369.8 | Y11: =10^$O11 -> 0.7767 | AA11: df | AB11: SS | AC11: MS | AD11: F | AE11: Significance F
A12: =+Results!D33 -> 1.08 | B12: =+Results!C33 -> 53299 | C12: =LOG(A12) -> 0.033423755 | D12: =LOG(B12) -> 4.7267191 | E12: =+C12^2 -> 0.0011171474 | F12: =+D12^2 -> 22.341873 | G12: =+C12*D12 -> 0.1579847 | H12: A1 | I12: =+I9/I7 -> -8.2851832 | J12: =+I12 -> -8.2851832 | K12: =1/J12 -> -0.12069739 | M12: =+C12 -> 0.033423755 | N12: =+$I$13+$I$12*M12 -> 4.8113001 | O12: =LOG($I$19+($I$20-$I$19)*(ROW()-2)/100) -> -0.10623824 | P12: =SQRT(2*$I$16*$K$24)*SQRT((1/$I$1)+((O12-$I$10)^2/$I$7)) -> 0.14048419 | Q12: =+$I$13+$I$12*O12 -> 5.9684253 | R12: =+$I$13+$I$12*O12-P12 -> 5.8279411 | S12: =+$I$13+$I$12*O12+P12 -> 6.1089095 | T12: =10^Q12 -> 929876.61 | U12: =10^O12 -> 0.783 | V12: =10^R12 -> 672885.44 | W12: =10^$O12 -> 0.783 | X12: =10^S12 -> 1285018.9 | Y12: =10^$O12 -> 0.783 | Z12: Regression | AA12: 1 | AB12: 669.20218 | AC12: 669.20218 | AD12: 28.150215 | AE12: 0.00072341619
A13: =+Results!D34 -> 0.765 | B13: =+Results!C34 -> 1350848 | C13: =LOG(A13) -> -0.11633856 | D13: =LOG(B13) -> 6.1306065 | E13: =+C13^2 -> 0.013534662 | F13: =+D13^2 -> 37.584336 | G13: =+C13*D13 -> -0.71322596 | H13: A0 | I13: =+I11-I12*I10 -> 5.0882221 | J13: =10^I13 -> 122524.25 | K13: =+J13^J12 -> 6.9686424e-43 | M13: =+C13 -> -0.11633856 | N13: =+$I$13+$I$12*M13 -> 6.0521084 | O13: =LOG($I$19+($I$20-$I$19)*(ROW()-2)/100) -> -0.1027579 | P13: =SQRT(2*$I$16*$K$24)*SQRT((1/$I$1)+((O13-$I$10)^2/$I$7)) -> 0.13758595 | Q13: =+$I$13+$I$12*O13 -> 5.9395901 | R13: =+$I$13+$I$12*O13-P13 -> 5.8020041 | S13: =+$I$13+$I$12*O13+P13 -> 6.077176 | T13: =10^Q13 -> 870141.86 | U13: =10^O13 -> 0.7893 | V13: =10^R13 -> 633875.71 | W13: =10^$O13 -> 0.7893 | X13: =10^S13 -> 1194472.1 | Y13: =10^$O13 -> 0.7893 | Z13: Residual | AA13: 8 | AB13: 190.18034 | AC13: 23.772542
H14: R2 | I14: =+I9^2/(I7*I8) -> 0.99282542 | J14: ="(X="&TEXT(J13,"0.0")&"Y^"&TEXT(J12,"0.00")&")" -> (X=122524.3Y^-8.29) | M14: =+C14 -> 0 | N14: =+$I$13+$I$12*M14 -> 5.0882221 | O14: =LOG($I$19+($I$20-$I$19)*(ROW()-2)/100) -> -0.099305226 | P14: =SQRT(2*$I$16*$K$24)*SQRT((1/$I$1)+((O14-$I$10)^2/$I$7)) -> 0.13475121 | Q14: =+$I$13+$I$12*O14 -> 5.910984 | R14: =+$I$13+$I$12*O14-P14 -> 5.7762328 | S14: =+$I$13+$I$12*O14+P14 -> 6.0457353 | T14: =10^Q14 -> 814674.35 | U14: =10^O14 -> 0.7956 | V14: =10^R14 -> 597355.46 | W14: =10^$O14 -> 0.7956 | X14: =10^S14 -> 1111054.2 | Y14: =10^$O14 -> 0.7956 | Z14: Total | AA14: 9 | AB14: 859.38251
H15: T-VALUE | I15: =VLOOKUP($J$24,$H$33:$J$69,2) -> 2.5706 | M15: =+C15 -> 0 | N15: =+$I$13+$I$12*M15 -> 5.0882221 | O15: =LOG($I$19+($I$20-$I$19)*(ROW()-2)/100) -> -0.095879787 | P15: =SQRT(2*$I$16*$K$24)*SQRT((1/$I$1)+((O15-$I$10)^2/$I$7)) -> 0.13198121 | Q15: =+$I$13+$I$12*O15 -> 5.8826037 | R15: =+$I$13+$I$12*O15-P15 -> 5.7506224 | S15: =+$I$13+$I$12*O15+P15 -> 6.0145849 | T15: =10^Q15 -> 763139.01 | U15: =10^O15 -> 0.8019 | V15: =10^R15 -> 563147.87 | W15: =10^$O15 -> 0.8019 | X15: =10^S15 -> 1034153.2 | Y15: =10^$O15 -> 0.8019
H16: F-VALUE | I16: =VLOOKUP($J$24,$H$33:$J$69,3) -> 5.79 | M16: =+C16 -> 0 | N16: =+$I$13+$I$12*M16 -> 5.0882221 | O16: =LOG($I$19+($I$20-$I$19)*(ROW()-2)/100) -> -0.092481154 | P16: =SQRT(2*$I$16*$K$24)*SQRT((1/$I$1)+((O16-$I$10)^2/$I$7)) -> 0.12927728 | Q16: =+$I$13+$I$12*O16 -> 5.8544454 | R16: =+$I$13+$I$12*O16-P16 -> 5.7251681 | S16: =+$I$13+$I$12*O16+P16 -> 5.9837226 | T16: =10^Q16 -> 715229.4 | U16: =10^O16 -> 0.8082 | V16: =10^R16 -> 531089.94 | W16: =10^$O16 -> 0.8082 | X16: =10^S16 -> 963213.68 | Y16: =10^$O16 -> 0.8082 | AA16: Coefficients | AB16: Standard Error | AC16: t Stat | AD16: P-value | AE16: Lower 95% | AF16: Upper 95% | AG16: Lower 95.0% | AH16: Upper 95.0%
H17: CONFIA1 | I17: =+I15*SQRT($K$24/$I$7) -> 0.80967983 | J17: =+I12+I17 -> -7.4755033 | K17: =+I12-I17 -> -9.094863 | M17: =+C17 -> 0 | N17: =+$I$13+$I$12*M17 -> 5.0882221 | O17: =LOG($I$19+($I$20-$I$19)*(ROW()-2)/100) -> -0.089108911 | P17: =SQRT(2*$I$16*$K$24)*SQRT((1/$I$1)+((O17-$I$10)^2/$I$7)) -> 0.12664087 | Q17: =+$I$13+$I$12*O17 -> 5.8265057 | R17: =+$I$13+$I$12*O17-P17 -> 5.6998648 | S17: =+$I$13+$I$12*O17+P17 -> 5.9531466 | T17: =10^Q17 -> 670665.11 | U17: =10^O17 -> 0.8145 | V17: =10^R17 -> 501031.28 | W17: =10^$O17 -> 0.8145 | X17: =10^S17 -> 897731.75 | Y17: =10^$O17 -> 0.8145 | Z17: Intercept | AA17: 86.958826 | AB17: 2.9348407 | AC17: 29.629828 | AD17: 1.8247423e-09 | AE17: 80.191067 | AF17: 93.726586 | AG17: 80.191067 | AH17: 93.726586
H18: CONFIA0 | I18: =+I15*SQRT(K24/I1) -> 0.06611881 | J18: =+I13-I18 -> 5.0221032 | K18: =+I13+I18 -> 5.1543409 | M18: =+C18 -> 0 | N18: =+$I$13+$I$12*M18 -> 5.0882221 | O18: =LOG($I$19+($I$20-$I$19)*(ROW()-2)/100) -> -0.085762652 | P18: =SQRT(2*$I$16*$K$24)*SQRT((1/$I$1)+((O18-$I$10)^2/$I$7)) -> 0.1240735 | Q18: =+$I$13+$I$12*O18 -> 5.7987813 | R18: =+$I$13+$I$12*O18-P18 -> 5.6747078 | S18: =+$I$13+$I$12*O18+P18 -> 5.9228548 | T18: =10^Q18 -> 629189.32 | U18: =10^O18 -> 0.8208 | V18: =10^R18 -> 472833.07 | W18: =10^$O18 -> 0.8208 | X18: =10^S18 -> 837249.39 | Y18: =10^$O18 -> 0.8208 | Z18: X Variable 1 | AA18: -0.00039353116 | AB18: 7.4171706e-05 | AC18: -5.3056776 | AD18: 0.00072341619 | AE18: -0.00056457153 | AF18: -0.00022249079 | AG18: -0.00056457153 | AH18: -0.00022249079
H19: Xmin | I19: =MIN(A:A) -> 0.72 | M19: =+C19 -> 0 | N19: =+$I$13+$I$12*M19 -> 5.0882221 | O19: =LOG($I$19+($I$20-$I$19)*(ROW()-2)/100) -> -0.082441979 | P19: =SQRT(2*$I$16*$K$24)*SQRT((1/$I$1)+((O19-$I$10)^2/$I$7)) -> 0.12157677 | Q19: =+$I$13+$I$12*O19 -> 5.771269 | R19: =+$I$13+$I$12*O19-P19 -> 5.6496922 | S19: =+$I$13+$I$12*O19+P19 -> 5.8928457 | T19: =10^Q19 -> 590566.7 | U19: =10^O19 -> 0.8271 | V19: =10^R19 -> 446367.11 | W19: =10^$O19 -> 0.8271 | X19: =10^S19 -> 781350.2 | Y19: =10^$O19 -> 0.8271
H20: Xmax | I20: =MAX(A:A) -> 1.35 | O20: =LOG($I$19+($I$20-$I$19)*(ROW()-2)/100) -> -0.079146504 | P20: =SQRT(2*$I$16*$K$24)*SQRT((1/$I$1)+((O20-$I$10)^2/$I$7)) -> 0.11915239 | Q20: =+$I$13+$I$12*O20 -> 5.7439653 | R20: =+$I$13+$I$12*O20-P20 -> 5.624813 | S20: =+$I$13+$I$12*O20+P20 -> 5.8631177 | T20: =10^Q20 -> 554581.45 | U20: =10^O20 -> 0.8334 | V20: =10^R20 -> 421514.92 | W20: =10^$O20 -> 0.8334 | X20: =10^S20 -> 729655.28 | Y20: =10^$O20 -> 0.8334
H21: Variansanalysetabel | O21: =LOG($I$19+($I$20-$I$19)*(ROW()-2)/100) -> -0.075875847 | P21: =SQRT(2*$I$16*$K$24)*SQRT((1/$I$1)+((O21-$I$10)^2/$I$7)) -> 0.11680214 | Q21: =+$I$13+$I$12*O21 -> 5.7168673 | R21: =+$I$13+$I$12*O21-P21 -> 5.6000652 | S21: =+$I$13+$I$12*O21+P21 -> 5.8336695 | T21: =10^Q21 -> 521035.54 | U21: =10^O21 -> 0.8397 | V21: =10^R21 -> 398166.95 | W21: =10^$O21 -> 0.8397 | X21: =10^S21 -> 681819.61 | Y21: =10^$O21 -> 0.8397
I22: SAK | J22: f | K22: S2 | L22: F | O22: =LOG($I$19+($I$20-$I$19)*(ROW()-2)/100) -> -0.072629637 | P22: =SQRT(2*$I$16*$K$24)*SQRT((1/$I$1)+((O22-$I$10)^2/$I$7)) -> 0.11452789 | Q22: =+$I$13+$I$12*O22 -> 5.6899719 | R22: =+$I$13+$I$12*O22-P22 -> 5.575444 | S22: =+$I$13+$I$12*O22+P22 -> 5.8044998 | T22: =10^Q22 -> 489747.14 | U22: =10^O22 -> 0.846 | V22: =10^R22 -> 376221.85 | W22: =10^$O22 -> 0.846 | X22: =10^S22 -> 637528.78 | Y22: =10^$O22 -> 0.846 | Z22: RESIDUAL OUTPUT
H23: Regress | I23: =+I9^2/I7 -> 3.2042448 | J23: 1 | K23: =+I23/1 -> 3.2042448 | L23: =+K23/K24 -> 691.9052 | O23: =LOG($I$19+($I$20-$I$19)*(ROW()-2)/100) -> -0.069407512 | P23: =SQRT(2*$I$16*$K$24)*SQRT((1/$I$1)+((O23-$I$10)^2/$I$7)) -> 0.11233158 | Q23: =+$I$13+$I$12*O23 -> 5.663276 | R23: =+$I$13+$I$12*O23-P23 -> 5.5509444 | S23: =+$I$13+$I$12*O23+P23 -> 5.7756076 | T23: =10^Q23 -> 460549.17 | U23: =10^O23 -> 0.8523 | V23: =10^R23 -> 355585.82 | W23: =10^$O23 -> 0.8523 | X23: =10^S23 -> 596496.06 | Y23: =10^$O23 -> 0.8523
H24: Residual | I24: =+I8-I23 -> 0.02315523 | J24: =+I1-2 -> 5 | K24: =+I24/($I$1-2) -> 0.004631046 | O24: =LOG($I$19+($I$20-$I$19)*(ROW()-2)/100) -> -0.066209116 | P24: =SQRT(2*$I$16*$K$24)*SQRT((1/$I$1)+((O24-$I$10)^2/$I$7)) -> 0.1102152 | Q24: =+$I$13+$I$12*O24 -> 5.6367767 | R24: =+$I$13+$I$12*O24-P24 -> 5.5265615 | S24: =+$I$13+$I$12*O24+P24 -> 5.7469919 | T24: =10^Q24 -> 433288.05 | U24: =10^O24 -> 0.8586 | V24: =10^R24 -> 336171.98 | W24: =10^$O24 -> 0.8586 | X24: =10^S24 -> 558459.79 | Y24: =10^$O24 -> 0.8586 | Z24: Observation | AA24: Predicted Y | AB24: Residuals | AC24: Standard Residuals
H25: Total | I25: =SUM(I23:I24) -> 3.2274 | J25: =SUM(J23:J24) -> 6 | O25: =LOG($I$19+($I$20-$I$19)*(ROW()-2)/100) -> -0.063034103 | P25: =SQRT(2*$I$16*$K$24)*SQRT((1/$I$1)+((O25-$I$10)^2/$I$7)) -> 0.10818081 | Q25: =+$I$13+$I$12*O25 -> 5.6104711 | R25: =+$I$13+$I$12*O25-P25 -> 5.5022903 | S25: =+$I$13+$I$12*O25+P25 -> 5.718652 | T25: =10^Q25 -> 407822.47 | U25: =10^O25 -> 0.8649 | V25: =10^R25 -> 317899.86 | W25: =10^$O25 -> 0.8649 | X25: =10^S25 -> 523181 | Y25: =10^$O25 -> 0.8649 | Z25: 1 | AA25: 64.962009 | AB25: 0.4744117 | AC25: 0.10320336
O26: =LOG($I$19+($I$20-$I$19)*(ROW()-2)/100) -> -0.059882133 | P26: =SQRT(2*$I$16*$K$24)*SQRT((1/$I$1)+((O26-$I$10)^2/$I$7)) -> 0.10623051 | Q26: =+$I$13+$I$12*O26 -> 5.5843565 | R26: =+$I$13+$I$12*O26-P26 -> 5.478126 | S26: =+$I$13+$I$12*O26+P26 -> 5.690587 | T26: =10^Q26 -> 384022.35 | U26: =10^O26 -> 0.8712 | V26: =10^R26 -> 300694.85 | W26: =10^$O26 -> 0.8712 | X26: =10^S26 -> 490441.28 | Y26: =10^$O26 -> 0.8712 | Z26: 2 | AA26: 84.735375 | AB26: 8.1224338 | AC26: 1.7669515
O27: =LOG($I$19+($I$20-$I$19)*(ROW()-2)/100) -> -0.056752875 | P27: =SQRT(2*$I$16*$K$24)*SQRT((1/$I$1)+((O27-$I$10)^2/$I$7)) -> 0.10436642 | Q27: =+$I$13+$I$12*O27 -> 5.55843 | R27: =+$I$13+$I$12*O27-P27 -> 5.4540636 | S27: =+$I$13+$I$12*O27+P27 -> 5.6627964 | T27: =10^Q27 -> 361767.9 | U27: =10^O27 -> 0.8775 | V27: =10^R27 -> 284487.77 | W27: =10^$O27 -> 0.8775 | X27: =10^S27 -> 460040.9 | Y27: =10^$O27 -> 0.8775 | Z27: 3 | AA27: 72.39896 | AB27: -3.7728516 | AC27: -0.82074485
O28: =LOG($I$19+($I$20-$I$19)*(ROW()-2)/100) -> -0.053646003 | P28: =SQRT(2*$I$16*$K$24)*SQRT((1/$I$1)+((O28-$I$10)^2/$I$7)) -> 0.10259067 | Q28: =+$I$13+$I$12*O28 -> 5.532689 | R28: =+$I$13+$I$12*O28-P28 -> 5.4300983 | S28: =+$I$13+$I$12*O28+P28 -> 5.6352797 | T28: =10^Q28 -> 340948.68 | U28: =10^O28 -> 0.8838 | V28: =10^R28 -> 269214.44 | W28: =10^$O28 -> 0.8838 | X28: =10^S28 -> 431797.07 | Y28: =10^$O28 -> 0.8838 | Z28: 4 | AA28: 83.96799 | AB28: 3.5389413 | AC28: 0.76986009
H29: N = | I29: =10^$I$13 -> 122524.25 | J29: * | K29: S^ | L29: =+I12 -> -8.2851832 | O29: =LOG($I$19+($I$20-$I$19)*(ROW()-2)/100) -> -0.050561199 | P29: =SQRT(2*$I$16*$K$24)*SQRT((1/$I$1)+((O29-$I$10)^2/$I$7)) -> 0.10090538 | Q29: =+$I$13+$I$12*O29 -> 5.5071309 | R29: =+$I$13+$I$12*O29-P29 -> 5.4062255 | S29: =+$I$13+$I$12*O29+P29 -> 5.6080362 | T29: =10^Q29 -> 321462.9 | U29: =10^O29 -> 0.8901 | V29: =10^R29 -> 254815.29 | W29: =10^$O29 -> 0.8901 | X29: =10^S29 -> 405542.37 | Y29: =10^$O29 -> 0.8901 | Z29: 5 | AA29: 80.249514 | AB29: -3.0746271 | AC29: -0.66885335
O30: =LOG($I$19+($I$20-$I$19)*(ROW()-2)/100) -> -0.047498152 | P30: =SQRT(2*$I$16*$K$24)*SQRT((1/$I$1)+((O30-$I$10)^2/$I$7)) -> 0.099312626 | Q30: =+$I$13+$I$12*O30 -> 5.481753 | R30: =+$I$13+$I$12*O30-P30 -> 5.3824403 | S30: =+$I$13+$I$12*O30+P30 -> 5.5810656 | T30: =10^Q30 -> 303216.58 | U30: =10^O30 -> 0.8964 | V30: =10^R30 -> 241235 | W30: =10^$O30 -> 0.8964 | X30: =10^S30 -> 381123.37 | Y30: =10^$O30 -> 0.8964 | Z30: 6 | AA30: 78.183475 | AB30: -4.5407035 | AC30: -0.9877831
O31: =LOG($I$19+($I$20-$I$19)*(ROW()-2)/100) -> -0.044456558 | P31: =SQRT(2*$I$16*$K$24)*SQRT((1/$I$1)+((O31-$I$10)^2/$I$7)) -> 0.097814444 | Q31: =+$I$13+$I$12*O31 -> 5.4565528 | R31: =+$I$13+$I$12*O31-P31 -> 5.3587383 | S31: =+$I$13+$I$12*O31+P31 -> 5.5543672 | T31: =10^Q31 -> 286123.01 | U31: =10^O31 -> 0.9027 | V31: =10^R31 -> 228422.21 | W31: =10^$O31 -> 0.9027 | X31: =10^S31 -> 358399.36 | Y31: =10^$O31 -> 0.9027 | Z31: 7 | AA31: 58.292049 | AB31: 5.5384636 | AC31: 1.2048355
H32: N | I32: TVALUE | J32: FVALUE | L32: 0.95 | O32: =LOG($I$19+($I$20-$I$19)*(ROW()-2)/100) -> -0.041436117 | P32: =SQRT(2*$I$16*$K$24)*SQRT((1/$I$1)+((O32-$I$10)^2/$I$7)) -> 0.096412773 | Q32: =+$I$13+$I$12*O32 -> 5.4315279 | R32: =+$I$13+$I$12*O32-P32 -> 5.3351151 | S32: =+$I$13+$I$12*O32+P32 -> 5.5279406 | T32: =10^Q32 -> 270102.05 | U32: =10^O32 -> 0.909 | V32: =10^R32 -> 216329.18 | W32: =10^$O32 -> 0.909 | X32: =10^S32 -> 337241.22 | Y32: =10^$O32 -> 0.909 | Z32: 8 | AA32: 76.17686 | AB32: -1.661665 | AC32: -0.36147805
H33: 1 | I33: 12.706 | J33: 199.5 | O33: =LOG($I$19+($I$20-$I$19)*(ROW()-2)/100) -> -0.038436538 | P33: =SQRT(2*$I$16*$K$24)*SQRT((1/$I$1)+((O33-$I$10)^2/$I$7)) -> 0.095109442 | Q33: =+$I$13+$I$12*O33 -> 5.4066758 | R33: =+$I$13+$I$12*O33-P33 -> 5.3115664 | S33: =+$I$13+$I$12*O33+P33 -> 5.5017853 | T33: =10^Q33 -> 255079.65 | U33: =10^O33 -> 0.9153 | V33: =10^R33 -> 204911.52 | W33: =10^$O33 -> 0.9153 | X33: =10^S33 -> 317530.36 | Y33: =10^$O33 -> 0.9153 | Z33: 9 | AA33: 66.378327 | AB33: 1.0806765 | AC33: 0.23508999
H34: 2 | I34: 4.303 | J34: 19 | O34: =LOG($I$19+($I$20-$I$19)*(ROW()-2)/100) -> -0.035457534 | P34: =SQRT(2*$I$16*$K$24)*SQRT((1/$I$1)+((O34-$I$10)^2/$I$7)) -> 0.093906138 | Q34: =+$I$13+$I$12*O34 -> 5.3819942 | R34: =+$I$13+$I$12*O34-P34 -> 5.2880881 | S34: =+$I$13+$I$12*O34+P34 -> 5.4759004 | T34: =10^Q34 -> 240987.34 | U34: =10^O34 -> 0.9216 | V34: =10^R34 -> 194127.96 | W34: =10^$O34 -> 0.9216 | X34: =10^S34 -> 299157.82 | Y34: =10^$O34 -> 0.9216 | Z34: 10 | AA34: 71.750028 | AB34: -5.7050796 | AC34: -1.2410811
H35: 3 | I35: 3.182 | J35: 9.55 | O35: =LOG($I$19+($I$20-$I$19)*(ROW()-2)/100) -> -0.032498825 | P35: =SQRT(2*$I$16*$K$24)*SQRT((1/$I$1)+((O35-$I$10)^2/$I$7)) -> 0.092804376 | Q35: =+$I$13+$I$12*O35 -> 5.3574808 | R35: =+$I$13+$I$12*O35-P35 -> 5.2646764 | S35: =+$I$13+$I$12*O35+P35 -> 5.4502852 | T35: =10^Q35 -> 227761.74 | U35: =10^O35 -> 0.9279 | V35: =10^R35 -> 183940.09 | W35: =10^$O35 -> 0.9279 | X35: =10^S35 -> 282023.41 | Y35: =10^$O35 -> 0.9279 | Z35: 11 | AA35: 1.8219741 | AB35: -0.023572384 | AC35: -2.1105589
H36: 4 | I36: 2.7764 | J36: 6.94 | O36: =LOG($I$19+($I$20-$I$19)*(ROW()-2)/100) -> -0.029560137 | P36: =SQRT(2*$I$16*$K$24)*SQRT((1/$I$1)+((O36-$I$10)^2/$I$7)) -> 0.091805468 | Q36: =+$I$13+$I$12*O36 -> 5.3331332 | R36: =+$I$13+$I$12*O36-P36 -> 5.2413277 | S36: =+$I$13+$I$12*O36+P36 -> 5.4249387 | T36: =10^Q36 -> 215344.22 | U36: =10^O36 -> 0.9342 | V36: =10^R36 -> 174312.18 | W36: =10^$O36 -> 0.9342 | X36: =10^S36 -> 266034.94 | Y36: =10^$O36 -> 0.9342 | Z36: 12 | AA36: 1.7418459 | AB36: 0.0051980261 | AC36: 0.46540648
H37: 5 | I37: 2.5706 | J37: 5.79 | O37: =LOG($I$19+($I$20-$I$19)*(ROW()-2)/100) -> -0.0266412 | P37: =SQRT(2*$I$16*$K$24)*SQRT((1/$I$1)+((O37-$I$10)^2/$I$7)) -> 0.090910497 | Q37: =+$I$13+$I$12*O37 -> 5.3089493 | R37: =+$I$13+$I$12*O37-P37 -> 5.2180388 | S37: =+$I$13+$I$12*O37+P37 -> 5.3998598 | T37: =10^Q37 -> 203680.42 | U37: =10^O37 -> 0.9405 | V37: =10^R37 -> 165210.93 | W37: =10^$O37 -> 0.9405 | X37: =10^S37 -> 251107.55 | Y37: =10^$O37 -> 0.9405
H38: 6 | I38: 2.4469 | J38: 5.14 | O38: =LOG($I$19+($I$20-$I$19)*(ROW()-2)/100) -> -0.023741751 | P38: =SQRT(2*$I$16*$K$24)*SQRT((1/$I$1)+((O38-$I$10)^2/$I$7)) -> 0.090120286 | Q38: =+$I$13+$I$12*O38 -> 5.2849268 | R38: =+$I$13+$I$12*O38-P38 -> 5.1948065 | S38: =+$I$13+$I$12*O38+P38 -> 5.3750471 | T38: =10^Q38 -> 192720.01 | U38: =10^O38 -> 0.9468 | V38: =10^R38 -> 156605.33 | W38: =10^$O38 -> 0.9468 | X38: =10^S38 -> 237163.09 | Y38: =10^$O38 -> 0.9468
H39: 7 | I39: 2.3646 | J39: 4.74 | O39: =LOG($I$19+($I$20-$I$19)*(ROW()-2)/100) -> -0.02086153 | P39: =SQRT(2*$I$16*$K$24)*SQRT((1/$I$1)+((O39-$I$10)^2/$I$7)) -> 0.089435378 | Q39: =+$I$13+$I$12*O39 -> 5.2610637 | R39: =+$I$13+$I$12*O39-P39 -> 5.1716283 | S39: =+$I$13+$I$12*O39+P39 -> 5.350499 | T39: =10^Q39 -> 182416.31 | U39: =10^O39 -> 0.9531 | V39: =10^R39 -> 148466.44 | W39: =10^$O39 -> 0.9531 | X39: =10^S39 -> 224129.51 | Y39: =10^$O39 -> 0.9531
H40: 8 | I40: 2.306 | J40: 4.46 | O40: =LOG($I$19+($I$20-$I$19)*(ROW()-2)/100) -> -0.018000286 | P40: =SQRT(2*$I$16*$K$24)*SQRT((1/$I$1)+((O40-$I$10)^2/$I$7)) -> 0.088856014 | Q40: =+$I$13+$I$12*O40 -> 5.2373577 | R40: =+$I$13+$I$12*O40-P40 -> 5.1485017 | S40: =+$I$13+$I$12*O40+P40 -> 5.3262137 | T40: =10^Q40 -> 172726 | U40: =10^O40 -> 0.9594 | V40: =10^R40 -> 140767.28 | W40: =10^$O40 -> 0.9594 | X40: =10^S40 -> 211940.39 | Y40: =10^$O40 -> 0.9594
...

Sheet ASTM E739 stat (Max Stress)
A1: SN Points | C1: X | D1: Y | E1: X^2 | F1: Y^2 | G1: X*Y | H1: N | I1: =COUNT(C:C) -> 7 | M1: X | N1: YHAT | O1: X | P1: Xconfi | Q1: Yavg | R1: Y1 | S1: Y2 | T1: SN-line | V1: Lower conf | X1: Upper Conf | Z1: SUMMARY OUTPUT
A2: =+Results!F25 -> 573.42719 | B2: =+Results!E25 -> 10766 | C2: =LOG(A2) -> 2.7584783 | D2: =LOG(B2) -> 4.0320544 | E2: =+C2^2 -> 7.6092024 | F2: =+D2^2 -> 16.257462 | G2: =+C2*D2 -> 11.122334 | H2: SUMX | I2: =SUM(C:C) -> 18.375358 | M2: =+#REF! -> #REF! | N2: =+$I$13+$I$12*M2 -> #REF! | O2: =LOG($I$19+($I$20-$I$19)*(ROW()-2)/100) -> 2.4861039 | P2: =SQRT(2*$I$16*$K$24)*SQRT((1/$I$1)+((O2-$I$10)^2/$I$7)) -> 0.12907963 | Q2: =+$I$13+$I$12*O2 -> 6.2109401 | R2: =+$I$13+$I$12*O2-P2 -> 6.0818605 | S2: =+$I$13+$I$12*O2+P2 -> 6.3400197 | T2: =10^Q2 -> 1625324.6 | U2: =10^$O2 -> 306.26963 | V2: =10^R2 -> 1207425.9 | W2: =10^$O2 -> 306.26963 | X2: =10^S2 -> 2187861.1 | Y2: =10^$O2 -> 306.26963
