Workbook

Sheet Plan
A1: Udmattelse
A3: prj nummer | B3: 44584-?? | J3: dato | K3: emner
A4: Plader: | B4: EQA03 | I4: Modtaget
A5: Geometri: | E5: Med tabs
B6: R= | C6: 0.1 | E6: Frekvens | F6: 5 Hz
B7: Specimen | C7: Width | D7: Thickness | E7: Area | F7: Max strain | G7: E-mod 1. load | H7: E-mod. 2. load | I7: Max load | J7: Min Load | K7: Frequency | L7: Cycles to failure | M7: Comments | N7: Prøvemaskine
A8: Date | B8: # | C8: (mm) | D8: (mm) | E8: (mm2) | F8: (%) | I8: (kN) | J8: (kN) | K8: (Hz)
A9: 42233 | B9: =+$B$4&"-0"&TEXT((ROW()-8),0) -> EQA03-01 | C9: 25.37 | D9: 4.4 | E9: =+C9*D9 -> 111.628 | K9: 2 m.m./min. | L9: Statisk | M9: O.K. | N9: 88R8033
A10: 42233 | B10: =+$B$4&"-0"&TEXT((ROW()-8),0) -> EQA03-02 | C10: 25.38 | D10: 4.51 | E10: =+C10*D10 -> 114.4638 | K10: 2 m.m./min. | L10: Statisk | M10: O.K. | N10: 88R8033
A11: 42233 | B11: =+$B$4&"-0"&TEXT((ROW()-8),0) -> EQA03-03 | C11: 25.41 | D11: 4.45 | E11: =+C11*D11 -> 113.0745 | K11: 2 m.m./min. | L11: Statisk | M11: O.K. | N11: 88R8033
B12: =+$B$4&"-0"&TEXT((ROW()-8),0) -> EQA03-04 | C12: 25.43 | D12: 4.42 | E12: =+C12*D12 -> 112.4006
A13: 42233 | B13: =+$B$4&"-0"&TEXT((ROW()-8),0) -> EQA03-05 | C13: 25.35 | D13: 4.49 | E13: =+C13*D13 -> 113.8215 | F13: 0.55 | G13: 35.93 | H13: 36.07 | I13: 22.58 | J13: 2.26 | K13: 5 | L13: 2000000 | M13: run out | N13: 88R1331
A14: 42233 | B14: =+$B$4&"-0"&TEXT((ROW()-8),0) -> EQA03-06 | C14: 25.38 | D14: 4.44 | E14: =+C14*D14 -> 112.6872 | F14: 0.7 | G14: 35.86 | H14: 35.79 | I14: 28.23 | J14: 2.82 | K14: 5 | L14: 234687 | N14: 88R8501
A15: 42230 | B15: =+$B$4&"-0"&TEXT((ROW()-8),0) -> EQA03-07 | C15: 25.42 | D15: 4.29 | E15: =+C15*D15 -> 109.0518 | F15: 0.6 | G15: 37.55 | H15: 37.52 | I15: 24.55 | J15: 2.45 | K15: 4 | L15: 417783 | N15: 88R8033
A16: 42230 | B16: =+$B$4&"-0"&TEXT((ROW()-8),0) -> EQA03-08 | C16: 25.39 | D16: 4.3 | E16: =+C16*D16 -> 109.177 | F16: 0.5 | G16: 37.78 | H16: 37.98 | I16: 20.73 | J16: 2.07 | K16: 4 | L16: 1500000 | N16: 88R1332
A17: 42230 | B17: =+$B$4&"-0"&TEXT((ROW()-8),0) -> EQA03-09 | C17: 25.53 | D17: 4.49 | E17: =+C17*D17 -> 114.6297 | F17: 1.3 | G17: 35.91 | H17: 35.72 | I17: 53.23 | J17: 5.32 | K17: 2 | L17: 4683 | M17: 36 grader ved 3 HZ | N17: 88R8033
A18: 42230 | B18: =+$B$4&"-"&TEXT((ROW()-8),0) -> EQA03-10 | C18: 25.45 | D18: 4.41 | E18: =+C18*D18 -> 112.2345 | F18: 1 | G18: 36.23 | H18: 36.27 | I18: 40.7 | J18: 4.07 | K18: 4 | L18: 20412 | N18: 88R1332
A19: 42230 | B19: =+$B$4&"-"&TEXT((ROW()-8),0) -> EQA03-11 | C19: 25.46 | D19: 4.43 | E19: =+C19*D19 -> 112.7878 | F19: 0.9 | G19: 37.12 | H19: 37.23 | I19: 37.8 | J19: 3.78 | K19: 4 | L19: 32980 | N19: 88R1342
A20: 42230 | B20: =+$B$4&"-"&TEXT((ROW()-8),0) -> EQA03-12 | C20: 25.44 | D20: 4.46 | E20: =+C20*D20 -> 113.4624 | F20: 0.8 | G20: 35.17 | H20: 35.3 | I20: 32.04 | J20: 3.2 | K20: 5 | L20: 95620 | N20: 88R8501

Sheet Results
A1: =+Plan!A1 -> Udmattelse | D1: =B4&" Fatigue test" -> EQA03 Fatigue test
A3: =+Plan!A3 -> prj nummer
A4: =+Plan!A4 -> Plader: | B4: =+Plan!B4 -> EQA03
A5: =+Plan!A5 -> Geometri:
C6: =+Plan!B6 -> R= | D6: =+Plan!C6 -> 0.1 | E6: =+Plan!E6 -> Frekvens | F6: =+Plan!F6 -> 5 Hz | N6: From Ten and Fat Datafiles | U6: Matlab "DataAnalysis"
A7: Date | B7: Specimen | C7: Width | D7: Thickness | E7: Area | F7: Cycles to failure | G7: Abs Max strain | H7: Strain Range | I7: Peak stress | J7: Max load | K7: Min Load | L7: Mean Load | M7: Amplitude | N7: Ini Emod | O7: E-mod | P7: E-mod 1 | Q7: E-mod 2 | R7: Bending ratio | S7: Comments | U7: From Ten-files
B8: # | C8: (mm) | D8: (mm) | E8: (mm2) | G8: (%) | H8: (%) | I8: (MPa) | J8: (kN) | K8: (kN) | L8: (kN) | M8: (kN) | N8: (GPa) | O8: (GPa) | P8: (GPa) | Q8: (GPa) | R8: |E1+E2|/|E1+E2| | T8: Spec. | U8: Modulus a [GPa]: | V8: Modulus b [GPa]: | W8: Modulus a1 [GPa]: | X8: Modulus b1 [GPa]: | Y8: Modulus a2 [GPa]: | Z8: Modulus b2 [GPa]:
A9: =+Plan!A9 -> 42233 | B9: =+Plan!B9 -> EQA03-01 | C9: =+Plan!C9 -> 25.37 | D9: =+Plan!D9 -> 4.4 | E9: =+Plan!E9 -> 111.628 | F9: =+Plan!L9 -> Statisk | G9: =+Plan!F9 -> 0 | H9: =IF(ISNUMBER(G9),+G9*(1-$D$6),"") -> 0 | I9: =+J9/E9*1000 -> 0 | J9: =+O9*G9*E9/100 -> 0 | K9: =+J9*$D$6 -> 0 | L9: =+(J9+K9)/2 -> 0 | M9: =+(J9-K9)/2 -> 0 | N9: =+U9 -> 0 | O9: =+V9 -> 0 | P9: =+X9 -> 0 | Q9: =+Z9 -> 0 | R9: =+ABS(P9-Q9)/(P9+Q9) -> #DIV/0! | S9: =+Plan!N9 -> 88R8033
A10: =+Plan!A10 -> 42233 | B10: =+Plan!B10 -> EQA03-02 | C10: =+Plan!C10 -> 25.38 | D10: =+Plan!D10 -> 4.51 | E10: =+Plan!E10 -> 114.4638 | F10: =+Plan!L10 -> Statisk | G10: =+Plan!F10 -> 0 | H10: =IF(ISNUMBER(G10),+G10*(1-$D$6),"") -> 0 | I10: =+J10/C10/D10*1000 -> 0 | J10: =+O10*G10*E10/100 -> 0 | K10: =+J10*$D$6 -> 0 | L10: =+(J10+K10)/2 -> 0 | M10: =+(J10-K10)/2 -> 0 | N10: =+U10 -> 0 | O10: =+V10 -> 0 | P10: =+X10 -> 0 | Q10: =+Z10 -> 0 | R10: =+ABS(P10-Q10)/(P10+Q10) -> #DIV/0! | S10: =+Plan!N10 -> 88R8033
A11: =+Plan!A11 -> 42233 | B11: =+Plan!B11 -> EQA03-03 | C11: =+Plan!C11 -> 25.41 | D11: =+Plan!D11 -> 4.45 | E11: =+Plan!E11 -> 113.0745 | F11: =+Plan!L11 -> Statisk | G11: =+Plan!F11 -> 0 | H11: =IF(ISNUMBER(G11),+G11*(1-$D$6),"") -> 0 | I11: =+J11/C11/D11*1000 -> 0 | J11: =+O11*G11*E11/100 -> 0 | K11: =+J11*$D$6 -> 0 | L11: =+(J11+K11)/2 -> 0 | M11: =+(J11-K11)/2 -> 0 | N11: =+U11 -> 0 | O11: =+V11 -> 0 | P11: =+X11 -> 0 | Q11: =+Z11 -> 0 | R11: =+ABS(P11-Q11)/(P11+Q11) -> #DIV/0! | S11: =+Plan!N11 -> 88R8033
A12: =+Plan!A12 -> 0 | B12: =+Plan!B12 -> EQA03-04 | C12: =+Plan!C12 -> 25.43 | D12: =+Plan!D12 -> 4.42 | E12: =+Plan!E12 -> 112.4006 | F12: =+Plan!L12 -> 0 | G12: =+Plan!F12 -> 0 | H12: =IF(ISNUMBER(G12),+G12*(1-$D$6),"") -> 0 | I12: =+J12/C12/D12*1000 -> 0 | J12: =+O12*G12*E12/100 -> 0 | K12: =+J12*$D$6 -> 0 | L12: =+(J12+K12)/2 -> 0 | M12: =+(J12-K12)/2 -> 0 | N12: =+U12 -> 0 | O12: =+V12 -> 0 | P12: =+X12 -> 0 | Q12: =+Z12 -> 0 | R12: =+ABS(P12-Q12)/(P12+Q12) -> #DIV/0! | S12: =+Plan!N12 -> 0
A13: =+Plan!A13 -> 42233 | B13: =+Plan!B13 -> EQA03-05 | C13: =+Plan!C13 -> 25.35 | D13: =+Plan!D13 -> 4.49 | E13: =+Plan!E13 -> 113.8215 | F13: =+Plan!L13 -> 2000000 | G13: =+Plan!F13 -> 0.55 | H13: =IF(ISNUMBER(G13),+G13*(1-$D$6),"") -> 0.495 | I13: =+J13/C13/D13*1000 -> 0 | J13: =+O13*G13*E13/100 -> 0 | K13: =+J13*$D$6 -> 0 | L13: =+(J13+K13)/2 -> 0 | M13: =+(J13-K13)/2 -> 0 | R13: =+ABS(P13-Q13)/(P13+Q13) -> #DIV/0! | S13: =+Plan!N13 -> 88R1331
A14: =+Plan!A14 -> 42233 | B14: =+Plan!B14 -> EQA03-06 | C14: =+Plan!C14 -> 25.38 | D14: =+Plan!D14 -> 4.44 | E14: =+Plan!E14 -> 112.6872 | F14: =+Plan!L14 -> 234687 | G14: =+Plan!F14 -> 0.7 | H14: =IF(ISNUMBER(G14),+G14*(1-$D$6),"") -> 0.63 | I14: =+J14/C14/D14*1000 -> 0 | J14: =+O14*G14*E14/100 -> 0 | K14: =+J14*$D$6 -> 0 | L14: =+(J14+K14)/2 -> 0 | M14: =+(J14-K14)/2 -> 0 | R14: =+ABS(P14-Q14)/(P14+Q14) -> #DIV/0! | S14: =+Plan!N14 -> 88R8501
A15: =+Plan!A15 -> 42230 | B15: =+Plan!B15 -> EQA03-07 | C15: =+Plan!C15 -> 25.42 | D15: =+Plan!D15 -> 4.29 | E15: =+Plan!E15 -> 109.0518 | F15: =+Plan!L15 -> 417783 | G15: =+Plan!F15 -> 0.6 | H15: =IF(ISNUMBER(G15),+G15*(1-$D$6),"") -> 0.54 | I15: =+J15/C15/D15*1000 -> 0 | J15: =+O15*G15*E15/100 -> 0 | K15: =+J15*$D$6 -> 0 | L15: =+(J15+K15)/2 -> 0 | M15: =+(J15-K15)/2 -> 0 | R15: =+ABS(P15-Q15)/(P15+Q15) -> #DIV/0! | S15: =+Plan!N15 -> 88R8033
A16: =+Plan!A16 -> 42230 | B16: =+Plan!B16 -> EQA03-08 | C16: =+Plan!C16 -> 25.39 | D16: =+Plan!D16 -> 4.3 | E16: =+Plan!E16 -> 109.177 | F16: =+Plan!L16 -> 1500000 | G16: =+Plan!F16 -> 0.5 | H16: =IF(ISNUMBER(G16),+G16*(1-$D$6),"") -> 0.45 | I16: =+J16/C16/D16*1000 -> 0 | J16: =+O16*G16*E16/100 -> 0 | K16: =+J16*$D$6 -> 0 | L16: =+(J16+K16)/2 -> 0 | M16: =+(J16-K16)/2 -> 0 | R16: =+ABS(P16-Q16)/(P16+Q16) -> #DIV/0! | S16: =+Plan!N16 -> 88R1332
A17: =+Plan!A17 -> 42230 | B17: =+Plan!B17 -> EQA03-09 | C17: =+Plan!C17 -> 25.53 | D17: =+Plan!D17 -> 4.49 | E17: =+Plan!E17 -> 114.6297 | F17: =+Plan!L17 -> 4683 | G17: =+Plan!F17 -> 1.3 | H17: =IF(ISNUMBER(G17),+G17*(1-$D$6),"") -> 1.17 | I17: =+J17/C17/D17*1000 -> 0 | J17: =+O17*G17*E17/100 -> 0 | K17: =+J17*$D$6 -> 0 | L17: =+(J17+K17)/2 -> 0 | M17: =+(J17-K17)/2 -> 0 | R17: =+ABS(P17-Q17)/(P17+Q17) -> #DIV/0! | S17: =+Plan!N17 -> 88R8033
A18: =+Plan!A18 -> 42230 | B18: =+Plan!B18 -> EQA03-10 | C18: =+Plan!C18 -> 25.45 | D18: =+Plan!D18 -> 4.41 | E18: =+Plan!E18 -> 112.2345 | F18: =+Plan!L18 -> 20412 | G18: =+Plan!F18 -> 1 | H18: =IF(ISNUMBER(G18),+G18*(1-$D$6),"") -> 0.9 | I18: =+J18/C18/D18*1000 -> 0 | J18: =+O18*G18*E18/100 -> 0 | K18: =+J18*$D$6 -> 0 | L18: =+(J18+K18)/2 -> 0 | M18: =+(J18-K18)/2 -> 0 | R18: =+ABS(P18-Q18)/(P18+Q18) -> #DIV/0! | S18: =+Plan!N18 -> 88R1332
A19: =+Plan!A19 -> 42230 | B19: =+Plan!B19 -> EQA03-11 | C19: =+Plan!C19 -> 25.46 | D19: =+Plan!D19 -> 4.43 | E19: =+Plan!E19 -> 112.7878 | F19: =+Plan!L19 -> 32980 | G19: =+Plan!F19 -> 0.9 | H19: =IF(ISNUMBER(G19),+G19*(1-$D$6),"") -> 0.81 | I19: =+J19/C19/D19*1000 -> 0 | J19: =+O19*G19*E19/100 -> 0 | K19: =+J19*$D$6 -> 0 | L19: =+(J19+K19)/2 -> 0 | M19: =+(J19-K19)/2 -> 0 | R19: =+ABS(P19-Q19)/(P19+Q19) -> #DIV/0! | S19: =+Plan!N19 -> 88R1342
A20: =+Plan!A20 -> 42230 | B20: =+Plan!B20 -> EQA03-12 | C20: =+Plan!C20 -> 25.44 | D20: =+Plan!D20 -> 4.46 | E20: =+Plan!E20 -> 113.4624 | F20: =+Plan!L20 -> 95620 | G20: =+Plan!F20 -> 0.8 | H20: =IF(ISNUMBER(G20),+G20*(1-$D$6),"") -> 0.72 | I20: =+J20/C20/D20*1000 -> 0 | J20: =+O20*G20*E20/100 -> 0 | K20: =+J20*$D$6 -> 0 | L20: =+(J20+K20)/2 -> 0 | M20: =+(J20-K20)/2 -> 0 | R20: =+ABS(P20-Q20)/(P20+Q20) -> #DIV/0! | S20: =+Plan!N20 -> 88R8501
A21: SN-Curve | B21: Astm Stat
A22: Cycles | B22: Max Strain | C22: Cycles | D22: Strain Range | E22: Cycles | F22: Max Stress
A23: =+F9 -> Statisk | B23: =+G9 -> 0 | C23: =+F9 -> Statisk | D23: =+H9 -> 0 | E23: =+F9 -> Statisk | F23: =+I9 -> 0
A24: =+F10 -> Statisk | B24: =+G10 -> 0 | C24: =+F10 -> Statisk | D24: =+H10 -> 0 | E24: =+F10 -> Statisk | F24: =+I10 -> 0
A25: =+F11 -> Statisk | B25: =+G11 -> 0 | C25: =+F11 -> Statisk | D25: =+H11 -> 0 | E25: =+F11 -> Statisk | F25: =+I11 -> 0
A26: =+F12 -> 0 | B26: =+G12 -> 0 | C26: =+F12 -> 0 | D26: =+H12 -> 0 | E26: =+F12 -> 0 | F26: =+I12 -> 0
A27: =+F13 -> 2000000 | B27: =+G13 -> 0.55 | C27: =+F13 -> 2000000 | D27: =+H13 -> 0.495 | E27: =+F13 -> 2000000 | F27: =+I13 -> 0
A28: =+F14 -> 234687 | B28: =+G14 -> 0.7 | C28: =+F14 -> 234687 | D28: =+H14 -> 0.63 | E28: =+F14 -> 234687 | F28: =+I14 -> 0
A29: =+F15 -> 417783 | B29: =+G15 -> 0.6 | C29: =+F15 -> 417783 | D29: =+H15 -> 0.54 | E29: =+F15 -> 417783 | F29: =+I15 -> 0
A30: =+F16 -> 1500000 | B30: =+G16 -> 0.5 | C30: =+F16 -> 1500000 | D30: =+H16 -> 0.45 | E30: =+F16 -> 1500000 | F30: =+I16 -> 0
A31: =+F17 -> 4683 | B31: =+G17 -> 1.3 | C31: =+F17 -> 4683 | D31: =+H17 -> 1.17 | E31: =+F17 -> 4683 | F31: =+I17 -> 0
A32: =+F18 -> 20412 | B32: =+G18 -> 1 | C32: =+F18 -> 20412 | D32: =+H18 -> 0.9 | E32: =+F18 -> 20412 | F32: =+I18 -> 0
A33: =+F19 -> 32980 | B33: =+G19 -> 0.9 | C33: =+F19 -> 32980 | D33: =+H19 -> 0.81 | E33: =+F19 -> 32980 | F33: =+I19 -> 0
A34: =+F20 -> 95620 | B34: =+G20 -> 0.8 | C34: =+F20 -> 95620 | D34: =+H20 -> 0.72 | E34: =+F20 -> 95620 | F34: =+I20 -> 0

Sheet ASTM E739 stat (Max Strain)
A1: SN Points | C1: X | D1: Y | E1: X^2 | F1: Y^2 | G1: X*Y | H1: N | I1: =COUNT(C:C) -> 6 | M1: X | N1: YHAT | O1: X | P1: Xconfi | Q1: Yavg | R1: Y1 | S1: Y2 | T1: SN-line | V1: Lower conf | X1: Upper Conf | Z1: SUMMARY OUTPUT
H2: SUMX | I2: =SUM(C:C) -> -0.40547486 | M2: =+C2 -> 0 | N2: =+$I$13+$I$12*M2 -> 4.335416 | O2: =LOG($I$19+($I$20-$I$19)*(ROW()-2)/100) -> -0.39794001 | P2: =SQRT(2*$I$16*$K$24)*SQRT((1/$I$1)+((O2-$I$10)^2/$I$7)) -> 0.39636255 | Q2: =+$I$13+$I$12*O2 -> 6.7478898 | R2: =+$I$13+$I$12*O2-P2 -> 6.3515272 | S2: =+$I$13+$I$12*O2+P2 -> 7.1442523 | T2: =10^Q2 -> 5596155.8 | U2: =10^$O2 -> 0.4 | V2: =10^R2 -> 2246607.7 | W2: =10^$O2 -> 0.4 | X2: =10^S2 -> 13939665 | Y2: =10^$O2 -> 0.4
H3: SUMY | I3: =SUM(D:D) -> 28.470649 | M3: =+C3 -> 0 | N3: =+$I$13+$I$12*M3 -> 4.335416 | O3: =LOG($I$19+($I$20-$I$19)*(ROW()-2)/100) -> -0.38827669 | P3: =SQRT(2*$I$16*$K$24)*SQRT((1/$I$1)+((O3-$I$10)^2/$I$7)) -> 0.38590757 | Q3: =+$I$13+$I$12*O3 -> 6.6893068 | R3: =+$I$13+$I$12*O3-P3 -> 6.3033993 | S3: =+$I$13+$I$12*O3+P3 -> 7.0752144 | T3: =10^Q3 -> 4889977.3 | U3: =10^O3 -> 0.409 | V3: =10^R3 -> 2010940.7 | W3: =10^$O3 -> 0.409 | X3: =10^S3 -> 11890892 | Y3: =10^$O3 -> 0.409 | Z3: Regression Statistics
H4: SUMXX | I4: =SUM(E:E) -> 0.097679871 | M4: =+C4 -> 0 | N4: =+$I$13+$I$12*M4 -> 4.335416 | O4: =LOG($I$19+($I$20-$I$19)*(ROW()-2)/100) -> -0.37882372 | P4: =SQRT(2*$I$16*$K$24)*SQRT((1/$I$1)+((O4-$I$10)^2/$I$7)) -> 0.37571129 | Q4: =+$I$13+$I$12*O4 -> 6.6319991 | R4: =+$I$13+$I$12*O4-P4 -> 6.2562878 | S4: =+$I$13+$I$12*O4+P4 -> 7.0077104 | T4: =10^Q4 -> 4285476.2 | U4: =10^O4 -> 0.418 | V4: =10^R4 -> 1804212.9 | W4: =10^$O4 -> 0.418 | X4: =10^S4 -> 10179123 | Y4: =10^$O4 -> 0.418 | Z4: Multiple R | AA4: 0.88244047
H5: SUMYY | I5: =SUM(F:F) -> 137.70556 | M5: =+C5 -> 0 | N5: =+$I$13+$I$12*M5 -> 4.335416 | O5: =LOG($I$19+($I$20-$I$19)*(ROW()-2)/100) -> -0.36957212 | P5: =SQRT(2*$I$16*$K$24)*SQRT((1/$I$1)+((O5-$I$10)^2/$I$7)) -> 0.36576452 | Q5: =+$I$13+$I$12*O5 -> 6.5759122 | R5: =+$I$13+$I$12*O5-P5 -> 6.2101476 | S5: =+$I$13+$I$12*O5+P5 -> 6.9416767 | T5: =10^Q5 -> 3766276.2 | U5: =10^O5 -> 0.427 | V5: =10^R5 -> 1622361.6 | W5: =10^$O5 -> 0.427 | X5: =10^S5 -> 8743326.4 | Y5: =10^$O5 -> 0.427 | Z5: R Square | AA5: 0.77870118
A6: =+Results!B27 -> 0.55 | B6: =+Results!A27 -> 2000000 | H6: SUMXY | I6: =SUM(G:G) -> -2.3500772 | M6: =+C6 -> 0 | N6: =+$I$13+$I$12*M6 -> 4.335416 | O6: =LOG($I$19+($I$20-$I$19)*(ROW()-2)/100) -> -0.36051351 | P6: =SQRT(2*$I$16*$K$24)*SQRT((1/$I$1)+((O6-$I$10)^2/$I$7)) -> 0.35605878 | Q6: =+$I$13+$I$12*O6 -> 6.5209952 | R6: =+$I$13+$I$12*O6-P6 -> 6.1649364 | S6: =+$I$13+$I$12*O6+P6 -> 6.877054 | T6: =10^Q6 -> 3318907.7 | U6: =10^O6 -> 0.436 | V6: =10^R6 -> 1461963 | W6: =10^$O6 -> 0.436 | X6: =10^S6 -> 7534491.7 | Y6: =10^$O6 -> 0.436 | Z6: Adjusted R Square | AA6: 0.75103883
A7: =+Results!B28 -> 0.7 | B7: =+Results!A28 -> 234687 | C7: =LOG(A7) -> -0.15490196 | D7: =LOG(B7) -> 5.370489 | E7: =+C7^2 -> 0.023994617 | F7: =+D7^2 -> 28.842152 | G7: =+C7*D7 -> -0.83189928 | H7: SAKX | I7: =+I4-I2^2/$I$1 -> 0.070278227 | M7: =+C7 -> -0.15490196 | N7: =+$I$13+$I$12*M7 -> 5.2744945 | O7: =LOG($I$19+($I$20-$I$19)*(ROW()-2)/100) -> -0.35163999 | P7: =SQRT(2*$I$16*$K$24)*SQRT((1/$I$1)+((O7-$I$10)^2/$I$7)) -> 0.34658625 | Q7: =+$I$13+$I$12*O7 -> 6.4672003 | R7: =+$I$13+$I$12*O7-P7 -> 6.120614 | S7: =+$I$13+$I$12*O7+P7 -> 6.8137865 | T7: =10^Q7 -> 2932245.2 | U7: =10^O7 -> 0.445 | V7: =10^R7 -> 1320121.9 | W7: =10^$O7 -> 0.445 | X7: =10^S7 -> 6513081.9 | Y7: =10^$O7 -> 0.445 | Z7: Standard Error | AA7: 4.8757094
A8: =+Results!B29 -> 0.6 | B8: =+Results!A29 -> 417783 | C8: =LOG(A8) -> -0.22184875 | D8: =LOG(B8) -> 5.6209508 | E8: =+C8^2 -> 0.049216868 | F8: =+D8^2 -> 31.595087 | G8: =+C8*D8 -> -1.2470009 | H8: SAKY (SAKtotal) | I8: =+I5-I3^2/$I$1 -> 2.6092476 | M8: =+C8 -> -0.22184875 | N8: =+$I$13+$I$12*M8 -> 5.6803531 | O8: =LOG($I$19+($I$20-$I$19)*(ROW()-2)/100) -> -0.34294415 | P8: =SQRT(2*$I$16*$K$24)*SQRT((1/$I$1)+((O8-$I$10)^2/$I$7)) -> 0.33733972 | Q8: =+$I$13+$I$12*O8 -> 6.4144826 | R8: =+$I$13+$I$12*O8-P8 -> 6.0771428 | S8: =+$I$13+$I$12*O8+P8 -> 6.7518223 | T8: =10^Q8 -> 2597063.5 | U8: =10^O8 -> 0.454 | V8: =10^R8 -> 1194380.9 | W8: =10^$O8 -> 0.454 | X8: =10^S8 -> 5647058.4 | Y8: =10^$O8 -> 0.454 | Z8: Observations | AA8: 10
A9: =+Results!B30 -> 0.5 | B9: =+Results!A30 -> 1500000 | H9: SAPXY | I9: =+I6-I2*I3/$I$1 -> -0.42605514 | M9: =+C9 -> 0 | N9: =+$I$13+$I$12*M9 -> 4.335416 | O9: =LOG($I$19+($I$20-$I$19)*(ROW()-2)/100) -> -0.33441901 | P9: =SQRT(2*$I$16*$K$24)*SQRT((1/$I$1)+((O9-$I$10)^2/$I$7)) -> 0.32831256 | Q9: =+$I$13+$I$12*O9 -> 6.3627997 | R9: =+$I$13+$I$12*O9-P9 -> 6.0344872 | S9: =+$I$13+$I$12*O9+P9 -> 6.6911123 | T9: =10^Q9 -> 2305683.6 | U9: =10^O9 -> 0.463 | V9: =10^R9 -> 1082647.7 | W9: =10^$O9 -> 0.463 | X9: =10^S9 -> 4910348 | Y9: =10^$O9 -> 0.463
A10: =+Results!B31 -> 1.3 | B10: =+Results!A31 -> 4683 | C10: =LOG(A10) -> 0.11394335 | D10: =LOG(B10) -> 3.6705242 | E10: =+C10^2 -> 0.012983088 | F10: =+D10^2 -> 13.472748 | G10: =+C10*D10 -> 0.41823183 | H10: XMEAN | I10: =+I2/$I$1 -> -0.067579143 | M10: =+C10 -> 0.11394335 | N10: =+$I$13+$I$12*M10 -> 3.6446451 | O10: =LOG($I$19+($I$20-$I$19)*(ROW()-2)/100) -> -0.326058 | P10: =SQRT(2*$I$16*$K$24)*SQRT((1/$I$1)+((O10-$I$10)^2/$I$7)) -> 0.31949869 | Q10: =+$I$13+$I$12*O10 -> 6.3121119 | R10: =+$I$13+$I$12*O10-P10 -> 5.9926132 | S10: =+$I$13+$I$12*O10+P10 -> 6.6316106 | T10: =10^Q10 -> 2051690.7 | U10: =10^O10 -> 0.472 | V10: =10^R10 -> 983135.11 | W10: =10^$O10 -> 0.472 | X10: =10^S10 -> 4281644.3 | Y10: =10^$O10 -> 0.472 | Z10: ANOVA
A11: =+Results!B32 -> 1 | B11: =+Results!A32 -> 20412 | C11: =LOG(A11) -> 0 | D11: =LOG(B11) -> 4.3098856 | E11: =+C11^2 -> 0 | F11: =+D11^2 -> 18.575114 | G11: =+C11*D11 -> 0 | H11: YMEAN | I11: =+I3/$I$1 -> 4.7451082 | M11: =+C11 -> 0 | N11: =+$I$13+$I$12*M11 -> 4.335416 | O11: =LOG($I$19+($I$20-$I$19)*(ROW()-2)/100) -> -0.31785492 | P11: =SQRT(2*$I$16*$K$24)*SQRT((1/$I$1)+((O11-$I$10)^2/$I$7)) -> 0.31089254 | Q11: =+$I$13+$I$12*O11 -> 6.2623815 | R11: =+$I$13+$I$12*O11-P11 -> 5.951489 | S11: =+$I$13+$I$12*O11+P11 -> 6.573274 | T11: =10^Q11 -> 1829706.8 | U11: =10^O11 -> 0.481 | V11: =10^R11 -> 894311.81 | W11: =10^$O11 -> 0.481 | X11: =10^S11 -> 3743467.3 | Y11: =10^$O11 -> 0.481 | AA11: df | AB11: SS | AC11: MS | AD11: F | AE11: Significance F
A12: =+Results!B33 -> 0.9 | B12: =+Results!A33 -> 32980 | C12: =LOG(A12) -> -0.045757491 | D12: =LOG(B12) -> 4.5182507 | E12: =+C12^2 -> 0.0020937479 | F12: =+D12^2 -> 20.414589 | G12: =+C12*D12 -> -0.20674381 | H12: A1 | I12: =+I9/I7 -> -6.0624059 | J12: =+I12 -> -6.0624059 | K12: =1/J12 -> -0.16495102 | M12: =+C12 -> -0.045757491 | N12: =+$I$13+$I$12*M12 -> 4.6128164 | O12: =LOG($I$19+($I$20-$I$19)*(ROW()-2)/100) -> -0.30980392 | P12: =SQRT(2*$I$16*$K$24)*SQRT((1/$I$1)+((O12-$I$10)^2/$I$7)) -> 0.30248905 | Q12: =+$I$13+$I$12*O12 -> 6.2135731 | R12: =+$I$13+$I$12*O12-P12 -> 5.911084 | S12: =+$I$13+$I$12*O12+P12 -> 6.5160621 | T12: =10^Q12 -> 1635208.2 | U12: =10^O12 -> 0.49 | V12: =10^R12 -> 814861.89 | W12: =10^$O12 -> 0.49 | X12: =10^S12 -> 3281422.1 | Y12: =10^$O12 -> 0.49 | Z12: Regression | AA12: 1 | AB12: 669.20218 | AC12: 669.20218 | AD12: 28.150215 | AE12: 0.00072341619
A13: =+Results!B34 -> 0.8 | B13: =+Results!A34 -> 95620 | C13: =LOG(A13) -> -0.096910013 | D13: =LOG(B13) -> 4.9805487 | E13: =+C13^2 -> 0.0093915506 | F13: =+D13^2 -> 24.805866 | G13: =+C13*D13 -> -0.48266504 | H13: A0 | I13: =+I11-I12*I10 -> 4.335416 | J13: =10^I13 -> 21647.909 | K13: =+J13^J12 -> 5.2113342e-27 | M13: =+C13 -> -0.096910013 | N13: =+$I$13+$I$12*M13 -> 4.9229238 | O13: =LOG($I$19+($I$20-$I$19)*(ROW()-2)/100) -> -0.30189945 | P13: =SQRT(2*$I$16*$K$24)*SQRT((1/$I$1)+((O13-$I$10)^2/$I$7)) -> 0.29428362 | Q13: =+$I$13+$I$12*O13 -> 6.165653 | R13: =+$I$13+$I$12*O13-P13 -> 5.8713694 | S13: =+$I$13+$I$12*O13+P13 -> 6.4599366 | T13: =10^Q13 -> 1464377.3 | U13: =10^O13 -> 0.499 | V13: =10^R13 -> 743651.33 | W13: =10^$O13 -> 0.499 | X13: =10^S13 -> 2883610.5 | Y13: =10^$O13 -> 0.499 | Z13: Residual | AA13: 8 | AB13: 190.18034 | AC13: 23.772542
H14: R2 | I14: =+I9^2/(I7*I8) -> 0.98990957 | J14: ="(X="&TEXT(J13,"0.0")&"Y^"&TEXT(J12,"0.00")&")" -> (X=21647.9Y^-6.06) | M14: =+C14 -> 0 | N14: =+$I$13+$I$12*M14 -> 4.335416 | O14: =LOG($I$19+($I$20-$I$19)*(ROW()-2)/100) -> -0.29413629 | P14: =SQRT(2*$I$16*$K$24)*SQRT((1/$I$1)+((O14-$I$10)^2/$I$7)) -> 0.28627211 | Q14: =+$I$13+$I$12*O14 -> 6.1185895 | R14: =+$I$13+$I$12*O14-P14 -> 5.8323174 | S14: =+$I$13+$I$12*O14+P14 -> 6.4048616 | T14: =10^Q14 -> 1313982.3 | U14: =10^O14 -> 0.508 | V14: =10^R14 -> 679700.2 | W14: =10^$O14 -> 0.508 | X14: =10^S14 -> 2540163.2 | Y14: =10^$O14 -> 0.508 | Z14: Total | AA14: 9 | AB14: 859.38251
H15: T-VALUE | I15: =VLOOKUP($J$24,$H$33:$J$69,2) -> 2.7764 | M15: =+C15 -> 0 | N15: =+$I$13+$I$12*M15 -> 4.335416 | O15: =LOG($I$19+($I$20-$I$19)*(ROW()-2)/100) -> -0.28650946 | P15: =SQRT(2*$I$16*$K$24)*SQRT((1/$I$1)+((O15-$I$10)^2/$I$7)) -> 0.27845083 | Q15: =+$I$13+$I$12*O15 -> 6.0723526 | R15: =+$I$13+$I$12*O15-P15 -> 5.7939017 | S15: =+$I$13+$I$12*O15+P15 -> 6.3508034 | T15: =10^Q15 -> 1181279.2 | U15: =10^O15 -> 0.517 | V15: =10^R15 -> 622159.5 | W15: =10^$O15 -> 0.517 | X15: =10^S15 -> 2242866.3 | Y15: =10^$O15 -> 0.517
H16: F-VALUE | I16: =VLOOKUP($J$24,$H$33:$J$69,3) -> 6.94 | M16: =+C16 -> 0 | N16: =+$I$13+$I$12*M16 -> 4.335416 | O16: =LOG($I$19+($I$20-$I$19)*(ROW()-2)/100) -> -0.27901426 | P16: =SQRT(2*$I$16*$K$24)*SQRT((1/$I$1)+((O16-$I$10)^2/$I$7)) -> 0.2708165 | Q16: =+$I$13+$I$12*O16 -> 6.0269136 | R16: =+$I$13+$I$12*O16-P16 -> 5.7560971 | S16: =+$I$13+$I$12*O16+P16 -> 6.2977301 | T16: =10^Q16 -> 1063931.4 | U16: =10^O16 -> 0.526 | V16: =10^R16 -> 570291.78 | W16: =10^$O16 -> 0.526 | X16: =10^S16 -> 1984861.1 | Y16: =10^$O16 -> 0.526 | AA16: Coefficients | AB16: Standard Error | AC16: t Stat | AD16: P-value | AE16: Lower 95% | AF16: Upper 95% | AG16: Lower 95.0% | AH16: Upper 95.0%
H17: CONFIA1 | I17: =+I15*SQRT($K$24/$I$7) -> 0.84967763 | J17: =+I12+I17 -> -5.2127282 | K17: =+I12-I17 -> -6.9120835 | M17: =+C17 -> 0 | N17: =+$I$13+$I$12*M17 -> 4.335416 | O17: =LOG($I$19+($I$20-$I$19)*(ROW()-2)/100) -> -0.27164622 | P17: =SQRT(2*$I$16*$K$24)*SQRT((1/$I$1)+((O17-$I$10)^2/$I$7)) -> 0.26336628 | Q17: =+$I$13+$I$12*O17 -> 5.9822456 | R17: =+$I$13+$I$12*O17-P17 -> 5.7188793 | S17: =+$I$13+$I$12*O17+P17 -> 6.2456119 | T17: =10^Q17 -> 959943.29 | U17: =10^O17 -> 0.535 | V17: =10^R17 -> 523454.93 | W17: =10^$O17 -> 0.535 | X17: =10^S17 -> 1760402 | Y17: =10^$O17 -> 0.535 | Z17: Intercept | AA17: 86.958826 | AB17: 2.9348407 | AC17: 29.629828 | AD17: 1.8247423e-09 | AE17: 80.191067 | AF17: 93.726586 | AG17: 80.191067 | AH17: 93.726586
H18: CONFIA0 | I18: =+I15*SQRT(K24/I1) -> 0.091957882 | J18: =+I13-I18 -> 4.2434581 | K18: =+I13+I18 -> 4.4273738 | M18: =+C18 -> 0 | N18: =+$I$13+$I$12*M18 -> 4.335416 | O18: =LOG($I$19+($I$20-$I$19)*(ROW()-2)/100) -> -0.2644011 | P18: =SQRT(2*$I$16*$K$24)*SQRT((1/$I$1)+((O18-$I$10)^2/$I$7)) -> 0.25609773 | Q18: =+$I$13+$I$12*O18 -> 5.9383227 | R18: =+$I$13+$I$12*O18-P18 -> 5.682225 | S18: =+$I$13+$I$12*O18+P18 -> 6.1944205 | T18: =10^Q18 -> 867606.37 | U18: =10^O18 -> 0.544 | V18: =10^R18 -> 481088.53 | W18: =10^$O18 -> 0.544 | X18: =10^S18 -> 1564661.8 | Y18: =10^$O18 -> 0.544 | Z18: X Variable 1 | AA18: -0.00039353116 | AB18: 7.4171706e-05 | AC18: -5.3056776 | AD18: 0.00072341619 | AE18: -0.00056457153 | AF18: -0.00022249079 | AG18: -0.00056457153 | AH18: -0.00022249079
H19: Xmin | I19: 0.4 | M19: =+C19 -> 0 | N19: =+$I$13+$I$12*M19 -> 4.335416 | O19: =LOG($I$19+($I$20-$I$19)*(ROW()-2)/100) -> -0.25727487 | P19: =SQRT(2*$I$16*$K$24)*SQRT((1/$I$1)+((O19-$I$10)^2/$I$7)) -> 0.24900881 | Q19: =+$I$13+$I$12*O19 -> 5.8951206 | R19: =+$I$13+$I$12*O19-P19 -> 5.6461118 | S19: =+$I$13+$I$12*O19+P19 -> 6.1441294 | T19: =10^Q19 -> 785453.77 | U19: =10^O19 -> 0.553 | V19: =10^R19 -> 442702.34 | W19: =10^$O19 -> 0.553 | X19: =10^S19 -> 1393572.1 | Y19: =10^$O19 -> 0.553
H20: Xmax | I20: 1.3 | O20: =LOG($I$19+($I$20-$I$19)*(ROW()-2)/100) -> -0.25026368 | P20: =SQRT(2*$I$16*$K$24)*SQRT((1/$I$1)+((O20-$I$10)^2/$I$7)) -> 0.24209789 | Q20: =+$I$13+$I$12*O20 -> 5.852616 | R20: =+$I$13+$I$12*O20-P20 -> 5.6105181 | S20: =+$I$13+$I$12*O20+P20 -> 6.0947139 | T20: =10^Q20 -> 712222.98 | U20: =10^O20 -> 0.562 | V20: =10^R20 -> 407866.55 | W20: =10^$O20 -> 0.562 | X20: =10^S20 -> 1243695 | Y20: =10^$O20 -> 0.562
H21: Variansanalysetabel | O21: =LOG($I$19+($I$20-$I$19)*(ROW()-2)/100) -> -0.24336389 | P21: =SQRT(2*$I$16*$K$24)*SQRT((1/$I$1)+((O21-$I$10)^2/$I$7)) -> 0.23536373 | Q21: =+$I$13+$I$12*O21 -> 5.8107866 | R21: =+$I$13+$I$12*O21-P21 -> 5.5754229 | S21: =+$I$13+$I$12*O21+P21 -> 6.0461504 | T21: =10^Q21 -> 646824.76 | U21: =10^O21 -> 0.571 | V21: =10^R21 -> 376203.56 | W21: =10^$O21 -> 0.571 | X21: =10^S21 -> 1112116.7 | Y21: =10^$O21 -> 0.571
I22: SAK | J22: f | K22: S2 | L22: F | O22: =LOG($I$19+($I$20-$I$19)*(ROW()-2)/100) -> -0.23657201 | P22: =SQRT(2*$I$16*$K$24)*SQRT((1/$I$1)+((O22-$I$10)^2/$I$7)) -> 0.2288055 | Q22: =+$I$13+$I$12*O22 -> 5.7696115 | R22: =+$I$13+$I$12*O22-P22 -> 5.540806 | S22: =+$I$13+$I$12*O22+P22 -> 5.998417 | T22: =10^Q22 -> 588317.1 | U22: =10^O22 -> 0.58 | V22: =10^R22 -> 347380.93 | W22: =10^$O22 -> 0.58 | X22: =10^S22 -> 996361.58 | Y22: =10^$O22 -> 0.58 | Z22: RESIDUAL OUTPUT
H23: Regress | I23: =+I9^2/I7 -> 2.5829192 | J23: 1 | K23: =+I23/1 -> 2.5829192 | L23: =+K23/K24 -> 392.41511 | O23: =LOG($I$19+($I$20-$I$19)*(ROW()-2)/100) -> -0.22988471 | P23: =SQRT(2*$I$16*$K$24)*SQRT((1/$I$1)+((O23-$I$10)^2/$I$7)) -> 0.22242275 | Q23: =+$I$13+$I$12*O23 -> 5.7290703 | R23: =+$I$13+$I$12*O23-P23 -> 5.5066476 | S23: =+$I$13+$I$12*O23+P23 -> 5.9514931 | T23: =10^Q23 -> 535883.44 | U23: =10^O23 -> 0.589 | V23: =10^R23 -> 321105.38 | W23: =10^$O23 -> 0.589 | X23: =10^S23 -> 894320.31 | Y23: =10^$O23 -> 0.589
H24: Residual | I24: =+I8-I23 -> 0.026328438 | J24: =+I1-2 -> 4 | K24: =+I24/($I$1-2) -> 0.0065821094 | O24: =LOG($I$19+($I$20-$I$19)*(ROW()-2)/100) -> -0.22329882 | P24: =SQRT(2*$I$16*$K$24)*SQRT((1/$I$1)+((O24-$I$10)^2/$I$7)) -> 0.21621544 | Q24: =+$I$13+$I$12*O24 -> 5.689144 | R24: =+$I$13+$I$12*O24-P24 -> 5.4729286 | S24: =+$I$13+$I$12*O24+P24 -> 5.9053594 | T24: =10^Q24 -> 488814.42 | U24: =10^O24 -> 0.598 | V24: =10^R24 -> 297117.72 | W24: =10^$O24 -> 0.598 | X24: =10^S24 -> 804191.45 | Y24: =10^$O24 -> 0.598 | Z24: Observation | AA24: Predicted Y | AB24: Residuals | AC24: Standard Residuals
H25: Total | I25: =SUM(I23:I24) -> 2.6092476 | J25: =SUM(J23:J24) -> 5 | O25: =LOG($I$19+($I$20-$I$19)*(ROW()-2)/100) -> -0.21681131 | P25: =SQRT(2*$I$16*$K$24)*SQRT((1/$I$1)+((O25-$I$10)^2/$I$7)) -> 0.21018393 | Q25: =+$I$13+$I$12*O25 -> 5.6498141 | R25: =+$I$13+$I$12*O25-P25 -> 5.4396302 | S25: =+$I$13+$I$12*O25+P25 -> 5.859998 | T25: =10^Q25 -> 446492.43 | U25: =10^O25 -> 0.607 | V25: =10^R25 -> 275188.43 | W25: =10^$O25 -> 0.607 | X25: =10^S25 -> 724432.68 | Y25: =10^$O25 -> 0.607 | Z25: 1 | AA25: 64.962009 | AB25: 0.4744117 | AC25: 0.10320336
O26: =LOG($I$19+($I$20-$I$19)*(ROW()-2)/100) -> -0.21041929 | P26: =SQRT(2*$I$16*$K$24)*SQRT((1/$I$1)+((O26-$I$10)^2/$I$7)) -> 0.20432897 | Q26: =+$I$13+$I$12*O26 -> 5.6110631 | R26: =+$I$13+$I$12*O26-P26 -> 5.4067341 | S26: =+$I$13+$I$12*O26+P26 -> 5.815392 | T26: =10^Q26 -> 408378.7 | U26: =10^O26 -> 0.616 | V26: =10^R26 -> 255113.89 | W26: =10^$O26 -> 0.616 | X26: =10^S26 -> 653720.41 | Y26: =10^$O26 -> 0.616 | Z26: 2 | AA26: 84.735375 | AB26: 8.1224338 | AC26: 1.7669515
O27: =LOG($I$19+($I$20-$I$19)*(ROW()-2)/100) -> -0.20411998 | P27: =SQRT(2*$I$16*$K$24)*SQRT((1/$I$1)+((O27-$I$10)^2/$I$7)) -> 0.1986517 | Q27: =+$I$13+$I$12*O27 -> 5.5728741 | R27: =+$I$13+$I$12*O27-P27 -> 5.3742224 | S27: =+$I$13+$I$12*O27+P27 -> 5.7715258 | T27: =10^Q27 -> 374002.18 | U27: =10^O27 -> 0.625 | V27: =10^R27 -> 236713.18 | W27: =10^$O27 -> 0.625 | X27: =10^S27 -> 590916.12 | Y27: =10^$O27 -> 0.625 | Z27: 3 | AA27: 72.39896 | AB27: -3.7728516 | AC27: -0.82074485
O28: =LOG($I$19+($I$20-$I$19)*(ROW()-2)/100) -> -0.19791074 | P28: =SQRT(2*$I$16*$K$24)*SQRT((1/$I$1)+((O28-$I$10)^2/$I$7)) -> 0.19315369 | Q28: =+$I$13+$I$12*O28 -> 5.5352312 | R28: =+$I$13+$I$12*O28-P28 -> 5.3420775 | S28: =+$I$13+$I$12*O28+P28 -> 5.7283849 | T28: =10^Q28 -> 342950.31 | U28: =10^O28 -> 0.634 | V28: =10^R28 -> 219825.21 | W28: =10^$O28 -> 0.634 | X28: =10^S28 -> 535038.32 | Y28: =10^$O28 -> 0.634 | Z28: 4 | AA28: 83.96799 | AB28: 3.5389413 | AC28: 0.76986009
H29: N = | I29: =10^$I$13 -> 21647.909 | J29: * | K29: S^ | L29: =+I12 -> -6.0624059 | O29: =LOG($I$19+($I$20-$I$19)*(ROW()-2)/100) -> -0.19178903 | P29: =SQRT(2*$I$16*$K$24)*SQRT((1/$I$1)+((O29-$I$10)^2/$I$7)) -> 0.18783688 | Q29: =+$I$13+$I$12*O29 -> 5.4981189 | R29: =+$I$13+$I$12*O29-P29 -> 5.310282 | S29: =+$I$13+$I$12*O29+P29 -> 5.6859558 | T29: =10^Q29 -> 314861 | U29: =10^O29 -> 0.643 | V29: =10^R29 -> 204306.41 | W29: =10^$O29 -> 0.643 | X29: =10^S29 -> 485239.07 | Y29: =10^$O29 -> 0.643 | Z29: 5 | AA29: 80.249514 | AB29: -3.0746271 | AC29: -0.66885335
O30: =LOG($I$19+($I$20-$I$19)*(ROW()-2)/100) -> -0.1857524 | P30: =SQRT(2*$I$16*$K$24)*SQRT((1/$I$1)+((O30-$I$10)^2/$I$7)) -> 0.18270361 | Q30: =+$I$13+$I$12*O30 -> 5.4615224 | R30: =+$I$13+$I$12*O30-P30 -> 5.2788188 | S30: =+$I$13+$I$12*O30+P30 -> 5.644226 | T30: =10^Q30 -> 289415.92 | U30: =10^O30 -> 0.652 | V30: =10^R30 -> 190028.53 | W30: =10^$O30 -> 0.652 | X30: =10^S30 -> 440784.21 | Y30: =10^$O30 -> 0.652 | Z30: 6 | AA30: 78.183475 | AB30: -4.5407035 | AC30: -0.9877831
O31: =LOG($I$19+($I$20-$I$19)*(ROW()-2)/100) -> -0.17979854 | P31: =SQRT(2*$I$16*$K$24)*SQRT((1/$I$1)+((O31-$I$10)^2/$I$7)) -> 0.17775658 | Q31: =+$I$13+$I$12*O31 -> 5.4254277 | R31: =+$I$13+$I$12*O31-P31 -> 5.2476711 | S31: =+$I$13+$I$12*O31+P31 -> 5.6031843 | T31: =10^Q31 -> 266334.66 | U31: =10^O31 -> 0.661 | V31: =10^R31 -> 176876.89 | W31: =10^$O31 -> 0.661 | X31: =10^S31 -> 401036.83 | Y31: =10^$O31 -> 0.661 | Z31: 7 | AA31: 58.292049 | AB31: 5.5384636 | AC31: 1.2048355
H32: N | I32: TVALUE | J32: FVALUE | L32: 0.95 | O32: =LOG($I$19+($I$20-$I$19)*(ROW()-2)/100) -> -0.1739252 | P32: =SQRT(2*$I$16*$K$24)*SQRT((1/$I$1)+((O32-$I$10)^2/$I$7)) -> 0.17299889 | Q32: =+$I$13+$I$12*O32 -> 5.3898211 | R32: =+$I$13+$I$12*O32-P32 -> 5.2168222 | S32: =+$I$13+$I$12*O32+P32 -> 5.56282 | T32: =10^Q32 -> 245369.79 | U32: =10^O32 -> 0.67 | V32: =10^R32 -> 164748.78 | W32: =10^$O32 -> 0.67 | X32: =10^S32 -> 365443.28 | Y32: =10^$O32 -> 0.67 | Z32: 8 | AA32: 76.17686 | AB32: -1.661665 | AC32: -0.36147805
H33: 1 | I33: 12.706 | J33: 199.5 | O33: =LOG($I$19+($I$20-$I$19)*(ROW()-2)/100) -> -0.16813023 | P33: =SQRT(2*$I$16*$K$24)*SQRT((1/$I$1)+((O33-$I$10)^2/$I$7)) -> 0.16843396 | Q33: =+$I$13+$I$12*O33 -> 5.3546896 | R33: =+$I$13+$I$12*O33-P33 -> 5.1862557 | S33: =+$I$13+$I$12*O33+P33 -> 5.5231236 | T33: =10^Q33 -> 226302.64 | U33: =10^O33 -> 0.679 | V33: =10^R33 -> 153552.06 | W33: =10^$O33 -> 0.679 | X33: =10^S33 -> 333521.3 | Y33: =10^$O33 -> 0.679 | Z33: 9 | AA33: 66.378327 | AB33: 1.0806765 | AC33: 0.23508999
H34: 2 | I34: 4.303 | J34: 19 | O34: =LOG($I$19+($I$20-$I$19)*(ROW()-2)/100) -> -0.16241156 | P34: =SQRT(2*$I$16*$K$24)*SQRT((1/$I$1)+((O34-$I$10)^2/$I$7)) -> 0.16406553 | Q34: =+$I$13+$I$12*O34 -> 5.3200208 | R34: =+$I$13+$I$12*O34-P34 -> 5.1559552 | S34: =+$I$13+$I$12*O34+P34 -> 5.4840863 | T34: =10^Q34 -> 208939.6 | U34: =10^O34 -> 0.688 | V34: =10^R34 -> 143204.03 | W34: =10^$O34 -> 0.688 | X34: =10^S34 -> 304850.06 | Y34: =10^$O34 -> 0.688 | Z34: 10 | AA34: 71.750028 | AB34: -5.7050796 | AC34: -1.2410811
H35: 3 | I35: 3.182 | J35: 9.55 | O35: =LOG($I$19+($I$20-$I$19)*(ROW()-2)/100) -> -0.15676722 | P35: =SQRT(2*$I$16*$K$24)*SQRT((1/$I$1)+((O35-$I$10)^2/$I$7)) -> 0.15989763 | Q35: =+$I$13+$I$12*O35 -> 5.2858025 | R35: =+$I$13+$I$12*O35-P35 -> 5.1259048 | S35: =+$I$13+$I$12*O35+P35 -> 5.4457001 | T35: =10^Q35 -> 193108.98 | U35: =10^O35 -> 0.697 | V35: =10^R35 -> 133630.27 | W35: =10^$O35 -> 0.697 | X35: =10^S35 -> 279061.62 | Y35: =10^$O35 -> 0.697 | Z35: 11 | AA35: 1.8219741 | AB35: -0.023572384 | AC35: -2.1105589
H36: 4 | I36: 2.7764 | J36: 6.94 | O36: =LOG($I$19+($I$20-$I$19)*(ROW()-2)/100) -> -0.1511953 | P36: =SQRT(2*$I$16*$K$24)*SQRT((1/$I$1)+((O36-$I$10)^2/$I$7)) -> 0.15593451 | Q36: =+$I$13+$I$12*O36 -> 5.2520232 | R36: =+$I$13+$I$12*O36-P36 -> 5.0960887 | S36: =+$I$13+$I$12*O36+P36 -> 5.4079577 | T36: =10^Q36 -> 178658.31 | U36: =10^O36 -> 0.706 | V36: =10^R36 -> 124763.83 | W36: =10^$O36 -> 0.706 | X36: =10^S36 -> 255833.69 | Y36: =10^$O36 -> 0.706 | Z36: 12 | AA36: 1.7418459 | AB36: 0.0051980261 | AC36: 0.46540648
H37: 5 | I37: 2.5706 | J37: 5.79 | O37: =LOG($I$19+($I$20-$I$19)*(ROW()-2)/100) -> -0.14569396 | P37: =SQRT(2*$I$16*$K$24)*SQRT((1/$I$1)+((O37-$I$10)^2/$I$7)) -> 0.15218061 | Q37: =+$I$13+$I$12*O37 -> 5.2186719 | R37: =+$I$13+$I$12*O37-P37 -> 5.0664912 | S37: =+$I$13+$I$12*O37+P37 -> 5.3708525 | T37: =10^Q37 -> 165451.94 | U37: =10^O37 -> 0.715 | V37: =10^R37 -> 116544.36 | W37: =10^$O37 -> 0.715 | X37: =10^S37 -> 234883.48 | Y37: =10^$O37 -> 0.715
H38: 6 | I38: 2.4469 | J38: 5.14 | O38: =LOG($I$19+($I$20-$I$19)*(ROW()-2)/100) -> -0.14026143 | P38: =SQRT(2*$I$16*$K$24)*SQRT((1/$I$1)+((O38-$I$10)^2/$I$7)) -> 0.14864048 | Q38: =+$I$13+$I$12*O38 -> 5.1857377 | R38: =+$I$13+$I$12*O38-P38 -> 5.0370972 | S38: =+$I$13+$I$12*O38+P38 -> 5.3343782 | T38: =10^Q38 -> 153369.04 | U38: =10^O38 -> 0.724 | V38: =10^R38 -> 108917.39 | W38: =10^$O38 -> 0.724 | X38: =10^S38 -> 215962.41 | Y38: =10^$O38 -> 0.724
H39: 7 | I39: 2.3646 | J39: 4.74 | O39: =LOG($I$19+($I$20-$I$19)*(ROW()-2)/100) -> -0.13489603 | P39: =SQRT(2*$I$16*$K$24)*SQRT((1/$I$1)+((O39-$I$10)^2/$I$7)) -> 0.14531866 | Q39: =+$I$13+$I$12*O39 -> 5.1532104 | R39: =+$I$13+$I$12*O39-P39 -> 5.0078917 | S39: =+$I$13+$I$12*O39+P39 -> 5.2985291 | T39: =10^Q39 -> 142301.81 | U39: =10^O39 -> 0.733 | V39: =10^R39 -> 101833.75 | W39: =10^$O39 -> 0.733 | X39: =10^S39 -> 198851.59 | Y39: =10^$O39 -> 0.733
H40: 8 | I40: 2.306 | J40: 4.46 | O40: =LOG($I$19+($I$20-$I$19)*(ROW()-2)/100) -> -0.12959609 | P40: =SQRT(2*$I$16*$K$24)*SQRT((1/$I$1)+((O40-$I$10)^2/$I$7)) -> 0.14221967 | Q40: =+$I$13+$I$12*O40 -> 5.1210801 | R40: =+$I$13+$I$12*O40-P40 -> 4.9788604 | S40: =+$I$13+$I$12*O40+P40 -> 5.2632998 | T40: =10^Q40 -> 132153.93 | U40: =10^O40 -> 0.742 | V40: =10^R40 -> 95248.996 | W40: =10^$O40 -> 0.742 | X40: =10^S40 -> 183357.95 | Y40: =10^$O40 -> 0.742
...

Sheet ASTM E739 stat (Strain Range)
A1: SN Points | C1: X | D1: Y | E1: X^2 | F1: Y^2 | G1: X*Y | H1: N | I1: =COUNT(C:C) -> 0 | M1: X | N1: YHAT | O1: X | P1: Xconfi | Q1: Yavg | R1: Y1 | S1: Y2 | T1: SN-line | V1: Lower conf | X1: Upper Conf | Z1: SUMMARY OUTPUT
A2: =+Results!D23 -> 0 | B2: =+Results!C23 -> Statisk | C2: =LOG(A2) -> #NUM! | D2: =LOG(B2) -> #VALUE! | E2: =+C2^2 -> #NUM! | F2: =+D2^2 -> #VALUE! | G2: =+C2*D2 -> #NUM! | H2: SUMX | I2: =SUM(C:C) -> #NUM! | M2: =+C2 -> #NUM! | N2: =+$I$13+$I$12*M2 -> #VALUE! | O2: =LOG($I$19+($I$20-$I$19)*(ROW()-2)/100) -> #NUM! | P2: =SQRT(2*$I$16*$K$24)*SQRT((1/$I$1)+((O2-$I$10)^2/$I$7)) -> #N/A | Q2: =+$I$13+$I$12*O2 -> #VALUE! | R2: =+$I$13+$I$12*O2-P2 -> #VALUE! | S2: =+$I$13+$I$12*O2+P2 -> #VALUE! | T2: =10^Q2 -> #VALUE! | U2: =10^$O2 -> #NUM! | V2: =10^R2 -> #VALUE! | W2: =10^$O2 -> #NUM! | X2: =10^S2 -> #VALUE! | Y2: =10^$O2 -> #NUM!
A3: =+Results!D24 -> 0 | B3: =+Results!C24 -> Statisk | C3: =LOG(A3) -> #NUM! | D3: =LOG(B3) -> #VALUE! | E3: =+C3^2 -> #NUM! | F3: =+D3^2 -> #VALUE! | G3: =+C3*D3 -> #NUM! | H3: SUMY | I3: =SUM(D:D) -> #VALUE! | M3: =+C3 -> #NUM! | N3: =+$I$13+$I$12*M3 -> #VALUE! | O3: =LOG($I$19+($I$20-$I$19)*(ROW()-2)/100) -> #NUM! | P3: =SQRT(2*$I$16*$K$24)*SQRT((1/$I$1)+((O3-$I$10)^2/$I$7)) -> #N/A | Q3: =+$I$13+$I$12*O3 -> #VALUE! | R3: =+$I$13+$I$12*O3-P3 -> #VALUE! | S3: =+$I$13+$I$12*O3+P3 -> #VALUE! | T3: =10^Q3 -> #VALUE! | U3: =10^O3 -> #NUM! | V3: =10^R3 -> #VALUE! | W3: =10^$O3 -> #NUM! | X3: =10^S3 -> #VALUE! | Y3: =10^$O3 -> #NUM! | Z3: Regression Statistics
A4: =+Results!D25 -> 0 | B4: =+Results!C25 -> Statisk | C4: =LOG(A4) -> #NUM! | D4: =LOG(B4) -> #VALUE! | E4: =+C4^2 -> #NUM! | F4: =+D4^2 -> #VALUE! | G4: =+C4*D4 -> #NUM! | H4: SUMXX | I4: =SUM(E:E) -> #NUM! | M4: =+C4 -> #NUM! | N4: =+$I$13+$I$12*M4 -> #VALUE! | O4: =LOG($I$19+($I$20-$I$19)*(ROW()-2)/100) -> #NUM! | P4: =SQRT(2*$I$16*$K$24)*SQRT((1/$I$1)+((O4-$I$10)^2/$I$7)) -> #N/A | Q4: =+$I$13+$I$12*O4 -> #VALUE! | R4: =+$I$13+$I$12*O4-P4 -> #VALUE! | S4: =+$I$13+$I$12*O4+P4 -> #VALUE! | T4: =10^Q4 -> #VALUE! | U4: =10^O4 -> #NUM! | V4: =10^R4 -> #VALUE! | W4: =10^$O4 -> #NUM! | X4: =10^S4 -> #VALUE! | Y4: =10^$O4 -> #NUM! | Z4: Multiple R | AA4: 0.88244047
A5: =+Results!D26 -> 0 | B5: =+Results!C26 -> 0 | C5: =LOG(A5) -> #NUM! | D5: =LOG(B5) -> #NUM! | E5: =+C5^2 -> #NUM! | F5: =+D5^2 -> #NUM! | G5: =+C5*D5 -> #NUM! | H5: SUMYY | I5: =SUM(F:F) -> #VALUE! | M5: =+C5 -> #NUM! | N5: =+$I$13+$I$12*M5 -> #VALUE! | O5: =LOG($I$19+($I$20-$I$19)*(ROW()-2)/100) -> #NUM! | P5: =SQRT(2*$I$16*$K$24)*SQRT((1/$I$1)+((O5-$I$10)^2/$I$7)) -> #N/A | Q5: =+$I$13+$I$12*O5 -> #VALUE! | R5: =+$I$13+$I$12*O5-P5 -> #VALUE! | S5: =+$I$13+$I$12*O5+P5 -> #VALUE! | T5: =10^Q5 -> #VALUE! | U5: =10^O5 -> #NUM! | V5: =10^R5 -> #VALUE! | W5: =10^$O5 -> #NUM! | X5: =10^S5 -> #VALUE! | Y5: =10^$O5 -> #NUM! | Z5: R Square | AA5: 0.77870118
H6: SUMXY | I6: =SUM(G:G) -> #NUM! | M6: =+C6 -> 0 | N6: =+$I$13+$I$12*M6 -> #VALUE! | O6: =LOG($I$19+($I$20-$I$19)*(ROW()-2)/100) -> #NUM! | P6: =SQRT(2*$I$16*$K$24)*SQRT((1/$I$1)+((O6-$I$10)^2/$I$7)) -> #N/A | Q6: =+$I$13+$I$12*O6 -> #VALUE! | R6: =+$I$13+$I$12*O6-P6 -> #VALUE! | S6: =+$I$13+$I$12*O6+P6 -> #VALUE! | T6: =10^Q6 -> #VALUE! | U6: =10^O6 -> #NUM! | V6: =10^R6 -> #VALUE! | W6: =10^$O6 -> #NUM! | X6: =10^S6 -> #VALUE! | Y6: =10^$O6 -> #NUM! | Z6: Adjusted R Square | AA6: 0.75103883
H7: SAKX | I7: =+I4-I2^2/$I$1 -> #NUM! | M7: =+C7 -> 0 | N7: =+$I$13+$I$12*M7 -> #VALUE! | O7: =LOG($I$19+($I$20-$I$19)*(ROW()-2)/100) -> #NUM! | P7: =SQRT(2*$I$16*$K$24)*SQRT((1/$I$1)+((O7-$I$10)^2/$I$7)) -> #N/A | Q7: =+$I$13+$I$12*O7 -> #VALUE! | R7: =+$I$13+$I$12*O7-P7 -> #VALUE! | S7: =+$I$13+$I$12*O7+P7 -> #VALUE! | T7: =10^Q7 -> #VALUE! | U7: =10^O7 -> #NUM! | V7: =10^R7 -> #VALUE! | W7: =10^$O7 -> #NUM! | X7: =10^S7 -> #VALUE! | Y7: =10^$O7 -> #NUM! | Z7: Standard Error | AA7: 4.8757094
H8: SAKY (SAKtotal) | I8: =+I5-I3^2/$I$1 -> #VALUE! | M8: =+C8 -> 0 | N8: =+$I$13+$I$12*M8 -> #VALUE! | O8: =LOG($I$19+($I$20-$I$19)*(ROW()-2)/100) -> #NUM! | P8: =SQRT(2*$I$16*$K$24)*SQRT((1/$I$1)+((O8-$I$10)^2/$I$7)) -> #N/A | Q8: =+$I$13+$I$12*O8 -> #VALUE! | R8: =+$I$13+$I$12*O8-P8 -> #VALUE! | S8: =+$I$13+$I$12*O8+P8 -> #VALUE! | T8: =10^Q8 -> #VALUE! | U8: =10^O8 -> #NUM! | V8: =10^R8 -> #VALUE! | W8: =10^$O8 -> #NUM! | X8: =10^S8 -> #VALUE! | Y8: =10^$O8 -> #NUM! | Z8: Observations | AA8: 10
H9: SAPXY | I9: =+I6-I2*I3/$I$1 -> #NUM! | M9: =+C9 -> 0 | N9: =+$I$13+$I$12*M9 -> #VALUE! | O9: =LOG($I$19+($I$20-$I$19)*(ROW()-2)/100) -> #NUM! | P9: =SQRT(2*$I$16*$K$24)*SQRT((1/$I$1)+((O9-$I$10)^2/$I$7)) -> #N/A | Q9: =+$I$13+$I$12*O9 -> #VALUE! | R9: =+$I$13+$I$12*O9-P9 -> #VALUE! | S9: =+$I$13+$I$12*O9+P9 -> #VALUE! | T9: =10^Q9 -> #VALUE! | U9: =10^O9 -> #NUM! | V9: =10^R9 -> #VALUE! | W9: =10^$O9 -> #NUM! | X9: =10^S9 -> #VALUE! | Y9: =10^$O9 -> #NUM!
H10: XMEAN | I10: =+I2/$I$1 -> #NUM! | M10: =+C10 -> 0 | N10: =+$I$13+$I$12*M10 -> #VALUE! | O10: =LOG($I$19+($I$20-$I$19)*(ROW()-2)/100) -> #NUM! | P10: =SQRT(2*$I$16*$K$24)*SQRT((1/$I$1)+((O10-$I$10)^2/$I$7)) -> #N/A | Q10: =+$I$13+$I$12*O10 -> #VALUE! | R10: =+$I$13+$I$12*O10-P10 -> #VALUE! | S10: =+$I$13+$I$12*O10+P10 -> #VALUE! | T10: =10^Q10 -> #VALUE! | U10: =10^O10 -> #NUM! | V10: =10^R10 -> #VALUE! | W10: =10^$O10 -> #NUM! | X10: =10^S10 -> #VALUE! | Y10: =10^$O10 -> #NUM! | Z10: ANOVA
H11: YMEAN | I11: =+I3/$I$1 -> #VALUE! | M11: =+C11 -> 0 | N11: =+$I$13+$I$12*M11 -> #VALUE! | O11: =LOG($I$19+($I$20-$I$19)*(ROW()-2)/100) -> #NUM! | P11: =SQRT(2*$I$16*$K$24)*SQRT((1/$I$1)+((O11-$I$10)^2/$I$7)) -> #N/A | Q11: =+$I$13+$I$12*O11 -> #VALUE! | R11: =+$I$13+$I$12*O11-P11 -> #VALUE! | S11: =+$I$13+$I$12*O11+P11 -> #VALUE! | T11: =10^Q11 -> #VALUE! | U11: =10^O11 -> #NUM! | V11: =10^R11 -> #VALUE! | W11: =10^$O11 -> #NUM! | X11: =10^S11 -> #VALUE! | Y11: =10^$O11 -> #NUM! | AA11: df | AB11: SS | AC11: MS | AD11: F | AE11: Significance F
H12: A1 | I12: =+I9/I7 -> #NUM! | J12: =+I12 -> #NUM! | K12: =1/J12 -> #NUM! | M12: =+C12 -> 0 | N12: =+$I$13+$I$12*M12 -> #VALUE! | O12: =LOG($I$19+($I$20-$I$19)*(ROW()-2)/100) -> #NUM! | P12: =SQRT(2*$I$16*$K$24)*SQRT((1/$I$1)+((O12-$I$10)^2/$I$7)) -> #N/A | Q12: =+$I$13+$I$12*O12 -> #VALUE! | R12: =+$I$13+$I$12*O12-P12 -> #VALUE! | S12: =+$I$13+$I$12*O12+P12 -> #VALUE! | T12: =10^Q12 -> #VALUE! | U12: =10^O12 -> #NUM! | V12: =10^R12 -> #VALUE! | W12: =10^$O12 -> #NUM! | X12: =10^S12 -> #VALUE! | Y12: =10^$O12 -> #NUM! | Z12: Regression | AA12: 1 | AB12: 669.20218 | AC12: 669.20218 | AD12: 28.150215 | AE12: 0.00072341619
H13: A0 | I13: =+I11-I12*I10 -> #VALUE! | J13: =10^I13 -> #VALUE! | K13: =+J13^J12 -> #VALUE! | M13: =+C13 -> 0 | N13: =+$I$13+$I$12*M13 -> #VALUE! | O13: =LOG($I$19+($I$20-$I$19)*(ROW()-2)/100) -> #NUM! | P13: =SQRT(2*$I$16*$K$24)*SQRT((1/$I$1)+((O13-$I$10)^2/$I$7)) -> #N/A | Q13: =+$I$13+$I$12*O13 -> #VALUE! | R13: =+$I$13+$I$12*O13-P13 -> #VALUE! | S13: =+$I$13+$I$12*O13+P13 -> #VALUE! | T13: =10^Q13 -> #VALUE! | U13: =10^O13 -> #NUM! | V13: =10^R13 -> #VALUE! | W13: =10^$O13 -> #NUM! | X13: =10^S13 -> #VALUE! | Y13: =10^$O13 -> #NUM! | Z13: Residual | AA13: 8 | AB13: 190.18034 | AC13: 23.772542
H14: R2 | I14: =+I9^2/(I7*I8) -> #NUM! | J14: ="(X="&TEXT(J13,"0.0")&"Y^"&TEXT(J12,"0.00")&")" -> #VALUE! | M14: =+C14 -> 0 | N14: =+$I$13+$I$12*M14 -> #VALUE! | O14: =LOG($I$19+($I$20-$I$19)*(ROW()-2)/100) -> #NUM! | P14: =SQRT(2*$I$16*$K$24)*SQRT((1/$I$1)+((O14-$I$10)^2/$I$7)) -> #N/A | Q14: =+$I$13+$I$12*O14 -> #VALUE! | R14: =+$I$13+$I$12*O14-P14 -> #VALUE! | S14: =+$I$13+$I$12*O14+P14 -> #VALUE! | T14: =10^Q14 -> #VALUE! | U14: =10^O14 -> #NUM! | V14: =10^R14 -> #VALUE! | W14: =10^$O14 -> #NUM! | X14: =10^S14 -> #VALUE! | Y14: =10^$O14 -> #NUM! | Z14: Total | AA14: 9 | AB14: 859.38251
H15: T-VALUE | I15: =VLOOKUP($J$24,$H$33:$J$69,2) -> #N/A | M15: =+C15 -> 0 | N15: =+$I$13+$I$12*M15 -> #VALUE! | O15: =LOG($I$19+($I$20-$I$19)*(ROW()-2)/100) -> #NUM! | P15: =SQRT(2*$I$16*$K$24)*SQRT((1/$I$1)+((O15-$I$10)^2/$I$7)) -> #N/A | Q15: =+$I$13+$I$12*O15 -> #VALUE! | R15: =+$I$13+$I$12*O15-P15 -> #VALUE! | S15: =+$I$13+$I$12*O15+P15 -> #VALUE! | T15: =10^Q15 -> #VALUE! | U15: =10^O15 -> #NUM! | V15: =10^R15 -> #VALUE! | W15: =10^$O15 -> #NUM! | X15: =10^S15 -> #VALUE! | Y15: =10^$O15 -> #NUM!
H16: F-VALUE | I16: =VLOOKUP($J$24,$H$33:$J$69,3) -> #N/A | M16: =+C16 -> 0 | N16: =+$I$13+$I$12*M16 -> #VALUE! | O16: =LOG($I$19+($I$20-$I$19)*(ROW()-2)/100) -> #NUM! | P16: =SQRT(2*$I$16*$K$24)*SQRT((1/$I$1)+((O16-$I$10)^2/$I$7)) -> #N/A | Q16: =+$I$13+$I$12*O16 -> #VALUE! | R16: =+$I$13+$I$12*O16-P16 -> #VALUE! | S16: =+$I$13+$I$12*O16+P16 -> #VALUE! | T16: =10^Q16 -> #VALUE! | U16: =10^O16 -> #NUM! | V16: =10^R16 -> #VALUE! | W16: =10^$O16 -> #NUM! | X16: =10^S16 -> #VALUE! | Y16: =10^$O16 -> #NUM! | AA16: Coefficients | AB16: Standard Error | AC16: t Stat | AD16: P-value | AE16: Lower 95% | AF16: Upper 95% | AG16: Lower 95.0% | AH16: Upper 95.0%
H17: CONFIA1 | I17: =+I15*SQRT($K$24/$I$7) -> #N/A | J17: =+I12+I17 -> #NUM! | K17: =+I12-I17 -> #NUM! | M17: =+C17 -> 0 | N17: =+$I$13+$I$12*M17 -> #VALUE! | O17: =LOG($I$19+($I$20-$I$19)*(ROW()-2)/100) -> #NUM! | P17: =SQRT(2*$I$16*$K$24)*SQRT((1/$I$1)+((O17-$I$10)^2/$I$7)) -> #N/A | Q17: =+$I$13+$I$12*O17 -> #VALUE! | R17: =+$I$13+$I$12*O17-P17 -> #VALUE! | S17: =+$I$13+$I$12*O17+P17 -> #VALUE! | T17: =10^Q17 -> #VALUE! | U17: =10^O17 -> #NUM! | V17: =10^R17 -> #VALUE! | W17: =10^$O17 -> #NUM! | X17: =10^S17 -> #VALUE! | Y17: =10^$O17 -> #NUM! | Z17: Intercept | AA17: 86.958826 | AB17: 2.9348407 | AC17: 29.629828 | AD17: 1.8247423e-09 | AE17: 80.191067 | AF17: 93.726586 | AG17: 80.191067 | AH17: 93.726586
H18: CONFIA0 | I18: =+I15*SQRT(K24/I1) -> #N/A | J18: =+I13-I18 -> #VALUE! | K18: =+I13+I18 -> #VALUE! | M18: =+C18 -> 0 | N18: =+$I$13+$I$12*M18 -> #VALUE! | O18: =LOG($I$19+($I$20-$I$19)*(ROW()-2)/100) -> #NUM! | P18: =SQRT(2*$I$16*$K$24)*SQRT((1/$I$1)+((O18-$I$10)^2/$I$7)) -> #N/A | Q18: =+$I$13+$I$12*O18 -> #VALUE! | R18: =+$I$13+$I$12*O18-P18 -> #VALUE! | S18: =+$I$13+$I$12*O18+P18 -> #VALUE! | T18: =10^Q18 -> #VALUE! | U18: =10^O18 -> #NUM! | V18: =10^R18 -> #VALUE! | W18: =10^$O18 -> #NUM! | X18: =10^S18 -> #VALUE! | Y18: =10^$O18 -> #NUM! | Z18: X Variable 1 | AA18: -0.00039353116 | AB18: 7.4171706e-05 | AC18: -5.3056776 | AD18: 0.00072341619 | AE18: -0.00056457153 | AF18: -0.00022249079 | AG18: -0.00056457153 | AH18: -0.00022249079
H19: Xmin | I19: =MIN(A:A) -> 0 | M19: =+C19 -> 0 | N19: =+$I$13+$I$12*M19 -> #VALUE! | O19: =LOG($I$19+($I$20-$I$19)*(ROW()-2)/100) -> #NUM! | P19: =SQRT(2*$I$16*$K$24)*SQRT((1/$I$1)+((O19-$I$10)^2/$I$7)) -> #N/A | Q19: =+$I$13+$I$12*O19 -> #VALUE! | R19: =+$I$13+$I$12*O19-P19 -> #VALUE! | S19: =+$I$13+$I$12*O19+P19 -> #VALUE! | T19: =10^Q19 -> #VALUE! | U19: =10^O19 -> #NUM! | V19: =10^R19 -> #VALUE! | W19: =10^$O19 -> #NUM! | X19: =10^S19 -> #VALUE! | Y19: =10^$O19 -> #NUM!
H20: Xmax | I20: =MAX(A:A) -> 0 | O20: =LOG($I$19+($I$20-$I$19)*(ROW()-2)/100) -> #NUM! | P20: =SQRT(2*$I$16*$K$24)*SQRT((1/$I$1)+((O20-$I$10)^2/$I$7)) -> #N/A | Q20: =+$I$13+$I$12*O20 -> #VALUE! | R20: =+$I$13+$I$12*O20-P20 -> #VALUE! | S20: =+$I$13+$I$12*O20+P20 -> #VALUE! | T20: =10^Q20 -> #VALUE! | U20: =10^O20 -> #NUM! | V20: =10^R20 -> #VALUE! | W20: =10^$O20 -> #NUM! | X20: =10^S20 -> #VALUE! | Y20: =10^$O20 -> #NUM!
H21: Variansanalysetabel | O21: =LOG($I$19+($I$20-$I$19)*(ROW()-2)/100) -> #NUM! | P21: =SQRT(2*$I$16*$K$24)*SQRT((1/$I$1)+((O21-$I$10)^2/$I$7)) -> #N/A | Q21: =+$I$13+$I$12*O21 -> #VALUE! | R21: =+$I$13+$I$12*O21-P21 -> #VALUE! | S21: =+$I$13+$I$12*O21+P21 -> #VALUE! | T21: =10^Q21 -> #VALUE! | U21: =10^O21 -> #NUM! | V21: =10^R21 -> #VALUE! | W21: =10^$O21 -> #NUM! | X21: =10^S21 -> #VALUE! | Y21: =10^$O21 -> #NUM!
I22: SAK | J22: f | K22: S2 | L22: F | O22: =LOG($I$19+($I$20-$I$19)*(ROW()-2)/100) -> #NUM! | P22: =SQRT(2*$I$16*$K$24)*SQRT((1/$I$1)+((O22-$I$10)^2/$I$7)) -> #N/A | Q22: =+$I$13+$I$12*O22 -> #VALUE! | R22: =+$I$13+$I$12*O22-P22 -> #VALUE! | S22: =+$I$13+$I$12*O22+P22 -> #VALUE! | T22: =10^Q22 -> #VALUE! | U22: =10^O22 -> #NUM! | V22: =10^R22 -> #VALUE! | W22: =10^$O22 -> #NUM! | X22: =10^S22 -> #VALUE! | Y22: =10^$O22 -> #NUM! | Z22: RESIDUAL OUTPUT
H23: Regress | I23: =+I9^2/I7 -> #NUM! | J23: 1 | K23: =+I23/1 -> #NUM! | L23: =+K23/K24 -> #NUM! | O23: =LOG($I$19+($I$20-$I$19)*(ROW()-2)/100) -> #NUM! | P23: =SQRT(2*$I$16*$K$24)*SQRT((1/$I$1)+((O23-$I$10)^2/$I$7)) -> #N/A | Q23: =+$I$13+$I$12*O23 -> #VALUE! | R23: =+$I$13+$I$12*O23-P23 -> #VALUE! | S23: =+$I$13+$I$12*O23+P23 -> #VALUE! | T23: =10^Q23 -> #VALUE! | U23: =10^O23 -> #NUM! | V23: =10^R23 -> #VALUE! | W23: =10^$O23 -> #NUM! | X23: =10^S23 -> #VALUE! | Y23: =10^$O23 -> #NUM!
H24: Residual | I24: =+I8-I23 -> #VALUE! | J24: =+I1-2 -> -2 | K24: =+I24/($I$1-2) -> #VALUE! | O24: =LOG($I$19+($I$20-$I$19)*(ROW()-2)/100) -> #NUM! | P24: =SQRT(2*$I$16*$K$24)*SQRT((1/$I$1)+((O24-$I$10)^2/$I$7)) -> #N/A | Q24: =+$I$13+$I$12*O24 -> #VALUE! | R24: =+$I$13+$I$12*O24-P24 -> #VALUE! | S24: =+$I$13+$I$12*O24+P24 -> #VALUE! | T24: =10^Q24 -> #VALUE! | U24: =10^O24 -> #NUM! | V24: =10^R24 -> #VALUE! | W24: =10^$O24 -> #NUM! | X24: =10^S24 -> #VALUE! | Y24: =10^$O24 -> #NUM! | Z24: Observation | AA24: Predicted Y | AB24: Residuals | AC24: Standard Residuals
H25: Total | I25: =SUM(I23:I24) -> #NUM! | J25: =SUM(J23:J24) -> -1 | O25: =LOG($I$19+($I$20-$I$19)*(ROW()-2)/100) -> #NUM! | P25: =SQRT(2*$I$16*$K$24)*SQRT((1/$I$1)+((O25-$I$10)^2/$I$7)) -> #N/A | Q25: =+$I$13+$I$12*O25 -> #VALUE! | R25: =+$I$13+$I$12*O25-P25 -> #VALUE! | S25: =+$I$13+$I$12*O25+P25 -> #VALUE! | T25: =10^Q25 -> #VALUE! | U25: =10^O25 -> #NUM! | V25: =10^R25 -> #VALUE! | W25: =10^$O25 -> #NUM! | X25: =10^S25 -> #VALUE! | Y25: =10^$O25 -> #NUM! | Z25: 1 | AA25: 64.962009 | AB25: 0.4744117 | AC25: 0.10320336
O26: =LOG($I$19+($I$20-$I$19)*(ROW()-2)/100) -> #NUM! | P26: =SQRT(2*$I$16*$K$24)*SQRT((1/$I$1)+((O26-$I$10)^2/$I$7)) -> #N/A | Q26: =+$I$13+$I$12*O26 -> #VALUE! | R26: =+$I$13+$I$12*O26-P26 -> #VALUE! | S26: =+$I$13+$I$12*O26+P26 -> #VALUE! | T26: =10^Q26 -> #VALUE! | U26: =10^O26 -> #NUM! | V26: =10^R26 -> #VALUE! | W26: =10^$O26 -> #NUM! | X26: =10^S26 -> #VALUE! | Y26: =10^$O26 -> #NUM! | Z26: 2 | AA26: 84.735375 | AB26: 8.1224338 | AC26: 1.7669515
O27: =LOG($I$19+($I$20-$I$19)*(ROW()-2)/100) -> #NUM! | P27: =SQRT(2*$I$16*$K$24)*SQRT((1/$I$1)+((O27-$I$10)^2/$I$7)) -> #N/A | Q27: =+$I$13+$I$12*O27 -> #VALUE! | R27: =+$I$13+$I$12*O27-P27 -> #VALUE! | S27: =+$I$13+$I$12*O27+P27 -> #VALUE! | T27: =10^Q27 -> #VALUE! | U27: =10^O27 -> #NUM! | V27: =10^R27 -> #VALUE! | W27: =10^$O27 -> #NUM! | X27: =10^S27 -> #VALUE! | Y27: =10^$O27 -> #NUM! | Z27: 3 | AA27: 72.39896 | AB27: -3.7728516 | AC27: -0.82074485
O28: =LOG($I$19+($I$20-$I$19)*(ROW()-2)/100) -> #NUM! | P28: =SQRT(2*$I$16*$K$24)*SQRT((1/$I$1)+((O28-$I$10)^2/$I$7)) -> #N/A | Q28: =+$I$13+$I$12*O28 -> #VALUE! | R28: =+$I$13+$I$12*O28-P28 -> #VALUE! | S28: =+$I$13+$I$12*O28+P28 -> #VALUE! | T28: =10^Q28 -> #VALUE! | U28: =10^O28 -> #NUM! | V28: =10^R28 -> #VALUE! | W28: =10^$O28 -> #NUM! | X28: =10^S28 -> #VALUE! | Y28: =10^$O28 -> #NUM! | Z28: 4 | AA28: 83.96799 | AB28: 3.5389413 | AC28: 0.76986009
H29: N = | I29: =10^$I$13 -> #VALUE! | J29: * | K29: S^ | L29: =+I12 -> #NUM! | O29: =LOG($I$19+($I$20-$I$19)*(ROW()-2)/100) -> #NUM! | P29: =SQRT(2*$I$16*$K$24)*SQRT((1/$I$1)+((O29-$I$10)^2/$I$7)) -> #N/A | Q29: =+$I$13+$I$12*O29 -> #VALUE! | R29: =+$I$13+$I$12*O29-P29 -> #VALUE! | S29: =+$I$13+$I$12*O29+P29 -> #VALUE! | T29: =10^Q29 -> #VALUE! | U29: =10^O29 -> #NUM! | V29: =10^R29 -> #VALUE! | W29: =10^$O29 -> #NUM! | X29: =10^S29 -> #VALUE! | Y29: =10^$O29 -> #NUM! | Z29: 5 | AA29: 80.249514 | AB29: -3.0746271 | AC29: -0.66885335
O30: =LOG($I$19+($I$20-$I$19)*(ROW()-2)/100) -> #NUM! | P30: =SQRT(2*$I$16*$K$24)*SQRT((1/$I$1)+((O30-$I$10)^2/$I$7)) -> #N/A | Q30: =+$I$13+$I$12*O30 -> #VALUE! | R30: =+$I$13+$I$12*O30-P30 -> #VALUE! | S30: =+$I$13+$I$12*O30+P30 -> #VALUE! | T30: =10^Q30 -> #VALUE! | U30: =10^O30 -> #NUM! | V30: =10^R30 -> #VALUE! | W30: =10^$O30 -> #NUM! | X30: =10^S30 -> #VALUE! | Y30: =10^$O30 -> #NUM! | Z30: 6 | AA30: 78.183475 | AB30: -4.5407035 | AC30: -0.9877831
O31: =LOG($I$19+($I$20-$I$19)*(ROW()-2)/100) -> #NUM! | P31: =SQRT(2*$I$16*$K$24)*SQRT((1/$I$1)+((O31-$I$10)^2/$I$7)) -> #N/A | Q31: =+$I$13+$I$12*O31 -> #VALUE! | R31: =+$I$13+$I$12*O31-P31 -> #VALUE! | S31: =+$I$13+$I$12*O31+P31 -> #VALUE! | T31: =10^Q31 -> #VALUE! | U31: =10^O31 -> #NUM! | V31: =10^R31 -> #VALUE! | W31: =10^$O31 -> #NUM! | X31: =10^S31 -> #VALUE! | Y31: =10^$O31 -> #NUM! | Z31: 7 | AA31: 58.292049 | AB31: 5.5384636 | AC31: 1.2048355
H32: N | I32: TVALUE | J32: FVALUE | L32: 0.95 | O32: =LOG($I$19+($I$20-$I$19)*(ROW()-2)/100) -> #NUM! | P32: =SQRT(2*$I$16*$K$24)*SQRT((1/$I$1)+((O32-$I$10)^2/$I$7)) -> #N/A | Q32: =+$I$13+$I$12*O32 -> #VALUE! | R32: =+$I$13+$I$12*O32-P32 -> #VALUE! | S32: =+$I$13+$I$12*O32+P32 -> #VALUE! | T32: =10^Q32 -> #VALUE! | U32: =10^O32 -> #NUM! | V32: =10^R32 -> #VALUE! | W32: =10^$O32 -> #NUM! | X32: =10^S32 -> #VALUE! | Y32: =10^$O32 -> #NUM! | Z32: 8 | AA32: 76.17686 | AB32: -1.661665 | AC32: -0.36147805
H33: 1 | I33: 12.706 | J33: 199.5 | O33: =LOG($I$19+($I$20-$I$19)*(ROW()-2)/100) -> #NUM! | P33: =SQRT(2*$I$16*$K$24)*SQRT((1/$I$1)+((O33-$I$10)^2/$I$7)) -> #N/A | Q33: =+$I$13+$I$12*O33 -> #VALUE! | R33: =+$I$13+$I$12*O33-P33 -> #VALUE! | S33: =+$I$13+$I$12*O33+P33 -> #VALUE! | T33: =10^Q33 -> #VALUE! | U33: =10^O33 -> #NUM! | V33: =10^R33 -> #VALUE! | W33: =10^$O33 -> #NUM! | X33: =10^S33 -> #VALUE! | Y33: =10^$O33 -> #NUM! | Z33: 9 | AA33: 66.378327 | AB33: 1.0806765 | AC33: 0.23508999
H34: 2 | I34: 4.303 | J34: 19 | O34: =LOG($I$19+($I$20-$I$19)*(ROW()-2)/100) -> #NUM! | P34: =SQRT(2*$I$16*$K$24)*SQRT((1/$I$1)+((O34-$I$10)^2/$I$7)) -> #N/A | Q34: =+$I$13+$I$12*O34 -> #VALUE! | R34: =+$I$13+$I$12*O34-P34 -> #VALUE! | S34: =+$I$13+$I$12*O34+P34 -> #VALUE! | T34: =10^Q34 -> #VALUE! | U34: =10^O34 -> #NUM! | V34: =10^R34 -> #VALUE! | W34: =10^$O34 -> #NUM! | X34: =10^S34 -> #VALUE! | Y34: =10^$O34 -> #NUM! | Z34: 10 | AA34: 71.750028 | AB34: -5.7050796 | AC34: -1.2410811
H35: 3 | I35: 3.182 | J35: 9.55 | O35: =LOG($I$19+($I$20-$I$19)*(ROW()-2)/100) -> #NUM! | P35: =SQRT(2*$I$16*$K$24)*SQRT((1/$I$1)+((O35-$I$10)^2/$I$7)) -> #N/A | Q35: =+$I$13+$I$12*O35 -> #VALUE! | R35: =+$I$13+$I$12*O35-P35 -> #VALUE! | S35: =+$I$13+$I$12*O35+P35 -> #VALUE! | T35: =10^Q35 -> #VALUE! | U35: =10^O35 -> #NUM! | V35: =10^R35 -> #VALUE! | W35: =10^$O35 -> #NUM! | X35: =10^S35 -> #VALUE! | Y35: =10^$O35 -> #NUM! | Z35: 11 | AA35: 1.8219741 | AB35: -0.023572384 | AC35: -2.1105589
H36: 4 | I36: 2.7764 | J36: 6.94 | O36: =LOG($I$19+($I$20-$I$19)*(ROW()-2)/100) -> #NUM! | P36: =SQRT(2*$I$16*$K$24)*SQRT((1/$I$1)+((O36-$I$10)^2/$I$7)) -> #N/A | Q36: =+$I$13+$I$12*O36 -> #VALUE! | R36: =+$I$13+$I$12*O36-P36 -> #VALUE! | S36: =+$I$13+$I$12*O36+P36 -> #VALUE! | T36: =10^Q36 -> #VALUE! | U36: =10^O36 -> #NUM! | V36: =10^R36 -> #VALUE! | W36: =10^$O36 -> #NUM! | X36: =10^S36 -> #VALUE! | Y36: =10^$O36 -> #NUM! | Z36: 12 | AA36: 1.7418459 | AB36: 0.0051980261 | AC36: 0.46540648
H37: 5 | I37: 2.5706 | J37: 5.79 | O37: =LOG($I$19+($I$20-$I$19)*(ROW()-2)/100) -> #NUM! | P37: =SQRT(2*$I$16*$K$24)*SQRT((1/$I$1)+((O37-$I$10)^2/$I$7)) -> #N/A | Q37: =+$I$13+$I$12*O37 -> #VALUE! | R37: =+$I$13+$I$12*O37-P37 -> #VALUE! | S37: =+$I$13+$I$12*O37+P37 -> #VALUE! | T37: =10^Q37 -> #VALUE! | U37: =10^O37 -> #NUM! | V37: =10^R37 -> #VALUE! | W37: =10^$O37 -> #NUM! | X37: =10^S37 -> #VALUE! | Y37: =10^$O37 -> #NUM!
H38: 6 | I38: 2.4469 | J38: 5.14 | O38: =LOG($I$19+($I$20-$I$19)*(ROW()-2)/100) -> #NUM! | P38: =SQRT(2*$I$16*$K$24)*SQRT((1/$I$1)+((O38-$I$10)^2/$I$7)) -> #N/A | Q38: =+$I$13+$I$12*O38 -> #VALUE! | R38: =+$I$13+$I$12*O38-P38 -> #VALUE! | S38: =+$I$13+$I$12*O38+P38 -> #VALUE! | T38: =10^Q38 -> #VALUE! | U38: =10^O38 -> #NUM! | V38: =10^R38 -> #VALUE! | W38: =10^$O38 -> #NUM! | X38: =10^S38 -> #VALUE! | Y38: =10^$O38 -> #NUM!
H39: 7 | I39: 2.3646 | J39: 4.74 | O39: =LOG($I$19+($I$20-$I$19)*(ROW()-2)/100) -> #NUM! | P39: =SQRT(2*$I$16*$K$24)*SQRT((1/$I$1)+((O39-$I$10)^2/$I$7)) -> #N/A | Q39: =+$I$13+$I$12*O39 -> #VALUE! | R39: =+$I$13+$I$12*O39-P39 -> #VALUE! | S39: =+$I$13+$I$12*O39+P39 -> #VALUE! | T39: =10^Q39 -> #VALUE! | U39: =10^O39 -> #NUM! | V39: =10^R39 -> #VALUE! | W39: =10^$O39 -> #NUM! | X39: =10^S39 -> #VALUE! | Y39: =10^$O39 -> #NUM!
H40: 8 | I40: 2.306 | J40: 4.46 | O40: =LOG($I$19+($I$20-$I$19)*(ROW()-2)/100) -> #NUM! | P40: =SQRT(2*$I$16*$K$24)*SQRT((1/$I$1)+((O40-$I$10)^2/$I$7)) -> #N/A | Q40: =+$I$13+$I$12*O40 -> #VALUE! | R40: =+$I$13+$I$12*O40-P40 -> #VALUE! | S40: =+$I$13+$I$12*O40+P40 -> #VALUE! | T40: =10^Q40 -> #VALUE! | U40: =10^O40 -> #NUM! | V40: =10^R40 -> #VALUE! | W40: =10^$O40 -> #NUM! | X40: =10^S40 -> #VALUE! | Y40: =10^$O40 -> #NUM!
...

Sheet ASTM E739 stat (Max Stress)
A1: SN Points | C1: X | D1: Y | E1: X^2 | F1: Y^2 | G1: X*Y | H1: N | I1: =COUNT(C:C) -> 0 | M1: X | N1: YHAT | O1: X | P1: Xconfi | Q1: Yavg | R1: Y1 | S1: Y2 | T1: SN-line | V1: Lower conf | X1: Upper Conf | Z1: SUMMARY OUTPUT
A2: =+Results!F23 -> 0 | B2: =+Results!E23 -> Statisk | C2: =LOG(A2) -> #NUM! | D2: =LOG(B2) -> #VALUE! | E2: =+C2^2 -> #NUM! | F2: =+D2^2 -> #VALUE! | G2: =+C2*D2 -> #NUM! | H2: SUMX | I2: =SUM(C:C) -> #NUM! | M2: =+C2 -> #NUM! | N2: =+$I$13+$I$12*M2 -> #VALUE! | O2: =LOG($I$19+($I$20-$I$19)*(ROW()-2)/100) -> #NUM! | P2: =SQRT(2*$I$16*$K$24)*SQRT((1/$I$1)+((O2-$I$10)^2/$I$7)) -> #N/A | Q2: =+$I$13+$I$12*O2 -> #VALUE! | R2: =+$I$13+$I$12*O2-P2 -> #VALUE! | S2: =+$I$13+$I$12*O2+P2 -> #VALUE! | T2: =10^Q2 -> #VALUE! | U2: =10^$O2 -> #NUM! | V2: =10^R2 -> #VALUE! | W2: =10^$O2 -> #NUM! | X2: =10^S2 -> #VALUE! | Y2: =10^$O2 -> #NUM!
A3: =+Results!F24 -> 0 | B3: =+Results!E24 -> Statisk | C3: =LOG(A3) -> #NUM! | D3: =LOG(B3) -> #VALUE! | E3: =+C3^2 -> #NUM! | F3: =+D3^2 -> #VALUE! | G3: =+C3*D3 -> #NUM! | H3: SUMY | I3: =SUM(D:D) -> #VALUE! | M3: =+C3 -> #NUM! | N3: =+$I$13+$I$12*M3 -> #VALUE! | O3: =LOG($I$19+($I$20-$I$19)*(ROW()-2)/100) -> #NUM! | P3: =SQRT(2*$I$16*$K$24)*SQRT((1/$I$1)+((O3-$I$10)^2/$I$7)) -> #N/A | Q3: =+$I$13+$I$12*O3 -> #VALUE! | R3: =+$I$13+$I$12*O3-P3 -> #VALUE! | S3: =+$I$13+$I$12*O3+P3 -> #VALUE! | T3: =10^Q3 -> #VALUE! | U3: =10^O3 -> #NUM! | V3: =10^R3 -> #VALUE! | W3: =10^$O3 -> #NUM! | X3: =10^S3 -> #VALUE! | Y3: =10^$O3 -> #NUM! | Z3: Regression Statistics
A4: =+Results!F25 -> 0 | B4: =+Results!E25 -> Statisk | C4: =LOG(A4) -> #NUM! | D4: =LOG(B4) -> #VALUE! | E4: =+C4^2 -> #NUM! | F4: =+D4^2 -> #VALUE! | G4: =+C4*D4 -> #NUM! | H4: SUMXX | I4: =SUM(E:E) -> #NUM! | M4: =+C4 -> #NUM! | N4: =+$I$13+$I$12*M4 -> #VALUE! | O4: =LOG($I$19+($I$20-$I$19)*(ROW()-2)/100) -> #NUM! | P4: =SQRT(2*$I$16*$K$24)*SQRT((1/$I$1)+((O4-$I$10)^2/$I$7)) -> #N/A | Q4: =+$I$13+$I$12*O4 -> #VALUE! | R4: =+$I$13+$I$12*O4-P4 -> #VALUE! | S4: =+$I$13+$I$12*O4+P4 -> #VALUE! | T4: =10^Q4 -> #VALUE! | U4: =10^O4 -> #NUM! | V4: =10^R4 -> #VALUE! | W4: =10^$O4 -> #NUM! | X4: =10^S4 -> #VALUE! | Y4: =10^$O4 -> #NUM! | Z4: Multiple R | AA4: 0.88244047
A5: =+Results!F26 -> 0 | B5: =+Results!E26 -> 0 | C5: =LOG(A5) -> #NUM! | D5: =LOG(B5) -> #NUM! | E5: =+C5^2 -> #NUM! | F5: =+D5^2 -> #NUM! | G5: =+C5*D5 -> #NUM! | H5: SUMYY | I5: =SUM(F:F) -> #VALUE! | M5: =+C5 -> #NUM! | N5: =+$I$13+$I$12*M5 -> #VALUE! | O5: =LOG($I$19+($I$20-$I$19)*(ROW()-2)/100) -> #NUM! | P5: =SQRT(2*$I$16*$K$24)*SQRT((1/$I$1)+((O5-$I$10)^2/$I$7)) -> #N/A | Q5: =+$I$13+$I$12*O5 -> #VALUE! | R5: =+$I$13+$I$12*O5-P5 -> #VALUE! | S5: =+$I$13+$I$12*O5+P5 -> #VALUE! | T5: =10^Q5 -> #VALUE! | U5: =10^O5 -> #NUM! | V5: =10^R5 -> #VALUE! | W5: =10^$O5 -> #NUM! | X5: =10^S5 -> #VALUE! | Y5: =10^$O5 -> #NUM! | Z5: R Square | AA5: 0.77870118
H6: SUMXY | I6: =SUM(G:G) -> #NUM! | M6: =+C6 -> 0 | N6: =+$I$13+$I$12*M6 -> #VALUE! | O6: =LOG($I$19+($I$20-$I$19)*(ROW()-2)/100) -> #NUM! | P6: =SQRT(2*$I$16*$K$24)*SQRT((1/$I$1)+((O6-$I$10)^2/$I$7)) -> #N/A | Q6: =+$I$13+$I$12*O6 -> #VALUE! | R6: =+$I$13+$I$12*O6-P6 -> #VALUE! | S6: =+$I$13+$I$12*O6+P6 -> #VALUE! | T6: =10^Q6 -> #VALUE! | U6: =10^O6 -> #NUM! | V6: =10^R6 -> #VALUE! | W6: =10^$O6 -> #NUM! | X6: =10^S6 -> #VALUE! | Y6: =10^$O6 -> #NUM! | Z6: Adjusted R Square | AA6: 0.75103883
H7: SAKX | I7: =+I4-I2^2/$I$1 -> #NUM! | M7: =+C7 -> 0 | N7: =+$I$13+$I$12*M7 -> #VALUE! | O7: =LOG($I$19+($I$20-$I$19)*(ROW()-2)/100) -> #NUM! | P7: =SQRT(2*$I$16*$K$24)*SQRT((1/$I$1)+((O7-$I$10)^2/$I$7)) -> #N/A | Q7: =+$I$13+$I$12*O7 -> #VALUE! | R7: =+$I$13+$I$12*O7-P7 -> #VALUE! | S7: =+$I$13+$I$12*O7+P7 -> #VALUE! | T7: =10^Q7 -> #VALUE! | U7: =10^O7 -> #NUM! | V7: =10^R7 -> #VALUE! | W7: =10^$O7 -> #NUM! | X7: =10^S7 -> #VALUE! | Y7: =10^$O7 -> #NUM! | Z7: Standard Error | AA7: 4.8757094
H8: SAKY (SAKtotal) | I8: =+I5-I3^2/$I$1 -> #VALUE! | M8: =+C8 -> 0 | N8: =+$I$13+$I$12*M8 -> #VALUE! | O8: =LOG($I$19+($I$20-$I$19)*(ROW()-2)/100) -> #NUM! | P8: =SQRT(2*$I$16*$K$24)*SQRT((1/$I$1)+((O8-$I$10)^2/$I$7)) -> #N/A | Q8: =+$I$13+$I$12*O8 -> #VALUE! | R8: =+$I$13+$I$12*O8-P8 -> #VALUE! | S8: =+$I$13+$I$12*O8+P8 -> #VALUE! | T8: =10^Q8 -> #VALUE! | U8: =10^O8 -> #NUM! | V8: =10^R8 -> #VALUE! | W8: =10^$O8 -> #NUM! | X8: =10^S8 -> #VALUE! | Y8: =10^$O8 -> #NUM! | Z8: Observations | AA8: 10
H9: SAPXY | I9: =+I6-I2*I3/$I$1 -> #NUM! | M9: =+C9 -> 0 | N9: =+$I$13+$I$12*M9 -> #VALUE! | O9: =LOG($I$19+($I$20-$I$19)*(ROW()-2)/100) -> #NUM! | P9: =SQRT(2*$I$16*$K$24)*SQRT((1/$I$1)+((O9-$I$10)^2/$I$7)) -> #N/A | Q9: =+$I$13+$I$12*O9 -> #VALUE! | R9: =+$I$13+$I$12*O9-P9 -> #VALUE! | S9: =+$I$13+$I$12*O9+P9 -> #VALUE! | T9: =10^Q9 -> #VALUE! | U9: =10^O9 -> #NUM! | V9: =10^R9 -> #VALUE! | W9: =10^$O9 -> #NUM! | X9: =10^S9 -> #VALUE! | Y9: =10^$O9 -> #NUM!
H10: XMEAN | I10: =+I2/$I$1 -> #NUM! | M10: =+C10 -> 0 | N10: =+$I$13+$I$12*M10 -> #VALUE! | O10: =LOG($I$19+($I$20-$I$19)*(ROW()-2)/100) -> #NUM! | P10: =SQRT(2*$I$16*$K$24)*SQRT((1/$I$1)+((O10-$I$10)^2/$I$7)) -> #N/A | Q10: =+$I$13+$I$12*O10 -> #VALUE! | R10: =+$I$13+$I$12*O10-P10 -> #VALUE! | S10: =+$I$13+$I$12*O10+P10 -> #VALUE! | T10: =10^Q10 -> #VALUE! | U10: =10^O10 -> #NUM! | V10: =10^R10 -> #VALUE! | W10: =10^$O10 -> #NUM! | X10: =10^S10 -> #VALUE! | Y10: =10^$O10 -> #NUM! | Z10: ANOVA
